Workbook

Sheet 1
A1: 心血管系统类立项指南项目对应及拟定情况（征求意见稿）
A2: 心血管系统类立项指南项目 | V2: 现行项目
A3: 序号 | B3: 项目代码 | C3: 项目名称 | D3: 归集口径 | E3: 服务产出 | F3: 价格构成 | G3: 计价单位 | H3: 计价说明 | I3: 省三甲价格 | J3: 省三甲以下价格 | K3: 平移价格 (市级) | L3: 平移价格 (县级) | M3: 平移价格 (基层) | N3: 拟定价格 (市级) | O3: 拟定价格 (县级) | P3: 拟定价格 (基层) | Q3: 医保 属性 | R3: 医保限定支付范围 | S3: 个人先行自付比例 | T3: 调整情况 | U3: 备注 | V3: 国家结算编码 | X3: 项目编码 | Y3: 项目名称 | Z3: 项目内涵 | AA3: 除外内容 | AB3: 计价单位 | AC3: 说明 | AD3: 价格 (市级) | AE3: 价格 (县级) | AF3: 价格 (基层) | AG3: 心脏使用胸腔镜、心脏及血管系统手术体外循环心脏不停跳心内直视手术的费用摊到相应手术中测算
A4: 1 | B4: 012408000020000 | C4: 心电监测费 | D4: 检查费 | E4: 实时监测患者心率、心律、心电波形等，必要时监测呼吸频率、呼吸波形、血压、血氧饱和度等参数。 | F4: 所定价格涵盖皮肤清洁、安放电极、连接设备、设定参数、实时监测等步骤所需的人力资源、设备运转成本与基本物质资源消耗。 | G4: 小时 | I4: 10 | J4: 10 | K4: 9.1929733 | L4: 8.762582 | M4: 7.4603179 | N4: 9.5 | O4: 9 | P4: 8 | Q4: 医保 | T4: 平移取整 | U4: 映射项目全部纳入价格构成，按照总金额除以最大量测算平移价格，同质化项目缩小价差 | V4: 003107010220000-310701022 | W4: 1 | X4: 310701022 | Y4: 心电监测 | Z4: 含无创血压监测 | AB4: 小时 | AD4: 4.5 | AE4: 4.1 | AF4: 3.4
V5: 003107010270000-310701027 | W5: 2 | X5: 310701027 | Y5: 指脉氧监测 | AB5: 小时 | AD5: 4.5 | AE5: 4.1 | AF5: 3.4
V6: 003107010280000-310701028 | W6: 3 | X6: 310701028 | Y6: 血氧饱和度监测 | AB6: 小时 | AD6: 4.5 | AE6: 4.1 | AF6: 3.4
V7: 003107010290000-310701033 | W7: 4 | X7: 310701033 | Y7: 经皮肢体氧分压测定 | Z7: 患者仰卧，连接氧分压测定仪于肢体不同部位，开启氧分压测定仪，分别检测肢体不同部位的氧分压，记录并报告。 | AB7: 次 | AD7: 70 | AE7: 70 | AF7: 59.5
A8: 分项 | B8: 012408000020100 | C8: 心电监测费-遥测心电监测（扩展） | D8: 检查费 | G8: 小时 | H8: 封顶每日不超过50元。 | I8: 10 | J8: 10 | K8: 8.8263158 | L8: 8.8461538 | M8: 6.95625 | N8: 9.5 | O8: 9 | P8: 8 | Q8: 医保 | U8: 整合项目，两个项目价格合计测算。 扩展项按主项价格执行 | V8: 003107010090000-310701009 | W8: 5 | X8: 310701009 | Y8: 心电监测电话传输 | Z8: 含电池、电极费用 | AB8: 日 | AD8: 57.5 | AE8: 50 | AF8: 42.5
V9: 003107010080000-310701008 | W9: 6 | X9: 310701008 | Y9: 遥测心电监护 | AB9: 小时 | AD9: 5.8 | AE9: 5 | AF9: 4.3
A10: 2 | B10: 012408000030000 | C10: 常规心电图检查费 | D10: 检查费 | E10: 通过心电图机体表采集十二导联及以下心电数据。 | F10: 所定价格涵盖皮肤清洁、安放电极、连接设备、采集信号、数据分析、出具报告等步骤所需的人力资源、设备运转成本与基本物质资源消耗。 | G10: 次 | H10: 含十二导联。 | I10: 29 | J10: 26 | K10: 26.963502 | L10: 25.252767 | M10: 21.527537 | N10: 27 | O10: 25 | P10: 23 | Q10: 医保 | T10: 平移取整 | U10: 加权平移后取整，同质化高的项目提高基层价格缩小价差 | V10: 003107010010000-310701001 | W10: 7 | X10: 310701001 | Y10: 常规心电图检查 | Z10: 含单通道、三通道、常规导联 | AB10: 次 | AC10: 附加导联加收20%；十二通道、床边心电图加收100% | AD10: 11.5 | AE10: 10 | AF10: 8.5
V11: 003107010010002-31070100102 | W11: 8 | X11: 31070100102 | Y11: 常规心电图检查（十二通道加收） | AB11: 次 | AC11: 十二通道加收 | AD11: 11.5 | AE11: 10 | AF11: 8.5
V12: 003107010010003-31070100103 | W12: 9 | X12: 31070100103 | Y12: 常规心电图检查（床边） | AB12: 次 | AC12: 床边心电图 | AD12: 23 | AE12: 20 | AF12: 17
V13: 003107010050000-310701005 | W13: 10 | X13: 310701005 | Y13: 标测心电图 | Z13: 含电极费用 | AB13: 次
V14: 003107010060000-310701006 | W14: 11 | X14: 310701006 | Y14: 体表窦房结心电图 | AB14: 次
V15: 003107010020000-310701002 | W15: 12 | X15: 310701002 | Y15: 食管内心电图 | AA15: 一次性导管 | AB15: 次 | AD15: 57.5 | AE15: 50 | AF15: 42.5
A16: 分项 | B16: 012408000030001 | C16: 常规心电图检查费十二导联以上（加收） | D16: 检查费 | G16: 次 | I16: 2 | J16: 2 | K16: 2.3 | L16: 2 | M16: 1.7 | N16: 2 | O16: 1.9 | P16: 1.8 | Q16: 医保 | U16: 平移后市按不超过省级定价，同质化项目缩小价差 | V16: 003107010010001-31070100101 | W16: 13 | X16: 31070100101 | Y16: 常规心电图检查（附加导联加收） | AB16: 次 | AC16: 附加导联加收 | AD16: 2.3 | AE16: 2 | AF16: 1.7
A17: 分项 | B17: 012408000030011 | C17: 常规心电图检查费-心脏晚电位检查（加收） | D17: 检查费 | G17: 次 | I17: 15 | J17: 14 | K17: 42 | L17: 35 | M17: 28 | N17: 15 | O17: 14 | P17: 13 | Q17: 医保 | U17: 按不超过省级拟定 | V17: 003107010150000-310701015 | W17: 14 | X17: 310701015 | Y17: 心室晚电位 | Z17: 含电极费用 | AB17: 次 | AD17: 69 | AE17: 60 | AF17: 51
V18: 003107010160000-310701016 | W18: 15 | X18: 310701016 | Y18: 心房晚电位 | Z18: 含电极费用 | AB18: 次 | AD18: 69 | AE18: 60 | AF18: 51
A19: 分项 | B19: 012408000030100 | C19: 常规心电图检查费-心电向量图（扩展） | D19: 检查费 | G19: 次 | I19: 29 | J19: 26 | K19: 34.5 | L19: 30 | M19: 25.5 | N19: 27 | O19: 25 | P19: 23 | Q19: 医保 | U19: 扩展项按主项价格执行 | V19: 003107010120000-310701012 | W19: 16 | X19: 310701012 | Y19: 心电向量图 | AB19: 次 | AD19: 34.5 | AE19: 30 | AF19: 25.5
A20: 分项 | B20: 012408000031100 | C20: 常规心电图检查费-频谱心电图（扩展） | D20: 检查费 | G20: 次 | I20: 29 | J20: 26 | K20: 46 | L20: 40 | M20: 34 | N20: 27 | O20: 25 | P20: 23 | Q20: 医保 | U20: 扩展项按主项价格执行 | V20: 003107010040000-310701004 | W20: 17 | X20: 310701004 | Y20: 频谱心电图 | Z20: 含电极费用 | AB20: 次 | AD20: 46 | AE20: 40 | AF20: 34
A21: 3 | B21: 012408000040000 | C21: 心率变异性分析检查费 | D21: 检查费 | E21: 通过连续记录心电图数据分析心率变化情况。 | F21: 所定价格涵盖皮肤清洁、安放电极、连接设备、采集信号、数据分析、出具报告等步骤所需的人力资源、设备运转成本与基本物质资源消耗。 | G21: 次 | I21: 80 | J21: 72 | K21: 92.002816 | L21: 80 | M21: 68.065073 | N21: 80 | O21: 72 | P21: 65 | Q21: 医保 | T21: 理顺，降低 | U21: 平移后按不超过省级价格下调，同质化高的项目持平省级价格 | V21: 003107010180000-310701018 | W21: 18 | X21: 310701018 | Y21: 心率变异性分析 | Z21: 包括短程或24小时 | AB21: 次 | AC21: 超过24小时基层加收12.8元，县级医院加收15元，市级加收17.3元 | AD21: 92 | AE21: 80 | AF21: 68
V22: 003107010180001-31070101801 | W22: 19 | X22: 31070101801 | Y22: 心率变异性分析（超过24小时加收） | AB22: 次 | AC22: 超过24小时加收 | AD22: 17.3 | AE22: 15 | AF22: 12.8
A23: 4 | B23: 012408000050000 | C23: 心电图负荷检查费 | D23: 检查费 | E23: 通过各类运动负荷或药物诱导试验等方式，对比监测心电和血压变化，协助诊断疾病。 | F23: 所定价格涵盖皮肤清洁、安放电极、记录静息心电图、增加负荷、监测心电和血压变化、数据分析、出具报告等步骤所需的人力资源、设备运转成本与基本物质资源消耗。 | G23: 次 | I23: 107 | J23: 96 | K23: 114.16034 | L23: 91.174863 | N23: 105 | O23: 95 | P23: 80 | Q23: 医保 | T23: 理顺，降低 | U23: 平移后市按不超过省级定价 | V23: 003107010100000-310701010 | W23: 20 | X23: 310701010 | Y23: 心电图踏车负荷试验 | Z23: 含电极费用、指平板运动试验 | AB23: 次 | AC23: 二阶梯基层每次只收25.5元，县级医院每次只收30元，市级医院每次只收34.5元 | AD23: 149.5 | AE23: 130 | AF23: 110.5
V24: 003107010100100-31070101001 | W24: 21 | X24: 31070101001 | Y24: 心电图踏车负荷试验（二阶梯） | AB24: 次 | AC24: 二阶梯 | AD24: 34.5 | AE24: 30 | AF24: 25.5
V25: 003107010110000-310701011 | W25: 22 | X25: 310701011 | Y25: 心电图药物负荷试验 | Z25: 含电极费用 | AB25: 次 | AD25: 51.8 | AE25: 45 | AF25: 38.3
A26: 5 | B26: 012408000060000 | C26: 动态心电图检查费 | D26: 检查费 | E26: 通过获取连续的心电图监测数据，协助诊断疾病。 | F26: 所定价格涵盖皮肤清洁、安放电极、连接设备、采集信号、数据分析、出具报告等步骤所需的人力资源、设备运转成本与基本物质资源消耗。 | G26: 日 | H26: 单次检查收取不超过3天，个别患者确有必要的最多可收取5天费用。 | I26: 150 | J26: 135 | K26: 172.5 | L26: 150.00539 | M26: 127.5 | N26: 150 | O26: 135 | P26: 120 | Q26: 医保 | T26: 理顺，降低 | U26: 平移后市按不超过省级定价，同质化高的项目持平省级价格，基层调低理顺比价 | V26: 003107010030000-310701003 | W26: 23 | X26: 310701003 | Y26: 动态心电图 | Z26: 含磁带、电池费用；含实时监测预警 | AB26: 次 | AD26: 172.5 | AE26: 150 | AF26: 127.5
V27: 003107010070000-310701007 | W27: 24 | X27: 310701007 | Y27: 心电事件记录 | Z27: 含磁带、电池费用 | AB27: 次 | AD27: 11.5 | AE27: 10 | AF27: 8.5
A28: 6 | B28: 013107000010000 | C28: 经食管心脏调搏费 | D28: 治疗费 | E28: 通过食管电极对左心房或邻近心脏组织进行电刺激，进行电生理评估或终止室上速。 | F28: 所定价格涵盖皮肤清洁、安置导管和电极、连接设备、电刺激、采集信号、数据分析、出具报告等步骤所需的人力资源、设备运转成本与基本物质资源消耗。 | G28: 次 | I28: 132 | J28: 119 | K28: 138 | L28: 120 | M28: 102 | N28: 132 | O28: 119 | P28: 102 | Q28: 医保 | T28: 理顺，降低 | U28: 平移后按不超过省级价格下调，同质化高的项目持平省级价格 | V28: 003107020150000-310702015 | W28: 25 | X28: 310702015 | Y28: 经食管心脏调搏术 | Z28: 指超速抑制心动过速治疗 | AB28: 次 | AC28: 使用大C臂数字减影X光机加收50% | AD28: 138 | AE28: 120 | AF28: 102
A29: 7 | B29: 013107000020000 | C29: 经食管心脏起搏费 | D29: 治疗费 | E29: 通过食管电极对左心房或邻近心脏组织进行电刺激，进行临时起搏。 | F29: 所定价格涵盖皮肤清洁、安置导管和电极、连接设备、电刺激、调整起搏参数等步骤所需的人力资源、设备运转成本与基本物质资源消耗。 | G29: 次 | I29: 132 | J29: 119 | K29: 138 | L29: 120 | M29: 102 | N29: 132 | O29: 119 | P29: 102 | Q29: 医保 | T29: 理顺，降低 | U29: 平移后按不超过省级价格下调。同质化高的项目持平省级价格 | V29: 003107020140000-310702014 | W29: 26 | X29: 310702014 | Y29: 经食管心脏起搏术 | AB29: 次 | AC29: 使用大C臂数字减影X光机加收50% | AD29: 138 | AE29: 120 | AF29: 102
A30: 8 | B30: 012408000080000 | C30: 心腔三维标测费 | D30: 检查费 | E30: 通过动脉、静脉或心包置入三维标测电极，利用三维重建技术获取心腔三维结构。 | F30: 所定价格涵盖应用各种三维标测技术构建心腔三维图像所需的人力资源与基本物质资源消耗。 | G30: 次 | I30: 700 | J30: 630 | N30: 665 | O30: 600 | P30: 510 | Q30: 非医保 | T30: 新增 | U30: 新增项目，参照检查类项目比价关系，暂按省级95%拟定 | W30: 27
A31: 9 | B31: 012408000090000 | C31: 直立倾斜检查费 | D31: 检查费 | E31: 通过改变体位，监测患者心率、血压和神智的变化，协助诊断疾病。 | F31: 所定价格涵盖皮肤清洁、安放电极、患者固定、改变体位、监测心电和血压变化、观察患者表现、数据分析、出具报告等步骤所需的人力资源与基本物质资源消耗。 | G31: 次 | H31: 不与“心电监测费”同时收取。 | I31: 160 | J31: 144 | K31: 184 | L31: 160 | M31: 136 | N31: 160 | O31: 144 | P31: 125 | Q31: 医保 | T31: 理顺，降低 | U31: 平移后按不超过省级价格下调，同质化高的项目持平省级价格 | V31: 003107010170000-310701017 | W31: 28 | X31: 310701017 | Y31: 倾斜试验 | AB31: 次 | AD31: 184 | AE31: 160 | AF31: 136
A32: 10 | B32: 012408000100000 | C32: 6分钟步行检查费 | D32: 检查费 | E32: 通过步行速度评估患者心脏功能及运动耐力。 | F32: 所定价格涵盖设备准备、测试过程中生命体征监测、撤除设备、出具报告等步骤所需的人力资源和基本物质资源消耗。 | G32: 次 | H32: 不与“心电监测费”同时收取。 | I32: 40 | J32: 36 | K32: 36 | L32: 32 | M32: 27 | N32: 36 | O32: 32 | P32: 27 | Q32: 非医保 | T32: 平移 | U32: 平移 | V32: 003402000070000-340200046 | W32: 29 | X32: 340200046 | Y32: 6分钟步行测试 | Z32: 采用标准化方法，对患者进行时间限定的步行距离、步行速度以及不适症状的检查。评价心肺疾病患者对治疗的反应情况；评价患者整体的功能状况（监测和记录患者在这6分钟步行范围内心率、血压、血氧、步行距离、费力指数等）。广泛适用于肺动脉高压、心力衰竭、COPD、间质性肺疾病、肺移植、肺减容术、肺切除术等病种评估。 | AB32: 次 | AD32: 36 | AE32: 32 | AF32: 27
A33: 11 | B33: 012408000110000 | C33: 无创动态血压监测费 | D33: 检查费 | E33: 通过无创的方式连续监测患者血压，获取24小时中多次血压监测数据。 | F33: 所定价格涵盖固定袖带、动态监测血压、采集数据、撤除袖带、分析、出具报告等步骤所需的人力资源与基本物质资源消耗。 | G33: 日 | I33: 200 | J33: 180 | K33: 257.24094 | L33: 179.93885 | M33: 195.92785 | N33: 200 | O33: 180 | P33: 165 | Q33: 医保 | T33: 理顺，降低 | U33: 市级每人次约监测22.4小时/天。县级每人次约监测18小时/天。基层每人次约监测23小时/天。平移后按不超过省级拟定（同质化高的检查项目，持平省级定价） | V33: 003107010210000-310701021 | W33: 30 | X33: 310701021 | Y33: 动态血压监测 | Z33: 含电池费用；包括运动血压监测 | AB33: 小时 | AD33: 11.5 | AE33: 10 | AF33: 8.5
V34: 003107010210100-31070102101 | W34: 31 | X34: 31070102101 | Y34: 动态血压监测（运动血压监测） | AB34: 小时 | AC34: 运动血压监测 | AD34: 11.5 | AE34: 10 | AF34: 8.5
A35: 12 | B35: 012408000120000 | C35: 无创肢体动脉检查费 | D35: 检查费 | E35: 通过无创的方式评估外周动脉病变情况。 | F35: 所定价格涵盖皮肤清洁、节段性测压或安置传感器、采集数据、撤除传感器、分析、出具报告等步骤所需的人力资源与基本物质资源消耗。 | G35: 次 | I35: 47 | J35: 42 | K35: 46.954731 | L35: #DIV/0! | M35: 37.650739 | N35: 47 | O35: 42 | P35: 37 | Q35: 医保 | T35: 平移取整 | U35: 平移取整 | V35: 353107010310000-310701029 | W35: 32 | X35: 310701029 | Y35: 动脉弹性功能检测 | Z35: 指测定C1、C2大小动脉的弹性数据指数 | AB35: 次 | AD35: 50 | AE35: 50 | AF35: 42.5
V36: 353107010300000-310701030 | W36: 33 | X36: 310701030 | Y36: 大动脉功能检测 | Z36: 含检测C-F、C-R、C-D三段脉搏波速度值 | AB36: 次 | AD36: 35 | AE36: 35 | AF36: 29.8
A37: 13 | B37: 013107000030000 | C37: 心脏电除颤/电复律费 | D37: 治疗费 | E37: 通过体外直流电除颤/电复律以改变心律。 | F37: 所定价格涵盖设备安装、除颤或复律、撤除设备等步骤所需的人力资源和基本物质资源消耗。 | G37: 次 | I37: 59 | J37: 53 | K37: 60.332611 | L37: 51.060606 | M37: 42.5 | N37: 57 | O37: 51 | P37: 43 | Q37: 医保 | T37: 理顺，降低 | U37: 县级开展量高于市级，以县级平移价格为基础，按比价关系测算市级价格。 | V37: 003107020130000-310702013 | W37: 34 | X37: 310702013 | Y37: 体外经胸型心脏临时起搏术 | AB37: 次 | AC37: 使用大C臂数字减影X光机加收50% | AD37: 51.8 | AE37: 45 | AF37: 38.3
V38: 003107020160000-310702016 | W38: 35 | X38: 310702016 | Y38: 心脏电复律术 | AB38: 次 | AC38: 使用大C臂数字减影X光机加收50% | AD38: 69 | AE38: 60 | AF38: 51
V39: 003107020170000-310702017 | W39: 36 | X39: 310702017 | Y39: 心脏电除颤术 | AB39: 次 | AC39: 使用大C臂数字减影X光机加收50% | AD39: 57.5 | AE39: 50 | AF39: 42.5
V40: 003107020180000-310702018 | W40: 37 | X40: 310702018 | Y40: 体外自动心脏变律除颤术 | Z40: 包括半自动 | AA40: 一次性复律除颤电极 | AB40: 次 | AC40: 使用大C臂数字减影X光机加收50% | AD40: 57.5 | AE40: 50 | AF40: 42.5
...

Sheet 1 (2)
A1: 心血管系统类立项指南项目对应及拟定情况（征求意见稿）
A2: 心血管系统类立项指南项目 | V2: 现行项目
A3: 序号 | B3: 项目代码 | C3: 项目名称 | D3: 归集口径 | E3: 服务产出 | F3: 价格构成 | G3: 计价单位 | H3: 计价说明 | I3: 省三甲价格 | J3: 省三甲以下价格 | K3: 平移价格 (市级) | L3: 平移价格 (县级) | M3: 平移价格 (基层) | N3: 拟定价格 (市级) | O3: 拟定价格 (县级) | P3: 拟定价格 (基层) | Q3: 医保 属性 | R3: 医保限定支付范围 | S3: 个人先行自付比例 | T3: 调整情况 | U3: 备注 | V3: 国家结算编码 | W3: 项目编码 | X3: 项目名称 | Y3: 项目内涵 | Z3: 除外内容 | AA3: 计价单位 | AB3: 说明 | AC3: 价格 (市级) | AD3: 价格 (县级) | AE3: 价格 (基层) | AF3: 心脏使用胸腔镜、心脏及血管系统手术体外循环心脏不停跳心内直视手术的费用摊到相应手术中测算
A4: 1 | B4: 012408000020000 | C4: 心电监测费 | D4: 检查费 | E4: 实时监测患者心率、心律、心电波形等，必要时监测呼吸频率、呼吸波形、血压、血氧饱和度等参数。 | F4: 所定价格涵盖皮肤清洁、安放电极、连接设备、设定参数、实时监测等步骤所需的人力资源、设备运转成本与基本物质资源消耗。 | G4: 小时 | I4: 10 | J4: 10 | K4: 9.1929733 | L4: 8.762582 | M4: 7.4603179 | N4: 9.5 | O4: 9 | P4: 8 | Q4: 医保 | T4: 平移取整 | U4: 映射项目全部纳入价格构成，按照总金额除以最大量测算平移价格，同质化项目缩小价差 | V4: 003107010220000-310701022 | W4: 310701022 | X4: 心电监测 | Y4: 含无创血压监测 | AA4: 小时 | AC4: 4.5 | AD4: 4.1 | AE4: 3.4 | AF4: =IFERROR(FIND("-儿童（加收）",C4,1),0) -> 0 | AG4: =SUBSTITUTE(C4,"-儿童（加收）","") -> 心电监测费 | AH4: =IF(AF4>0,_xlfn.MAXIFS(N:N,C:C,SUBSTITUTE(C4,"-儿童（加收）","")),0)+N4 -> 9.5 | AI4: =IF(AF4>0,_xlfn.MAXIFS(O:O,C:C,SUBSTITUTE(C4,"-儿童（加收）","")),0)+O4 -> 9 | AJ4: =IF(AF4>0,_xlfn.MAXIFS(P:P,C:C,SUBSTITUTE(C4,"-儿童（加收）","")),0)+P4 -> 8
C5: 心电监测费 | N5: 9.5 | O5: 9 | P5: 8 | V5: 003107010270000-310701027 | W5: 310701027 | X5: 指脉氧监测 | AA5: 小时 | AC5: 4.5 | AD5: 4.1 | AE5: 3.4 | AF5: =IFERROR(FIND("-儿童（加收）",C5,1),0) -> 0 | AG5: =SUBSTITUTE(C5,"-儿童（加收）","") -> 心电监测费 | AH5: =IF(AF5>0,_xlfn.MAXIFS(N:N,C:C,SUBSTITUTE(C5,"-儿童（加收）","")),0)+N5 -> 9.5 | AI5: =IF(AF5>0,_xlfn.MAXIFS(O:O,C:C,SUBSTITUTE(C5,"-儿童（加收）","")),0)+O5 -> 9 | AJ5: =IF(AF5>0,_xlfn.MAXIFS(P:P,C:C,SUBSTITUTE(C5,"-儿童（加收）","")),0)+P5 -> 8
C6: 心电监测费 | N6: 9.5 | O6: 9 | P6: 8 | V6: 003107010280000-310701028 | W6: 310701028 | X6: 血氧饱和度监测 | AA6: 小时 | AC6: 4.5 | AD6: 4.1 | AE6: 3.4 | AF6: =IFERROR(FIND("-儿童（加收）",C6,1),0) -> 0 | AG6: =SUBSTITUTE(C6,"-儿童（加收）","") -> 心电监测费 | AH6: =IF(AF6>0,_xlfn.MAXIFS(N:N,C:C,SUBSTITUTE(C6,"-儿童（加收）","")),0)+N6 -> 9.5 | AI6: =IF(AF6>0,_xlfn.MAXIFS(O:O,C:C,SUBSTITUTE(C6,"-儿童（加收）","")),0)+O6 -> 9 | AJ6: =IF(AF6>0,_xlfn.MAXIFS(P:P,C:C,SUBSTITUTE(C6,"-儿童（加收）","")),0)+P6 -> 8
C7: 心电监测费 | N7: 9.5 | O7: 9 | P7: 8 | V7: 003107010290000-310701033 | W7: 310701033 | X7: 经皮肢体氧分压测定 | Y7: 患者仰卧，连接氧分压测定仪于肢体不同部位，开启氧分压测定仪，分别检测肢体不同部位的氧分压，记录并报告。 | AA7: 次 | AC7: 70 | AD7: 70 | AE7: 59.5 | AF7: =IFERROR(FIND("-儿童（加收）",C7,1),0) -> 0 | AG7: =SUBSTITUTE(C7,"-儿童（加收）","") -> 心电监测费 | AH7: =IF(AF7>0,_xlfn.MAXIFS(N:N,C:C,SUBSTITUTE(C7,"-儿童（加收）","")),0)+N7 -> 9.5 | AI7: =IF(AF7>0,_xlfn.MAXIFS(O:O,C:C,SUBSTITUTE(C7,"-儿童（加收）","")),0)+O7 -> 9 | AJ7: =IF(AF7>0,_xlfn.MAXIFS(P:P,C:C,SUBSTITUTE(C7,"-儿童（加收）","")),0)+P7 -> 8
A8: 分项 | B8: 012408000020100 | C8: 心电监测费-遥测心电监测（扩展） | D8: 检查费 | G8: 小时 | H8: 封顶每日不超过50元。 | I8: 10 | J8: 10 | K8: 8.8263158 | L8: 8.8461538 | M8: 6.95625 | N8: 9.5 | O8: 9 | P8: 8 | Q8: 医保 | U8: 整合项目，两个项目价格合计测算。 扩展项按主项价格执行 | V8: 003107010090000-310701009 | W8: 310701009 | X8: 心电监测电话传输 | Y8: 含电池、电极费用 | AA8: 日 | AC8: 57.5 | AD8: 50 | AE8: 42.5 | AF8: =IFERROR(FIND("-儿童（加收）",C8,1),0) -> 0 | AG8: =SUBSTITUTE(C8,"-儿童（加收）","") -> 心电监测费-遥测心电监测（扩展） | AH8: =IF(AF8>0,_xlfn.MAXIFS(N:N,C:C,SUBSTITUTE(C8,"-儿童（加收）","")),0)+N8 -> 9.5 | AI8: =IF(AF8>0,_xlfn.MAXIFS(O:O,C:C,SUBSTITUTE(C8,"-儿童（加收）","")),0)+O8 -> 9 | AJ8: =IF(AF8>0,_xlfn.MAXIFS(P:P,C:C,SUBSTITUTE(C8,"-儿童（加收）","")),0)+P8 -> 8
C9: 心电监测费-遥测心电监测（扩展） | N9: 9.5 | O9: 9 | P9: 8 | V9: 003107010080000-310701008 | W9: 310701008 | X9: 遥测心电监护 | AA9: 小时 | AC9: 5.8 | AD9: 5 | AE9: 4.3 | AF9: =IFERROR(FIND("-儿童（加收）",C9,1),0) -> 0 | AG9: =SUBSTITUTE(C9,"-儿童（加收）","") -> 心电监测费-遥测心电监测（扩展） | AH9: =IF(AF9>0,_xlfn.MAXIFS(N:N,C:C,SUBSTITUTE(C9,"-儿童（加收）","")),0)+N9 -> 9.5 | AI9: =IF(AF9>0,_xlfn.MAXIFS(O:O,C:C,SUBSTITUTE(C9,"-儿童（加收）","")),0)+O9 -> 9 | AJ9: =IF(AF9>0,_xlfn.MAXIFS(P:P,C:C,SUBSTITUTE(C9,"-儿童（加收）","")),0)+P9 -> 8
A10: 2 | B10: 012408000030000 | C10: 常规心电图检查费 | D10: 检查费 | E10: 通过心电图机体表采集十二导联及以下心电数据。 | F10: 所定价格涵盖皮肤清洁、安放电极、连接设备、采集信号、数据分析、出具报告等步骤所需的人力资源、设备运转成本与基本物质资源消耗。 | G10: 次 | H10: 含十二导联。 | I10: 29 | J10: 26 | K10: 26.963502 | L10: 25.252767 | M10: 21.527537 | N10: 27 | O10: 25 | P10: 23 | Q10: 医保 | T10: 平移取整 | U10: 加权平移后取整，同质化高的项目提高基层价格缩小价差 | V10: 003107010010000-310701001 | W10: 310701001 | X10: 常规心电图检查 | Y10: 含单通道、三通道、常规导联 | AA10: 次 | AB10: 附加导联加收20%；十二通道、床边心电图加收100% | AC10: 11.5 | AD10: 10 | AE10: 8.5 | AF10: =IFERROR(FIND("-儿童（加收）",C10,1),0) -> 0 | AG10: =SUBSTITUTE(C10,"-儿童（加收）","") -> 常规心电图检查费 | AH10: =IF(AF10>0,_xlfn.MAXIFS(N:N,C:C,SUBSTITUTE(C10,"-儿童（加收）","")),0)+N10 -> 27 | AI10: =IF(AF10>0,_xlfn.MAXIFS(O:O,C:C,SUBSTITUTE(C10,"-儿童（加收）","")),0)+O10 -> 25 | AJ10: =IF(AF10>0,_xlfn.MAXIFS(P:P,C:C,SUBSTITUTE(C10,"-儿童（加收）","")),0)+P10 -> 23
C11: 常规心电图检查费 | N11: 27 | O11: 25 | P11: 23 | V11: 003107010010002-31070100102 | W11: 31070100102 | X11: 常规心电图检查（十二通道加收） | AA11: 次 | AB11: 十二通道加收 | AC11: 11.5 | AD11: 10 | AE11: 8.5 | AF11: =IFERROR(FIND("-儿童（加收）",C11,1),0) -> 0 | AG11: =SUBSTITUTE(C11,"-儿童（加收）","") -> 常规心电图检查费 | AH11: =IF(AF11>0,_xlfn.MAXIFS(N:N,C:C,SUBSTITUTE(C11,"-儿童（加收）","")),0)+N11 -> 27 | AI11: =IF(AF11>0,_xlfn.MAXIFS(O:O,C:C,SUBSTITUTE(C11,"-儿童（加收）","")),0)+O11 -> 25 | AJ11: =IF(AF11>0,_xlfn.MAXIFS(P:P,C:C,SUBSTITUTE(C11,"-儿童（加收）","")),0)+P11 -> 23
C12: 常规心电图检查费 | N12: 27 | O12: 25 | P12: 23 | V12: 003107010010003-31070100103 | W12: 31070100103 | X12: 常规心电图检查（床边） | AA12: 次 | AB12: 床边心电图 | AC12: 23 | AD12: 20 | AE12: 17 | AF12: =IFERROR(FIND("-儿童（加收）",C12,1),0) -> 0 | AG12: =SUBSTITUTE(C12,"-儿童（加收）","") -> 常规心电图检查费 | AH12: =IF(AF12>0,_xlfn.MAXIFS(N:N,C:C,SUBSTITUTE(C12,"-儿童（加收）","")),0)+N12 -> 27 | AI12: =IF(AF12>0,_xlfn.MAXIFS(O:O,C:C,SUBSTITUTE(C12,"-儿童（加收）","")),0)+O12 -> 25 | AJ12: =IF(AF12>0,_xlfn.MAXIFS(P:P,C:C,SUBSTITUTE(C12,"-儿童（加收）","")),0)+P12 -> 23
C13: 常规心电图检查费 | N13: 27 | O13: 25 | P13: 23 | V13: 003107010050000-310701005 | W13: 310701005 | X13: 标测心电图 | Y13: 含电极费用 | AA13: 次 | AF13: =IFERROR(FIND("-儿童（加收）",C13,1),0) -> 0 | AG13: =SUBSTITUTE(C13,"-儿童（加收）","") -> 常规心电图检查费 | AH13: =IF(AF13>0,_xlfn.MAXIFS(N:N,C:C,SUBSTITUTE(C13,"-儿童（加收）","")),0)+N13 -> 27 | AI13: =IF(AF13>0,_xlfn.MAXIFS(O:O,C:C,SUBSTITUTE(C13,"-儿童（加收）","")),0)+O13 -> 25 | AJ13: =IF(AF13>0,_xlfn.MAXIFS(P:P,C:C,SUBSTITUTE(C13,"-儿童（加收）","")),0)+P13 -> 23
C14: 常规心电图检查费 | N14: 27 | O14: 25 | P14: 23 | V14: 003107010060000-310701006 | W14: 310701006 | X14: 体表窦房结心电图 | AA14: 次 | AF14: =IFERROR(FIND("-儿童（加收）",C14,1),0) -> 0 | AG14: =SUBSTITUTE(C14,"-儿童（加收）","") -> 常规心电图检查费 | AH14: =IF(AF14>0,_xlfn.MAXIFS(N:N,C:C,SUBSTITUTE(C14,"-儿童（加收）","")),0)+N14 -> 27 | AI14: =IF(AF14>0,_xlfn.MAXIFS(O:O,C:C,SUBSTITUTE(C14,"-儿童（加收）","")),0)+O14 -> 25 | AJ14: =IF(AF14>0,_xlfn.MAXIFS(P:P,C:C,SUBSTITUTE(C14,"-儿童（加收）","")),0)+P14 -> 23
C15: 常规心电图检查费 | N15: 27 | O15: 25 | P15: 23 | V15: 003107010020000-310701002 | W15: 310701002 | X15: 食管内心电图 | Z15: 一次性导管 | AA15: 次 | AC15: 57.5 | AD15: 50 | AE15: 42.5 | AF15: =IFERROR(FIND("-儿童（加收）",C15,1),0) -> 0 | AG15: =SUBSTITUTE(C15,"-儿童（加收）","") -> 常规心电图检查费 | AH15: =IF(AF15>0,_xlfn.MAXIFS(N:N,C:C,SUBSTITUTE(C15,"-儿童（加收）","")),0)+N15 -> 27 | AI15: =IF(AF15>0,_xlfn.MAXIFS(O:O,C:C,SUBSTITUTE(C15,"-儿童（加收）","")),0)+O15 -> 25 | AJ15: =IF(AF15>0,_xlfn.MAXIFS(P:P,C:C,SUBSTITUTE(C15,"-儿童（加收）","")),0)+P15 -> 23
A16: 分项 | B16: 012408000030001 | C16: 常规心电图检查费十二导联以上（加收） | D16: 检查费 | G16: 次 | I16: 2 | J16: 2 | K16: 2.3 | L16: 2 | M16: 1.7 | N16: 2 | O16: 1.9 | P16: 1.8 | Q16: 医保 | U16: 平移后市按不超过省级定价，同质化项目缩小价差 | V16: 003107010010001-31070100101 | W16: 31070100101 | X16: 常规心电图检查（附加导联加收） | AA16: 次 | AB16: 附加导联加收 | AC16: 2.3 | AD16: 2 | AE16: 1.7 | AF16: =IFERROR(FIND("-儿童（加收）",C16,1),0) -> 0 | AG16: =SUBSTITUTE(C16,"-儿童（加收）","") -> 常规心电图检查费十二导联以上（加收） | AH16: =IF(AF16>0,_xlfn.MAXIFS(N:N,C:C,SUBSTITUTE(C16,"-儿童（加收）","")),0)+N16 -> 2 | AI16: =IF(AF16>0,_xlfn.MAXIFS(O:O,C:C,SUBSTITUTE(C16,"-儿童（加收）","")),0)+O16 -> 1.9 | AJ16: =IF(AF16>0,_xlfn.MAXIFS(P:P,C:C,SUBSTITUTE(C16,"-儿童（加收）","")),0)+P16 -> 1.8
A17: 分项 | B17: 012408000030011 | C17: 常规心电图检查费-心脏晚电位检查（加收） | D17: 检查费 | G17: 次 | I17: 15 | J17: 14 | K17: 42 | L17: 35 | M17: 28 | N17: 15 | O17: 14 | P17: 13 | Q17: 医保 | U17: 按不超过省级拟定 | V17: 003107010150000-310701015 | W17: 310701015 | X17: 心室晚电位 | Y17: 含电极费用 | AA17: 次 | AC17: 69 | AD17: 60 | AE17: 51 | AF17: =IFERROR(FIND("-儿童（加收）",C17,1),0) -> 0 | AG17: =SUBSTITUTE(C17,"-儿童（加收）","") -> 常规心电图检查费-心脏晚电位检查（加收） | AH17: =IF(AF17>0,_xlfn.MAXIFS(N:N,C:C,SUBSTITUTE(C17,"-儿童（加收）","")),0)+N17 -> 15 | AI17: =IF(AF17>0,_xlfn.MAXIFS(O:O,C:C,SUBSTITUTE(C17,"-儿童（加收）","")),0)+O17 -> 14 | AJ17: =IF(AF17>0,_xlfn.MAXIFS(P:P,C:C,SUBSTITUTE(C17,"-儿童（加收）","")),0)+P17 -> 13
C18: 常规心电图检查费-心脏晚电位检查（加收） | N18: 15 | O18: 14 | P18: 13 | V18: 003107010160000-310701016 | W18: 310701016 | X18: 心房晚电位 | Y18: 含电极费用 | AA18: 次 | AC18: 69 | AD18: 60 | AE18: 51 | AF18: =IFERROR(FIND("-儿童（加收）",C18,1),0) -> 0 | AG18: =SUBSTITUTE(C18,"-儿童（加收）","") -> 常规心电图检查费-心脏晚电位检查（加收） | AH18: =IF(AF18>0,_xlfn.MAXIFS(N:N,C:C,SUBSTITUTE(C18,"-儿童（加收）","")),0)+N18 -> 15 | AI18: =IF(AF18>0,_xlfn.MAXIFS(O:O,C:C,SUBSTITUTE(C18,"-儿童（加收）","")),0)+O18 -> 14 | AJ18: =IF(AF18>0,_xlfn.MAXIFS(P:P,C:C,SUBSTITUTE(C18,"-儿童（加收）","")),0)+P18 -> 13
A19: 分项 | B19: 012408000030100 | C19: 常规心电图检查费-心电向量图（扩展） | D19: 检查费 | G19: 次 | I19: 29 | J19: 26 | K19: 34.5 | L19: 30 | M19: 25.5 | N19: 27 | O19: 25 | P19: 23 | Q19: 医保 | U19: 扩展项按主项价格执行 | V19: 003107010120000-310701012 | W19: 310701012 | X19: 心电向量图 | AA19: 次 | AC19: 34.5 | AD19: 30 | AE19: 25.5 | AF19: =IFERROR(FIND("-儿童（加收）",C19,1),0) -> 0 | AG19: =SUBSTITUTE(C19,"-儿童（加收）","") -> 常规心电图检查费-心电向量图（扩展） | AH19: =IF(AF19>0,_xlfn.MAXIFS(N:N,C:C,SUBSTITUTE(C19,"-儿童（加收）","")),0)+N19 -> 27 | AI19: =IF(AF19>0,_xlfn.MAXIFS(O:O,C:C,SUBSTITUTE(C19,"-儿童（加收）","")),0)+O19 -> 25 | AJ19: =IF(AF19>0,_xlfn.MAXIFS(P:P,C:C,SUBSTITUTE(C19,"-儿童（加收）","")),0)+P19 -> 23
A20: 分项 | B20: 012408000031100 | C20: 常规心电图检查费-频谱心电图（扩展） | D20: 检查费 | G20: 次 | I20: 29 | J20: 26 | K20: 46 | L20: 40 | M20: 34 | N20: 27 | O20: 25 | P20: 23 | Q20: 医保 | U20: 扩展项按主项价格执行 | V20: 003107010040000-310701004 | W20: 310701004 | X20: 频谱心电图 | Y20: 含电极费用 | AA20: 次 | AC20: 46 | AD20: 40 | AE20: 34 | AF20: =IFERROR(FIND("-儿童（加收）",C20,1),0) -> 0 | AG20: =SUBSTITUTE(C20,"-儿童（加收）","") -> 常规心电图检查费-频谱心电图（扩展） | AH20: =IF(AF20>0,_xlfn.MAXIFS(N:N,C:C,SUBSTITUTE(C20,"-儿童（加收）","")),0)+N20 -> 27 | AI20: =IF(AF20>0,_xlfn.MAXIFS(O:O,C:C,SUBSTITUTE(C20,"-儿童（加收）","")),0)+O20 -> 25 | AJ20: =IF(AF20>0,_xlfn.MAXIFS(P:P,C:C,SUBSTITUTE(C20,"-儿童（加收）","")),0)+P20 -> 23
A21: 3 | B21: 012408000040000 | C21: 心率变异性分析检查费 | D21: 检查费 | E21: 通过连续记录心电图数据分析心率变化情况。 | F21: 所定价格涵盖皮肤清洁、安放电极、连接设备、采集信号、数据分析、出具报告等步骤所需的人力资源、设备运转成本与基本物质资源消耗。 | G21: 次 | I21: 80 | J21: 72 | K21: 92.002816 | L21: 80 | M21: 68.065073 | N21: 80 | O21: 72 | P21: 65 | Q21: 医保 | T21: 理顺，降低 | U21: 平移后按不超过省级价格下调，同质化高的项目持平省级价格 | V21: 003107010180000-310701018 | W21: 310701018 | X21: 心率变异性分析 | Y21: 包括短程或24小时 | AA21: 次 | AB21: 超过24小时基层加收12.8元，县级医院加收15元，市级加收17.3元 | AC21: 92 | AD21: 80 | AE21: 68 | AF21: =IFERROR(FIND("-儿童（加收）",C21,1),0) -> 0 | AG21: =SUBSTITUTE(C21,"-儿童（加收）","") -> 心率变异性分析检查费 | AH21: =IF(AF21>0,_xlfn.MAXIFS(N:N,C:C,SUBSTITUTE(C21,"-儿童（加收）","")),0)+N21 -> 80 | AI21: =IF(AF21>0,_xlfn.MAXIFS(O:O,C:C,SUBSTITUTE(C21,"-儿童（加收）","")),0)+O21 -> 72 | AJ21: =IF(AF21>0,_xlfn.MAXIFS(P:P,C:C,SUBSTITUTE(C21,"-儿童（加收）","")),0)+P21 -> 65
C22: 心率变异性分析检查费 | N22: 80 | O22: 72 | P22: 65 | V22: 003107010180001-31070101801 | W22: 31070101801 | X22: 心率变异性分析（超过24小时加收） | AA22: 次 | AB22: 超过24小时加收 | AC22: 17.3 | AD22: 15 | AE22: 12.8 | AF22: =IFERROR(FIND("-儿童（加收）",C22,1),0) -> 0 | AG22: =SUBSTITUTE(C22,"-儿童（加收）","") -> 心率变异性分析检查费 | AH22: =IF(AF22>0,_xlfn.MAXIFS(N:N,C:C,SUBSTITUTE(C22,"-儿童（加收）","")),0)+N22 -> 80 | AI22: =IF(AF22>0,_xlfn.MAXIFS(O:O,C:C,SUBSTITUTE(C22,"-儿童（加收）","")),0)+O22 -> 72 | AJ22: =IF(AF22>0,_xlfn.MAXIFS(P:P,C:C,SUBSTITUTE(C22,"-儿童（加收）","")),0)+P22 -> 65
A23: 4 | B23: 012408000050000 | C23: 心电图负荷检查费 | D23: 检查费 | E23: 通过各类运动负荷或药物诱导试验等方式，对比监测心电和血压变化，协助诊断疾病。 | F23: 所定价格涵盖皮肤清洁、安放电极、记录静息心电图、增加负荷、监测心电和血压变化、数据分析、出具报告等步骤所需的人力资源、设备运转成本与基本物质资源消耗。 | G23: 次 | I23: 107 | J23: 96 | K23: 114.16034 | L23: 91.174863 | N23: 105 | O23: 95 | P23: 80 | Q23: 医保 | T23: 理顺，降低 | U23: 平移后市按不超过省级定价 | V23: 003107010100000-310701010 | W23: 310701010 | X23: 心电图踏车负荷试验 | Y23: 含电极费用、指平板运动试验 | AA23: 次 | AB23: 二阶梯基层每次只收25.5元，县级医院每次只收30元，市级医院每次只收34.5元 | AC23: 149.5 | AD23: 130 | AE23: 110.5 | AF23: =IFERROR(FIND("-儿童（加收）",C23,1),0) -> 0 | AG23: =SUBSTITUTE(C23,"-儿童（加收）","") -> 心电图负荷检查费 | AH23: =IF(AF23>0,_xlfn.MAXIFS(N:N,C:C,SUBSTITUTE(C23,"-儿童（加收）","")),0)+N23 -> 105 | AI23: =IF(AF23>0,_xlfn.MAXIFS(O:O,C:C,SUBSTITUTE(C23,"-儿童（加收）","")),0)+O23 -> 95 | AJ23: =IF(AF23>0,_xlfn.MAXIFS(P:P,C:C,SUBSTITUTE(C23,"-儿童（加收）","")),0)+P23 -> 80
C24: 心电图负荷检查费 | N24: 105 | O24: 95 | P24: 80 | V24: 003107010100100-31070101001 | W24: 31070101001 | X24: 心电图踏车负荷试验（二阶梯） | AA24: 次 | AB24: 二阶梯 | AC24: 34.5 | AD24: 30 | AE24: 25.5 | AF24: =IFERROR(FIND("-儿童（加收）",C24,1),0) -> 0 | AG24: =SUBSTITUTE(C24,"-儿童（加收）","") -> 心电图负荷检查费 | AH24: =IF(AF24>0,_xlfn.MAXIFS(N:N,C:C,SUBSTITUTE(C24,"-儿童（加收）","")),0)+N24 -> 105 | AI24: =IF(AF24>0,_xlfn.MAXIFS(O:O,C:C,SUBSTITUTE(C24,"-儿童（加收）","")),0)+O24 -> 95 | AJ24: =IF(AF24>0,_xlfn.MAXIFS(P:P,C:C,SUBSTITUTE(C24,"-儿童（加收）","")),0)+P24 -> 80
C25: 心电图负荷检查费 | N25: 105 | O25: 95 | P25: 80 | V25: 003107010110000-310701011 | W25: 310701011 | X25: 心电图药物负荷试验 | Y25: 含电极费用 | AA25: 次 | AC25: 51.8 | AD25: 45 | AE25: 38.3 | AF25: =IFERROR(FIND("-儿童（加收）",C25,1),0) -> 0 | AG25: =SUBSTITUTE(C25,"-儿童（加收）","") -> 心电图负荷检查费 | AH25: =IF(AF25>0,_xlfn.MAXIFS(N:N,C:C,SUBSTITUTE(C25,"-儿童（加收）","")),0)+N25 -> 105 | AI25: =IF(AF25>0,_xlfn.MAXIFS(O:O,C:C,SUBSTITUTE(C25,"-儿童（加收）","")),0)+O25 -> 95 | AJ25: =IF(AF25>0,_xlfn.MAXIFS(P:P,C:C,SUBSTITUTE(C25,"-儿童（加收）","")),0)+P25 -> 80
A26: 5 | B26: 012408000060000 | C26: 动态心电图检查费 | D26: 检查费 | E26: 通过获取连续的心电图监测数据，协助诊断疾病。 | F26: 所定价格涵盖皮肤清洁、安放电极、连接设备、采集信号、数据分析、出具报告等步骤所需的人力资源、设备运转成本与基本物质资源消耗。 | G26: 日 | H26: 单次检查收取不超过3天，个别患者确有必要的最多可收取5天费用。 | I26: 150 | J26: 135 | K26: 172.5 | L26: 150.00539 | M26: 127.5 | N26: 150 | O26: 135 | P26: 120 | Q26: 医保 | T26: 理顺，降低 | U26: 平移后市按不超过省级定价，同质化高的项目持平省级价格，基层调低理顺比价 | V26: 003107010030000-310701003 | W26: 310701003 | X26: 动态心电图 | Y26: 含磁带、电池费用；含实时监测预警 | AA26: 次 | AC26: 172.5 | AD26: 150 | AE26: 127.5 | AF26: =IFERROR(FIND("-儿童（加收）",C26,1),0) -> 0 | AG26: =SUBSTITUTE(C26,"-儿童（加收）","") -> 动态心电图检查费 | AH26: =IF(AF26>0,_xlfn.MAXIFS(N:N,C:C,SUBSTITUTE(C26,"-儿童（加收）","")),0)+N26 -> 150 | AI26: =IF(AF26>0,_xlfn.MAXIFS(O:O,C:C,SUBSTITUTE(C26,"-儿童（加收）","")),0)+O26 -> 135 | AJ26: =IF(AF26>0,_xlfn.MAXIFS(P:P,C:C,SUBSTITUTE(C26,"-儿童（加收）","")),0)+P26 -> 120
C27: 动态心电图检查费 | N27: 150 | O27: 135 | P27: 120 | V27: 003107010070000-310701007 | W27: 310701007 | X27: 心电事件记录 | Y27: 含磁带、电池费用 | AA27: 次 | AC27: 11.5 | AD27: 10 | AE27: 8.5 | AF27: =IFERROR(FIND("-儿童（加收）",C27,1),0) -> 0 | AG27: =SUBSTITUTE(C27,"-儿童（加收）","") -> 动态心电图检查费 | AH27: =IF(AF27>0,_xlfn.MAXIFS(N:N,C:C,SUBSTITUTE(C27,"-儿童（加收）","")),0)+N27 -> 150 | AI27: =IF(AF27>0,_xlfn.MAXIFS(O:O,C:C,SUBSTITUTE(C27,"-儿童（加收）","")),0)+O27 -> 135 | AJ27: =IF(AF27>0,_xlfn.MAXIFS(P:P,C:C,SUBSTITUTE(C27,"-儿童（加收）","")),0)+P27 -> 120
A28: 6 | B28: 013107000010000 | C28: 经食管心脏调搏费 | D28: 治疗费 | E28: 通过食管电极对左心房或邻近心脏组织进行电刺激，进行电生理评估或终止室上速。 | F28: 所定价格涵盖皮肤清洁、安置导管和电极、连接设备、电刺激、采集信号、数据分析、出具报告等步骤所需的人力资源、设备运转成本与基本物质资源消耗。 | G28: 次 | I28: 132 | J28: 119 | K28: 138 | L28: 120 | M28: 102 | N28: 132 | O28: 119 | P28: 102 | Q28: 医保 | T28: 理顺，降低 | U28: 平移后按不超过省级价格下调，同质化高的项目持平省级价格 | V28: 003107020150000-310702015 | W28: 310702015 | X28: 经食管心脏调搏术 | Y28: 指超速抑制心动过速治疗 | AA28: 次 | AB28: 使用大C臂数字减影X光机加收50% | AC28: 138 | AD28: 120 | AE28: 102 | AF28: =IFERROR(FIND("-儿童（加收）",C28,1),0) -> 0 | AG28: =SUBSTITUTE(C28,"-儿童（加收）","") -> 经食管心脏调搏费 | AH28: =IF(AF28>0,_xlfn.MAXIFS(N:N,C:C,SUBSTITUTE(C28,"-儿童（加收）","")),0)+N28 -> 132 | AI28: =IF(AF28>0,_xlfn.MAXIFS(O:O,C:C,SUBSTITUTE(C28,"-儿童（加收）","")),0)+O28 -> 119 | AJ28: =IF(AF28>0,_xlfn.MAXIFS(P:P,C:C,SUBSTITUTE(C28,"-儿童（加收）","")),0)+P28 -> 102
A29: 7 | B29: 013107000020000 | C29: 经食管心脏起搏费 | D29: 治疗费 | E29: 通过食管电极对左心房或邻近心脏组织进行电刺激，进行临时起搏。 | F29: 所定价格涵盖皮肤清洁、安置导管和电极、连接设备、电刺激、调整起搏参数等步骤所需的人力资源、设备运转成本与基本物质资源消耗。 | G29: 次 | I29: 132 | J29: 119 | K29: 138 | L29: 120 | M29: 102 | N29: 132 | O29: 119 | P29: 102 | Q29: 医保 | T29: 理顺，降低 | U29: 平移后按不超过省级价格下调。同质化高的项目持平省级价格 | V29: 003107020140000-310702014 | W29: 310702014 | X29: 经食管心脏起搏术 | AA29: 次 | AB29: 使用大C臂数字减影X光机加收50% | AC29: 138 | AD29: 120 | AE29: 102 | AF29: =IFERROR(FIND("-儿童（加收）",C29,1),0) -> 0 | AG29: =SUBSTITUTE(C29,"-儿童（加收）","") -> 经食管心脏起搏费 | AH29: =IF(AF29>0,_xlfn.MAXIFS(N:N,C:C,SUBSTITUTE(C29,"-儿童（加收）","")),0)+N29 -> 132 | AI29: =IF(AF29>0,_xlfn.MAXIFS(O:O,C:C,SUBSTITUTE(C29,"-儿童（加收）","")),0)+O29 -> 119 | AJ29: =IF(AF29>0,_xlfn.MAXIFS(P:P,C:C,SUBSTITUTE(C29,"-儿童（加收）","")),0)+P29 -> 102
A30: 9 | B30: 012408000090000 | C30: 直立倾斜检查费 | D30: 检查费 | E30: 通过改变体位，监测患者心率、血压和神智的变化，协助诊断疾病。 | F30: 所定价格涵盖皮肤清洁、安放电极、患者固定、改变体位、监测心电和血压变化、观察患者表现、数据分析、出具报告等步骤所需的人力资源与基本物质资源消耗。 | G30: 次 | H30: 不与“心电监测费”同时收取。 | I30: 160 | J30: 144 | K30: 184 | L30: 160 | M30: 136 | N30: 160 | O30: 144 | P30: 125 | Q30: 医保 | T30: 理顺，降低 | U30: 平移后按不超过省级价格下调，同质化高的项目持平省级价格 | V30: 003107010170000-310701017 | W30: 310701017 | X30: 倾斜试验 | AA30: 次 | AC30: 184 | AD30: 160 | AE30: 136 | AF30: =IFERROR(FIND("-儿童（加收）",C30,1),0) -> 0 | AG30: =SUBSTITUTE(C30,"-儿童（加收）","") -> 直立倾斜检查费 | AH30: =IF(AF30>0,_xlfn.MAXIFS(N:N,C:C,SUBSTITUTE(C30,"-儿童（加收）","")),0)+N30 -> 160 | AI30: =IF(AF30>0,_xlfn.MAXIFS(O:O,C:C,SUBSTITUTE(C30,"-儿童（加收）","")),0)+O30 -> 144 | AJ30: =IF(AF30>0,_xlfn.MAXIFS(P:P,C:C,SUBSTITUTE(C30,"-儿童（加收）","")),0)+P30 -> 125
A31: 10 | B31: 012408000100000 | C31: 6分钟步行检查费 | D31: 检查费 | E31: 通过步行速度评估患者心脏功能及运动耐力。 | F31: 所定价格涵盖设备准备、测试过程中生命体征监测、撤除设备、出具报告等步骤所需的人力资源和基本物质资源消耗。 | G31: 次 | H31: 不与“心电监测费”同时收取。 | I31: 40 | J31: 36 | K31: 36 | L31: 32 | M31: 27 | N31: 36 | O31: 32 | P31: 27 | Q31: 非医保 | T31: 平移 | U31: 平移 | V31: 003402000070000-340200046 | W31: 340200046 | X31: 6分钟步行测试 | Y31: 采用标准化方法，对患者进行时间限定的步行距离、步行速度以及不适症状的检查。评价心肺疾病患者对治疗的反应情况；评价患者整体的功能状况（监测和记录患者在这6分钟步行范围内心率、血压、血氧、步行距离、费力指数等）。广泛适用于肺动脉高压、心力衰竭、COPD、间质性肺疾病、肺移植、肺减容术、肺切除术等病种评估。 | AA31: 次 | AC31: 36 | AD31: 32 | AE31: 27 | AF31: =IFERROR(FIND("-儿童（加收）",C31,1),0) -> 0 | AG31: =SUBSTITUTE(C31,"-儿童（加收）","") -> 6分钟步行检查费 | AH31: =IF(AF31>0,_xlfn.MAXIFS(N:N,C:C,SUBSTITUTE(C31,"-儿童（加收）","")),0)+N31 -> 36 | AI31: =IF(AF31>0,_xlfn.MAXIFS(O:O,C:C,SUBSTITUTE(C31,"-儿童（加收）","")),0)+O31 -> 32 | AJ31: =IF(AF31>0,_xlfn.MAXIFS(P:P,C:C,SUBSTITUTE(C31,"-儿童（加收）","")),0)+P31 -> 27
A32: 11 | B32: 012408000110000 | C32: 无创动态血压监测费 | D32: 检查费 | E32: 通过无创的方式连续监测患者血压，获取24小时中多次血压监测数据。 | F32: 所定价格涵盖固定袖带、动态监测血压、采集数据、撤除袖带、分析、出具报告等步骤所需的人力资源与基本物质资源消耗。 | G32: 日 | I32: 200 | J32: 180 | K32: 257.24094 | L32: 179.93885 | M32: 195.92785 | N32: 200 | O32: 180 | P32: 165 | Q32: 医保 | T32: 理顺，降低 | U32: 市级每人次约监测22.4小时/天。县级每人次约监测18小时/天。基层每人次约监测23小时/天。平移后按不超过省级拟定（同质化高的检查项目，持平省级定价） | V32: 003107010210000-310701021 | W32: 310701021 | X32: 动态血压监测 | Y32: 含电池费用；包括运动血压监测 | AA32: 小时 | AC32: 11.5 | AD32: 10 | AE32: 8.5 | AF32: =IFERROR(FIND("-儿童（加收）",C32,1),0) -> 0 | AG32: =SUBSTITUTE(C32,"-儿童（加收）","") -> 无创动态血压监测费 | AH32: =IF(AF32>0,_xlfn.MAXIFS(N:N,C:C,SUBSTITUTE(C32,"-儿童（加收）","")),0)+N32 -> 200 | AI32: =IF(AF32>0,_xlfn.MAXIFS(O:O,C:C,SUBSTITUTE(C32,"-儿童（加收）","")),0)+O32 -> 180 | AJ32: =IF(AF32>0,_xlfn.MAXIFS(P:P,C:C,SUBSTITUTE(C32,"-儿童（加收）","")),0)+P32 -> 165
C33: 无创动态血压监测费 | N33: 200 | O33: 180 | P33: 165 | V33: 003107010210100-31070102101 | W33: 31070102101 | X33: 动态血压监测（运动血压监测） | AA33: 小时 | AB33: 运动血压监测 | AC33: 11.5 | AD33: 10 | AE33: 8.5 | AF33: =IFERROR(FIND("-儿童（加收）",C33,1),0) -> 0 | AG33: =SUBSTITUTE(C33,"-儿童（加收）","") -> 无创动态血压监测费 | AH33: =IF(AF33>0,_xlfn.MAXIFS(N:N,C:C,SUBSTITUTE(C33,"-儿童（加收）","")),0)+N33 -> 200 | AI33: =IF(AF33>0,_xlfn.MAXIFS(O:O,C:C,SUBSTITUTE(C33,"-儿童（加收）","")),0)+O33 -> 180 | AJ33: =IF(AF33>0,_xlfn.MAXIFS(P:P,C:C,SUBSTITUTE(C33,"-儿童（加收）","")),0)+P33 -> 165
A34: 12 | B34: 012408000120000 | C34: 无创肢体动脉检查费 | D34: 检查费 | E34: 通过无创的方式评估外周动脉病变情况。 | F34: 所定价格涵盖皮肤清洁、节段性测压或安置传感器、采集数据、撤除传感器、分析、出具报告等步骤所需的人力资源与基本物质资源消耗。 | G34: 次 | I34: 47 | J34: 42 | K34: 46.954731 | L34: #DIV/0! | M34: 37.650739 | N34: 47 | O34: 42 | P34: 37 | Q34: 医保 | T34: 平移取整 | U34: 平移取整 | V34: 353107010310000-310701029 | W34: 310701029 | X34: 动脉弹性功能检测 | Y34: 指测定C1、C2大小动脉的弹性数据指数 | AA34: 次 | AC34: 50 | AD34: 50 | AE34: 42.5 | AF34: =IFERROR(FIND("-儿童（加收）",C34,1),0) -> 0 | AG34: =SUBSTITUTE(C34,"-儿童（加收）","") -> 无创肢体动脉检查费 | AH34: =IF(AF34>0,_xlfn.MAXIFS(N:N,C:C,SUBSTITUTE(C34,"-儿童（加收）","")),0)+N34 -> 47 | AI34: =IF(AF34>0,_xlfn.MAXIFS(O:O,C:C,SUBSTITUTE(C34,"-儿童（加收）","")),0)+O34 -> 42 | AJ34: =IF(AF34>0,_xlfn.MAXIFS(P:P,C:C,SUBSTITUTE(C34,"-儿童（加收）","")),0)+P34 -> 37
C35: 无创肢体动脉检查费 | N35: 47 | O35: 42 | P35: 37 | V35: 353107010300000-310701030 | W35: 310701030 | X35: 大动脉功能检测 | Y35: 含检测C-F、C-R、C-D三段脉搏波速度值 | AA35: 次 | AC35: 35 | AD35: 35 | AE35: 29.8 | AF35: =IFERROR(FIND("-儿童（加收）",C35,1),0) -> 0 | AG35: =SUBSTITUTE(C35,"-儿童（加收）","") -> 无创肢体动脉检查费 | AH35: =IF(AF35>0,_xlfn.MAXIFS(N:N,C:C,SUBSTITUTE(C35,"-儿童（加收）","")),0)+N35 -> 47 | AI35: =IF(AF35>0,_xlfn.MAXIFS(O:O,C:C,SUBSTITUTE(C35,"-儿童（加收）","")),0)+O35 -> 42 | AJ35: =IF(AF35>0,_xlfn.MAXIFS(P:P,C:C,SUBSTITUTE(C35,"-儿童（加收）","")),0)+P35 -> 37
A36: 13 | B36: 013107000030000 | C36: 心脏电除颤/电复律费 | D36: 治疗费 | E36: 通过体外直流电除颤/电复律以改变心律。 | F36: 所定价格涵盖设备安装、除颤或复律、撤除设备等步骤所需的人力资源和基本物质资源消耗。 | G36: 次 | I36: 59 | J36: 53 | K36: 60.332611 | L36: 51.060606 | M36: 42.5 | N36: 57 | O36: 51 | P36: 43 | Q36: 医保 | T36: 理顺，降低 | U36: 县级开展量高于市级，以县级平移价格为基础，按比价关系测算市级价格。 | V36: 003107020130000-310702013 | W36: 310702013 | X36: 体外经胸型心脏临时起搏术 | AA36: 次 | AB36: 使用大C臂数字减影X光机加收50% | AC36: 51.8 | AD36: 45 | AE36: 38.3 | AF36: =IFERROR(FIND("-儿童（加收）",C36,1),0) -> 0 | AG36: =SUBSTITUTE(C36,"-儿童（加收）","") -> 心脏电除颤/电复律费 | AH36: =IF(AF36>0,_xlfn.MAXIFS(N:N,C:C,SUBSTITUTE(C36,"-儿童（加收）","")),0)+N36 -> 57 | AI36: =IF(AF36>0,_xlfn.MAXIFS(O:O,C:C,SUBSTITUTE(C36,"-儿童（加收）","")),0)+O36 -> 51 | AJ36: =IF(AF36>0,_xlfn.MAXIFS(P:P,C:C,SUBSTITUTE(C36,"-儿童（加收）","")),0)+P36 -> 43
C37: 心脏电除颤/电复律费 | N37: 57 | O37: 51 | P37: 43 | V37: 003107020160000-310702016 | W37: 310702016 | X37: 心脏电复律术 | AA37: 次 | AB37: 使用大C臂数字减影X光机加收50% | AC37: 69 | AD37: 60 | AE37: 51 | AF37: =IFERROR(FIND("-儿童（加收）",C37,1),0) -> 0 | AG37: =SUBSTITUTE(C37,"-儿童（加收）","") -> 心脏电除颤/电复律费 | AH37: =IF(AF37>0,_xlfn.MAXIFS(N:N,C:C,SUBSTITUTE(C37,"-儿童（加收）","")),0)+N37 -> 57 | AI37: =IF(AF37>0,_xlfn.MAXIFS(O:O,C:C,SUBSTITUTE(C37,"-儿童（加收）","")),0)+O37 -> 51 | AJ37: =IF(AF37>0,_xlfn.MAXIFS(P:P,C:C,SUBSTITUTE(C37,"-儿童（加收）","")),0)+P37 -> 43
C38: 心脏电除颤/电复律费 | N38: 57 | O38: 51 | P38: 43 | V38: 003107020170000-310702017 | W38: 310702017 | X38: 心脏电除颤术 | AA38: 次 | AB38: 使用大C臂数字减影X光机加收50% | AC38: 57.5 | AD38: 50 | AE38: 42.5 | AF38: =IFERROR(FIND("-儿童（加收）",C38,1),0) -> 0 | AG38: =SUBSTITUTE(C38,"-儿童（加收）","") -> 心脏电除颤/电复律费 | AH38: =IF(AF38>0,_xlfn.MAXIFS(N:N,C:C,SUBSTITUTE(C38,"-儿童（加收）","")),0)+N38 -> 57 | AI38: =IF(AF38>0,_xlfn.MAXIFS(O:O,C:C,SUBSTITUTE(C38,"-儿童（加收）","")),0)+O38 -> 51 | AJ38: =IF(AF38>0,_xlfn.MAXIFS(P:P,C:C,SUBSTITUTE(C38,"-儿童（加收）","")),0)+P38 -> 43
C39: 心脏电除颤/电复律费 | N39: 57 | O39: 51 | P39: 43 | V39: 003107020180000-310702018 | W39: 310702018 | X39: 体外自动心脏变律除颤术 | Y39: 包括半自动 | Z39: 一次性复律除颤电极 | AA39: 次 | AB39: 使用大C臂数字减影X光机加收50% | AC39: 57.5 | AD39: 50 | AE39: 42.5 | AF39: =IFERROR(FIND("-儿童（加收）",C39,1),0) -> 0 | AG39: =SUBSTITUTE(C39,"-儿童（加收）","") -> 心脏电除颤/电复律费 | AH39: =IF(AF39>0,_xlfn.MAXIFS(N:N,C:C,SUBSTITUTE(C39,"-儿童（加收）","")),0)+N39 -> 57 | AI39: =IF(AF39>0,_xlfn.MAXIFS(O:O,C:C,SUBSTITUTE(C39,"-儿童（加收）","")),0)+O39 -> 51 | AJ39: =IF(AF39>0,_xlfn.MAXIFS(P:P,C:C,SUBSTITUTE(C39,"-儿童（加收）","")),0)+P39 -> 43
A40: 14 | B40: 012408000140000 | C40: 有创血流动力学监测费 | D40: 检查费 | E40: 通过侵入性的方式测量血流动力学参数指标。 | F40: 所定价格涵盖连接设备、监测血流动力学相关数据、撤除设备等步骤所需的人力资源和基本物质资源消耗。 | G40: 小时 | I40: 15 | J40: 14 | K40: 19.346657 | L40: 17.504578 | M40: 12.8 | N40: 15 | O40: 14 | P40: 13 | Q40: 医保 | T40: 理顺，降低 | U40: 省级按项目间及区域间比价关系下调，我市按比价关系下调拟定（同质化高的检查项目，持平省级定价） | V40: 003107020010000-310702001 | W40: 310702001 | X40: 有创性血流动力学监测（床旁） | Y40: 含各房室腔内压力监测、心排血量测定 | Z40: 漂浮导管 | AA40: 次 | AB40: 使用大C臂数字减影X光机加收50%。心电、压力连续示波基层30元/小时，县级医院35元/小时，市级医院40.3元/小时 | AC40: 115 | AD40: 100 | AE40: 85 | AF40: =IFERROR(FIND("-儿童（加收）",C40,1),0) -> 0 | AG40: =SUBSTITUTE(C40,"-儿童（加收）","") -> 有创血流动力学监测费 | AH40: =IF(AF40>0,_xlfn.MAXIFS(N:N,C:C,SUBSTITUTE(C40,"-儿童（加收）","")),0)+N40 -> 15 | AI40: =IF(AF40>0,_xlfn.MAXIFS(O:O,C:C,SUBSTITUTE(C40,"-儿童（加收）","")),0)+O40 -> 14 | AJ40: =IF(AF40>0,_xlfn.MAXIFS(P:P,C:C,SUBSTITUTE(C40,"-儿童（加收）","")),0)+P40 -> 13
...

Sheet 改变收费方式
A1: 国家结算编码 | B1: 项目编码 | C1: 项目名称 | D1: 项目内涵 | E1: 除外内容 | F1: 计价单位 | G1: 说明 | H1: 价格 (市级) | I1: 价格 (县级) | J1: 价格 (基层) | K1: 现收费 (市级) | L1: 现收费 (县级) | M1: 现收费 (基层) | N1: 项目代码 | O1: 项目名称 | P1: 归集口径 | Q1: 服务产出 | R1: 价格构成 | S1: 计价单位 | T1: 计价说明 | U1: 拟定价格 (市级) | V1: 拟定价格 (县级) | W1: 拟定价格 (基层)
A2: 003308020040000-330802004 | B2: 330802004 | C2: 冠脉搭桥+换瓣术 | D2: 包括瓣成形术 | F2: 每支吻合血管 | G2: 每增一支市级医院加收540元，县级医院加收485元，基层加收415元 | H2: 9900 | I2: 8910 | J2: 7570 | K2: =U2+U3*0.5 -> 10600 | L2: =V2+V3*0.5 -> 9545 | M2: =W2+W3*0.5 -> 8115 | N2: 013308000310000 | O2: 冠状动脉旁路移植费 | P2: 手术费 | Q2: 通过人工血管或生物血管，连接狭窄冠状动脉的远端和主动脉。 | R2: 所定价格涵盖手术计划、术区准备、消毒、切开、吻合血管、缝合、处理用物等步骤所需的人力资源和基本物质资源消耗。 | S2: 次 | U2: 7950 | V2: 7160 | W2: 6090
N3: 013308000650000 | O3: 二尖瓣置换费 | P3: 手术费 | Q3: 通过手术对二尖瓣瓣膜进行替换。 | R3: 所定价格涵盖手术计划、术区准备、消毒、切开、置换、缝合、处理用物，必要时补片修补等步骤所需的人力资源和基本物质资源消耗。 | S3: 次 | U3: 5300 | V3: 4770 | W3: 4050
A4: 003308020040000-33080200402 | B4: 33080200402 | C4: 小儿冠脉搭桥+换瓣术 | F4: 每支吻合血管 | H4: 12870 | I4: 11585 | J4: 9845 | K4: =U4+U5+(U6+U7)*0.5 -> 13780 | L4: =V4+V5+(V6+V7)*0.5 -> 12410 | M4: =W4+W5+(W6+W7)*0.5 -> 10547.5 | N4: 013308000310000 | O4: 冠状动脉旁路移植费 | P4: 手术费 | Q4: 通过人工血管或生物血管，连接狭窄冠状动脉的远端和主动脉。 | R4: 所定价格涵盖手术计划、术区准备、消毒、切开、吻合血管、缝合、处理用物等步骤所需的人力资源和基本物质资源消耗。 | S4: 次 | U4: 7950 | V4: 7160 | W4: 6090
N5: 013308000310001 | O5: 冠状动脉旁路移植费-儿童（加收） | P5: 手术费 | S5: 次 | U5: 2385 | V5: 2150 | W5: 1825
N6: 013308000650000 | O6: 二尖瓣置换费 | P6: 手术费 | Q6: 通过手术对二尖瓣瓣膜进行替换。 | R6: 所定价格涵盖手术计划、术区准备、消毒、切开、置换、缝合、处理用物，必要时补片修补等步骤所需的人力资源和基本物质资源消耗。 | S6: 次 | U6: 5300 | V6: 4770 | W6: 4050
N7: 013308000650001 | O7: 二尖瓣置换费-儿童（加收） | P7: 手术费 | S7: 次 | U7: 1590 | V7: 1430 | W7: 1215
A8: 003308020050000-330802005 | B8: 330802005 | C8: 冠脉搭桥+人工血管置换术 | F8: 每支吻合血管 | G8: 每增一支市级医院加收540元，县级医院加收485元，基层加收415元 | H8: 10100 | I8: 9090 | J8: 7730 | K8: =U9+U8*0.5 -> 12640 | L8: =V9+V8*0.5 -> 11380 | M8: =W9+W8*0.5 -> 9675 | N8: 013308000310000 | O8: 冠状动脉旁路移植费 | P8: 手术费 | Q8: 通过人工血管或生物血管，连接狭窄冠状动脉的远端和主动脉。 | R8: 所定价格涵盖手术计划、术区准备、消毒、切开、吻合血管、缝合、处理用物等步骤所需的人力资源和基本物质资源消耗。 | S8: 次 | U8: 7950 | V8: 7160 | W8: 6090
N9: 013308000750000 | O9: 升主动脉替换费 | P9: 手术费 | Q9: 通过手术对升主动脉进行替换。 | R9: 所定价格涵盖手术计划、术区准备、消毒、切开、替换、缝合、处理用物，必要时补片修补等步骤所需的人力资源和基本物质资源消耗。 | S9: 次 | U9: 8665 | V9: 7800 | W9: 6630
A10: 003308020050000-33080200502 | B10: 33080200502 | C10: 小儿冠脉搭桥+人工血管置换术 | F10: 每支吻合血管 | H10: 13130 | I10: 11815 | J10: 10045 | K10: =U12+U13+(U10+U11)*0.5 -> 16432.5 | L10: =V12+V13+(V10+V11)*0.5 -> 14795 | M10: =W12+W13+(W10+W11)*0.5 -> 12577.5 | N10: 013308000310000 | O10: 冠状动脉旁路移植费 | P10: 手术费 | Q10: 通过人工血管或生物血管，连接狭窄冠状动脉的远端和主动脉。 | R10: 所定价格涵盖手术计划、术区准备、消毒、切开、吻合血管、缝合、处理用物等步骤所需的人力资源和基本物质资源消耗。 | S10: 次 | U10: 7950 | V10: 7160 | W10: 6090
N11: 013308000310001 | O11: 冠状动脉旁路移植费-儿童（加收） | P11: 手术费 | S11: 次 | U11: 2385 | V11: 2150 | W11: 1825
N12: 013308000750000 | O12: 升主动脉替换费 | P12: 手术费 | Q12: 通过手术对升主动脉进行替换。 | R12: 所定价格涵盖手术计划、术区准备、消毒、切开、替换、缝合、处理用物，必要时补片修补等步骤所需的人力资源和基本物质资源消耗。 | S12: 次 | U12: 8665 | V12: 7800 | W12: 6630
N13: 013308000750001 | O13: 升主动脉替换费-儿童（加收） | P13: 手术费 | S13: 次 | U13: 2600 | V13: 2340 | W13: 1990
A14: 003308020300000-330802030 | B14: 330802030 | C14: 升主动脉替换加主动脉瓣替换术（Wheat′s手术） | D14: 包括升主动脉替换加主动脉瓣替换 | F14: 次 | H14: 7480 | I14: 6730 | J14: 5380 | K14: =U14+U15*0.5 -> 11415 | L14: =V14+V15*0.5 -> 10275 | M14: =W14+W15*0.5 -> 8730 | N14: 013308000750000 | O14: 升主动脉替换费 | P14: 手术费 | Q14: 通过手术对升主动脉进行替换。 | R14: 所定价格涵盖手术计划、术区准备、消毒、切开、替换、缝合、处理用物，必要时补片修补等步骤所需的人力资源和基本物质资源消耗。 | S14: 次 | U14: 8665 | V14: 7800 | W14: 6630
N15: 013308000630000 | O15: 主动脉瓣置换费 | P15: 手术费 | Q15: 通过手术对主动脉瓣瓣膜进行替换。 | R15: 所定价格涵盖手术计划、术区准备、消毒、切开、置换、缝合、处理用物，必要时补片修补等步骤所需的人力资源和基本物质资源消耗。 | S15: 次 | T15: 双瓣置换术三甲医院12000元，三甲以下医院10800元。 | U15: 5500 | V15: 4950 | W15: 4200
A16: 003308020300000-33080203001 | B16: 33080203001 | C16: 小儿升主动脉替换加主动脉瓣替换术（Wheat′s手术） | F16: 次 | H16: 9725 | I16: 8750 | J16: 6995 | K16: =U16+U17+(U18+U19)*0.5 -> 14840 | L16: =V16+V17+(V18+V19)*0.5 -> 13357.5 | M16: =W16+W17+(W18+W19)*0.5 -> 11350 | N16: 013308000750000 | O16: 升主动脉替换费 | P16: 手术费 | Q16: 通过手术对升主动脉进行替换。 | R16: 所定价格涵盖手术计划、术区准备、消毒、切开、替换、缝合、处理用物，必要时补片修补等步骤所需的人力资源和基本物质资源消耗。 | S16: 次 | U16: 8665 | V16: 7800 | W16: 6630
N17: 013308000750001 | O17: 升主动脉替换费-儿童（加收） | P17: 手术费 | S17: 次 | U17: 2600 | V17: 2340 | W17: 1990
N18: 013308000630000 | O18: 主动脉瓣置换费 | P18: 手术费 | Q18: 通过手术对主动脉瓣瓣膜进行替换。 | R18: 所定价格涵盖手术计划、术区准备、消毒、切开、置换、缝合、处理用物，必要时补片修补等步骤所需的人力资源和基本物质资源消耗。 | S18: 次 | T18: 双瓣置换术三甲医院12000元，三甲以下医院10800元。 | U18: 5500 | V18: 4950 | W18: 4200
N19: 013308000630001 | O19: 主动脉瓣置换费-儿童（加收） | P19: 手术费 | S19: 次 | U19: 1650 | V19: 1485 | W19: 1260

Sheet Sheet1
A1: id | B1: code | C1: sever_type | D1: change_time | E1: old_hilist_code | F1: new_hilist_code | G1: hilist_name | H1: selfpay_prop | I1: old_price | J1: old_price_city | K1: old_price_town | L1: old_price_village | M1: new_price | N1: new_price_city | O1: new_price_town | P1: new_price_village | Q1: unit | R1: batch | S1: is_use_old | T1: merge_type | U1: cnt_change_model | V1: cnt_change_value | W1: ="insert into server_list_change_all_20250525 ("&_xlfn.TEXTJOIN(",",TRUE,A1:V1)&") values" -> insert into server_list_change_all_20250525 (id,code,sever_type,change_time,old_hilist_code,new_hilist_code,hilist_name,selfpay_prop,old_price,old_price_city,old_price_town,old_price_village,new_price,new_price_city,new_price_town,new_price_village,unit,batch,is_use_old,merge_type,cnt_change_model,cnt_change_value) values
A2: 1695 | B2: null | C2: 1 | D2: 2026-03-24 00:00:00 | E2: 003107010220000-310701022 | F2: 003107010220000-310701022 | G2: 心电监测 | H2: null | I2: null | J2: 4.5 | K2: 4.1 | L2: 3.4 | M2: null | N2: 4.75 | O2: 4.5 | P2: 4 | Q2: 小时 | R2: 23 | S2: 1 | T2: merge | U2: main | V2: 0 | W2: ="("&A2&","&B2&","&C2&",'"&D2&"','"&E2&"','"&F2&"','"&G2&"',"&H2&","&I2&","&J2&","&K2&","&L2&","&M2&","&N2&","&O2&","&P2&",'"&Q2&"',"&R2&","&S2&",'"&T2&"','"&U2&"',"&V2&")," -> (1695,null,1,'2026-03-24 00:00:00','003107010220000-310701022','003107010220000-310701022','心电监测',null,null,4.5,4.1,3.4,null,4.75,4.5,4,'小时',23,1,'merge','main',0),
A3: 1696 | B3: null | C3: 1 | D3: 2026-03-24 00:00:00 | E3: 003107010090000-310701009 | F3: 003107010090000-310701009 | G3: 心电监测电话传输 | H3: null | I3: null | J3: 57.5 | K3: 50 | L3: 42.5 | M3: null | N3: 180.5 | O3: 171 | P3: 152 | Q3: 日 | R3: 23 | S3: 1 | T3: merge | U3: main | V3: 0 | W3: ="("&A3&","&B3&","&C3&",'"&D3&"','"&E3&"','"&F3&"','"&G3&"',"&H3&","&I3&","&J3&","&K3&","&L3&","&M3&","&N3&","&O3&","&P3&",'"&Q3&"',"&R3&","&S3&",'"&T3&"','"&U3&"',"&V3&")," -> (1696,null,1,'2026-03-24 00:00:00','003107010090000-310701009','003107010090000-310701009','心电监测电话传输',null,null,57.5,50,42.5,null,180.5,171,152,'日',23,1,'merge','main',0),
A4: 1697 | B4: null | C4: 1 | D4: 2026-03-24 00:00:00 | E4: 003107010010000-310701001 | F4: 003107010010000-310701001 | G4: 常规心电图检查 | H4: null | I4: null | J4: 11.5 | K4: 10 | L4: 8.5 | M4: null | N4: 27 | O4: 25 | P4: 23 | Q4: 次 | R4: 23 | S4: 1 | T4: normal | U4: main | V4: 0 | W4: ="("&A4&","&B4&","&C4&",'"&D4&"','"&E4&"','"&F4&"','"&G4&"',"&H4&","&I4&","&J4&","&K4&","&L4&","&M4&","&N4&","&O4&","&P4&",'"&Q4&"',"&R4&","&S4&",'"&T4&"','"&U4&"',"&V4&")," -> (1697,null,1,'2026-03-24 00:00:00','003107010010000-310701001','003107010010000-310701001','常规心电图检查',null,null,11.5,10,8.5,null,27,25,23,'次',23,1,'normal','main',0),
A5: 1698 | B5: null | C5: 1 | D5: 2026-03-24 00:00:00 | E5: 003107010010002-31070100102 | F5: 003107010010002-31070100102 | G5: 常规心电图检查（十二通道加收） | H5: null | I5: null | J5: 11.5 | K5: 10 | L5: 8.5 | M5: null | N5: 0 | O5: 0 | P5: 0 | Q5: 次 | R5: 23 | S5: 1 | T5: normal | U5: main | V5: 0 | W5: ="("&A5&","&B5&","&C5&",'"&D5&"','"&E5&"','"&F5&"','"&G5&"',"&H5&","&I5&","&J5&","&K5&","&L5&","&M5&","&N5&","&O5&","&P5&",'"&Q5&"',"&R5&","&S5&",'"&T5&"','"&U5&"',"&V5&")," -> (1698,null,1,'2026-03-24 00:00:00','003107010010002-31070100102','003107010010002-31070100102','常规心电图检查（十二通道加收）',null,null,11.5,10,8.5,null,0,0,0,'次',23,1,'normal','main',0),
A6: 1699 | B6: null | C6: 1 | D6: 2026-03-24 00:00:00 | E6: 003107010010003-31070100103 | F6: 003107010010003-31070100103 | G6: 常规心电图检查（床边） | H6: null | I6: null | J6: 23 | K6: 20 | L6: 17 | M6: null | N6: 0 | O6: 0 | P6: 0 | Q6: 次 | R6: 23 | S6: 1 | T6: normal | U6: main | V6: 0 | W6: ="("&A6&","&B6&","&C6&",'"&D6&"','"&E6&"','"&F6&"','"&G6&"',"&H6&","&I6&","&J6&","&K6&","&L6&","&M6&","&N6&","&O6&","&P6&",'"&Q6&"',"&R6&","&S6&",'"&T6&"','"&U6&"',"&V6&")," -> (1699,null,1,'2026-03-24 00:00:00','003107010010003-31070100103','003107010010003-31070100103','常规心电图检查（床边）',null,null,23,20,17,null,0,0,0,'次',23,1,'normal','main',0),
A7: 1700 | B7: null | C7: 1 | D7: 2026-03-24 00:00:00 | E7: 003107010050000-310701005 | F7: 003107010050000-310701005 | G7: 标测心电图 | H7: null | I7: null | J7: 0 | K7: 0 | L7: 0 | M7: null | N7: 0 | O7: 0 | P7: 0 | Q7: 次 | R7: 23 | S7: 1 | T7: normal | U7: main | V7: 0 | W7: ="("&A7&","&B7&","&C7&",'"&D7&"','"&E7&"','"&F7&"','"&G7&"',"&H7&","&I7&","&J7&","&K7&","&L7&","&M7&","&N7&","&O7&","&P7&",'"&Q7&"',"&R7&","&S7&",'"&T7&"','"&U7&"',"&V7&")," -> (1700,null,1,'2026-03-24 00:00:00','003107010050000-310701005','003107010050000-310701005','标测心电图',null,null,0,0,0,null,0,0,0,'次',23,1,'normal','main',0),
A8: 1701 | B8: null | C8: 1 | D8: 2026-03-24 00:00:00 | E8: 003107010060000-310701006 | F8: 003107010060000-310701006 | G8: 体表窦房结心电图 | H8: null | I8: null | J8: 0 | K8: 0 | L8: 0 | M8: null | N8: 0 | O8: 0 | P8: 0 | Q8: 次 | R8: 23 | S8: 1 | T8: normal | U8: main | V8: 0 | W8: ="("&A8&","&B8&","&C8&",'"&D8&"','"&E8&"','"&F8&"','"&G8&"',"&H8&","&I8&","&J8&","&K8&","&L8&","&M8&","&N8&","&O8&","&P8&",'"&Q8&"',"&R8&","&S8&",'"&T8&"','"&U8&"',"&V8&")," -> (1701,null,1,'2026-03-24 00:00:00','003107010060000-310701006','003107010060000-310701006','体表窦房结心电图',null,null,0,0,0,null,0,0,0,'次',23,1,'normal','main',0),
A9: 1702 | B9: null | C9: 1 | D9: 2026-03-24 00:00:00 | E9: 003107010010001-31070100101 | F9: 003107010010001-31070100101 | G9: 常规心电图检查（附加导联加收） | H9: null | I9: null | J9: 2.3 | K9: 2 | L9: 1.7 | M9: null | N9: 2 | O9: 1.9 | P9: 1.8 | Q9: 次 | R9: 23 | S9: 1 | T9: normal | U9: main | V9: 0 | W9: ="("&A9&","&B9&","&C9&",'"&D9&"','"&E9&"','"&F9&"','"&G9&"',"&H9&","&I9&","&J9&","&K9&","&L9&","&M9&","&N9&","&O9&","&P9&",'"&Q9&"',"&R9&","&S9&",'"&T9&"','"&U9&"',"&V9&")," -> (1702,null,1,'2026-03-24 00:00:00','003107010010001-31070100101','003107010010001-31070100101','常规心电图检查（附加导联加收）',null,null,2.3,2,1.7,null,2,1.9,1.8,'次',23,1,'normal','main',0),
A10: 1703 | B10: null | C10: 1 | D10: 2026-03-24 00:00:00 | E10: 003107010150000-310701015 | F10: 003107010150000-310701015 | G10: 心室晚电位 | H10: null | I10: null | J10: 69 | K10: 60 | L10: 51 | M10: null | N10: 15 | O10: 14 | P10: 13 | Q10: 次 | R10: 23 | S10: 1 | T10: normal | U10: main | V10: 0 | W10: ="("&A10&","&B10&","&C10&",'"&D10&"','"&E10&"','"&F10&"','"&G10&"',"&H10&","&I10&","&J10&","&K10&","&L10&","&M10&","&N10&","&O10&","&P10&",'"&Q10&"',"&R10&","&S10&",'"&T10&"','"&U10&"',"&V10&")," -> (1703,null,1,'2026-03-24 00:00:00','003107010150000-310701015','003107010150000-310701015','心室晚电位',null,null,69,60,51,null,15,14,13,'次',23,1,'normal','main',0),
A11: 1704 | B11: null | C11: 1 | D11: 2026-03-24 00:00:00 | E11: 003107010160000-310701016 | F11: 003107010160000-310701016 | G11: 心房晚电位 | H11: null | I11: null | J11: 69 | K11: 60 | L11: 51 | M11: null | N11: 15 | O11: 14 | P11: 13 | Q11: 次 | R11: 23 | S11: 1 | T11: normal | U11: main | V11: 0 | W11: ="("&A11&","&B11&","&C11&",'"&D11&"','"&E11&"','"&F11&"','"&G11&"',"&H11&","&I11&","&J11&","&K11&","&L11&","&M11&","&N11&","&O11&","&P11&",'"&Q11&"',"&R11&","&S11&",'"&T11&"','"&U11&"',"&V11&")," -> (1704,null,1,'2026-03-24 00:00:00','003107010160000-310701016','003107010160000-310701016','心房晚电位',null,null,69,60,51,null,15,14,13,'次',23,1,'normal','main',0),
A12: 1705 | B12: null | C12: 1 | D12: 2026-03-24 00:00:00 | E12: 003107010120000-310701012 | F12: 003107010120000-310701012 | G12: 心电向量图 | H12: null | I12: null | J12: 34.5 | K12: 30 | L12: 25.5 | M12: null | N12: 27 | O12: 25 | P12: 23 | Q12: 次 | R12: 23 | S12: 1 | T12: normal | U12: main | V12: 0 | W12: ="("&A12&","&B12&","&C12&",'"&D12&"','"&E12&"','"&F12&"','"&G12&"',"&H12&","&I12&","&J12&","&K12&","&L12&","&M12&","&N12&","&O12&","&P12&",'"&Q12&"',"&R12&","&S12&",'"&T12&"','"&U12&"',"&V12&")," -> (1705,null,1,'2026-03-24 00:00:00','003107010120000-310701012','003107010120000-310701012','心电向量图',null,null,34.5,30,25.5,null,27,25,23,'次',23,1,'normal','main',0),
A13: 1706 | B13: null | C13: 1 | D13: 2026-03-24 00:00:00 | E13: 003107010040000-310701004 | F13: 003107010040000-310701004 | G13: 频谱心电图 | H13: null | I13: null | J13: 46 | K13: 40 | L13: 34 | M13: null | N13: 27 | O13: 25 | P13: 23 | Q13: 次 | R13: 23 | S13: 1 | T13: normal | U13: main | V13: 0 | W13: ="("&A13&","&B13&","&C13&",'"&D13&"','"&E13&"','"&F13&"','"&G13&"',"&H13&","&I13&","&J13&","&K13&","&L13&","&M13&","&N13&","&O13&","&P13&",'"&Q13&"',"&R13&","&S13&",'"&T13&"','"&U13&"',"&V13&")," -> (1706,null,1,'2026-03-24 00:00:00','003107010040000-310701004','003107010040000-310701004','频谱心电图',null,null,46,40,34,null,27,25,23,'次',23,1,'normal','main',0),
... A372: 2065 | B372: null | C372: 1 | D372: 2026-03-24 00:00:00 | E372: 003308010150000-33080101501 | F372: 003308010150000-33080101501 | G372: 小儿瓣周漏修补术 | H372: null | I372: null | J372: 6580 | K372: 5915 | L372: 5030 | M372: null | N372: 6760 | O372: 6110 | P372: 5200 | Q372: 次 | R372: 23 | S372: 1 | T372: normal | U372: main | V372: 0 | W372: ="("&A372&","&B372&","&C372&",'"&D372&"','"&E372&"','"&F372&"','"&G372&"',"&H372&","&I372&","&J372&","&K372&","&L372&","&M372&","&N372&","&O372&","&P372&",'"&Q372&"',"&R372&","&S372&",'"&T372&"','"&U372&"',"&V372&")," -> (2065,null,1,'2026-03-24 00:00:00','003308010150000-33080101501','003308010150000-33080101501','小儿瓣周漏修补术',null,null,6580,5915,5030,null,6760,6110,5200,'次',23,1,'normal','main',0),

Sheet Sheet2
A1: id | B1: server_list_id | C1: code | D1: old_hilist_code | E1: new_hilist_code | F1: hilist_name | G1: selfpay_prop | H1: old_price | I1: old_price_city | J1: old_price_town | K1: old_price_village | L1: new_price | M1: new_price_city | N1: new_price_town | O1: new_price_village | P1: unit | Q1: is_use_old | R1: is_main | S1: main_code | T1: ="insert into server_list_column_20250525 ("&_xlfn.TEXTJOIN(",",TRUE,A1:S1)&") values" -> insert into server_list_column_20250525 (id,server_list_id,code,old_hilist_code,new_hilist_code,hilist_name,selfpay_prop,old_price,old_price_city,old_price_town,old_price_village,new_price,new_price_city,new_price_town,new_price_village,unit,is_use_old,is_main,main_code) values
A2: 198 | B2: 1695 | C2: null | D2: 003107010220000-310701022 | E2: 003107010220000-310701022 | F2: 心电监测 | G2: null | H2: null | I2: 4.5 | J2: 4.1 | K2: 3.4 | L2: null | M2: 4.75 | N2: 4.5 | O2: 4 | P2: 小时 | Q2: 1 | R2: 1 | T2: ="("&A2&","&B2&","&C2&",'"&D2&"','"&E2&"','"&F2&"',"&G2&","&H2&","&I2&","&J2&","&K2&","&L2&","&M2&","&N2&","&O2&",'"&P2&"',"&Q2&","&R2&",'"&S2&"')," -> (198,1695,null,'003107010220000-310701022','003107010220000-310701022','心电监测',null,null,4.5,4.1,3.4,null,4.75,4.5,4,'小时',1,1,''),
A3: 199 | B3: 1695 | C3: null | D3: 003107010270000-310701027 | E3: 003107010270000-310701027 | F3: 指脉氧监测 | G3: null | H3: null | I3: 4.5 | J3: 4.1 | K3: 3.4 | L3: null | M3: 4.75 | N3: 4.5 | O3: 4 | P3: 小时 | Q3: 1 | R3: 1 | T3: ="("&A3&","&B3&","&C3&",'"&D3&"','"&E3&"','"&F3&"',"&G3&","&H3&","&I3&","&J3&","&K3&","&L3&","&M3&","&N3&","&O3&",'"&P3&"',"&Q3&","&R3&",'"&S3&"')," -> (199,1695,null,'003107010270000-310701027','003107010270000-310701027','指脉氧监测',null,null,4.5,4.1,3.4,null,4.75,4.5,4,'小时',1,1,''),
A4: 200 | B4: 1695 | C4: null | D4: 003107010280000-310701028 | E4: 003107010280000-310701028 | F4: 血氧饱和度监测 | G4: null | H4: null | I4: 4.5 | J4: 4.1 | K4: 3.4 | L4: null | M4: 4.75 | N4: 4.5 | O4: 4 | P4: 小时 | Q4: 1 | R4: 1 | T4: ="("&A4&","&B4&","&C4&",'"&D4&"','"&E4&"','"&F4&"',"&G4&","&H4&","&I4&","&J4&","&K4&","&L4&","&M4&","&N4&","&O4&",'"&P4&"',"&Q4&","&R4&",'"&S4&"')," -> (200,1695,null,'003107010280000-310701028','003107010280000-310701028','血氧饱和度监测',null,null,4.5,4.1,3.4,null,4.75,4.5,4,'小时',1,1,''),
A5: 201 | B5: 1695 | C5: null | D5: 003107010290000-310701033 | E5: 003107010290000-310701033 | F5: 经皮肢体氧分压测定 | G5: null | H5: null | I5: 70 | J5: 70 | K5: 59.5 | L5: null | M5: 9.5 | N5: 9 | O5: 8 | P5: 次 | Q5: 1 | R5: 1 | T5: ="("&A5&","&B5&","&C5&",'"&D5&"','"&E5&"','"&F5&"',"&G5&","&H5&","&I5&","&J5&","&K5&","&L5&","&M5&","&N5&","&O5&",'"&P5&"',"&Q5&","&R5&",'"&S5&"')," -> (201,1695,null,'003107010290000-310701033','003107010290000-310701033','经皮肢体氧分压测定',null,null,70,70,59.5,null,9.5,9,8,'次',1,1,''),
A6: 202 | B6: 1696 | C6: null | D6: 003107010090000-310701009 | E6: 003107010090000-310701009 | F6: 心电监测电话传输 | G6: null | H6: null | I6: 57.5 | J6: 50 | K6: 42.5 | L6: null | M6: 180.5 | N6: 171 | O6: 152 | P6: 日 | Q6: 1 | R6: 1 | T6: ="("&A6&","&B6&","&C6&",'"&D6&"','"&E6&"','"&F6&"',"&G6&","&H6&","&I6&","&J6&","&K6&","&L6&","&M6&","&N6&","&O6&",'"&P6&"',"&Q6&","&R6&",'"&S6&"')," -> (202,1696,null,'003107010090000-310701009','003107010090000-310701009','心电监测电话传输',null,null,57.5,50,42.5,null,180.5,171,152,'日',1,1,''),
A7: 203 | B7: 1696 | C7: null | D7: 003107010080000-310701008 | E7: 003107010080000-310701008 | F7: 遥测心电监护 | G7: null | H7: null | I7: 5.8 | J7: 5 | K7: 4.3 | L7: null | M7: 180.5 | N7: 171 | O7: 152 | P7: 小时 | Q7: 1 | R7: 0 | T7: ="("&A7&","&B7&","&C7&",'"&D7&"','"&E7&"','"&F7&"',"&G7&","&H7&","&I7&","&J7&","&K7&","&L7&","&M7&","&N7&","&O7&",'"&P7&"',"&Q7&","&R7&",'"&S7&"')," -> (203,1696,null,'003107010080000-310701008','003107010080000-310701008','遥测心电监护',null,null,5.8,5,4.3,null,180.5,171,152,'小时',1,0,''),

Sheet Sheet3
B1: A | C1: B | D1: C | E1: D | G1: E | H1: F | I1: G | J1: H | K1: I | L1: J | M1: K | N1: L | O1: M | P1: N | Q1: O | R1: P | S1: Q | T1: R | U1: S | V1: T | W1: U | X1: V | Y1: W | Z1: X | AA1: Y
B2: id | C2: list_type | D2: list_type_name | E2: old_hilist_code | G2: old_price | H2: old_price_city | I2: old_price_town | J2: old_price_village | K2: new_price | L2: new_price_city | M2: new_price_town | N2: new_price_village | O2: is_use_old | P2: is_main | Q2: cnt_change_model | R2: cnt_change_value | S2: 数量3 | T2: 数量2 | U2: 数量1 | V2: 预计差额3 | W2: 预计差额2 | X2: 预计差额1 | Y2: 实际差额3 | Z2: 实际差额2 | AA2: 实际差额1
A3: 129 | B3: 1695 | C3: 201 | D3: 服务项目 | E3: 003107010220000-310701022 | F3: =VLOOKUP(E3,Sheet1!E:G,3,0) -> 心电监测 | H3: 4.5 | I3: 4.1 | J3: 3.4 | L3: 4.75 | M3: 4.5 | N3: 4 | O3: 1 | P3: 1 | Q3: sum | R3: 0 | S3: 7412091 | T3: 6084372 | U3: 503570.23 | V3: 1853022.7 | W3: 2433748.8 | X3: 302142.14 | Y3: 1853024.2 | Z3: 2414171.4 | AA3: 302142.14 | AB3: =VLOOKUP(E3,'1'!V:W,2,0) -> 1
A4: 130 | B4: 1695 | C4: 201 | D4: 服务项目 | E4: 003107010270000-310701027 | F4: =VLOOKUP(E4,Sheet1!E:G,3,0) -> #N/A | H4: 4.5 | I4: 4.1 | J4: 3.4 | L4: 4.75 | M4: 4.5 | N4: 4 | O4: 1 | P4: 1 | Q4: sum | R4: 0 | S4: 745773.64 | T4: 1389709.9 | U4: 9599 | V4: 186443.41 | W4: 555883.95 | X4: 5759.4 | Y4: 186443.41 | Z4: 565663.16 | AA4: 5759.4 | AB4: =VLOOKUP(E4,'1'!V:W,2,0) -> 2
A5: 131 | B5: 1695 | C5: 201 | D5: 服务项目 | E5: 003107010280000-310701028 | F5: =VLOOKUP(E5,Sheet1!E:G,3,0) -> #N/A | H5: 4.5 | I5: 4.1 | J5: 3.4 | L5: 4.75 | M5: 4.5 | N5: 4 | O5: 1 | P5: 1 | Q5: sum | R5: 0 | S5: 8129172.9 | T5: 5537951.4 | U5: 505076.74 | V5: 2032293.2 | W5: 2215180.5 | X5: 303046.04 | Y5: 2032308.2 | Z5: 2183592.2 | AA5: 303046.05 | AB5: =VLOOKUP(E5,'1'!V:W,2,0) -> 3
A6: 128 | B6: 1695 | C6: 201 | D6: 服务项目 | E6: 003107010290000-310701033 | F6: =VLOOKUP(E6,Sheet1!E:G,3,0) -> #N/A | H6: 70 | I6: 70 | J6: 59.5 | L6: 4.75 | M6: 4.5 | N6: 4 | O6: 1 | P6: 1 | Q6: sum | R6: 0 | S6: 6217 | T6: 9530 | U6: 0 | V6: -405659.25 | W6: -624215 | X6: 0 | Y6: -405659.25 | Z6: -624215 | AA6: 0 | AB6: =VLOOKUP(E6,'1'!V:W,2,0) -> 4
A7: 132 | B7: 1696 | C7: 201 | D7: 服务项目 | E7: 003107010090000-310701009 | F7: =VLOOKUP(E7,Sheet1!E:G,3,0) -> 心电监测电话传输 | H7: 57.5 | I7: 50 | J7: 42.5 | L7: 180.5 | M7: 171 | N7: 152 | O7: 1 | P7: 1 | Q7: main | R7: 0 | S7: 2 | T7: 1 | U7: 0 | V7: 246 | W7: 121 | X7: 0 | Y7: 246 | Z7: 121 | AA7: 0 | AB7: =VLOOKUP(E7,'1'!V:W,2,0) -> 5
A8: 28 | B8: 0 | C8: 201 | D8: 服务项目 | E8: 003107010010000-310701001 | F8: =VLOOKUP(E8,Sheet1!E:G,3,0) -> 常规心电图检查 | H8: 11.5 | I8: 10 | J8: 8.5 | L8: 27 | M8: 25 | N8: 23 | O8: 1 | P8: 1 | Q8: main | R8: 0 | S8: 172048.75 | T8: 218444.57 | U8: 113107.6 | V8: 2666755.6 | W8: 3276668.5 | X8: 1640060.2 | Y8: 2666755.6 | Z8: 3268794.1 | AA8: 1640060.2 | AB8: =VLOOKUP(E8,'1'!V:W,2,0) -> 7
A9: 15 | B9: 0 | C9: 201 | D9: 服务项目 | E9: 003107010010002-31070100102 | F9: =VLOOKUP(E9,Sheet1!E:G,3,0) -> 常规心电图检查（十二通道加收） | H9: 11.5 | I9: 10 | J9: 8.5 | L9: 0 | M9: 0 | N9: 0 | O9: 1 | P9: 1 | Q9: main | R9: 0 | S9: 210531.41 | T9: 249270.66 | U9: 111632.3 | V9: -2421111.2 | W9: -2492706.6 | X9: -948874.55 | Y9: -2421111.2 | Z9: -2501025.5 | AA9: -948874.55 | AB9: =VLOOKUP(E9,'1'!V:W,2,0) -> 8
A10: 87 | B10: 0 | C10: 201 | D10: 服务项目 | E10: 003107010010003-31070100103 | F10: =VLOOKUP(E10,Sheet1!E:G,3,0) -> 常规心电图检查（床边） | H10: 23 | I10: 20 | J10: 17 | L10: 0 | M10: 0 | N10: 0 | O10: 1 | P10: 1 | Q10: main | R10: 0 | S10: 41294.763 | T10: 49956.232 | U10: 6406.8 | V10: -949779.55 | W10: -999124.65 | X10: -108915.6 | Y10: -949774.95 | Z10: -999517.85 | AA10: -106187.1 | AB10: =VLOOKUP(E10,'1'!V:W,2,0) -> 9
A11: 120 | B11: 0 | C11: 201 | D11: 服务项目 | E11: 003107010010001-31070100101 | F11: =VLOOKUP(E11,Sheet1!E:G,3,0) -> 常规心电图检查（附加导联加收） | H11: 2.3 | I11: 2 | J11: 1.7 | L11: 2 | M11: 1.9 | N11: 1.8 | O11: 1 | P11: 1 | Q11: main | R11: 0 | S11: 916 | T11: 9583 | U11: 2417.2 | V11: -274.8 | W11: -958.3 | X11: 241.72 | Y11: -274.8 | Z11: -1009 | AA11: 241.72 | AB11: =VLOOKUP(E11,'1'!V:W,2,0) -> 13
A12: 119 | B12: 0 | C12: 201 | D12: 服务项目 | E12: 003107010150000-310701015 | F12: =VLOOKUP(E12,Sheet1!E:G,3,0) -> 心室晚电位 | H12: 69 | I12: 60 | J12: 51 | L12: 15 | M12: 14 | N12: 13 | O12: 1 | P12: 1 | Q12: main | R12: 0 | S12: 0 | T12: 0 | U12: 197 | V12: 0 | W12: 0 | X12: -7486 | Y12: 0 | Z12: 0 | AA12: -7486 | AB12: =VLOOKUP(E12,'1'!V:W,2,0) -> 14
A13: 3 | B13: 0 | C13: 201 | D13: 服务项目 | E13: 003107010120000-310701012 | F13: =VLOOKUP(E13,Sheet1!E:G,3,0) -> 心电向量图 | H13: 34.5 | I13: 30 | J13: 25.5 | L13: 27 | M13: 25 | N13: 23 | O13: 1 | P13: 1 | Q13: main | R13: 0 | S13: 0 | T13: 0 | U13: 1 | V13: 0 | W13: 0 | X13: -2.5 | Y13: 0 | Z13: 0 | AA13: -2.5 | AB13: =VLOOKUP(E13,'1'!V:W,2,0) -> 16
A14: 105 | B14: 0 | C14: 201 | D14: 服务项目 | E14: 003107010180000-310701018 | F14: =VLOOKUP(E14,Sheet1!E:G,3,0) -> 心率变异性分析 | H14: 92 | I14: 80 | J14: 68 | L14: 80 | M14: 72 | N14: 65 | O14: 1 | P14: 1 | Q14: main | R14: 0 | S14: 22415.79 | T14: 14062.8 | U14: 2596.1 | V14: -268989.48 | W14: -112502.4 | X14: -7788.3 | Y14: -268989.48 | Z14: -110558.4 | AA14: -7788.3 | AB14: =VLOOKUP(E14,'1'!V:W,2,0) -> 18
... A134: 52 | B134: 0 | C134: 201 | D134: 服务项目 | E134: 003308020220000-330802022 | F134: =VLOOKUP(E134,Sheet1!E:G,3,0) -> 体静脉引流入肺静脉侧心房矫治术 | H134: 5060 | I134: 4550 | J134: 3870 | L134: 735 | M134: 665 | N134: 565 | O134: 1 | P134: 1 | Q134: main | R134: 0 | S134: 0 | T134: 2 | U134: 0 | V134: 0 | W134: -7770 | X134: 0 | Y134: 0 | Z134: -7770 | AA134: 0 | AB134: =VLOOKUP(E134,'1'!V:W,2,0) -> 444
