Workbook

Sheet 映射
A1: 疝甲乳类立项指南项目对应及拟定情况（征求意见稿）
A2: 疝甲乳立项指南项目 | U2: 现行项目
A3: 序号 | B3: 项目代码 | C3: 项目名称 | D3: 服务产出 | E3: 价格构成 | F3: 计价单位 | G3: 计价说明 | H3: 省三甲价格 | I3: 省三甲以下价格 | J3: 平移价格 (市级) | K3: 平移价格 (县级) | L3: 平移价格 (基层) | M3: 拟定价格 (市级) | N3: 拟定价格 (县级) | O3: 拟定价格 (基层) | P3: 医保 属性 | Q3: 医保限定支付范围 | R3: 个人先行自付比例 | S3: 调整情况 | T3: 备注 | U3: 国家结算编码 | V3: 项目代码 | W3: 项目名称 | X3: 项目内涵 | Y3: 除外内容 | Z3: 计价单位 | AA3: 说明 | AB3: 价格 (市级) | AC3: 价格 (县级) | AD3: 价格 (基层) | AE3: 医保属性
A4: 1 | B4: 013310001230000 | C4: 食管裂孔疝修补费 | D4: 通过手术对食管裂孔疝进行修补。 | E4: 所定价格涵盖手术计划、术区准备、消毒、切开、探查、分离、修补、固定、引流、冲洗、止血、缝合、处理用物，必要时行抗返流操作等步骤所需的人力资源和基本物质资源消耗。 | F4: 次 | G4: 如出现“复杂疝修补费”所称复杂情况，按“复杂疝修补费”收取。 | H4: 3000 | I4: 2700 | J4: 2694.7115 | K4: 2432.7273 | M4: 2700 | N4: 2435 | O4: 2070 | P4: 医保 | S4: 平移取整 | T4: 加权平移后取整 | U4: 003307030330000-330703033 | V4: 330703033 | W4: 先天性食管裂孔疝修补术 | X4: 含食管旁疝修补术；不含反流性食管狭窄扩张 | Z4: 次 | AA4: 合并肠回转不良及其他须矫治畸形者加收20% | AB4: 2250 | AC4: 2160 | AD4: 1836 | AE4: 医保
U5: 003307030330001-33070303301 | V5: 33070303301 | W5: 先天性食管裂孔疝修补术（合并肠回转不良及其他须矫治畸形者） | Z5: 次 | AA5: 合并肠回转不良及其他须矫治畸形者 | AB5: 2700 | AC5: 2592 | AD5: 2203.2 | AE5: 医保
U6: 003307030330000-33070303304 | V6: 33070303304 | W6: 经胸腔镜先天性食管裂孔疝修补术 | Z6: 次 | AB6: 2875 | AC6: 2760 | AD6: 2346 | AE6: 医保
U7: 003307030330001-33070303305 | V7: 33070303305 | W7: 经胸腔镜先天性食管裂孔疝修补术（合并肠回转不良及其他须矫治畸形者） | Z7: 次 | AA7: 合并肠回转不良及其他须矫治畸形者 | AB7: 3325 | AC7: 3192 | AD7: 2713.2 | AE7: 医保
U8: 003307030340000-330703034 | V8: 330703034 | W8: 食管裂孔疝修补术 | X8: 包括经腹、经胸各类修补术及抗返流手术 | Z8: 次 | AB8: 2250 | AC8: 2160 | AD8: 1836 | AE8: 医保
U9: 003307030340001-33070303402 | V9: 33070303402 | W9: 经胸腔镜食管裂孔疝修补术 | Z9: 次 | AB9: 2875 | AC9: 2760 | AD9: 2346 | AE9: 医保
A10: 分项 | B10: 013310001230001 | C10: 食管裂孔疝修补费-儿童（加收） | F10: 次 | H10: 900 | I10: 810 | M10: 810 | N10: 730 | O10: 620 | P10: 医保 | T10: 儿童加收30% | U10: 003307030330000-33070303302 | V10: 33070303302 | W10: 小儿先天性食管裂孔疝修补术 | Z10: 次 | AB10: 2925 | AC10: 2810 | AD10: 2390 | AE10: 医保
U11: 003307030330001-33070303303 | V11: 33070303303 | W11: 小儿先天性食管裂孔疝修补术（合并肠回转不良及其他须矫治畸形者） | Z11: 次 | AA11: 合并肠回转不良及其他须矫治畸形者 | AB11: 3510 | AC11: 3370 | AD11: 2865 | AE11: 医保
U12: 003307030330000-33070303306 | V12: 33070303306 | W12: 小儿经胸腔镜先天性食管裂孔疝修补术 | Z12: 次 | AB12: 3550 | AC12: 3410 | AD12: 2900 | AE12: 医保
U13: 003307030330001-33070303307 | V13: 33070303307 | W13: 小儿经胸腔镜先天性食管裂孔疝修补术（合并肠回转不良及其他须矫治畸形者） | Z13: 次 | AA13: 合并肠回转不良及其他须矫治畸形者 | AB13: 4135 | AC13: 3970 | AD13: 3375 | AE13: 医保
U14: 003307030340000-33070303401 | V14: 33070303401 | W14: 小儿食管裂孔疝修补术 | Z14: 次 | AB14: 2925 | AC14: 2810 | AD14: 2390 | AE14: 医保
U15: 003307030340001-33070303403 | V15: 33070303403 | W15: 小儿经胸腔镜食管裂孔疝修补术 | Z15: 次 | AB15: 3550 | AC15: 3410 | AD15: 2900 | AE15: 医保
A16: 2 | B16: 013310001240000 | C16: 腹壁疝修补费 | D16: 通过手术对切口疝、脐疝、腹白线疝、半月线疝等腹壁疝进行修补。 | E16: 所定价格涵盖手术计划、术区准备、消毒、切开、探查、分离、还纳、修补、引流、冲洗、止血、缝合、处理用物等步骤所需的人力资源和基本物质资源消耗。 | F16: 次 | G16: 如出现“复杂疝修补费”所称复杂情况，按“复杂疝修补费”收取。 | H16: 1700 | I16: 1530 | J16: 1549.0891 | K16: 1392.9114 | L16: 1197.3913 | M16: 1550 | N16: 1395 | O16: 1200 | P16: 医保 | S16: 平移取整 | T16: 加权平移后取整 | U16: 003310080040000-331008004 | V16: 331008004 | W16: 脐疝修补术 | Z16: 次 | AB16: 1000 | AC16: 960 | AD16: 816 | AE16: 医保
U17: 003310080040000-33100800402 | V17: 33100800402 | W17: 经腹腔镜脐疝修补术 | Z17: 次 | AB17: 1625 | AC17: 1560 | AD17: 1326 | AE17: 医保
U18: 003310080050000-331008005 | V18: 331008005 | W18: 腹壁切口疝修补术 | X18: 包括腹白线疝或腰疝修补 | Z18: 次 | AB18: 1125 | AC18: 1080 | AD18: 918 | AE18: 医保
U19: 003310080050000-33100800502 | V19: 33100800502 | W19: 经腹腔镜腹壁切口疝修补术 | Z19: 次 | AB19: 1750 | AC19: 1680 | AD19: 1428 | AE19: 医保
U20: 003310080040000-33100800401 | V20: 33100800401 | W20: 小儿脐疝修补术 | Z20: 次 | AB20: 1300 | AC20: 1250 | AD20: 1065 | AE20: 医保
U21: 003310080040000-33100800403 | V21: 33100800403 | W21: 小儿经腹腔镜脐疝修补术 | Z21: 次 | AB21: 1925 | AC21: 1850 | AD21: 1575 | AE21: 医保
U22: 003310080050000-33100800501 | V22: 33100800501 | W22: 小儿腹壁切口疝修补术 | Z22: 次 | AB22: 1465 | AC22: 1405 | AD22: 1195 | AE22: 医保
U23: 003310080050000-33100800503 | V23: 33100800503 | W23: 小儿经腹腔镜腹壁切口疝修补术 | Z23: 次 | AB23: 2090 | AC23: 2005 | AD23: 1705 | AE23: 医保
A24: 3 | B24: 013310001250000 | C24: 腹股沟疝修补费 | D24: 通过手术对腹股沟疝进行修补。 | E24: 所定价格涵盖手术计划、术区准备、消毒、切开、探查、分离、还纳、修补/结扎、引流、冲洗、止血、缝合、处理用物等步骤所需的人力资源和基本物质资源消耗。 | F24: 单侧 | G24: 如出现“复杂疝修补费”所称复杂情况，按“复杂疝修补费”收取。 | H24: 1600 | I24: 1440 | J24: 1498.5756 | K24: 1469.1633 | L24: 1188.8656 | M24: 1500 | N24: 1430 | O24: 1200 | P24: 医保 | S24: 平移取整 | T24: 加权平移后取整，县级按不高于省级调整，基层对应调整 | U24: 003310080010000-331008001 | V24: 331008001 | W24: 腹股沟疝修补术 | X24: 包括各种方法修补 | Z24: 单侧 | AB24: 1000 | AC24: 960 | AD24: 816 | AE24: 医保
U25: 003310080010001-33100800102 | V25: 33100800102 | W25: 经腹腔镜腹股沟疝修补术 | Z25: 单侧 | AB25: 1625 | AC25: 1560 | AD25: 1326 | AE25: 医保
U26: 003310080030000-331008003 | V26: 331008003 | W26: 充填式无张力疝修补术 | Y26: 填充物 | Z26: 单侧 | AB26: 1125 | AC26: 1080 | AD26: 918 | AE26: 医保
U27: 003310080030000-33100800302 | V27: 33100800302 | W27: 经腹腔镜充填式无张力疝修补术 | Z27: 单侧 | AB27: 1750 | AC27: 1680 | AD27: 1428 | AE27: 医保
A28: 分项 | B28: 013310001250001 | C28: 腹股沟疝修补费-儿童（加收） | F28: 单侧 | H28: 480 | I28: 432 | J28: 407.28883 | K28: 357.01068 | L28: 341 | M28: 450 | N28: 430 | O28: 360 | P28: 医保 | T28: 儿童加收30% | U28: 003310080010000-33100800101 | V28: 33100800101 | W28: 小儿腹股沟疝修补术 | Z28: 单侧 | AB28: 1300 | AC28: 1250 | AD28: 1065 | AE28: 医保
U29: 003310080010001-33100800103 | V29: 33100800103 | W29: 小儿经腹腔镜腹股沟疝修补术 | Z29: 单侧 | AB29: 1925 | AC29: 1850 | AD29: 1575 | AE29: 医保
U30: 003310080030000-33100800301 | V30: 33100800301 | W30: 小儿充填式无张力疝修补术 | Z30: 单侧 | AB30: 1465 | AC30: 1405 | AD30: 1195 | AE30: 医保
U31: 003310080030000-33100800303 | V31: 33100800303 | W31: 小儿经腹腔镜充填式无张力疝修补术 | Z31: 单侧 | AB31: 2090 | AC31: 2005 | AD31: 1705 | AE31: 医保
A32: 4 | B32: 013310001260000 | C32: 盆底疝修补费 | D32: 通过手术对会阴疝、坐骨孔疝、闭孔疝等盆底疝进行修补。 | E32: 所定价格涵盖手术计划、术区准备、消毒、切开、探查、分离、还纳、修补、引流、冲洗、止血、缝合、处理用物等步骤所需的人力资源和基本物质资源消耗。 | F32: 次 | G32: 如出现“复杂疝修补费”所称复杂情况，按“复杂疝修补费”收取。 | H32: 1900 | I32: 1710 | J32: 1000 | K32: 960 | L32: 816 | M32: 1700 | N32: 1530 | O32: 1300 | P32: 医保 | S32: 提高 | T32: 省级根据区域间和项目间比价关系调高（我省价格在全国低位），我市根据比价关系提高（开展量仅1.5例） | U32: 003310080060000-331008006 | V32: 331008006 | W32: 会阴疝修补术 | Z32: 次 | AB32: 1000 | AC32: 960 | AD32: 816 | AE32: 医保
A33: 分项 | B33: 013310001260001 | C33: 盆底疝修补费-儿童（加收） | F33: 次 | H33: 570 | I33: 513 | M33: 510 | N33: 459 | O33: 390 | P33: 医保 | U33: 003310080060000-33100800601 | V33: 33100800601 | W33: 小儿会阴疝修补术 | Z33: 次 | AB33: 1300 | AC33: 1250 | AD33: 1065 | AE33: 医保
A34: 5 | B34: 013310001270000 | C34: 造口旁疝修补费 | D34: 通过手术对造口旁疝进行修补。 | E34: 所定价格涵盖手术计划、术区准备、消毒、切开、探查、分离、还纳、修补、引流、冲洗、止血、缝合、处理用物等步骤所需的人力资源和基本物质资源消耗。 | F34: 次 | G34: 如出现“复杂疝修补费”所称复杂情况，按“复杂疝修补费”收取。 | H34: 1900 | I34: 1710 | M34: 1700 | N34: 1530 | O34: 1300 | P34: 医保 | S34: 新增 | T34: 新增项目，按项目间比价关系，与盆底疝修补费持平定价 | AE34: 医保
A35: 分项 | B35: 013310001270001 | C35: 造口旁疝修补费-儿童（加收） | F35: 次 | H35: 570 | I35: 513 | M35: 510 | N35: 459 | O35: 390 | P35: 医保 | T35: 儿童加收30% | U35: 003310080050000-33100800501 | V35: 33100800501 | W35: 小儿腹壁切口疝修补术 | Z35: 次 | AB35: 1465 | AC35: 1405 | AD35: 1195 | AE35: 医保
U36: 003310080050000-33100800503 | V36: 33100800503 | W36: 小儿经腹腔镜腹壁切口疝修补术 | Z36: 次 | AB36: 2090 | AC36: 2005 | AD36: 1705 | AE36: 医保
A37: 6 | B37: 013310001280000 | C37: 腹内疝修补费 | D37: 通过手术对腹内疝进行修补。 | E37: 所定价格涵盖手术计划、术区准备、消毒、切开、探查、分离、松解、还纳、修补、引流、冲洗、止血、缝合、处理用物等步骤所需的人力资源和基本物质资源消耗。 | F37: 次 | G37: 1.本项目中的“腹内疝”指：系膜裂孔疝、网膜裂孔疝、腹膜隐窝疝等。 2.如出现“复杂疝修补费”所称复杂情况，按“复杂疝修补费”收取。 | H37: 1900 | I37: 1710 | M37: 1700 | N37: 1530 | O37: 1300 | P37: 医保 | R37: 0.2 | S37: 新增 | T37: 新增项目，按项目间比价关系，与盆底疝修补费持平定价
A38: 分项 | B38: 013310001280001 | C38: 腹内疝修补费-儿童（加收） | F38: 次 | H38: 570 | I38: 513 | M38: 510 | N38: 459 | O38: 390 | P38: 医保 | R38: 0.2 | T38: 儿童加收30%
A39: 7 | B39: 013310001290000 | C39: 复杂疝修补费 | D39: 通过手术对各类疝的复杂情况进行修补。 | E39: 所定价格涵盖手术计划、术区准备、消毒、切开、探查、分离、还纳、修补、引流、冲洗、止血、缝合、处理用物等步骤所需的人力资源和基本物质资源消耗。 | F39: 次 | G39: 本项目中的“复杂”指：“巨大疝（疝环大于12cm以上）、嵌顿坏死、合并腹水、复发疝、多发疝、边缘性腹壁疝”的疝修补。 | H39: 2400 | I39: 2160 | J39: 1125 | K39: 1080 | L39: 918 | M39: 2150 | N39: 1930 | O39: 1640 | P39: 医保 | S39: 提高 | T39: 省级根据区域间和项目间比价关系调高（我省价格在全国低位），我市根据比价关系提高 | U39: 003310080020000-331008002 | V39: 331008002 | W39: 嵌顿疝复位修补术 | X39: 不含肠切除吻合 | Z39: 单侧 | AB39: 1125 | AC39: 1080 | AD39: 918 | AE39: 医保
A40: 分项 | B40: 013310001290001 | C40: 复杂疝修补费-儿童（加收） | F40: 次 | H40: 720 | I40: 648 | J40: -685 | K40: -525 | L40: -445 | M40: 645 | N40: 580 | O40: 495 | P40: 医保 | T40: 儿童加收30% | U40: 003310080020000-33100800201 | V40: 33100800201 | W40: 小儿嵌顿疝复位修补术 | Z40: 单侧 | AB40: 1465 | AC40: 1405 | AD40: 1195 | AE40: 医保
...

Sheet 映射 (3)
A1: 疝甲乳类立项指南项目对应及拟定情况（征求意见稿）
A2: 疝甲乳立项指南项目 | V2: 现行项目
A3: 序号 | B3: 项目代码 | C3: 项目名称 | D3: 服务产出 | E3: 价格构成 | G3: 计价单位 | H3: 计价说明 | I3: 省三甲价格 | J3: 省三甲以下价格 | K3: 平移价格 (市级) | L3: 平移价格 (县级) | M3: 平移价格 (基层) | N3: 拟定价格 (市级) | O3: 拟定价格 (县级) | P3: 拟定价格 (基层) | Q3: 医保 属性 | R3: 医保限定支付范围 | S3: 个人先行自付比例 | T3: 调整情况 | U3: 备注 | V3: 国家结算编码 | W3: 项目代码 | X3: 项目名称 | Y3: 项目内涵 | Z3: 除外内容 | AA3: 计价单位 | AB3: 说明 | AC3: 价格 (市级) | AD3: 价格 (县级) | AE3: 价格 (基层)
A4: 1 | B4: 013310001230000 | C4: 食管裂孔疝修补费 | D4: 通过手术对食管裂孔疝进行修补。 | E4: 所定价格涵盖手术计划、术区准备、消毒、切开、探查、分离、修补、固定、引流、冲洗、止血、缝合、处理用物，必要时行抗返流操作等步骤所需的人力资源和基本物质资源消耗。 | G4: 次 | H4: 如出现“复杂疝修补费”所称复杂情况，按“复杂疝修补费”收取。 | I4: 3000 | J4: 2700 | K4: 2694.7115 | L4: 2432.7273 | N4: 2700 | O4: 2435 | P4: 2070 | Q4: 医保 | T4: 平移取整 | U4: 加权平移后取整 | V4: 003307030330000-330703033 | W4: 330703033 | X4: 先天性食管裂孔疝修补术 | Y4: 含食管旁疝修补术；不含反流性食管狭窄扩张 | AA4: 次 | AB4: 合并肠回转不良及其他须矫治畸形者加收20% | AC4: 2250 | AD4: 2160 | AE4: 1836 | AF4: =IFERROR(FIND("-儿童（加收）",C4,1),0) -> 0 | AG4: =SUBSTITUTE(C4,"-儿童（加收）","") -> 食管裂孔疝修补费 | AH4: =IF(AF4>0,_xlfn.MAXIFS(N:N,C:C,SUBSTITUTE(C4,"-儿童（加收）","")),0)+N4 -> 2700 | AI4: =IF(AF4>0,_xlfn.MAXIFS(O:O,C:C,SUBSTITUTE(C4,"-儿童（加收）","")),0)+O4 -> 2435 | AJ4: =IF(AF4>0,_xlfn.MAXIFS(P:P,C:C,SUBSTITUTE(C4,"-儿童（加收）","")),0)+P4 -> 2070 | AK4: =VLOOKUP(V4,Sheet2!E:E,1,0) -> 003307030330000-330703033
C5: 食管裂孔疝修补费 | N5: 2700 | O5: 2435 | P5: 2070 | V5: 003307030330001-33070303301 | W5: 33070303301 | X5: 先天性食管裂孔疝修补术（合并肠回转不良及其他须矫治畸形者） | AA5: 次 | AB5: 合并肠回转不良及其他须矫治畸形者 | AC5: 2700 | AD5: 2592 | AE5: 2203.2 | AF5: =IFERROR(FIND("-儿童（加收）",C5,1),0) -> 0 | AG5: =SUBSTITUTE(C5,"-儿童（加收）","") -> 食管裂孔疝修补费 | AH5: =IF(AF5>0,_xlfn.MAXIFS(N:N,C:C,SUBSTITUTE(C5,"-儿童（加收）","")),0)+N5 -> 2700 | AI5: =IF(AF5>0,_xlfn.MAXIFS(O:O,C:C,SUBSTITUTE(C5,"-儿童（加收）","")),0)+O5 -> 2435 | AJ5: =IF(AF5>0,_xlfn.MAXIFS(P:P,C:C,SUBSTITUTE(C5,"-儿童（加收）","")),0)+P5 -> 2070 | AK5: =VLOOKUP(V5,Sheet2!E:E,1,0) -> 003307030330001-33070303301
C6: 食管裂孔疝修补费 | N6: 2700 | O6: 2435 | P6: 2070 | V6: 003307030330000-33070303304 | W6: 33070303304 | X6: 经胸腔镜先天性食管裂孔疝修补术 | AA6: 次 | AC6: 2875 | AD6: 2760 | AE6: 2346 | AF6: =IFERROR(FIND("-儿童（加收）",C6,1),0) -> 0 | AG6: =SUBSTITUTE(C6,"-儿童（加收）","") -> 食管裂孔疝修补费 | AH6: =IF(AF6>0,_xlfn.MAXIFS(N:N,C:C,SUBSTITUTE(C6,"-儿童（加收）","")),0)+N6 -> 2700 | AI6: =IF(AF6>0,_xlfn.MAXIFS(O:O,C:C,SUBSTITUTE(C6,"-儿童（加收）","")),0)+O6 -> 2435 | AJ6: =IF(AF6>0,_xlfn.MAXIFS(P:P,C:C,SUBSTITUTE(C6,"-儿童（加收）","")),0)+P6 -> 2070 | AK6: =VLOOKUP(V6,Sheet2!E:E,1,0) -> 003307030330000-33070303304
C7: 食管裂孔疝修补费 | N7: 2700 | O7: 2435 | P7: 2070 | V7: 003307030330001-33070303305 | W7: 33070303305 | X7: 经胸腔镜先天性食管裂孔疝修补术（合并肠回转不良及其他须矫治畸形者） | AA7: 次 | AB7: 合并肠回转不良及其他须矫治畸形者 | AC7: 3325 | AD7: 3192 | AE7: 2713.2 | AF7: =IFERROR(FIND("-儿童（加收）",C7,1),0) -> 0 | AG7: =SUBSTITUTE(C7,"-儿童（加收）","") -> 食管裂孔疝修补费 | AH7: =IF(AF7>0,_xlfn.MAXIFS(N:N,C:C,SUBSTITUTE(C7,"-儿童（加收）","")),0)+N7 -> 2700 | AI7: =IF(AF7>0,_xlfn.MAXIFS(O:O,C:C,SUBSTITUTE(C7,"-儿童（加收）","")),0)+O7 -> 2435 | AJ7: =IF(AF7>0,_xlfn.MAXIFS(P:P,C:C,SUBSTITUTE(C7,"-儿童（加收）","")),0)+P7 -> 2070 | AK7: =VLOOKUP(V7,Sheet2!E:E,1,0) -> 003307030330001-33070303305
C8: 食管裂孔疝修补费 | N8: 2700 | O8: 2435 | P8: 2070 | V8: 003307030340000-330703034 | W8: 330703034 | X8: 食管裂孔疝修补术 | Y8: 包括经腹、经胸各类修补术及抗返流手术 | AA8: 次 | AC8: 2250 | AD8: 2160 | AE8: 1836 | AF8: =IFERROR(FIND("-儿童（加收）",C8,1),0) -> 0 | AG8: =SUBSTITUTE(C8,"-儿童（加收）","") -> 食管裂孔疝修补费 | AH8: =IF(AF8>0,_xlfn.MAXIFS(N:N,C:C,SUBSTITUTE(C8,"-儿童（加收）","")),0)+N8 -> 2700 | AI8: =IF(AF8>0,_xlfn.MAXIFS(O:O,C:C,SUBSTITUTE(C8,"-儿童（加收）","")),0)+O8 -> 2435 | AJ8: =IF(AF8>0,_xlfn.MAXIFS(P:P,C:C,SUBSTITUTE(C8,"-儿童（加收）","")),0)+P8 -> 2070 | AK8: =VLOOKUP(V8,Sheet2!E:E,1,0) -> 003307030340000-330703034
C9: 食管裂孔疝修补费 | N9: 2700 | O9: 2435 | P9: 2070 | V9: 003307030340001-33070303402 | W9: 33070303402 | X9: 经胸腔镜食管裂孔疝修补术 | AA9: 次 | AC9: 2875 | AD9: 2760 | AE9: 2346 | AF9: =IFERROR(FIND("-儿童（加收）",C9,1),0) -> 0 | AG9: =SUBSTITUTE(C9,"-儿童（加收）","") -> 食管裂孔疝修补费 | AH9: =IF(AF9>0,_xlfn.MAXIFS(N:N,C:C,SUBSTITUTE(C9,"-儿童（加收）","")),0)+N9 -> 2700 | AI9: =IF(AF9>0,_xlfn.MAXIFS(O:O,C:C,SUBSTITUTE(C9,"-儿童（加收）","")),0)+O9 -> 2435 | AJ9: =IF(AF9>0,_xlfn.MAXIFS(P:P,C:C,SUBSTITUTE(C9,"-儿童（加收）","")),0)+P9 -> 2070 | AK9: =VLOOKUP(V9,Sheet2!E:E,1,0) -> 003307030340001-33070303402
A10: 分项 | B10: 013310001230001 | C10: 食管裂孔疝修补费-儿童（加收） | G10: 次 | I10: 900 | J10: 810 | N10: 810 | O10: 730 | P10: 620 | Q10: 医保 | U10: 儿童加收30% | V10: 003307030330000-33070303302 | W10: 33070303302 | X10: 小儿先天性食管裂孔疝修补术 | AA10: 次 | AC10: 2925 | AD10: 2810 | AE10: 2390 | AF10: =IFERROR(FIND("-儿童（加收）",C10,1),0) -> 9 | AG10: =SUBSTITUTE(C10,"-儿童（加收）","") -> 食管裂孔疝修补费 | AH10: =IF(AF10>0,_xlfn.MAXIFS(N:N,C:C,SUBSTITUTE(C10,"-儿童（加收）","")),0)+N10 -> 3510 | AI10: =IF(AF10>0,_xlfn.MAXIFS(O:O,C:C,SUBSTITUTE(C10,"-儿童（加收）","")),0)+O10 -> 3165 | AJ10: =IF(AF10>0,_xlfn.MAXIFS(P:P,C:C,SUBSTITUTE(C10,"-儿童（加收）","")),0)+P10 -> 2690 | AK10: =VLOOKUP(V10,Sheet2!E:E,1,0) -> 003307030330000-33070303302
C11: 食管裂孔疝修补费-儿童（加收） | N11: 810 | O11: 730 | P11: 620 | V11: 003307030330001-33070303303 | W11: 33070303303 | X11: 小儿先天性食管裂孔疝修补术（合并肠回转不良及其他须矫治畸形者） | AA11: 次 | AB11: 合并肠回转不良及其他须矫治畸形者 | AC11: 3510 | AD11: 3370 | AE11: 2865 | AF11: =IFERROR(FIND("-儿童（加收）",C11,1),0) -> 9 | AG11: =SUBSTITUTE(C11,"-儿童（加收）","") -> 食管裂孔疝修补费 | AH11: =IF(AF11>0,_xlfn.MAXIFS(N:N,C:C,SUBSTITUTE(C11,"-儿童（加收）","")),0)+N11 -> 3510 | AI11: =IF(AF11>0,_xlfn.MAXIFS(O:O,C:C,SUBSTITUTE(C11,"-儿童（加收）","")),0)+O11 -> 3165 | AJ11: =IF(AF11>0,_xlfn.MAXIFS(P:P,C:C,SUBSTITUTE(C11,"-儿童（加收）","")),0)+P11 -> 2690 | AK11: =VLOOKUP(V11,Sheet2!E:E,1,0) -> 003307030330001-33070303303
C12: 食管裂孔疝修补费-儿童（加收） | N12: 810 | O12: 730 | P12: 620 | V12: 003307030330000-33070303306 | W12: 33070303306 | X12: 小儿经胸腔镜先天性食管裂孔疝修补术 | AA12: 次 | AC12: 3550 | AD12: 3410 | AE12: 2900 | AF12: =IFERROR(FIND("-儿童（加收）",C12,1),0) -> 9 | AG12: =SUBSTITUTE(C12,"-儿童（加收）","") -> 食管裂孔疝修补费 | AH12: =IF(AF12>0,_xlfn.MAXIFS(N:N,C:C,SUBSTITUTE(C12,"-儿童（加收）","")),0)+N12 -> 3510 | AI12: =IF(AF12>0,_xlfn.MAXIFS(O:O,C:C,SUBSTITUTE(C12,"-儿童（加收）","")),0)+O12 -> 3165 | AJ12: =IF(AF12>0,_xlfn.MAXIFS(P:P,C:C,SUBSTITUTE(C12,"-儿童（加收）","")),0)+P12 -> 2690 | AK12: =VLOOKUP(V12,Sheet2!E:E,1,0) -> 003307030330000-33070303306
C13: 食管裂孔疝修补费-儿童（加收） | N13: 810 | O13: 730 | P13: 620 | V13: 003307030330001-33070303307 | W13: 33070303307 | X13: 小儿经胸腔镜先天性食管裂孔疝修补术（合并肠回转不良及其他须矫治畸形者） | AA13: 次 | AB13: 合并肠回转不良及其他须矫治畸形者 | AC13: 4135 | AD13: 3970 | AE13: 3375 | AF13: =IFERROR(FIND("-儿童（加收）",C13,1),0) -> 9 | AG13: =SUBSTITUTE(C13,"-儿童（加收）","") -> 食管裂孔疝修补费 | AH13: =IF(AF13>0,_xlfn.MAXIFS(N:N,C:C,SUBSTITUTE(C13,"-儿童（加收）","")),0)+N13 -> 3510 | AI13: =IF(AF13>0,_xlfn.MAXIFS(O:O,C:C,SUBSTITUTE(C13,"-儿童（加收）","")),0)+O13 -> 3165 | AJ13: =IF(AF13>0,_xlfn.MAXIFS(P:P,C:C,SUBSTITUTE(C13,"-儿童（加收）","")),0)+P13 -> 2690 | AK13: =VLOOKUP(V13,Sheet2!E:E,1,0) -> 003307030330001-33070303307
C14: 食管裂孔疝修补费-儿童（加收） | N14: 810 | O14: 730 | P14: 620 | V14: 003307030340000-33070303401 | W14: 33070303401 | X14: 小儿食管裂孔疝修补术 | AA14: 次 | AC14: 2925 | AD14: 2810 | AE14: 2390 | AF14: =IFERROR(FIND("-儿童（加收）",C14,1),0) -> 9 | AG14: =SUBSTITUTE(C14,"-儿童（加收）","") -> 食管裂孔疝修补费 | AH14: =IF(AF14>0,_xlfn.MAXIFS(N:N,C:C,SUBSTITUTE(C14,"-儿童（加收）","")),0)+N14 -> 3510 | AI14: =IF(AF14>0,_xlfn.MAXIFS(O:O,C:C,SUBSTITUTE(C14,"-儿童（加收）","")),0)+O14 -> 3165 | AJ14: =IF(AF14>0,_xlfn.MAXIFS(P:P,C:C,SUBSTITUTE(C14,"-儿童（加收）","")),0)+P14 -> 2690 | AK14: =VLOOKUP(V14,Sheet2!E:E,1,0) -> 003307030340000-33070303401
C15: 食管裂孔疝修补费-儿童（加收） | N15: 810 | O15: 730 | P15: 620 | V15: 003307030340001-33070303403 | W15: 33070303403 | X15: 小儿经胸腔镜食管裂孔疝修补术 | AA15: 次 | AC15: 3550 | AD15: 3410 | AE15: 2900 | AF15: =IFERROR(FIND("-儿童（加收）",C15,1),0) -> 9 | AG15: =SUBSTITUTE(C15,"-儿童（加收）","") -> 食管裂孔疝修补费 | AH15: =IF(AF15>0,_xlfn.MAXIFS(N:N,C:C,SUBSTITUTE(C15,"-儿童（加收）","")),0)+N15 -> 3510 | AI15: =IF(AF15>0,_xlfn.MAXIFS(O:O,C:C,SUBSTITUTE(C15,"-儿童（加收）","")),0)+O15 -> 3165 | AJ15: =IF(AF15>0,_xlfn.MAXIFS(P:P,C:C,SUBSTITUTE(C15,"-儿童（加收）","")),0)+P15 -> 2690 | AK15: =VLOOKUP(V15,Sheet2!E:E,1,0) -> 003307030340001-33070303403
A16: 2 | B16: 013310001240000 | C16: 腹壁疝修补费 | D16: 通过手术对切口疝、脐疝、腹白线疝、半月线疝等腹壁疝进行修补。 | E16: 所定价格涵盖手术计划、术区准备、消毒、切开、探查、分离、还纳、修补、引流、冲洗、止血、缝合、处理用物等步骤所需的人力资源和基本物质资源消耗。 | G16: 次 | H16: 如出现“复杂疝修补费”所称复杂情况，按“复杂疝修补费”收取。 | I16: 1700 | J16: 1530 | K16: 1549.0891 | L16: 1392.9114 | M16: 1197.3913 | N16: 1550 | O16: 1395 | P16: 1200 | Q16: 医保 | T16: 平移取整 | U16: 加权平移后取整 | V16: 003310080040000-331008004 | W16: 331008004 | X16: 脐疝修补术 | AA16: 次 | AC16: 1000 | AD16: 960 | AE16: 816 | AF16: =IFERROR(FIND("-儿童（加收）",C16,1),0) -> 0 | AG16: =SUBSTITUTE(C16,"-儿童（加收）","") -> 腹壁疝修补费 | AH16: =IF(AF16>0,_xlfn.MAXIFS(N:N,C:C,SUBSTITUTE(C16,"-儿童（加收）","")),0)+N16 -> 1550 | AI16: =IF(AF16>0,_xlfn.MAXIFS(O:O,C:C,SUBSTITUTE(C16,"-儿童（加收）","")),0)+O16 -> 1395 | AJ16: =IF(AF16>0,_xlfn.MAXIFS(P:P,C:C,SUBSTITUTE(C16,"-儿童（加收）","")),0)+P16 -> 1200 | AK16: =VLOOKUP(V16,Sheet2!E:E,1,0) -> 003310080040000-331008004
C17: 腹壁疝修补费 | N17: 1550 | O17: 1395 | P17: 1200 | V17: 003310080040000-33100800402 | W17: 33100800402 | X17: 经腹腔镜脐疝修补术 | AA17: 次 | AC17: 1625 | AD17: 1560 | AE17: 1326 | AF17: =IFERROR(FIND("-儿童（加收）",C17,1),0) -> 0 | AG17: =SUBSTITUTE(C17,"-儿童（加收）","") -> 腹壁疝修补费 | AH17: =IF(AF17>0,_xlfn.MAXIFS(N:N,C:C,SUBSTITUTE(C17,"-儿童（加收）","")),0)+N17 -> 1550 | AI17: =IF(AF17>0,_xlfn.MAXIFS(O:O,C:C,SUBSTITUTE(C17,"-儿童（加收）","")),0)+O17 -> 1395 | AJ17: =IF(AF17>0,_xlfn.MAXIFS(P:P,C:C,SUBSTITUTE(C17,"-儿童（加收）","")),0)+P17 -> 1200 | AK17: =VLOOKUP(V17,Sheet2!E:E,1,0) -> 003310080040000-33100800402
C18: 腹壁疝修补费 | N18: 1550 | O18: 1395 | P18: 1200 | V18: 003310080050000-331008005 | W18: 331008005 | X18: 腹壁切口疝修补术 | Y18: 包括腹白线疝或腰疝修补 | AA18: 次 | AC18: 1125 | AD18: 1080 | AE18: 918 | AF18: =IFERROR(FIND("-儿童（加收）",C18,1),0) -> 0 | AG18: =SUBSTITUTE(C18,"-儿童（加收）","") -> 腹壁疝修补费 | AH18: =IF(AF18>0,_xlfn.MAXIFS(N:N,C:C,SUBSTITUTE(C18,"-儿童（加收）","")),0)+N18 -> 1550 | AI18: =IF(AF18>0,_xlfn.MAXIFS(O:O,C:C,SUBSTITUTE(C18,"-儿童（加收）","")),0)+O18 -> 1395 | AJ18: =IF(AF18>0,_xlfn.MAXIFS(P:P,C:C,SUBSTITUTE(C18,"-儿童（加收）","")),0)+P18 -> 1200 | AK18: =VLOOKUP(V18,Sheet2!E:E,1,0) -> 003310080050000-331008005
C19: 腹壁疝修补费 | N19: 1550 | O19: 1395 | P19: 1200 | V19: 003310080050000-33100800502 | W19: 33100800502 | X19: 经腹腔镜腹壁切口疝修补术 | AA19: 次 | AC19: 1750 | AD19: 1680 | AE19: 1428 | AF19: =IFERROR(FIND("-儿童（加收）",C19,1),0) -> 0 | AG19: =SUBSTITUTE(C19,"-儿童（加收）","") -> 腹壁疝修补费 | AH19: =IF(AF19>0,_xlfn.MAXIFS(N:N,C:C,SUBSTITUTE(C19,"-儿童（加收）","")),0)+N19 -> 1550 | AI19: =IF(AF19>0,_xlfn.MAXIFS(O:O,C:C,SUBSTITUTE(C19,"-儿童（加收）","")),0)+O19 -> 1395 | AJ19: =IF(AF19>0,_xlfn.MAXIFS(P:P,C:C,SUBSTITUTE(C19,"-儿童（加收）","")),0)+P19 -> 1200 | AK19: =VLOOKUP(V19,Sheet2!E:E,1,0) -> 003310080050000-33100800502
A20: 3 | B20: 013310001250000 | C20: 腹股沟疝修补费 | D20: 通过手术对腹股沟疝进行修补。 | E20: 所定价格涵盖手术计划、术区准备、消毒、切开、探查、分离、还纳、修补/结扎、引流、冲洗、止血、缝合、处理用物等步骤所需的人力资源和基本物质资源消耗。 | G20: 单侧 | H20: 如出现“复杂疝修补费”所称复杂情况，按“复杂疝修补费”收取。 | I20: 1600 | J20: 1440 | K20: 1498.5756 | L20: 1469.1633 | M20: 1188.8656 | N20: 1500 | O20: 1430 | P20: 1200 | Q20: 医保 | T20: 平移取整 | U20: 加权平移后取整，县级按不高于省级调整，基层对应调整 | V20: 003310080010000-331008001 | W20: 331008001 | X20: 腹股沟疝修补术 | Y20: 包括各种方法修补 | AA20: 单侧 | AC20: 1000 | AD20: 960 | AE20: 816 | AF20: =IFERROR(FIND("-儿童（加收）",C20,1),0) -> 0 | AG20: =SUBSTITUTE(C20,"-儿童（加收）","") -> 腹股沟疝修补费 | AH20: =IF(AF20>0,_xlfn.MAXIFS(N:N,C:C,SUBSTITUTE(C20,"-儿童（加收）","")),0)+N20 -> 1500 | AI20: =IF(AF20>0,_xlfn.MAXIFS(O:O,C:C,SUBSTITUTE(C20,"-儿童（加收）","")),0)+O20 -> 1430 | AJ20: =IF(AF20>0,_xlfn.MAXIFS(P:P,C:C,SUBSTITUTE(C20,"-儿童（加收）","")),0)+P20 -> 1200 | AK20: =VLOOKUP(V20,Sheet2!E:E,1,0) -> 003310080010000-331008001
C21: 腹股沟疝修补费 | N21: 1500 | O21: 1430 | P21: 1200 | V21: 003310080010001-33100800102 | W21: 33100800102 | X21: 经腹腔镜腹股沟疝修补术 | AA21: 单侧 | AC21: 1625 | AD21: 1560 | AE21: 1326 | AF21: =IFERROR(FIND("-儿童（加收）",C21,1),0) -> 0 | AG21: =SUBSTITUTE(C21,"-儿童（加收）","") -> 腹股沟疝修补费 | AH21: =IF(AF21>0,_xlfn.MAXIFS(N:N,C:C,SUBSTITUTE(C21,"-儿童（加收）","")),0)+N21 -> 1500 | AI21: =IF(AF21>0,_xlfn.MAXIFS(O:O,C:C,SUBSTITUTE(C21,"-儿童（加收）","")),0)+O21 -> 1430 | AJ21: =IF(AF21>0,_xlfn.MAXIFS(P:P,C:C,SUBSTITUTE(C21,"-儿童（加收）","")),0)+P21 -> 1200 | AK21: =VLOOKUP(V21,Sheet2!E:E,1,0) -> 003310080010001-33100800102
C22: 腹股沟疝修补费 | N22: 1500 | O22: 1430 | P22: 1200 | V22: 003310080030000-331008003 | W22: 331008003 | X22: 充填式无张力疝修补术 | Z22: 填充物 | AA22: 单侧 | AC22: 1125 | AD22: 1080 | AE22: 918 | AF22: =IFERROR(FIND("-儿童（加收）",C22,1),0) -> 0 | AG22: =SUBSTITUTE(C22,"-儿童（加收）","") -> 腹股沟疝修补费 | AH22: =IF(AF22>0,_xlfn.MAXIFS(N:N,C:C,SUBSTITUTE(C22,"-儿童（加收）","")),0)+N22 -> 1500 | AI22: =IF(AF22>0,_xlfn.MAXIFS(O:O,C:C,SUBSTITUTE(C22,"-儿童（加收）","")),0)+O22 -> 1430 | AJ22: =IF(AF22>0,_xlfn.MAXIFS(P:P,C:C,SUBSTITUTE(C22,"-儿童（加收）","")),0)+P22 -> 1200 | AK22: =VLOOKUP(V22,Sheet2!E:E,1,0) -> 003310080030000-331008003
C23: 腹股沟疝修补费 | N23: 1500 | O23: 1430 | P23: 1200 | V23: 003310080030000-33100800302 | W23: 33100800302 | X23: 经腹腔镜充填式无张力疝修补术 | AA23: 单侧 | AC23: 1750 | AD23: 1680 | AE23: 1428 | AF23: =IFERROR(FIND("-儿童（加收）",C23,1),0) -> 0 | AG23: =SUBSTITUTE(C23,"-儿童（加收）","") -> 腹股沟疝修补费 | AH23: =IF(AF23>0,_xlfn.MAXIFS(N:N,C:C,SUBSTITUTE(C23,"-儿童（加收）","")),0)+N23 -> 1500 | AI23: =IF(AF23>0,_xlfn.MAXIFS(O:O,C:C,SUBSTITUTE(C23,"-儿童（加收）","")),0)+O23 -> 1430 | AJ23: =IF(AF23>0,_xlfn.MAXIFS(P:P,C:C,SUBSTITUTE(C23,"-儿童（加收）","")),0)+P23 -> 1200 | AK23: =VLOOKUP(V23,Sheet2!E:E,1,0) -> 003310080030000-33100800302
A24: 分项 | B24: 013310001250001 | C24: 腹股沟疝修补费-儿童（加收） | G24: 单侧 | I24: 480 | J24: 432 | K24: 407.28883 | L24: 357.01068 | M24: 341 | N24: 450 | O24: 430 | P24: 360 | Q24: 医保 | U24: 儿童加收30% | V24: 003310080010000-33100800101 | W24: 33100800101 | X24: 小儿腹股沟疝修补术 | AA24: 单侧 | AC24: 1300 | AD24: 1250 | AE24: 1065 | AF24: =IFERROR(FIND("-儿童（加收）",C24,1),0) -> 8 | AG24: =SUBSTITUTE(C24,"-儿童（加收）","") -> 腹股沟疝修补费 | AH24: =IF(AF24>0,_xlfn.MAXIFS(N:N,C:C,SUBSTITUTE(C24,"-儿童（加收）","")),0)+N24 -> 1950 | AI24: =IF(AF24>0,_xlfn.MAXIFS(O:O,C:C,SUBSTITUTE(C24,"-儿童（加收）","")),0)+O24 -> 1860 | AJ24: =IF(AF24>0,_xlfn.MAXIFS(P:P,C:C,SUBSTITUTE(C24,"-儿童（加收）","")),0)+P24 -> 1560 | AK24: =VLOOKUP(V24,Sheet2!E:E,1,0) -> 003310080010000-33100800101
C25: 腹股沟疝修补费-儿童（加收） | N25: 450 | O25: 430 | P25: 360 | V25: 003310080010001-33100800103 | W25: 33100800103 | X25: 小儿经腹腔镜腹股沟疝修补术 | AA25: 单侧 | AC25: 1925 | AD25: 1850 | AE25: 1575 | AF25: =IFERROR(FIND("-儿童（加收）",C25,1),0) -> 8 | AG25: =SUBSTITUTE(C25,"-儿童（加收）","") -> 腹股沟疝修补费 | AH25: =IF(AF25>0,_xlfn.MAXIFS(N:N,C:C,SUBSTITUTE(C25,"-儿童（加收）","")),0)+N25 -> 1950 | AI25: =IF(AF25>0,_xlfn.MAXIFS(O:O,C:C,SUBSTITUTE(C25,"-儿童（加收）","")),0)+O25 -> 1860 | AJ25: =IF(AF25>0,_xlfn.MAXIFS(P:P,C:C,SUBSTITUTE(C25,"-儿童（加收）","")),0)+P25 -> 1560 | AK25: =VLOOKUP(V25,Sheet2!E:E,1,0) -> 003310080010001-33100800103
C26: 腹股沟疝修补费-儿童（加收） | N26: 450 | O26: 430 | P26: 360 | V26: 003310080030000-33100800301 | W26: 33100800301 | X26: 小儿充填式无张力疝修补术 | AA26: 单侧 | AC26: 1465 | AD26: 1405 | AE26: 1195 | AF26: =IFERROR(FIND("-儿童（加收）",C26,1),0) -> 8 | AG26: =SUBSTITUTE(C26,"-儿童（加收）","") -> 腹股沟疝修补费 | AH26: =IF(AF26>0,_xlfn.MAXIFS(N:N,C:C,SUBSTITUTE(C26,"-儿童（加收）","")),0)+N26 -> 1950 | AI26: =IF(AF26>0,_xlfn.MAXIFS(O:O,C:C,SUBSTITUTE(C26,"-儿童（加收）","")),0)+O26 -> 1860 | AJ26: =IF(AF26>0,_xlfn.MAXIFS(P:P,C:C,SUBSTITUTE(C26,"-儿童（加收）","")),0)+P26 -> 1560 | AK26: =VLOOKUP(V26,Sheet2!E:E,1,0) -> 003310080030000-33100800301
C27: 腹股沟疝修补费-儿童（加收） | N27: 450 | O27: 430 | P27: 360 | V27: 003310080030000-33100800303 | W27: 33100800303 | X27: 小儿经腹腔镜充填式无张力疝修补术 | AA27: 单侧 | AC27: 2090 | AD27: 2005 | AE27: 1705 | AF27: =IFERROR(FIND("-儿童（加收）",C27,1),0) -> 8 | AG27: =SUBSTITUTE(C27,"-儿童（加收）","") -> 腹股沟疝修补费 | AH27: =IF(AF27>0,_xlfn.MAXIFS(N:N,C:C,SUBSTITUTE(C27,"-儿童（加收）","")),0)+N27 -> 1950 | AI27: =IF(AF27>0,_xlfn.MAXIFS(O:O,C:C,SUBSTITUTE(C27,"-儿童（加收）","")),0)+O27 -> 1860 | AJ27: =IF(AF27>0,_xlfn.MAXIFS(P:P,C:C,SUBSTITUTE(C27,"-儿童（加收）","")),0)+P27 -> 1560 | AK27: =VLOOKUP(V27,Sheet2!E:E,1,0) -> 003310080030000-33100800303
A28: 4 | B28: 013310001260000 | C28: 盆底疝修补费 | D28: 通过手术对会阴疝、坐骨孔疝、闭孔疝等盆底疝进行修补。 | E28: 所定价格涵盖手术计划、术区准备、消毒、切开、探查、分离、还纳、修补、引流、冲洗、止血、缝合、处理用物等步骤所需的人力资源和基本物质资源消耗。 | G28: 次 | H28: 如出现“复杂疝修补费”所称复杂情况，按“复杂疝修补费”收取。 | I28: 1900 | J28: 1710 | K28: 1000 | L28: 960 | M28: 816 | N28: 1700 | O28: 1530 | P28: 1300 | Q28: 医保 | T28: 提高 | U28: 省级根据区域间和项目间比价关系调高（我省价格在全国低位），我市根据比价关系提高（开展量仅1.5例） | V28: 003310080060000-331008006 | W28: 331008006 | X28: 会阴疝修补术 | AA28: 次 | AC28: 1000 | AD28: 960 | AE28: 816 | AF28: =IFERROR(FIND("-儿童（加收）",C28,1),0) -> 0 | AG28: =SUBSTITUTE(C28,"-儿童（加收）","") -> 盆底疝修补费 | AH28: =IF(AF28>0,_xlfn.MAXIFS(N:N,C:C,SUBSTITUTE(C28,"-儿童（加收）","")),0)+N28 -> 1700 | AI28: =IF(AF28>0,_xlfn.MAXIFS(O:O,C:C,SUBSTITUTE(C28,"-儿童（加收）","")),0)+O28 -> 1530 | AJ28: =IF(AF28>0,_xlfn.MAXIFS(P:P,C:C,SUBSTITUTE(C28,"-儿童（加收）","")),0)+P28 -> 1300 | AK28: =VLOOKUP(V28,Sheet2!E:E,1,0) -> 003310080060000-331008006
A29: 分项 | B29: 013310001260001 | C29: 盆底疝修补费-儿童（加收） | G29: 次 | I29: 570 | J29: 513 | N29: 510 | O29: 459 | P29: 390 | Q29: 医保 | V29: 003310080060000-33100800601 | W29: 33100800601 | X29: 小儿会阴疝修补术 | AA29: 次 | AC29: 1300 | AD29: 1250 | AE29: 1065 | AF29: =IFERROR(FIND("-儿童（加收）",C29,1),0) -> 7 | AG29: =SUBSTITUTE(C29,"-儿童（加收）","") -> 盆底疝修补费 | AH29: =IF(AF29>0,_xlfn.MAXIFS(N:N,C:C,SUBSTITUTE(C29,"-儿童（加收）","")),0)+N29 -> 2210 | AI29: =IF(AF29>0,_xlfn.MAXIFS(O:O,C:C,SUBSTITUTE(C29,"-儿童（加收）","")),0)+O29 -> 1989 | AJ29: =IF(AF29>0,_xlfn.MAXIFS(P:P,C:C,SUBSTITUTE(C29,"-儿童（加收）","")),0)+P29 -> 1690 | AK29: =VLOOKUP(V29,Sheet2!E:E,1,0) -> 003310080060000-33100800601
A30: 分项 | B30: 013310001270001 | C30: 造口旁疝修补费-儿童（加收） | G30: 次 | I30: 570 | J30: 513 | N30: 510 | O30: 459 | P30: 390 | Q30: 医保 | U30: 儿童加收30% | V30: 003310080050000-33100800501 | W30: 33100800501 | X30: 小儿腹壁切口疝修补术 | AA30: 次 | AC30: 1465 | AD30: 1405 | AE30: 1195 | AF30: =IFERROR(FIND("-儿童（加收）",C30,1),0) -> 8 | AG30: =SUBSTITUTE(C30,"-儿童（加收）","") -> 造口旁疝修补费 | AH30: =IF(AF30>0,_xlfn.MAXIFS(N:N,C:C,SUBSTITUTE(C30,"-儿童（加收）","")),0)+N30 -> 510 | AI30: =IF(AF30>0,_xlfn.MAXIFS(O:O,C:C,SUBSTITUTE(C30,"-儿童（加收）","")),0)+O30 -> 459 | AJ30: =IF(AF30>0,_xlfn.MAXIFS(P:P,C:C,SUBSTITUTE(C30,"-儿童（加收）","")),0)+P30 -> 390 | AK30: =VLOOKUP(V30,Sheet2!E:E,1,0) -> 003310080050000-33100800501
C31: 造口旁疝修补费-儿童（加收） | N31: 510 | O31: 459 | P31: 390 | V31: 003310080050000-33100800503 | W31: 33100800503 | X31: 小儿经腹腔镜腹壁切口疝修补术 | AA31: 次 | AC31: 2090 | AD31: 2005 | AE31: 1705 | AF31: =IFERROR(FIND("-儿童（加收）",C31,1),0) -> 8 | AG31: =SUBSTITUTE(C31,"-儿童（加收）","") -> 造口旁疝修补费 | AH31: =IF(AF31>0,_xlfn.MAXIFS(N:N,C:C,SUBSTITUTE(C31,"-儿童（加收）","")),0)+N31 -> 510 | AI31: =IF(AF31>0,_xlfn.MAXIFS(O:O,C:C,SUBSTITUTE(C31,"-儿童（加收）","")),0)+O31 -> 459 | AJ31: =IF(AF31>0,_xlfn.MAXIFS(P:P,C:C,SUBSTITUTE(C31,"-儿童（加收）","")),0)+P31 -> 390 | AK31: =VLOOKUP(V31,Sheet2!E:E,1,0) -> 003310080050000-33100800503
A32: 7 | B32: 013310001290000 | C32: 复杂疝修补费 | D32: 通过手术对各类疝的复杂情况进行修补。 | E32: 所定价格涵盖手术计划、术区准备、消毒、切开、探查、分离、还纳、修补、引流、冲洗、止血、缝合、处理用物等步骤所需的人力资源和基本物质资源消耗。 | G32: 次 | H32: 本项目中的“复杂”指：“巨大疝（疝环大于12cm以上）、嵌顿坏死、合并腹水、复发疝、多发疝、边缘性腹壁疝”的疝修补。 | I32: 2400 | J32: 2160 | K32: 1125 | L32: 1080 | M32: 918 | N32: 2150 | O32: 1930 | P32: 1640 | Q32: 医保 | T32: 提高 | U32: 省级根据区域间和项目间比价关系调高（我省价格在全国低位），我市根据比价关系提高 | V32: 003310080020000-331008002 | W32: 331008002 | X32: 嵌顿疝复位修补术 | Y32: 不含肠切除吻合 | AA32: 单侧 | AC32: 1125 | AD32: 1080 | AE32: 918 | AF32: =IFERROR(FIND("-儿童（加收）",C32,1),0) -> 0 | AG32: =SUBSTITUTE(C32,"-儿童（加收）","") -> 复杂疝修补费 | AH32: =IF(AF32>0,_xlfn.MAXIFS(N:N,C:C,SUBSTITUTE(C32,"-儿童（加收）","")),0)+N32 -> 2150 | AI32: =IF(AF32>0,_xlfn.MAXIFS(O:O,C:C,SUBSTITUTE(C32,"-儿童（加收）","")),0)+O32 -> 1930 | AJ32: =IF(AF32>0,_xlfn.MAXIFS(P:P,C:C,SUBSTITUTE(C32,"-儿童（加收）","")),0)+P32 -> 1640 | AK32: =VLOOKUP(V32,Sheet2!E:E,1,0) -> 003310080020000-331008002
A33: 分项 | B33: 013310001290001 | C33: 复杂疝修补费-儿童（加收） | G33: 次 | I33: 720 | J33: 648 | K33: -685 | L33: -525 | M33: -445 | N33: 645 | O33: 580 | P33: 495 | Q33: 医保 | U33: 儿童加收30% | V33: 003310080020000-33100800201 | W33: 33100800201 | X33: 小儿嵌顿疝复位修补术 | AA33: 单侧 | AC33: 1465 | AD33: 1405 | AE33: 1195 | AF33: =IFERROR(FIND("-儿童（加收）",C33,1),0) -> 7 | AG33: =SUBSTITUTE(C33,"-儿童（加收）","") -> 复杂疝修补费 | AH33: =IF(AF33>0,_xlfn.MAXIFS(N:N,C:C,SUBSTITUTE(C33,"-儿童（加收）","")),0)+N33 -> 2795 | AI33: =IF(AF33>0,_xlfn.MAXIFS(O:O,C:C,SUBSTITUTE(C33,"-儿童（加收）","")),0)+O33 -> 2510 | AJ33: =IF(AF33>0,_xlfn.MAXIFS(P:P,C:C,SUBSTITUTE(C33,"-儿童（加收）","")),0)+P33 -> 2135 | AK33: =VLOOKUP(V33,Sheet2!E:E,1,0) -> 003310080020000-33100800201
A34: 8 | B34: 013310001300000 | C34: 腹壁缺损修复费 | D34: 通过手术修复腹壁缺损。 | E34: 所定价格涵盖手术计划、术区准备、消毒、切开、探查、分离、修复、引流、冲洗、止血、缝合、处理用物等步骤所需的人力资源和基本物质资源消耗。 | G34: 次 | I34: 1700 | J34: 1530 | K34: 1760.8696 | L34: 1500 | N34: 1650 | O34: 1500 | P34: 1280 | Q34: 医保 | T34: 理顺，降低 | U34: 平移后按不超过省级拟定，开展量少，与序号10“腹膜病变切除费”稍拉开价差。 | V34: 003310080070000-331008007 | W34: 331008007 | X34: 脐瘘切除+修补术 | Y34: 含脐肠瘘切除术；不含脐尿管瘘切除术 | AA34: 次 | AC34: 750 | AD34: 720 | AE34: 612 | AF34: =IFERROR(FIND("-儿童（加收）",C34,1),0) -> 0 | AG34: =SUBSTITUTE(C34,"-儿童（加收）","") -> 腹壁缺损修复费 | AH34: =IF(AF34>0,_xlfn.MAXIFS(N:N,C:C,SUBSTITUTE(C34,"-儿童（加收）","")),0)+N34 -> 1650 | AI34: =IF(AF34>0,_xlfn.MAXIFS(O:O,C:C,SUBSTITUTE(C34,"-儿童（加收）","")),0)+O34 -> 1500 | AJ34: =IF(AF34>0,_xlfn.MAXIFS(P:P,C:C,SUBSTITUTE(C34,"-儿童（加收）","")),0)+P34 -> 1280 | AK34: =VLOOKUP(V34,Sheet2!E:E,1,0) -> 003310080070000-331008007
C35: 腹壁缺损修复费 | N35: 1650 | O35: 1500 | P35: 1280 | V35: 003310080200000-331008020 | W35: 331008020 | X35: 先天性脐膨出修补术 | Y35: 不含已破溃内脏外露处理 | AA35: 次 | AC35: 1375 | AD35: 1320 | AE35: 1122 | AF35: =IFERROR(FIND("-儿童（加收）",C35,1),0) -> 0 | AG35: =SUBSTITUTE(C35,"-儿童（加收）","") -> 腹壁缺损修复费 | AH35: =IF(AF35>0,_xlfn.MAXIFS(N:N,C:C,SUBSTITUTE(C35,"-儿童（加收）","")),0)+N35 -> 1650 | AI35: =IF(AF35>0,_xlfn.MAXIFS(O:O,C:C,SUBSTITUTE(C35,"-儿童（加收）","")),0)+O35 -> 1500 | AJ35: =IF(AF35>0,_xlfn.MAXIFS(P:P,C:C,SUBSTITUTE(C35,"-儿童（加收）","")),0)+P35 -> 1280 | AK35: =VLOOKUP(V35,Sheet2!E:E,1,0) -> 003310080200000-331008020
C36: 腹壁缺损修复费 | N36: 1650 | O36: 1500 | P36: 1280 | V36: 003310080200000-33100802002 | W36: 33100802002 | X36: 经腹腔镜先天性脐膨出修补术 | AA36: 次 | AC36: 2000 | AD36: 1920 | AE36: 1632 | AF36: =IFERROR(FIND("-儿童（加收）",C36,1),0) -> 0 | AG36: =SUBSTITUTE(C36,"-儿童（加收）","") -> 腹壁缺损修复费 | AH36: =IF(AF36>0,_xlfn.MAXIFS(N:N,C:C,SUBSTITUTE(C36,"-儿童（加收）","")),0)+N36 -> 1650 | AI36: =IF(AF36>0,_xlfn.MAXIFS(O:O,C:C,SUBSTITUTE(C36,"-儿童（加收）","")),0)+O36 -> 1500 | AJ36: =IF(AF36>0,_xlfn.MAXIFS(P:P,C:C,SUBSTITUTE(C36,"-儿童（加收）","")),0)+P36 -> 1280 | AK36: =VLOOKUP(V36,Sheet2!E:E,1,0) -> 003310080200000-33100802002
C37: 腹壁缺损修复费 | N37: 1650 | O37: 1500 | P37: 1280 | V37: 003310080210000-331008021 | W37: 331008021 | X37: 先天性腹壁裂修补术 | Y37: 不含合并胸骨裂 | AA37: 次 | AC37: 1375 | AD37: 1320 | AE37: 1122 | AF37: =IFERROR(FIND("-儿童（加收）",C37,1),0) -> 0 | AG37: =SUBSTITUTE(C37,"-儿童（加收）","") -> 腹壁缺损修复费 | AH37: =IF(AF37>0,_xlfn.MAXIFS(N:N,C:C,SUBSTITUTE(C37,"-儿童（加收）","")),0)+N37 -> 1650 | AI37: =IF(AF37>0,_xlfn.MAXIFS(O:O,C:C,SUBSTITUTE(C37,"-儿童（加收）","")),0)+O37 -> 1500 | AJ37: =IF(AF37>0,_xlfn.MAXIFS(P:P,C:C,SUBSTITUTE(C37,"-儿童（加收）","")),0)+P37 -> 1280 | AK37: =VLOOKUP(V37,Sheet2!E:E,1,0) -> 003310080210000-331008021
C38: 腹壁缺损修复费 | N38: 1650 | O38: 1500 | P38: 1280 | V38: 003310080210000-33100802102 | W38: 33100802102 | X38: 经腹腔镜先天性腹壁裂修补术 | AA38: 次 | AC38: 2000 | AD38: 1920 | AE38: 1632 | AF38: =IFERROR(FIND("-儿童（加收）",C38,1),0) -> 0 | AG38: =SUBSTITUTE(C38,"-儿童（加收）","") -> 腹壁缺损修复费 | AH38: =IF(AF38>0,_xlfn.MAXIFS(N:N,C:C,SUBSTITUTE(C38,"-儿童（加收）","")),0)+N38 -> 1650 | AI38: =IF(AF38>0,_xlfn.MAXIFS(O:O,C:C,SUBSTITUTE(C38,"-儿童（加收）","")),0)+O38 -> 1500 | AJ38: =IF(AF38>0,_xlfn.MAXIFS(P:P,C:C,SUBSTITUTE(C38,"-儿童（加收）","")),0)+P38 -> 1280 | AK38: =VLOOKUP(V38,Sheet2!E:E,1,0) -> 003310080210000-33100802102
C39: 腹壁缺损修复费 | N39: 1650 | O39: 1500 | P39: 1280 | V39: 003310080220000-331008022 | W39: 331008022 | X39: 腹壁缺损修复术 | Y39: 不含膀胱修补和植皮术 | AA39: 次 | AC39: 1500 | AD39: 1440 | AE39: 1224 | AF39: =IFERROR(FIND("-儿童（加收）",C39,1),0) -> 0 | AG39: =SUBSTITUTE(C39,"-儿童（加收）","") -> 腹壁缺损修复费 | AH39: =IF(AF39>0,_xlfn.MAXIFS(N:N,C:C,SUBSTITUTE(C39,"-儿童（加收）","")),0)+N39 -> 1650 | AI39: =IF(AF39>0,_xlfn.MAXIFS(O:O,C:C,SUBSTITUTE(C39,"-儿童（加收）","")),0)+O39 -> 1500 | AJ39: =IF(AF39>0,_xlfn.MAXIFS(P:P,C:C,SUBSTITUTE(C39,"-儿童（加收）","")),0)+P39 -> 1280 | AK39: =VLOOKUP(V39,Sheet2!E:E,1,0) -> 003310080220000-331008022
C40: 腹壁缺损修复费 | N40: 1650 | O40: 1500 | P40: 1280 | V40: 003310080220000-33100802202 | W40: 33100802202 | X40: 经腹腔镜腹壁缺损修复术 | AA40: 次 | AC40: 2125 | AD40: 2040 | AE40: 1734 | AF40: =IFERROR(FIND("-儿童（加收）",C40,1),0) -> 0 | AG40: =SUBSTITUTE(C40,"-儿童（加收）","") -> 腹壁缺损修复费 | AH40: =IF(AF40>0,_xlfn.MAXIFS(N:N,C:C,SUBSTITUTE(C40,"-儿童（加收）","")),0)+N40 -> 1650 | AI40: =IF(AF40>0,_xlfn.MAXIFS(O:O,C:C,SUBSTITUTE(C40,"-儿童（加收）","")),0)+O40 -> 1500 | AJ40: =IF(AF40>0,_xlfn.MAXIFS(P:P,C:C,SUBSTITUTE(C40,"-儿童（加收）","")),0)+P40 -> 1280 | AK40: =VLOOKUP(V40,Sheet2!E:E,1,0) -> 003310080220000-33100802202
...

Sheet Sheet1
A1: 国家结算编码 | B1: 项目代码 | C1: 项目名称 | D1: 项目内涵 | E1: 除外内容 | F1: 计价单位 | G1: 说明 | H1: 省属三甲价格（元） | I1: 省属三甲以下价格（元） | J1: 价格 (市级) | K1: 价格 (县级) | L1: 价格 (基层) | M1: 项目代码 | N1: 项目名称 | O1: 服务产出 | P1: 价格构成 | Q1: 计价单位 | R1: 计价说明 | S1: 拟定价格 (市级) | T1: 拟定价格 (县级) | U1: 拟定价格 (基层)
A2: 003316010080000-331601008 | B2: 331601008 | C2: 乳腺癌根治+乳房再造术 | D2: 含Ⅰ期乳房再造；不含带血管蒂的肌皮组织移植、Ⅱ期乳房再造 | F2: 单侧 | H2: 4800 | I2: 4320 | J2: 4220 | K2: 3800 | L2: 3230 | M2: 013316000370000 | N2: 乳腺全切除费 | O2: 通过手术切除全部乳腺。 | P2: 所定价格涵盖手术计划、术区准备、消毒、切开、探查、分离、切除、冲洗、止血、引流、缝合、处理用物等步骤所需的人力资源和基本物质资源消耗。 | Q2: 单侧 | R2: 1.本项目中的“恶性肿瘤扩大根治性切除”指联合多脏器切除，且不含淋巴结清扫。 2.本项目不含胸壁、乳房重建。
M3: 美容整形类的乳房造费用
A4: 003316010080000-33160100801 | B4: 33160100801 | C4: 小儿乳腺癌根治+乳房再造术 | F4: 单侧 | H4: 6240 | I4: 5615 | J4: 5485 | K4: 4940 | L4: 4200
A6: 003303000080000-33030000801 | B6: 33030000801 | C6: 甲状腺部分切除术（双侧） | F6: 双侧 | G6: 双侧 | H6: 1620 | I6: 1460 | J6: 1500 | K6: 1440 | L6: 1224
A7: 003303000080000-33030000805 | B7: 33030000805 | C7: 经腔镜甲状腺部分切除术（双侧） | F7: 双侧 | G7: 双侧 | H7: 2420 | I7: 2180 | J7: 2125 | K7: 2040 | L7: 1734
A8: 003303000090000-33030000901 | B8: 33030000901 | C8: 甲状腺次全切除术（双侧） | F8: 双侧 | G8: 双侧 | H8: 2030 | I8: 1820 | J8: 1875 | K8: 1800 | L8: 1530
A9: 003303000090000-33030000905 | B9: 33030000905 | C9: 经腔镜甲状腺次全切除术（双侧） | F9: 双侧 | G9: 双侧 | H9: 2830 | I9: 2540 | J9: 2500 | K9: 2400 | L9: 2040
A10: 003303000100000-33030001001 | B10: 33030001001 | C10: 甲状腺全切术（双侧） | F10: 双侧 | G10: 双侧 | H10: 2160 | I10: 1945 | J10: 3285 | K10: 2955 | L10: 2512
A11: 003303000100000-33030001005 | B11: 33030001005 | C11: 经腔镜甲状腺全切术（双侧） | F11: 双侧 | G11: 双侧 | H11: 2960 | I11: 2665 | J11: 3910 | K11: 3555 | L11: 3022
A12: 003303000130000-330300013 | B12: 330300013 | C12: 甲状腺癌根治术联合胸骨劈开上纵隔清扫术 | F12: 次 | H12: 6600 | I12: 5540 | J12: 5090 | K12: 4580 | L12: 3890
A13: 003303000110000-330300011 | B13: 330300011 | C13: 甲状腺癌根治术 | E13: 胶原蛋白海绵 | F13: 次 | H13: 4220 | I13: 3800 | J13: 3500 | K13: 3150 | L13: 2650
A14: 003303000110000-33030001102 | B14: 33030001102 | C14: 经腔镜甲状腺癌根治术 | F14: 次 | H14: 4640 | I14: 4180 | J14: 4125 | K14: 3750 | L14: 3160
A15: 003303000060000-330300006 | B15: 330300006 | C15: 甲状旁腺癌根治术 | F15: 次 | H15: 4320 | I15: 3890 | J15: 3710 | K15: 3340 | L15: 2840 | M15: 802.3 | N15: 214.5 | O15: 4
A16: 003303000060000-33030000602 | B16: 33030000602 | C16: 经腔镜甲状旁腺癌根治术 | F16: 次 | H16: 5120 | I16: 4610 | J16: 4335 | K16: 3940 | L16: 3350 | M16: 321.3 | N16: 42 | O16: 7
A17: 003309000030000-330900003 | B17: 330900003 | C17: 颈淋巴结清扫术 | F17: 次 | J17: 2730 | K17: 2590 | L17: 2200

Sheet Sheet2
A1: id | B1: code | C1: sever_type | D1: change_time | E1: old_hilist_code | F1: new_hilist_code | G1: hilist_name | H1: selfpay_prop | I1: old_price | J1: old_price_city | K1: old_price_town | L1: old_price_village | M1: new_price | N1: new_price_city | O1: new_price_town | P1: new_price_village | Q1: unit | R1: batch | S1: is_use_old | T1: merge_type | U1: cnt_change_model | V1: cnt_change_value | W1: ="insert into server_list_change_all_20250525 ("&_xlfn.TEXTJOIN(",",TRUE,A1:V1)&") values" -> insert into server_list_change_all_20250525 (id,code,sever_type,change_time,old_hilist_code,new_hilist_code,hilist_name,selfpay_prop,old_price,old_price_city,old_price_town,old_price_village,new_price,new_price_city,new_price_town,new_price_village,unit,batch,is_use_old,merge_type,cnt_change_model,cnt_change_value) values
A2: 1568 | B2: null | C2: 1 | D2: 2026-03-24 00:00:00 | E2: 003307030330000-330703033 | F2: 003307030330000-330703033 | G2: 先天性食管裂孔疝修补术 | H2: null | I2: null | J2: 2250 | K2: 2160 | L2: 1836 | M2: null | N2: 2700 | O2: 2435 | P2: 2070 | Q2: 次 | R2: 22 | S2: 1 | T2: normal | U2: main | V2: 0 | W2: ="("&A2&","&B2&","&C2&",'"&D2&"','"&E2&"','"&F2&"','"&G2&"',"&H2&","&I2&","&J2&","&K2&","&L2&","&M2&","&N2&","&O2&","&P2&",'"&Q2&"',"&R2&","&S2&",'"&T2&"','"&U2&"',"&V2&")," -> (1568,null,1,'2026-03-24 00:00:00','003307030330000-330703033','003307030330000-330703033','先天性食管裂孔疝修补术',null,null,2250,2160,1836,null,2700,2435,2070,'次',22,1,'normal','main',0),
A3: 1569 | B3: null | C3: 1 | D3: 2026-03-24 00:00:00 | E3: 003307030330001-33070303301 | F3: 003307030330001-33070303301 | G3: 先天性食管裂孔疝修补术（合并肠回转不良及其他须矫治畸形者） | H3: null | I3: null | J3: 2700 | K3: 2592 | L3: 2203.2 | M3: null | N3: 2700 | O3: 2435 | P3: 2070 | Q3: 次 | R3: 22 | S3: 1 | T3: normal | U3: main | V3: 0 | W3: ="("&A3&","&B3&","&C3&",'"&D3&"','"&E3&"','"&F3&"','"&G3&"',"&H3&","&I3&","&J3&","&K3&","&L3&","&M3&","&N3&","&O3&","&P3&",'"&Q3&"',"&R3&","&S3&",'"&T3&"','"&U3&"',"&V3&")," -> (1569,null,1,'2026-03-24 00:00:00','003307030330001-33070303301','003307030330001-33070303301','先天性食管裂孔疝修补术（合并肠回转不良及其他须矫治畸形者）',null,null,2700,2592,2203.2,null,2700,2435,2070,'次',22,1,'normal','main',0),
A4: 1570 | B4: null | C4: 1 | D4: 2026-03-24 00:00:00 | E4: 003307030330000-33070303304 | F4: 003307030330000-33070303304 | G4: 经胸腔镜先天性食管裂孔疝修补术 | H4: null | I4: null | J4: 2875 | K4: 2760 | L4: 2346 | M4: null | N4: 2700 | O4: 2435 | P4: 2070 | Q4: 次 | R4: 22 | S4: 1 | T4: normal | U4: main | V4: 0 | W4: ="("&A4&","&B4&","&C4&",'"&D4&"','"&E4&"','"&F4&"','"&G4&"',"&H4&","&I4&","&J4&","&K4&","&L4&","&M4&","&N4&","&O4&","&P4&",'"&Q4&"',"&R4&","&S4&",'"&T4&"','"&U4&"',"&V4&")," -> (1570,null,1,'2026-03-24 00:00:00','003307030330000-33070303304','003307030330000-33070303304','经胸腔镜先天性食管裂孔疝修补术',null,null,2875,2760,2346,null,2700,2435,2070,'次',22,1,'normal','main',0),
A5: 1571 | B5: null | C5: 1 | D5: 2026-03-24 00:00:00 | E5: 003307030330001-33070303305 | F5: 003307030330001-33070303305 | G5: 经胸腔镜先天性食管裂孔疝修补术（合并肠回转不良及其他须矫治畸形者） | H5: null | I5: null | J5: 3325 | K5: 3192 | L5: 2713.2 | M5: null | N5: 2700 | O5: 2435 | P5: 2070 | Q5: 次 | R5: 22 | S5: 1 | T5: normal | U5: main | V5: 0 | W5: ="("&A5&","&B5&","&C5&",'"&D5&"','"&E5&"','"&F5&"','"&G5&"',"&H5&","&I5&","&J5&","&K5&","&L5&","&M5&","&N5&","&O5&","&P5&",'"&Q5&"',"&R5&","&S5&",'"&T5&"','"&U5&"',"&V5&")," -> (1571,null,1,'2026-03-24 00:00:00','003307030330001-33070303305','003307030330001-33070303305','经胸腔镜先天性食管裂孔疝修补术（合并肠回转不良及其他须矫治畸形者）',null,null,3325,3192,2713.2,null,2700,2435,2070,'次',22,1,'normal','main',0),
A6: 1572 | B6: null | C6: 1 | D6: 2026-03-24 00:00:00 | E6: 003307030340000-330703034 | F6: 003307030340000-330703034 | G6: 食管裂孔疝修补术 | H6: null | I6: null | J6: 2250 | K6: 2160 | L6: 1836 | M6: null | N6: 2700 | O6: 2435 | P6: 2070 | Q6: 次 | R6: 22 | S6: 1 | T6: normal | U6: main | V6: 0 | W6: ="("&A6&","&B6&","&C6&",'"&D6&"','"&E6&"','"&F6&"','"&G6&"',"&H6&","&I6&","&J6&","&K6&","&L6&","&M6&","&N6&","&O6&","&P6&",'"&Q6&"',"&R6&","&S6&",'"&T6&"','"&U6&"',"&V6&")," -> (1572,null,1,'2026-03-24 00:00:00','003307030340000-330703034','003307030340000-330703034','食管裂孔疝修补术',null,null,2250,2160,1836,null,2700,2435,2070,'次',22,1,'normal','main',0),
A7: 1573 | B7: null | C7: 1 | D7: 2026-03-24 00:00:00 | E7: 003307030340001-33070303402 | F7: 003307030340001-33070303402 | G7: 经胸腔镜食管裂孔疝修补术 | H7: null | I7: null | J7: 2875 | K7: 2760 | L7: 2346 | M7: null | N7: 2700 | O7: 2435 | P7: 2070 | Q7: 次 | R7: 22 | S7: 1 | T7: normal | U7: main | V7: 0 | W7: ="("&A7&","&B7&","&C7&",'"&D7&"','"&E7&"','"&F7&"','"&G7&"',"&H7&","&I7&","&J7&","&K7&","&L7&","&M7&","&N7&","&O7&","&P7&",'"&Q7&"',"&R7&","&S7&",'"&T7&"','"&U7&"',"&V7&")," -> (1573,null,1,'2026-03-24 00:00:00','003307030340001-33070303402','003307030340001-33070303402','经胸腔镜食管裂孔疝修补术',null,null,2875,2760,2346,null,2700,2435,2070,'次',22,1,'normal','main',0),
A8: 1574 | B8: null | C8: 1 | D8: 2026-03-24 00:00:00 | E8: 003307030330000-33070303302 | F8: 003307030330000-33070303302 | G8: 小儿先天性食管裂孔疝修补术 | H8: null | I8: null | J8: 2925 | K8: 2810 | L8: 2390 | M8: null | N8: 3510 | O8: 3165 | P8: 2690 | Q8: 次 | R8: 22 | S8: 1 | T8: normal | U8: main | V8: 0 | W8: ="("&A8&","&B8&","&C8&",'"&D8&"','"&E8&"','"&F8&"','"&G8&"',"&H8&","&I8&","&J8&","&K8&","&L8&","&M8&","&N8&","&O8&","&P8&",'"&Q8&"',"&R8&","&S8&",'"&T8&"','"&U8&"',"&V8&")," -> (1574,null,1,'2026-03-24 00:00:00','003307030330000-33070303302','003307030330000-33070303302','小儿先天性食管裂孔疝修补术',null,null,2925,2810,2390,null,3510,3165,2690,'次',22,1,'normal','main',0),
A9: 1575 | B9: null | C9: 1 | D9: 2026-03-24 00:00:00 | E9: 003307030330001-33070303303 | F9: 003307030330001-33070303303 | G9: 小儿先天性食管裂孔疝修补术（合并肠回转不良及其他须矫治畸形者） | H9: null | I9: null | J9: 3510 | K9: 3370 | L9: 2865 | M9: null | N9: 3510 | O9: 3165 | P9: 2690 | Q9: 次 | R9: 22 | S9: 1 | T9: normal | U9: main | V9: 0 | W9: ="("&A9&","&B9&","&C9&",'"&D9&"','"&E9&"','"&F9&"','"&G9&"',"&H9&","&I9&","&J9&","&K9&","&L9&","&M9&","&N9&","&O9&","&P9&",'"&Q9&"',"&R9&","&S9&",'"&T9&"','"&U9&"',"&V9&")," -> (1575,null,1,'2026-03-24 00:00:00','003307030330001-33070303303','003307030330001-33070303303','小儿先天性食管裂孔疝修补术（合并肠回转不良及其他须矫治畸形者）',null,null,3510,3370,2865,null,3510,3165,2690,'次',22,1,'normal','main',0),
A10: 1576 | B10: null | C10: 1 | D10: 2026-03-24 00:00:00 | E10: 003307030330000-33070303306 | F10: 003307030330000-33070303306 | G10: 小儿经胸腔镜先天性食管裂孔疝修补术 | H10: null | I10: null | J10: 3550 | K10: 3410 | L10: 2900 | M10: null | N10: 3510 | O10: 3165 | P10: 2690 | Q10: 次 | R10: 22 | S10: 1 | T10: normal | U10: main | V10: 0 | W10: ="("&A10&","&B10&","&C10&",'"&D10&"','"&E10&"','"&F10&"','"&G10&"',"&H10&","&I10&","&J10&","&K10&","&L10&","&M10&","&N10&","&O10&","&P10&",'"&Q10&"',"&R10&","&S10&",'"&T10&"','"&U10&"',"&V10&")," -> (1576,null,1,'2026-03-24 00:00:00','003307030330000-33070303306','003307030330000-33070303306','小儿经胸腔镜先天性食管裂孔疝修补术',null,null,3550,3410,2900,null,3510,3165,2690,'次',22,1,'normal','main',0),
A11: 1577 | B11: null | C11: 1 | D11: 2026-03-24 00:00:00 | E11: 003307030330001-33070303307 | F11: 003307030330001-33070303307 | G11: 小儿经胸腔镜先天性食管裂孔疝修补术（合并肠回转不良及其他须矫治畸形者） | H11: null | I11: null | J11: 4135 | K11: 3970 | L11: 3375 | M11: null | N11: 3510 | O11: 3165 | P11: 2690 | Q11: 次 | R11: 22 | S11: 1 | T11: normal | U11: main | V11: 0 | W11: ="("&A11&","&B11&","&C11&",'"&D11&"','"&E11&"','"&F11&"','"&G11&"',"&H11&","&I11&","&J11&","&K11&","&L11&","&M11&","&N11&","&O11&","&P11&",'"&Q11&"',"&R11&","&S11&",'"&T11&"','"&U11&"',"&V11&")," -> (1577,null,1,'2026-03-24 00:00:00','003307030330001-33070303307','003307030330001-33070303307','小儿经胸腔镜先天性食管裂孔疝修补术（合并肠回转不良及其他须矫治畸形者）',null,null,4135,3970,3375,null,3510,3165,2690,'次',22,1,'normal','main',0),
A12: 1578 | B12: null | C12: 1 | D12: 2026-03-24 00:00:00 | E12: 003307030340000-33070303401 | F12: 003307030340000-33070303401 | G12: 小儿食管裂孔疝修补术 | H12: null | I12: null | J12: 2925 | K12: 2810 | L12: 2390 | M12: null | N12: 3510 | O12: 3165 | P12: 2690 | Q12: 次 | R12: 22 | S12: 1 | T12: normal | U12: main | V12: 0 | W12: ="("&A12&","&B12&","&C12&",'"&D12&"','"&E12&"','"&F12&"','"&G12&"',"&H12&","&I12&","&J12&","&K12&","&L12&","&M12&","&N12&","&O12&","&P12&",'"&Q12&"',"&R12&","&S12&",'"&T12&"','"&U12&"',"&V12&")," -> (1578,null,1,'2026-03-24 00:00:00','003307030340000-33070303401','003307030340000-33070303401','小儿食管裂孔疝修补术',null,null,2925,2810,2390,null,3510,3165,2690,'次',22,1,'normal','main',0),
A13: 1579 | B13: null | C13: 1 | D13: 2026-03-24 00:00:00 | E13: 003307030340001-33070303403 | F13: 003307030340001-33070303403 | G13: 小儿经胸腔镜食管裂孔疝修补术 | H13: null | I13: null | J13: 3550 | K13: 3410 | L13: 2900 | M13: null | N13: 3510 | O13: 3165 | P13: 2690 | Q13: 次 | R13: 22 | S13: 1 | T13: normal | U13: main | V13: 0 | W13: ="("&A13&","&B13&","&C13&",'"&D13&"','"&E13&"','"&F13&"','"&G13&"',"&H13&","&I13&","&J13&","&K13&","&L13&","&M13&","&N13&","&O13&","&P13&",'"&Q13&"',"&R13&","&S13&",'"&T13&"','"&U13&"',"&V13&")," -> (1579,null,1,'2026-03-24 00:00:00','003307030340001-33070303403','003307030340001-33070303403','小儿经胸腔镜食管裂孔疝修补术',null,null,3550,3410,2900,null,3510,3165,2690,'次',22,1,'normal','main',0),
... A120: 1694 | B120: null | C120: 1 | D120: 2026-03-24 00:00:00 | E120: 003303000150000-33030001502 | F120: 003303000150000-33030001502 | G120: 小儿甲状舌管瘘切除术 | H120: null | I120: null | J120: 1140 | K120: 1090 | L120: 925 | M120: null | N120: 1140 | O120: 1090 | P120: 929 | Q120: 次 | R120: 22 | S120: 1 | T120: normal | U120: main | V120: 0 | W120: ="("&A120&","&B120&","&C120&",'"&D120&"','"&E120&"','"&F120&"','"&G120&"',"&H120&","&I120&","&J120&","&K120&","&L120&","&M120&","&N120&","&O120&","&P120&",'"&Q120&"',"&R120&","&S120&",'"&T120&"','"&U120&"',"&V120&")," -> (1694,null,1,'2026-03-24 00:00:00','003303000150000-33030001502','003303000150000-33030001502','小儿甲状舌管瘘切除术',null,null,1140,1090,925,null,1140,1090,929,'次',22,1,'normal','main',0),

Sheet Sheet3
A1: id | B1: server_list_id | C1: code | D1: old_hilist_code | E1: new_hilist_code | F1: hilist_name | G1: selfpay_prop | H1: old_price | I1: old_price_city | J1: old_price_town | K1: old_price_village | L1: new_price | M1: new_price_city | N1: new_price_town | O1: new_price_village | P1: unit | Q1: is_use_old | R1: is_main | S1: main_code | T1: ="insert into server_list_column_20250525 ("&_xlfn.TEXTJOIN(",",TRUE,A1:S1)&") values" -> insert into server_list_column_20250525 (id,server_list_id,code,old_hilist_code,new_hilist_code,hilist_name,selfpay_prop,old_price,old_price_city,old_price_town,old_price_village,new_price,new_price_city,new_price_town,new_price_village,unit,is_use_old,is_main,main_code) values

Sheet Sheet4
B1: A | C1: B | D1: C | E1: D | F1: E | G1: F | H1: G | I1: H | J1: I | K1: J | L1: K | M1: L | N1: M | O1: N | P1: O | Q1: P | R1: Q | S1: R | T1: S | U1: T | V1: U | W1: V
B2: old_hilist_code | C2: old_price | D2: old_price_city | E2: old_price_town | F2: old_price_village | G2: new_price | H2: new_price_city | I2: new_price_town | J2: new_price_village | K2: is_use_old | L2: is_main | M2: cnt_change_model | N2: cnt_change_value | O2: 数量3 | P2: 数量2 | Q2: 数量1 | R2: 预计差额3 | S2: 预计差额2 | T2: 预计差额1 | U2: 实际差额3 | V2: 实际差额2 | W2: 实际差额1
A3: 1 | B3: 003303000150000-330300015 | D3: 875 | E3: 840 | F3: 714 | H3: 875 | I3: 840 | J3: 714 | K3: 1 | L3: 1 | M3: main | N3: 0 | O3: 6 | P3: 11 | Q3: 2 | R3: 0 | S3: 0 | T3: 0 | U3: 0 | V3: 0 | W3: 0 | X3: =SUM(U3:W3) -> 0
A4: 2 | B4: 003112010640000-31120106401 | D4: 495 | E4: 450 | F4: 382.5 | H4: 600 | I4: 540 | J4: 460 | K4: 1 | L4: 1 | M4: main | N4: 0 | O4: 0 | P4: 2 | Q4: 0 | R4: 0 | S4: 180 | T4: 0 | U4: 0 | V4: 180 | W4: 0 | X4: =SUM(U4:W4) -> 180
A5: 3 | B5: 003303000100000-33030001004 | D5: 2815 | E5: 2570 | F5: 2180 | H5: 2300 | I5: 2030 | J5: 1800 | K5: 1 | L5: 1 | M5: main | N5: 0 | O5: 98.3 | P5: 31 | Q5: 16 | R5: -50624.5 | S5: -16740 | T5: -6080 | U5: -50624.5 | V5: -16740 | W5: -6080 | X5: =SUM(U5:W5) -> -73444.5
A6: 4 | B6: 003310080040000-33100800402 | D6: 1625 | E6: 1560 | F6: 1326 | H6: 1550 | I6: 1395 | J6: 1200 | K6: 1 | L6: 1 | M6: main | N6: 0 | O6: 19 | P6: 7 | Q6: 3 | R6: -1425 | S6: -1155 | T6: -378 | U6: -1425 | V6: -1155 | W6: -378 | X6: =SUM(U6:W6) -> -2958
A7: 5 | B7: 003310080020000-331008002 | D7: 1125 | E7: 1080 | F7: 918 | H7: 2150 | I7: 1930 | J7: 1640 | K7: 1 | L7: 1 | M7: main | N7: 0 | O7: 33.5 | P7: 50 | Q7: 6.5 | R7: 34337.5 | S7: 42500 | T7: 4693 | U7: 34337.5 | V7: 42662 | W7: 4693 | X7: =SUM(U7:W7) -> 81692.5
A8: 6 | B8: 003303000080000-33030000804 | D8: 1625 | E8: 1560 | F8: 1326 | H8: 1185 | I8: 1075 | J8: 950 | K8: 1 | L8: 1 | M8: main | N8: 0 | O8: 17 | P8: 2 | Q8: 0 | R8: -7480 | S8: -970 | T8: 0 | U8: -7480 | V8: -970 | W8: 0 | X8: =SUM(U8:W8) -> -8450
A9: 7 | B9: 003310080170000-33100801702 | D9: 1140 | E9: 1090 | F9: 925 | H9: 300 | I9: 275 | J9: 235 | K9: 1 | L9: 1 | M9: main | N9: 0 | O9: 0.5 | P9: 0 | Q9: 0 | R9: -420 | S9: 0 | T9: 0 | U9: -420 | V9: 0 | W9: 0 | X9: =SUM(U9:W9) -> -420
A10: 8 | B10: 003303000120000-330300012 | D10: 4630 | E10: 4170 | F10: 3540 | H10: 2300 | I10: 2030 | J10: 1800 | K10: 1 | L10: 1 | M10: main | N10: 0 | O10: 87 | P10: 34 | Q10: 0 | R10: -202710 | S10: -72760 | T10: 0 | U10: -202710 | V10: -72760 | W10: 0 | X10: =SUM(U10:W10) -> -275470
A11: 9 | B11: 003316010060000-331601006 | D11: 3380 | E11: 3040 | F11: 2580 | H11: 2860 | I11: 2575 | J11: 2205 | K11: 1 | L11: 1 | M11: main | N11: 0 | O11: 4 | P11: 1 | Q11: 0 | R11: -2080 | S11: -465 | T11: 0 | U11: -2080 | V11: -465 | W11: 0 | X11: =SUM(U11:W11) -> -2545
A12: 10 | B12: 003303000030000-33030000302 | D12: 2250 | E12: 2160 | F12: 1836 | H12: 1780 | I12: 1615 | J12: 1430 | K12: 1 | L12: 1 | M12: main | N12: 0 | O12: 0 | P12: 2 | Q12: 0 | R12: 0 | S12: -1090 | T12: 0 | U12: 0 | V12: -1090 | W12: 0 | X12: =SUM(U12:W12) -> -1090
A13: 11 | B13: 003310080220000-331008022 | D13: 1500 | E13: 1440 | F13: 1224 | H13: 1650 | I13: 1500 | J13: 1280 | K13: 1 | L13: 1 | M13: main | N13: 0 | O13: 5 | P13: 9.5 | Q13: 0 | R13: 750 | S13: 570 | T13: 0 | U13: 750 | V13: 1290 | W13: 0 | X13: =SUM(U13:W13) -> 2040
A14: 12 | B14: 003303000020000-33030000202 | D14: 2125 | E14: 2040 | F14: 1734 | H14: 1780 | I14: 1615 | J14: 1430 | K14: 1 | L14: 1 | M14: main | N14: 0 | O14: 8 | P14: 0 | Q14: 0 | R14: -2760 | S14: 0 | T14: 0 | U14: -2760 | V14: 0 | W14: 0 | X14: =SUM(U14:W14) -> -2760
... A60: 58 | B60: 003310080010001-33100800103 | D60: 1925 | E60: 1850 | F60: 1575 | H60: 450 | I60: 430 | J60: 360 | K60: 1 | L60: 1 | M60: main | N60: 0 | O60: 693.5 | P60: 185.5 | Q60: 6 | R60: -1022912.5 | S60: -263410 | T60: -7290 | U60: -1022912.5 | V60: -263410 | W60: -7290 | X60: =SUM(U60:W60) -> -1293612.5
