Workbook

Sheet 映射表
A1: 呼吸系统类立项指南项目对应及拟定情况（征求意见稿）
A2: 呼吸系统类立项指南项目 | V2: 现行项目
A3: 序号 | B3: 项目代码 | C3: 项目名称 | D3: 归集口径 | E3: 服务产出 | F3: 价格构成 | G3: 计价单位 | H3: 计价说明 | I3: 省三甲价格 | J3: 省三甲以下价格 | K3: 平移价格 (市级) | L3: 平移价格 (县级) | M3: 平移价格 (基层) | N3: 拟定价格 (市级) | O3: 拟定价格 (县级) | P3: 拟定价格 (基层) | Q3: 医保 属性 | R3: 医保限定支付范围 | S3: 个人先行自付比例 | T3: 调整情况 | U3: 备注 | V3: 国家结算编码 | W3: 项目编码 | X3: 项目名称 | Y3: 项目内涵 | Z3: 除外内容 | AA3: 计价单位 | AB3: 说明 | AC3: 价格 (市级) | AD3: 价格 (县级) | AE3: 价格 (基层) | AF3: 医保属性
A4: 1 | B4: 012407000010000 | C4: 肺容积检查费 | D4: 检查费 | E4: 通过各种方式测量肺容纳的气体量。 | F4: 所定价格涵盖设备准备、仪器测定、撤除、处理用物、出具报告等步骤所需的人力资源和基本物质资源消耗。 | G4: 次 | I4: 50 | J4: 45 | K4: 57.5 | L4: 50 | M4: 42.5 | N4: 50 | O4: 45 | P4: 39 | Q4: 医保 | T4: 理顺，调低 | U4: 平移后按不超过省级拟定；同质化检查类项目持平省级 | V4: 003106010050000-310601005 | W4: 310601005 | X4: 残气容积测定 | Y4: 包括体描法，氦气平衡法，氮气稀释法，重复呼吸法 | AA4: 项 | AC4: 57.5 | AD4: 50 | AE4: 42.5 | AF4: 医保
A5: 2 | B5: 012407000020000 | C5: 肺通气功能检查费 | D5: 检查费 | E5: 通过各种方式测量肺与外界环境之间的气体交换情况。 | F5: 所定价格涵盖设备准备、仪器测定、撤除、处理用物、出具报告等步骤所需的人力资源和基本物质资源消耗。 | G5: 次 | H5: 支气管舒张试验按两次肺通气功能检查费收取。 | I5: 105 | J5: 95 | K5: 171.79046 | L5: 215.44649 | M5: 131.10052 | N5: 105 | O5: 95 | P5: 85 | Q5: 医保 | T5: 理顺，调低 | U5: 平移后按不超过省级拟定；同质化检查类项目持平省级 | V5: 003106010010000-310601001 | W5: 310601001 | X5: 肺通气功能检查 | Y5: 含潮气量、肺活量、每分通气量、补吸、呼气量、深吸气量、用力肺活量、一秒钟用力呼吸容积；不含最大通气量 | AA5: 次 | AB5: 最大通气量基层加收29.8元，县级医院加收35元，市级医院加收40.3元 | AC5: 74.8 | AD5: 65 | AE5: 55.3 | AF5: 医保
V6: 003106010010000-31060100101 | W6: 31060100101 | X6: 肺通气功能检查（最大通气量加收） | AA6: 次 | AB6: 最大通气量加收 | AC6: 40.3 | AD6: 35 | AE6: 29.8 | AF6: 医保 | AG6: 纳入价格构成
V7: 003106010080000-310601008 | W7: 310601008 | X7: 流速容量曲线（V—V曲线） | Y7: 含最大吸气和呼气流量曲线 | AA7: 项 | AC7: 34.5 | AD7: 30 | AE7: 25.5 | AF7: 医保
V8: 003106010090000-310601009 | W8: 310601009 | X8: 二氧化碳反应曲线 | AA8: 项 | AC8: 34.5 | AD8: 30 | AE8: 25.5 | AF8: 医保
C9: 肺通气功能检查费（支气管舒张试验） | I9: =I5*2 -> 210 | J9: =J5*2 -> 190 | K9: 115 | L9: 100 | M9: 85 | N9: 210 | O9: 190 | P9: 170 | U9: 支气管舒张试验按两次肺通气功能检查费收取。 | V9: 003106010120000-310601012 | W9: 310601012 | X9: 支气管舒张试验 | Y9: 含通气功能测定2次 | AA9: 项 | AC9: 115 | AD9: 100 | AE9: 85 | AF9: 医保
A10: 分项 | B10: 012407000020001 | C10: 肺通气功能检查费-儿童（加收） | D10: 检查费 | G10: 次 | I10: 32 | J10: 29 | N10: 32 | O10: 29 | P10: 26 | Q10: 医保 | U10: 儿童加收30%
A11: 分项 | B11: 012407000020011 | C11: 肺通气功能检查费-简易肺功能检查（减收） | D11: 检查费 | G11: 次 | I11: 65 | J11: 59 | K11: 59 | L11: 55 | M11: 51 | N11: 65 | O11: 59 | P11: 51 | Q11: 医保 | U11: 主项扣除原项目价格，得减收的平移价格，我市原项目价格倒挂省级，现减收后调整为不超过省级。 | V11: 003106020010000-310602001 | W11: 310602001 | X11: 床边简易肺功能测定（肺通气功能测定） | AA11: 次 | AB11: 即肺通气功能测定 | AC11: 46 | AD11: 40 | AE11: 34 | AF11: 医保
A12: 3 | B12: 012407000030000 | C12: 支气管激发试验检查费 | D12: 检查费 | E12: 通过各种刺激方式评估气道反应性。 | F12: 所定价格涵盖设备准备、仪器测定、撤除、处理用物、出具报告等步骤所需的人力资源和基本物质资源消耗。 | G12: 次 | I12: 100 | J12: 90 | K12: 115 | L12: 100 | M12: 85 | N12: 100 | O12: 90 | P12: 77 | Q12: 医保 | T12: 理顺，调低 | U12: 平移后按不超过省级拟定；同质化检查类项目持平省级 | V12: 003106010100000-310601010 | W12: 310601010 | X12: 支气管激发试验 | AA12: 项 | AC12: 115 | AD12: 100 | AE12: 85 | AF12: 医保
V13: 003106010110000-310601011 | W13: 310601011 | X13: 运动激发试验 | Y13: 含通气功能测定7次；不含心电监测 | AA13: 项 | AC13: 115 | AD13: 100 | AE13: 85 | AF13: 医保
A14: 4 | B14: 012407000040000 | C14: 肺弥散功能检查费 | D14: 检查费 | E14: 通过各种方式测量肺泡与肺毛细血管血液之间的气体交换情况。 | F14: 所定价格涵盖设备准备、仪器测定、撤除、处理用物、出具报告等步骤所需的人力资源和基本物质资源消耗。 | G14: 次 | I14: 60 | J14: 54 | K14: 69 | L14: 60 | M14: 51 | N14: 60 | O14: 54 | P14: 46 | Q14: 医保 | T14: 理顺，调低 | U14: 平移后按不超过省级拟定；同质化检查类项目持平省级 | V14: 003106010020000-310601002 | W14: 310601002 | X14: 肺弥散功能检查 | Y14: 包括一口气法，重复呼吸法 | AA14: 项 | AC14: 69 | AD14: 60 | AE14: 51 | AF14: 医保
A15: 5 | B15: 012407000050000 | C15: 呼吸阻力检查费 | D15: 检查费 | E15: 通过各种方式测量气道内单位流量所产生的压力差。 | F15: 所定价格涵盖设备准备、仪器测定、撤除、处理用物、出具报告等步骤所需的人力资源和基本物质资源消耗。 | G15: 次 | I15: 110 | J15: 99 | K15: 99.931637 | L15: 88.698049 | M15: 76.35989 | N15: 100 | O15: 90 | P15: 77 | Q15: 医保 | T15: 平移取整 | U15: 平移取整 | V15: 003106010040000-310601004 | W15: 310601004 | X15: 气道阻力测定 | Y15: 包括阻断法；不含残气容积测定 | AA15: 项 | AC15: 57.5 | AD15: 50 | AE15: 42.5 | AF15: 医保
V16: 003106010060000-310601006 | W16: 310601006 | X16: 强迫振荡肺功能检查 | AA16: 项 | AC16: 115 | AD16: 100 | AE16: 85 | AF16: 医保
V17: 003106010070000-310601007 | W17: 310601007 | X17: 第一秒平静吸气口腔闭合压测定 | AA17: 项 | AG17: 纳入价格构成
A18: 6 | B18: 012407000060000 | C18: 运动心肺功能检查费 | D18: 检查费 | E18: 通过在运动状态下监测心肺功能指标，判断心脏、肺脏和循环系统之间的相互作用与贮备能力。 | F18: 所定价格涵盖设备准备、仪器测定、撤除、处理用物、出具报告等步骤所需的人力资源和基本物质资源消耗。 | G18: 次 | I18: 160 | J18: 144 | K18: 184 | L18: 160 | M18: 136 | N18: 160 | O18: 144 | P18: 123 | Q18: 医保 | T18: 理顺，调低 | U18: 平移后按不超过省级拟定；同质化检查类项目持平省级 | V18: 003106010030000-310601003 | W18: 310601003 | X18: 运动心肺功能检查 | Y18: 不含心电监测 | AA18: 项 | AB18: 因病情变化未能完成本试验者，亦按本标准计价 | AC18: 184 | AD18: 160 | AE18: 136 | AF18: 医保
A19: 7 | B19: 012407000070000 | C19: 肺阻抗血流图检查费 | D19: 检查费 | E19: 通过测量肺部血流的物理性质和速度，检查肺部是否存在阻力增加。 | F19: 所定价格涵盖设备准备、仪器测定、撤除、处理用物、出具报告等步骤所需的人力资源和基本物质资源消耗。 | G19: 次 | I19: 12 | J19: 11 | K19: 11.5 | L19: 10 | M19: 8.5 | N19: 11.5 | O19: 10 | P19: 8.5 | Q19: 医保 | T19: 平移 | U19: 平移 | V19: 003106020020000-310602002 | W19: 310602002 | X19: 肺阻抗血流图 | AC19: 11.5 | AD19: 10 | AE19: 8.5
A20: 8 | B20: 012407000080000 | C20: 肺电阻抗成像检查费 | D20: 检查费 | E20: 通过检查呼吸周期中胸部电阻抗变化，检查肺部通气、血流等指标的变化。 | F20: 所定价格涵盖设备准备、仪器测定、撤除、处理用物、出具报告等步骤所需的人力资源和基本物质资源消耗。 | G20: 次 | I20: 160 | J20: 144 | N20: 150 | O20: 135 | P20: 115 | Q20: 非医保 | T20: 新增 | U20: 新增项目，同质化检查类项目暂按不超过省级95%拟定
A21: 9 | B21: 012407000090000 | C21: 呼吸肌功能检查费 | D21: 检查费 | E21: 通过测量气道压力和流量变化等指标评估患者呼吸肌力量。 | F21: 所定价格涵盖设备准备、仪器测定、撤除、处理用物、出具报告等步骤所需的人力资源和基本物质资源消耗。 | G21: 次 | I21: 60 | J21: 54 | K21: 69 | L21: 60 | M21: 51 | N21: 60 | O21: 54 | P21: 46 | Q21: 医保 | T21: 理顺，调低 | U21: 平移后按不超过省级拟定；同质化检查类项目持平省级 | V21: 003106020030000-310602003 | W21: 310602003 | X21: 呼吸肌功能测定 | Y21: 含最大吸气、呼气压、膈肌功能测定 | AA21: 次 | AC21: 69 | AD21: 60 | AE21: 51 | AF21: 医保
A22: 10 | B22: 012407000100000 | C22: 膈肌功能检查费 | D22: 检查费 | E22: 通过电活动或压力测定，评估患者膈肌功能。 | F22: 所定价格涵盖设备准备、仪器测定、撤除、处理用物、出具报告等步骤所需的人力资源和基本物质资源消耗。 | G22: 次 | I22: 60 | J22: 54 | K22: 69 | L22: 60 | M22: 51 | N22: 60 | O22: 54 | P22: 46 | Q22: 医保 | T22: 理顺，调低 | U22: 平移后按不超过省级拟定；同质化检查类项目持平省级 | V22: 003106020030000-310602003 | W22: 310602003 | X22: 呼吸肌功能测定 | Y22: 含最大吸气、呼气压、膈肌功能测定 | AA22: 次 | AC22: 69 | AD22: 60 | AE22: 51 | AF22: 医保
A23: 11 | B23: 012407000110000 | C23: 睡眠呼吸监测费 | D23: 检查费 | E23: 对睡眠状态下患者呼吸行为状、呼吸功能进行监测，同步观察患者必要的生命体征及电生理指标。 | F23: 所定价格涵盖设备准备、仪器测定、撤除、处理用物、出具报告等步骤所需的人力资源和基本物质资源消耗。 | G23: 次 | H23: 不得同时收取心电、脑电、肌电、眼动、呼吸监测和血氧饱和度测定费用。 | I23: 400 | J23: 360 | K23: 379.5 | L23: 356.5 | M23: 333.5 | N23: 380 | O23: 357 | P23: 335 | Q23: 医保 | T23: 平移取整 | U23: 计价单位由小时改为次，一次按11-12小时计算。 | V23: 003106040010000-310604001 | W23: 310604001 | X23: 睡眠呼吸监测 | Y23: 含心电、脑电、肌电、眼动、呼吸监测和血氧饱和度测定 | AA23: 小时 | AC23: 33 | AD23: 31 | AE23: 29 | AF23: 医保
A24: 分项 | B24: 012407000110001 | C24: 睡眠呼吸监测费-便携睡眠呼吸监测（减收） | G24: 次 | I24: 277 | J24: 249 | K24: 230.5 | L24: 227 | M24: 224.5 | N24: 250 | O24: 242 | P24: 186 | Q24: 医保 | U24: 主项扣除原项目价格，得出减收的平移价格，我市原项目价格倒挂省级，现减收后调整为不超过省级。 | V24: 003106020040000-310602004 | W24: 310602004 | X24: 动态呼吸监测（呼吸Holter） | AA24: 次 | AC24: 115 | AD24: 100 | AE24: 85 | AF24: 医保
V25: 003106040020000-310604002 | W25: 310604002 | X25: 睡眠呼吸监测过筛试验 | Y25: 含口鼻呼吸、胸腹呼吸、血氧饱和度测定 | AA25: 次 | AC25: 149.5 | AD25: 130 | AE25: 110.5
A26: 12 | B26: 012407000120000 | C26: 经皮氧分压/二氧化碳监测费 | D26: 检查费 | E26: 通过经皮测定方法，持续测定氧分压和/或二氧化碳。 | F26: 所定价格涵盖设备准备、仪器测定、撤除、处理用物等步骤所需的人力资源和基本物质资源消耗。 | G26: 小时 | H26: 超过3小时按3小时收费。 | I26: 15 | J26: 14 | N26: 14 | O26: 13 | P26: 12 | Q26: 医保 | T26: 新增 | U26: 按比价拟定，同质化检查类项目暂按不超过省级95%拟定 | Y26: 患者仰卧，连接氧分压测定仪于肢体不同部位，开启氧分压测定仪，分别检测肢体不同部位的氧分压，记录并报告。
A27: 13 | B27: 012407000130000 | C27: 支气管镜检查费（常规内镜） | D27: 检查费 | E27: 通过支气管镜观察和诊断支气管、气管、气管壁或肺部等部位的疾病。 | F27: 所定价格涵盖设备准备、体位摆放、入镜、观察、图像采集、撤镜、处理用物、出具报告等步骤所需的人力资源和基本物质资源消耗。 | G27: 次 | H27: 本项目中的“特殊光源”指：荧光、窄谱光源。 | I27: 250 | J27: 225 | K27: 239.43968 | L27: 215.61159 | M27: 192 | N27: 240 | O27: 216 | P27: 190 | Q27: 医保 | S27: 0.2 | T27: 平移取整 | U27: 平移取整 | V27: 003106050020000-310605002 | W27: 310605002 | X27: 纤维支气管镜检查 | Y27: 包括针吸活检、支气管刷片 | Z27: 特殊穿刺针 | AA27: 次 | AC27: 138 | AD27: 120 | AE27: 102 | AF27: 医保
V28: 003106050010000-310605001 | W28: 310605001 | X28: 硬质气管镜检查 | AA28: 次 | AC28: 115 | AD28: 100 | AE28: 85 | AF28: 医保
V29: 003106050000001-31060500002 | W29: 31060500002 | X29: 呼吸系统窥镜诊疗（使用电子支气管镜加收） | AA29: 次 | AB29: 使用电子支气管镜加收 | AC29: 138 | AD29: 120 | AE29: 102 | AF29: 医保 | AG29: 纳入价格构成
V30: 003106050000001-31060500001 | W30: 31060500001 | X30: 呼吸系统窥镜诊疗（使用电子纤维内镜加收） | AA30: 次 | AB30: 使用电子纤维内镜加收 | AC30: 115 | AD30: 100 | AE30: 85 | AF30: 医保 | AG30: 纳入价格构成
A31: 分项 | B31: 012407000130001 | C31: 支气管镜检查费（常规内镜）-特殊光源检查（加收） | D31: 检查费 | G31: 次 | H31: 本项目中的“特殊光源”指：荧光、窄谱光源。 | I31: 85 | J31: 77 | N31: 82 | O31: 74 | P31: 65 | Q31: 医保 | S31: 0.2 | U31: 新增加项，为主项的34%
A32: 14 | B32: 012407000140000 | C32: 支气管镜检查费（超声内镜） | D32: 检查费 | E32: 通过超声支气管镜观察和诊断支气管、气管、气管壁、气管腔外或肺部等部位的疾病。 | F32: 所定价格涵盖设备准备、体位摆放、入镜、观察、图像采集、撤镜、处理用物、出具报告等步骤所需的人力资源和基本物质资源消耗。 | G32: 次 | I32: 650 | J32: 585 | K32: 585 | L32: 527 | M32: 448 | N32: 585 | O32: 527 | P32: 448 | Q32: 医保 | S32: 0.2 | T32: 平移 | U32: 平移 | V32: 003106050020000-310605015 | W32: 310605015 | X32: 超声支气管镜检查 | Y32: 咽部麻醉、润滑，插入超声支气管镜，观察气道变化，将超声水囊充满，观察支气管壁及壁外结构，定位后进行经支气管淋巴结针吸活检。标本送细胞学和组织学等检查。不含病理学检查、活检。 | Z32: 穿刺针 | AA32: 次 | AC32: 585 | AD32: 527 | AE32: 448 | AF32: 医保
A33: 15 | B33: 012407000150000 | C33: 支气管镜检查费（共聚焦激光显微内镜） | D33: 检查费 | E33: 通过共聚焦激光显微支气管镜观察和诊断支气管、气管、气管壁或肺部等部位的疾病。 | F33: 所定价格涵盖设备准备、体位摆放、入镜、观察、图像采集、撤镜、处理用物、出具报告等步骤所需的人力资源和基本物质资源消耗。 | G33: 次 | I33: 695 | J33: 626 | N33: 630 | O33: 570 | P33: 485 | Q33: 非医保 | T33: 新增 | U33: 新增项目，按比价拟定
A34: 16 | B34: 012407000160000 | C34: 肺叶通气功能检查费 | D34: 检查费 | E34: 通过无创方式置入球囊导管，评估支气管通气情况。 | F34: 所定价格涵盖设备准备、体位摆放、导管置入、球囊充气、数据采集、设备撤除、处理用物人力资源、设备运转成本与基本物质资源消耗。 | G34: 次 | I34: 594 | J34: 535 | N34: 540 | O34: 490 | P34: 415 | Q34: 非医保 | T34: 新增 | U34: 新增项目，按比价拟定
A35: 17 | B35: 012407000170000 | C35: 纵隔镜探查费 | D35: 检查费 | E35: 通过纵隔镜观察和诊断纵隔、支气管、气管、胸腺、食管、淋巴结或肺部等部位的疾病。 | F35: 所定价格涵盖设备准备、体位摆放、切开、入镜、观察、撤镜、缝合、关闭、处理用物等手术步骤所需的人力资源和基本物质资源消耗。 | G35: 次 | I35: 550 | J35: 495 | K35: 575 | L35: 500 | M35: 425 | N35: 540 | O35: 490 | P35: 415 | Q35: 医保 | T35: 理顺，调低 | U35: 平移后按不超过省级拟定 | V35: 003106050140000-310605014 | W35: 310605014 | X35: 纵隔镜检查 | Y35: 含纵隔淋巴结活检 | AA35: 次 | AC35: 575 | AD35: 500 | AE35: 425 | AF35: 医保
A36: 18 | B36: 013106000010000 | C36: 体外膈肌起搏治疗费 | D36: 治疗费 | E36: 通过电刺激，诱导膈肌主动收缩。 | F36: 所定价格涵盖设备准备、连接电极、起搏治疗、撤除、处理用物等步骤所需的人力资源和基本物质资源消耗。 | G36: 次 | I36: 15 | J36: 15 | K36: 17.3 | L36: 15 | M36: 12.8 | N36: 15 | O36: 14 | P36: 13 | Q36: 医保 | T36: 理顺，调低 | U36: 平移后按不超过省级拟定 | V36: 003106030030000-310603003 | W36: 310603003 | X36: 体外膈肌起搏治疗 | AA36: 次 | AC36: 17.3 | AD36: 15 | AE36: 12.8 | AF36: 医保
A37: 19 | B37: 013106000020000 | C37: 一氧化氮吸入治疗费 | D37: 治疗费 | E37: 通过吸入一氧化氮进行治疗。 | F37: 所定价格涵盖设备准备、气体调节、吸入治疗、调节、监测、处理用物等步骤所需的人力资源、设备运转成本消耗与基本物质资源消耗。 | G37: 小时 | I37: 50 | J37: 50 | K37: 9 | L37: 9 | M37: 9 | N37: 45 | O37: 45 | P37: 41 | Q37: 医保 | T37: 提高 | U37: 省级通过区域间比价提高价格（我省价格过低），我市按比价提高，市县持平，基层拉开比价。 | V37: 353106040090000-12030000140 | W37: 12030000140 | X37: 一氧化氮吸入 | Y37: 机械通气的同时，连接一氧化氮装置，监测一氧化氮及二氧化氮浓度，根据患者病情调节浓度，观察使用效果。 | AA37: 小时 | AB37: 每日不超过90元 | AC37: 9 | AD37: 9 | AE37: 9 | AF37: 医保
A38: 20 | B38: 013106000030000 | C38: 雾化吸入治疗费 | D38: 治疗费 | E38: 通过各种方式吸入气雾或气溶胶颗粒进行治疗。 | F38: 所定价格涵盖设备准备、成分制备、连接、调节、吸入、观察、记录、处理用物等所需的人力资源和基本物质资源消耗。 | G38: 次 | H38: 多种药物确需分开雾化吸入的可分别计价收费。 | I38: 15 | J38: 15 | K38: 12.205279 | L38: 12.202812 | M38: 11.500005 | N38: 14 | O38: 13 | P38: 12 | Q38: 医保 | T38: 提高 | U38: 一次性雾化吸入器纳入价格构成，我市医疗机构采购均价约7.2元。叠加项目价格购平移。 省级通过区域间比价提高价格（我省价格过低），我市按比价提高，同质化项目缩小价差 | V38: 001207000010000-120700001 | W38: 120700001 | X38: 雾化吸入 | Y38: 包括超声、高压泵、氧化雾化、蒸气雾化吸入及机械通气经呼吸机管道雾化给药 | Z38: 药物、一次性雾化器 | AA38: 次 | AF38: 医保
V39: 001207000010100-12070000101 | W39: 12070000101 | X39: 超声雾化吸入 | AA39: 次 | AC39: 5 | AD39: 5 | AE39: 4.3 | AF39: 医保
V40: 001207000010200-12070000102 | W40: 12070000102 | X40: 高压泵雾化吸入 | AA40: 次 | AC40: 5 | AD40: 5 | AE40: 4.3 | AF40: 医保
...

Sheet 映射表 (2)
A1: 呼吸系统类立项指南项目对应及拟定情况（征求意见稿）
A2: 呼吸系统类立项指南项目 | V2: 现行项目
A3: 序号 | B3: 项目代码 | C3: 项目名称 | D3: 归集口径 | E3: 服务产出 | F3: 价格构成 | G3: 计价单位 | H3: 计价说明 | I3: 省三甲价格 | J3: 省三甲以下价格 | K3: 平移价格 (市级) | L3: 平移价格 (县级) | M3: 平移价格 (基层) | N3: 拟定价格 (市级) | O3: 拟定价格 (县级) | P3: 拟定价格 (基层) | Q3: 医保 属性 | R3: 医保限定支付范围 | S3: 个人先行自付比例 | T3: 调整情况 | U3: 备注 | V3: 国家结算编码 | W3: 项目编码 | X3: 项目名称 | Y3: 项目内涵 | Z3: 除外内容 | AA3: 计价单位 | AB3: 说明 | AC3: 价格 (市级) | AD3: 价格 (县级) | AE3: 价格 (基层)
A4: 1 | B4: 012407000010000 | C4: 肺容积检查费 | D4: 检查费 | E4: 通过各种方式测量肺容纳的气体量。 | F4: 所定价格涵盖设备准备、仪器测定、撤除、处理用物、出具报告等步骤所需的人力资源和基本物质资源消耗。 | G4: 次 | I4: 50 | J4: 45 | K4: 57.5 | L4: 50 | M4: 42.5 | N4: 50 | O4: 45 | P4: 39 | Q4: 医保 | T4: 理顺，调低 | U4: 平移后按不超过省级拟定；同质化检查类项目持平省级 | V4: 003106010050000-310601005 | W4: 310601005 | X4: 残气容积测定 | Y4: 包括体描法，氦气平衡法，氮气稀释法，重复呼吸法 | AA4: 项 | AC4: 57.5 | AD4: 50 | AE4: 42.5 | AF4: =IFERROR(FIND("-儿童（加收）",C4,1),0) -> 0 | AG4: =SUBSTITUTE(C4,"-儿童（加收）","") -> 肺容积检查费 | AH4: =IF(AF4>0,_xlfn.MAXIFS(N:N,C:C,SUBSTITUTE(C4,"-儿童（加收）","")),0)+N4 -> 50 | AI4: =IF(AF4>0,_xlfn.MAXIFS(O:O,C:C,SUBSTITUTE(C4,"-儿童（加收）","")),0)+O4 -> 45 | AJ4: =IF(AF4>0,_xlfn.MAXIFS(P:P,C:C,SUBSTITUTE(C4,"-儿童（加收）","")),0)+P4 -> 39
A5: 2 | B5: 012407000020000 | C5: 肺通气功能检查费 | D5: 检查费 | E5: 通过各种方式测量肺与外界环境之间的气体交换情况。 | F5: 所定价格涵盖设备准备、仪器测定、撤除、处理用物、出具报告等步骤所需的人力资源和基本物质资源消耗。 | G5: 次 | H5: 支气管舒张试验按两次肺通气功能检查费收取。 | I5: 105 | J5: 95 | K5: 171.79046 | L5: 215.44649 | M5: 131.10052 | N5: 105 | O5: 95 | P5: 85 | Q5: 医保 | T5: 理顺，调低 | U5: 平移后按不超过省级拟定；同质化检查类项目持平省级 | V5: 003106010010000-310601001 | W5: 310601001 | X5: 肺通气功能检查 | Y5: 含潮气量、肺活量、每分通气量、补吸、呼气量、深吸气量、用力肺活量、一秒钟用力呼吸容积；不含最大通气量 | AA5: 次 | AB5: 最大通气量基层加收29.8元，县级医院加收35元，市级医院加收40.3元 | AC5: 74.8 | AD5: 65 | AE5: 55.3 | AF5: =IFERROR(FIND("-儿童（加收）",C5,1),0) -> 0 | AG5: =SUBSTITUTE(C5,"-儿童（加收）","") -> 肺通气功能检查费 | AH5: =IF(AF5>0,_xlfn.MAXIFS(N:N,C:C,SUBSTITUTE(C5,"-儿童（加收）","")),0)+N5 -> 105 | AI5: =IF(AF5>0,_xlfn.MAXIFS(O:O,C:C,SUBSTITUTE(C5,"-儿童（加收）","")),0)+O5 -> 95 | AJ5: =IF(AF5>0,_xlfn.MAXIFS(P:P,C:C,SUBSTITUTE(C5,"-儿童（加收）","")),0)+P5 -> 85
C6: 肺通气功能检查费 | N6: 105 | O6: 95 | P6: 85 | V6: 003106010010000-31060100101 | W6: 31060100101 | X6: 肺通气功能检查（最大通气量加收） | AA6: 次 | AB6: 最大通气量加收 | AC6: 40.3 | AD6: 35 | AE6: 29.8 | AF6: =IFERROR(FIND("-儿童（加收）",C6,1),0) -> 0 | AG6: =SUBSTITUTE(C6,"-儿童（加收）","") -> 肺通气功能检查费 | AH6: =IF(AF6>0,_xlfn.MAXIFS(N:N,C:C,SUBSTITUTE(C6,"-儿童（加收）","")),0)+N6 -> 105 | AI6: =IF(AF6>0,_xlfn.MAXIFS(O:O,C:C,SUBSTITUTE(C6,"-儿童（加收）","")),0)+O6 -> 95 | AJ6: =IF(AF6>0,_xlfn.MAXIFS(P:P,C:C,SUBSTITUTE(C6,"-儿童（加收）","")),0)+P6 -> 85
C7: 肺通气功能检查费 | N7: 105 | O7: 95 | P7: 85 | V7: 003106010080000-310601008 | W7: 310601008 | X7: 流速容量曲线（V—V曲线） | Y7: 含最大吸气和呼气流量曲线 | AA7: 项 | AC7: 34.5 | AD7: 30 | AE7: 25.5 | AF7: =IFERROR(FIND("-儿童（加收）",C7,1),0) -> 0 | AG7: =SUBSTITUTE(C7,"-儿童（加收）","") -> 肺通气功能检查费 | AH7: =IF(AF7>0,_xlfn.MAXIFS(N:N,C:C,SUBSTITUTE(C7,"-儿童（加收）","")),0)+N7 -> 105 | AI7: =IF(AF7>0,_xlfn.MAXIFS(O:O,C:C,SUBSTITUTE(C7,"-儿童（加收）","")),0)+O7 -> 95 | AJ7: =IF(AF7>0,_xlfn.MAXIFS(P:P,C:C,SUBSTITUTE(C7,"-儿童（加收）","")),0)+P7 -> 85
C8: 肺通气功能检查费 | N8: 105 | O8: 95 | P8: 85 | V8: 003106010090000-310601009 | W8: 310601009 | X8: 二氧化碳反应曲线 | AA8: 项 | AC8: 34.5 | AD8: 30 | AE8: 25.5 | AF8: =IFERROR(FIND("-儿童（加收）",C8,1),0) -> 0 | AG8: =SUBSTITUTE(C8,"-儿童（加收）","") -> 肺通气功能检查费 | AH8: =IF(AF8>0,_xlfn.MAXIFS(N:N,C:C,SUBSTITUTE(C8,"-儿童（加收）","")),0)+N8 -> 105 | AI8: =IF(AF8>0,_xlfn.MAXIFS(O:O,C:C,SUBSTITUTE(C8,"-儿童（加收）","")),0)+O8 -> 95 | AJ8: =IF(AF8>0,_xlfn.MAXIFS(P:P,C:C,SUBSTITUTE(C8,"-儿童（加收）","")),0)+P8 -> 85
C9: 肺通气功能检查费（支气管舒张试验） | I9: =I5*2 -> 210 | J9: =J5*2 -> 190 | K9: 115 | L9: 100 | M9: 85 | N9: 210 | O9: 190 | P9: 170 | U9: 支气管舒张试验按两次肺通气功能检查费收取。 | V9: 003106010120000-310601012 | W9: 310601012 | X9: 支气管舒张试验 | Y9: 含通气功能测定2次 | AA9: 项 | AC9: 115 | AD9: 100 | AE9: 85 | AF9: =IFERROR(FIND("-儿童（加收）",C9,1),0) -> 0 | AG9: =SUBSTITUTE(C9,"-儿童（加收）","") -> 肺通气功能检查费（支气管舒张试验） | AH9: =IF(AF9>0,_xlfn.MAXIFS(N:N,C:C,SUBSTITUTE(C9,"-儿童（加收）","")),0)+N9 -> 210 | AI9: =IF(AF9>0,_xlfn.MAXIFS(O:O,C:C,SUBSTITUTE(C9,"-儿童（加收）","")),0)+O9 -> 190 | AJ9: =IF(AF9>0,_xlfn.MAXIFS(P:P,C:C,SUBSTITUTE(C9,"-儿童（加收）","")),0)+P9 -> 170
A10: 分项 | B10: 012407000020011 | C10: 肺通气功能检查费-简易肺功能检查（减收） | D10: 检查费 | G10: 次 | I10: 65 | J10: 59 | K10: 59 | L10: 55 | M10: 51 | N10: 65 | O10: 59 | P10: 51 | Q10: 医保 | U10: 主项扣除原项目价格，得减收的平移价格，我市原项目价格倒挂省级，现减收后调整为不超过省级。 | V10: 003106020010000-310602001 | W10: 310602001 | X10: 床边简易肺功能测定（肺通气功能测定） | AA10: 次 | AB10: 即肺通气功能测定 | AC10: 46 | AD10: 40 | AE10: 34 | AF10: =IFERROR(FIND("-儿童（加收）",C10,1),0) -> 0 | AG10: =SUBSTITUTE(C10,"-儿童（加收）","") -> 肺通气功能检查费-简易肺功能检查（减收） | AH10: =IF(AF10>0,_xlfn.MAXIFS(N:N,C:C,SUBSTITUTE(C10,"-儿童（加收）","")),0)+N10 -> 65 | AI10: =IF(AF10>0,_xlfn.MAXIFS(O:O,C:C,SUBSTITUTE(C10,"-儿童（加收）","")),0)+O10 -> 59 | AJ10: =IF(AF10>0,_xlfn.MAXIFS(P:P,C:C,SUBSTITUTE(C10,"-儿童（加收）","")),0)+P10 -> 51
A11: 3 | B11: 012407000030000 | C11: 支气管激发试验检查费 | D11: 检查费 | E11: 通过各种刺激方式评估气道反应性。 | F11: 所定价格涵盖设备准备、仪器测定、撤除、处理用物、出具报告等步骤所需的人力资源和基本物质资源消耗。 | G11: 次 | I11: 100 | J11: 90 | K11: 115 | L11: 100 | M11: 85 | N11: 100 | O11: 90 | P11: 77 | Q11: 医保 | T11: 理顺，调低 | U11: 平移后按不超过省级拟定；同质化检查类项目持平省级 | V11: 003106010100000-310601010 | W11: 310601010 | X11: 支气管激发试验 | AA11: 项 | AC11: 115 | AD11: 100 | AE11: 85 | AF11: =IFERROR(FIND("-儿童（加收）",C11,1),0) -> 0 | AG11: =SUBSTITUTE(C11,"-儿童（加收）","") -> 支气管激发试验检查费 | AH11: =IF(AF11>0,_xlfn.MAXIFS(N:N,C:C,SUBSTITUTE(C11,"-儿童（加收）","")),0)+N11 -> 100 | AI11: =IF(AF11>0,_xlfn.MAXIFS(O:O,C:C,SUBSTITUTE(C11,"-儿童（加收）","")),0)+O11 -> 90 | AJ11: =IF(AF11>0,_xlfn.MAXIFS(P:P,C:C,SUBSTITUTE(C11,"-儿童（加收）","")),0)+P11 -> 77
C12: 支气管激发试验检查费 | N12: 100 | O12: 90 | P12: 77 | V12: 003106010110000-310601011 | W12: 310601011 | X12: 运动激发试验 | Y12: 含通气功能测定7次；不含心电监测 | AA12: 项 | AC12: 115 | AD12: 100 | AE12: 85 | AF12: =IFERROR(FIND("-儿童（加收）",C12,1),0) -> 0 | AG12: =SUBSTITUTE(C12,"-儿童（加收）","") -> 支气管激发试验检查费 | AH12: =IF(AF12>0,_xlfn.MAXIFS(N:N,C:C,SUBSTITUTE(C12,"-儿童（加收）","")),0)+N12 -> 100 | AI12: =IF(AF12>0,_xlfn.MAXIFS(O:O,C:C,SUBSTITUTE(C12,"-儿童（加收）","")),0)+O12 -> 90 | AJ12: =IF(AF12>0,_xlfn.MAXIFS(P:P,C:C,SUBSTITUTE(C12,"-儿童（加收）","")),0)+P12 -> 77
A13: 4 | B13: 012407000040000 | C13: 肺弥散功能检查费 | D13: 检查费 | E13: 通过各种方式测量肺泡与肺毛细血管血液之间的气体交换情况。 | F13: 所定价格涵盖设备准备、仪器测定、撤除、处理用物、出具报告等步骤所需的人力资源和基本物质资源消耗。 | G13: 次 | I13: 60 | J13: 54 | K13: 69 | L13: 60 | M13: 51 | N13: 60 | O13: 54 | P13: 46 | Q13: 医保 | T13: 理顺，调低 | U13: 平移后按不超过省级拟定；同质化检查类项目持平省级 | V13: 003106010020000-310601002 | W13: 310601002 | X13: 肺弥散功能检查 | Y13: 包括一口气法，重复呼吸法 | AA13: 项 | AC13: 69 | AD13: 60 | AE13: 51 | AF13: =IFERROR(FIND("-儿童（加收）",C13,1),0) -> 0 | AG13: =SUBSTITUTE(C13,"-儿童（加收）","") -> 肺弥散功能检查费 | AH13: =IF(AF13>0,_xlfn.MAXIFS(N:N,C:C,SUBSTITUTE(C13,"-儿童（加收）","")),0)+N13 -> 60 | AI13: =IF(AF13>0,_xlfn.MAXIFS(O:O,C:C,SUBSTITUTE(C13,"-儿童（加收）","")),0)+O13 -> 54 | AJ13: =IF(AF13>0,_xlfn.MAXIFS(P:P,C:C,SUBSTITUTE(C13,"-儿童（加收）","")),0)+P13 -> 46
A14: 5 | B14: 012407000050000 | C14: 呼吸阻力检查费 | D14: 检查费 | E14: 通过各种方式测量气道内单位流量所产生的压力差。 | F14: 所定价格涵盖设备准备、仪器测定、撤除、处理用物、出具报告等步骤所需的人力资源和基本物质资源消耗。 | G14: 次 | I14: 110 | J14: 99 | K14: 99.931637 | L14: 88.698049 | M14: 76.35989 | N14: 100 | O14: 90 | P14: 77 | Q14: 医保 | T14: 平移取整 | U14: 平移取整 | V14: 003106010040000-310601004 | W14: 310601004 | X14: 气道阻力测定 | Y14: 包括阻断法；不含残气容积测定 | AA14: 项 | AC14: 57.5 | AD14: 50 | AE14: 42.5 | AF14: =IFERROR(FIND("-儿童（加收）",C14,1),0) -> 0 | AG14: =SUBSTITUTE(C14,"-儿童（加收）","") -> 呼吸阻力检查费 | AH14: =IF(AF14>0,_xlfn.MAXIFS(N:N,C:C,SUBSTITUTE(C14,"-儿童（加收）","")),0)+N14 -> 100 | AI14: =IF(AF14>0,_xlfn.MAXIFS(O:O,C:C,SUBSTITUTE(C14,"-儿童（加收）","")),0)+O14 -> 90 | AJ14: =IF(AF14>0,_xlfn.MAXIFS(P:P,C:C,SUBSTITUTE(C14,"-儿童（加收）","")),0)+P14 -> 77
C15: 呼吸阻力检查费 | N15: 100 | O15: 90 | P15: 77 | V15: 003106010060000-310601006 | W15: 310601006 | X15: 强迫振荡肺功能检查 | AA15: 项 | AC15: 115 | AD15: 100 | AE15: 85 | AF15: =IFERROR(FIND("-儿童（加收）",C15,1),0) -> 0 | AG15: =SUBSTITUTE(C15,"-儿童（加收）","") -> 呼吸阻力检查费 | AH15: =IF(AF15>0,_xlfn.MAXIFS(N:N,C:C,SUBSTITUTE(C15,"-儿童（加收）","")),0)+N15 -> 100 | AI15: =IF(AF15>0,_xlfn.MAXIFS(O:O,C:C,SUBSTITUTE(C15,"-儿童（加收）","")),0)+O15 -> 90 | AJ15: =IF(AF15>0,_xlfn.MAXIFS(P:P,C:C,SUBSTITUTE(C15,"-儿童（加收）","")),0)+P15 -> 77
C16: 呼吸阻力检查费 | N16: 100 | O16: 90 | P16: 77 | V16: 003106010070000-310601007 | W16: 310601007 | X16: 第一秒平静吸气口腔闭合压测定 | AA16: 项 | AF16: =IFERROR(FIND("-儿童（加收）",C16,1),0) -> 0 | AG16: =SUBSTITUTE(C16,"-儿童（加收）","") -> 呼吸阻力检查费 | AH16: =IF(AF16>0,_xlfn.MAXIFS(N:N,C:C,SUBSTITUTE(C16,"-儿童（加收）","")),0)+N16 -> 100 | AI16: =IF(AF16>0,_xlfn.MAXIFS(O:O,C:C,SUBSTITUTE(C16,"-儿童（加收）","")),0)+O16 -> 90 | AJ16: =IF(AF16>0,_xlfn.MAXIFS(P:P,C:C,SUBSTITUTE(C16,"-儿童（加收）","")),0)+P16 -> 77
A17: 6 | B17: 012407000060000 | C17: 运动心肺功能检查费 | D17: 检查费 | E17: 通过在运动状态下监测心肺功能指标，判断心脏、肺脏和循环系统之间的相互作用与贮备能力。 | F17: 所定价格涵盖设备准备、仪器测定、撤除、处理用物、出具报告等步骤所需的人力资源和基本物质资源消耗。 | G17: 次 | I17: 160 | J17: 144 | K17: 184 | L17: 160 | M17: 136 | N17: 160 | O17: 144 | P17: 123 | Q17: 医保 | T17: 理顺，调低 | U17: 平移后按不超过省级拟定；同质化检查类项目持平省级 | V17: 003106010030000-310601003 | W17: 310601003 | X17: 运动心肺功能检查 | Y17: 不含心电监测 | AA17: 项 | AB17: 因病情变化未能完成本试验者，亦按本标准计价 | AC17: 184 | AD17: 160 | AE17: 136 | AF17: =IFERROR(FIND("-儿童（加收）",C17,1),0) -> 0 | AG17: =SUBSTITUTE(C17,"-儿童（加收）","") -> 运动心肺功能检查费 | AH17: =IF(AF17>0,_xlfn.MAXIFS(N:N,C:C,SUBSTITUTE(C17,"-儿童（加收）","")),0)+N17 -> 160 | AI17: =IF(AF17>0,_xlfn.MAXIFS(O:O,C:C,SUBSTITUTE(C17,"-儿童（加收）","")),0)+O17 -> 144 | AJ17: =IF(AF17>0,_xlfn.MAXIFS(P:P,C:C,SUBSTITUTE(C17,"-儿童（加收）","")),0)+P17 -> 123
A18: 7 | B18: 012407000070000 | C18: 肺阻抗血流图检查费 | D18: 检查费 | E18: 通过测量肺部血流的物理性质和速度，检查肺部是否存在阻力增加。 | F18: 所定价格涵盖设备准备、仪器测定、撤除、处理用物、出具报告等步骤所需的人力资源和基本物质资源消耗。 | G18: 次 | I18: 12 | J18: 11 | K18: 11.5 | L18: 10 | M18: 8.5 | N18: 11.5 | O18: 10 | P18: 8.5 | Q18: 医保 | T18: 平移 | U18: 平移 | V18: 003106020020000-310602002 | W18: 310602002 | X18: 肺阻抗血流图 | AC18: 11.5 | AD18: 10 | AE18: 8.5 | AF18: =IFERROR(FIND("-儿童（加收）",C18,1),0) -> 0 | AG18: =SUBSTITUTE(C18,"-儿童（加收）","") -> 肺阻抗血流图检查费 | AH18: =IF(AF18>0,_xlfn.MAXIFS(N:N,C:C,SUBSTITUTE(C18,"-儿童（加收）","")),0)+N18 -> 11.5 | AI18: =IF(AF18>0,_xlfn.MAXIFS(O:O,C:C,SUBSTITUTE(C18,"-儿童（加收）","")),0)+O18 -> 10 | AJ18: =IF(AF18>0,_xlfn.MAXIFS(P:P,C:C,SUBSTITUTE(C18,"-儿童（加收）","")),0)+P18 -> 8.5
A19: 9 | B19: 012407000090000 | C19: 呼吸肌功能检查费 | D19: 检查费 | E19: 通过测量气道压力和流量变化等指标评估患者呼吸肌力量。 | F19: 所定价格涵盖设备准备、仪器测定、撤除、处理用物、出具报告等步骤所需的人力资源和基本物质资源消耗。 | G19: 次 | I19: 60 | J19: 54 | K19: 69 | L19: 60 | M19: 51 | N19: 60 | O19: 54 | P19: 46 | Q19: 医保 | T19: 理顺，调低 | U19: 平移后按不超过省级拟定；同质化检查类项目持平省级 | V19: 003106020030000-310602003 | W19: 310602003 | X19: 呼吸肌功能测定 | Y19: 含最大吸气、呼气压、膈肌功能测定 | AA19: 次 | AC19: 69 | AD19: 60 | AE19: 51 | AF19: =IFERROR(FIND("-儿童（加收）",C19,1),0) -> 0 | AG19: =SUBSTITUTE(C19,"-儿童（加收）","") -> 呼吸肌功能检查费 | AH19: =IF(AF19>0,_xlfn.MAXIFS(N:N,C:C,SUBSTITUTE(C19,"-儿童（加收）","")),0)+N19 -> 60 | AI19: =IF(AF19>0,_xlfn.MAXIFS(O:O,C:C,SUBSTITUTE(C19,"-儿童（加收）","")),0)+O19 -> 54 | AJ19: =IF(AF19>0,_xlfn.MAXIFS(P:P,C:C,SUBSTITUTE(C19,"-儿童（加收）","")),0)+P19 -> 46
A20: 10 | B20: 012407000100000 | C20: 膈肌功能检查费 | D20: 检查费 | E20: 通过电活动或压力测定，评估患者膈肌功能。 | F20: 所定价格涵盖设备准备、仪器测定、撤除、处理用物、出具报告等步骤所需的人力资源和基本物质资源消耗。 | G20: 次 | I20: 60 | J20: 54 | K20: 69 | L20: 60 | M20: 51 | N20: 60 | O20: 54 | P20: 46 | Q20: 医保 | T20: 理顺，调低 | U20: 平移后按不超过省级拟定；同质化检查类项目持平省级 | V20: 003106020030000-310602003 | W20: 310602003 | X20: 呼吸肌功能测定 | Y20: 含最大吸气、呼气压、膈肌功能测定 | AA20: 次 | AC20: 69 | AD20: 60 | AE20: 51 | AF20: =IFERROR(FIND("-儿童（加收）",C20,1),0) -> 0 | AG20: =SUBSTITUTE(C20,"-儿童（加收）","") -> 膈肌功能检查费 | AH20: =IF(AF20>0,_xlfn.MAXIFS(N:N,C:C,SUBSTITUTE(C20,"-儿童（加收）","")),0)+N20 -> 60 | AI20: =IF(AF20>0,_xlfn.MAXIFS(O:O,C:C,SUBSTITUTE(C20,"-儿童（加收）","")),0)+O20 -> 54 | AJ20: =IF(AF20>0,_xlfn.MAXIFS(P:P,C:C,SUBSTITUTE(C20,"-儿童（加收）","")),0)+P20 -> 46
A21: 11 | B21: 012407000110000 | C21: 睡眠呼吸监测费 | D21: 检查费 | E21: 对睡眠状态下患者呼吸行为状、呼吸功能进行监测，同步观察患者必要的生命体征及电生理指标。 | F21: 所定价格涵盖设备准备、仪器测定、撤除、处理用物、出具报告等步骤所需的人力资源和基本物质资源消耗。 | G21: 次 | H21: 不得同时收取心电、脑电、肌电、眼动、呼吸监测和血氧饱和度测定费用。 | I21: 400 | J21: 360 | K21: 379.5 | L21: 356.5 | M21: 333.5 | N21: 380 | O21: 357 | P21: 335 | Q21: 医保 | T21: 平移取整 | U21: 计价单位由小时改为次，一次按11-12小时计算。 | V21: 003106040010000-310604001 | W21: 310604001 | X21: 睡眠呼吸监测 | Y21: 含心电、脑电、肌电、眼动、呼吸监测和血氧饱和度测定 | AA21: 小时 | AC21: 33 | AD21: 31 | AE21: 29 | AF21: =IFERROR(FIND("-儿童（加收）",C21,1),0) -> 0 | AG21: =SUBSTITUTE(C21,"-儿童（加收）","") -> 睡眠呼吸监测费 | AH21: =IF(AF21>0,_xlfn.MAXIFS(N:N,C:C,SUBSTITUTE(C21,"-儿童（加收）","")),0)+N21 -> 380 | AI21: =IF(AF21>0,_xlfn.MAXIFS(O:O,C:C,SUBSTITUTE(C21,"-儿童（加收）","")),0)+O21 -> 357 | AJ21: =IF(AF21>0,_xlfn.MAXIFS(P:P,C:C,SUBSTITUTE(C21,"-儿童（加收）","")),0)+P21 -> 335
A22: 分项 | B22: 012407000110001 | C22: 睡眠呼吸监测费-便携睡眠呼吸监测（减收） | G22: 次 | I22: 277 | J22: 249 | K22: 230.5 | L22: 227 | M22: 224.5 | N22: 250 | O22: 242 | P22: 186 | Q22: 医保 | U22: 主项扣除原项目价格，得出减收的平移价格，我市原项目价格倒挂省级，现减收后调整为不超过省级。 | V22: 003106020040000-310602004 | W22: 310602004 | X22: 动态呼吸监测（呼吸Holter） | AA22: 次 | AC22: 115 | AD22: 100 | AE22: 85 | AF22: =IFERROR(FIND("-儿童（加收）",C22,1),0) -> 0 | AG22: =SUBSTITUTE(C22,"-儿童（加收）","") -> 睡眠呼吸监测费-便携睡眠呼吸监测（减收） | AH22: =IF(AF22>0,_xlfn.MAXIFS(N:N,C:C,SUBSTITUTE(C22,"-儿童（加收）","")),0)+N22 -> 250 | AI22: =IF(AF22>0,_xlfn.MAXIFS(O:O,C:C,SUBSTITUTE(C22,"-儿童（加收）","")),0)+O22 -> 242 | AJ22: =IF(AF22>0,_xlfn.MAXIFS(P:P,C:C,SUBSTITUTE(C22,"-儿童（加收）","")),0)+P22 -> 186
C23: 睡眠呼吸监测费-便携睡眠呼吸监测（减收） | N23: 250 | O23: 242 | P23: 186 | V23: 003106040020000-310604002 | W23: 310604002 | X23: 睡眠呼吸监测过筛试验 | Y23: 含口鼻呼吸、胸腹呼吸、血氧饱和度测定 | AA23: 次 | AC23: 149.5 | AD23: 130 | AE23: 110.5 | AF23: =IFERROR(FIND("-儿童（加收）",C23,1),0) -> 0 | AG23: =SUBSTITUTE(C23,"-儿童（加收）","") -> 睡眠呼吸监测费-便携睡眠呼吸监测（减收） | AH23: =IF(AF23>0,_xlfn.MAXIFS(N:N,C:C,SUBSTITUTE(C23,"-儿童（加收）","")),0)+N23 -> 250 | AI23: =IF(AF23>0,_xlfn.MAXIFS(O:O,C:C,SUBSTITUTE(C23,"-儿童（加收）","")),0)+O23 -> 242 | AJ23: =IF(AF23>0,_xlfn.MAXIFS(P:P,C:C,SUBSTITUTE(C23,"-儿童（加收）","")),0)+P23 -> 186
A24: 13 | B24: 012407000130000 | C24: 支气管镜检查费（常规内镜） | D24: 检查费 | E24: 通过支气管镜观察和诊断支气管、气管、气管壁或肺部等部位的疾病。 | F24: 所定价格涵盖设备准备、体位摆放、入镜、观察、图像采集、撤镜、处理用物、出具报告等步骤所需的人力资源和基本物质资源消耗。 | G24: 次 | H24: 本项目中的“特殊光源”指：荧光、窄谱光源。 | I24: 250 | J24: 225 | K24: 239.43968 | L24: 215.61159 | M24: 192 | N24: 240 | O24: 216 | P24: 190 | Q24: 医保 | S24: 0.2 | T24: 平移取整 | U24: 平移取整 | V24: 003106050020000-310605002 | W24: 310605002 | X24: 纤维支气管镜检查 | Y24: 包括针吸活检、支气管刷片 | Z24: 特殊穿刺针 | AA24: 次 | AC24: 138 | AD24: 120 | AE24: 102 | AF24: =IFERROR(FIND("-儿童（加收）",C24,1),0) -> 0 | AG24: =SUBSTITUTE(C24,"-儿童（加收）","") -> 支气管镜检查费（常规内镜） | AH24: =IF(AF24>0,_xlfn.MAXIFS(N:N,C:C,SUBSTITUTE(C24,"-儿童（加收）","")),0)+N24 -> 240 | AI24: =IF(AF24>0,_xlfn.MAXIFS(O:O,C:C,SUBSTITUTE(C24,"-儿童（加收）","")),0)+O24 -> 216 | AJ24: =IF(AF24>0,_xlfn.MAXIFS(P:P,C:C,SUBSTITUTE(C24,"-儿童（加收）","")),0)+P24 -> 190
C25: 支气管镜检查费（常规内镜） | N25: 240 | O25: 216 | P25: 190 | V25: 003106050010000-310605001 | W25: 310605001 | X25: 硬质气管镜检查 | AA25: 次 | AC25: 115 | AD25: 100 | AE25: 85 | AF25: =IFERROR(FIND("-儿童（加收）",C25,1),0) -> 0 | AG25: =SUBSTITUTE(C25,"-儿童（加收）","") -> 支气管镜检查费（常规内镜） | AH25: =IF(AF25>0,_xlfn.MAXIFS(N:N,C:C,SUBSTITUTE(C25,"-儿童（加收）","")),0)+N25 -> 240 | AI25: =IF(AF25>0,_xlfn.MAXIFS(O:O,C:C,SUBSTITUTE(C25,"-儿童（加收）","")),0)+O25 -> 216 | AJ25: =IF(AF25>0,_xlfn.MAXIFS(P:P,C:C,SUBSTITUTE(C25,"-儿童（加收）","")),0)+P25 -> 190
C26: 支气管镜检查费（常规内镜） | N26: 240 | O26: 216 | P26: 190 | V26: 003106050000001-31060500002 | W26: 31060500002 | X26: 呼吸系统窥镜诊疗（使用电子支气管镜加收） | AA26: 次 | AB26: 使用电子支气管镜加收 | AC26: 138 | AD26: 120 | AE26: 102 | AF26: =IFERROR(FIND("-儿童（加收）",C26,1),0) -> 0 | AG26: =SUBSTITUTE(C26,"-儿童（加收）","") -> 支气管镜检查费（常规内镜） | AH26: =IF(AF26>0,_xlfn.MAXIFS(N:N,C:C,SUBSTITUTE(C26,"-儿童（加收）","")),0)+N26 -> 240 | AI26: =IF(AF26>0,_xlfn.MAXIFS(O:O,C:C,SUBSTITUTE(C26,"-儿童（加收）","")),0)+O26 -> 216 | AJ26: =IF(AF26>0,_xlfn.MAXIFS(P:P,C:C,SUBSTITUTE(C26,"-儿童（加收）","")),0)+P26 -> 190
C27: 支气管镜检查费（常规内镜） | N27: 240 | O27: 216 | P27: 190 | V27: 003106050000001-31060500001 | W27: 31060500001 | X27: 呼吸系统窥镜诊疗（使用电子纤维内镜加收） | AA27: 次 | AB27: 使用电子纤维内镜加收 | AC27: 115 | AD27: 100 | AE27: 85 | AF27: =IFERROR(FIND("-儿童（加收）",C27,1),0) -> 0 | AG27: =SUBSTITUTE(C27,"-儿童（加收）","") -> 支气管镜检查费（常规内镜） | AH27: =IF(AF27>0,_xlfn.MAXIFS(N:N,C:C,SUBSTITUTE(C27,"-儿童（加收）","")),0)+N27 -> 240 | AI27: =IF(AF27>0,_xlfn.MAXIFS(O:O,C:C,SUBSTITUTE(C27,"-儿童（加收）","")),0)+O27 -> 216 | AJ27: =IF(AF27>0,_xlfn.MAXIFS(P:P,C:C,SUBSTITUTE(C27,"-儿童（加收）","")),0)+P27 -> 190
A28: 14 | B28: 012407000140000 | C28: 支气管镜检查费（超声内镜） | D28: 检查费 | E28: 通过超声支气管镜观察和诊断支气管、气管、气管壁、气管腔外或肺部等部位的疾病。 | F28: 所定价格涵盖设备准备、体位摆放、入镜、观察、图像采集、撤镜、处理用物、出具报告等步骤所需的人力资源和基本物质资源消耗。 | G28: 次 | I28: 650 | J28: 585 | K28: 585 | L28: 527 | M28: 448 | N28: 585 | O28: 527 | P28: 448 | Q28: 医保 | S28: 0.2 | T28: 平移 | U28: 平移 | V28: 003106050020000-310605015 | W28: 310605015 | X28: 超声支气管镜检查 | Y28: 咽部麻醉、润滑，插入超声支气管镜，观察气道变化，将超声水囊充满，观察支气管壁及壁外结构，定位后进行经支气管淋巴结针吸活检。标本送细胞学和组织学等检查。不含病理学检查、活检。 | Z28: 穿刺针 | AA28: 次 | AC28: 585 | AD28: 527 | AE28: 448 | AF28: =IFERROR(FIND("-儿童（加收）",C28,1),0) -> 0 | AG28: =SUBSTITUTE(C28,"-儿童（加收）","") -> 支气管镜检查费（超声内镜） | AH28: =IF(AF28>0,_xlfn.MAXIFS(N:N,C:C,SUBSTITUTE(C28,"-儿童（加收）","")),0)+N28 -> 585 | AI28: =IF(AF28>0,_xlfn.MAXIFS(O:O,C:C,SUBSTITUTE(C28,"-儿童（加收）","")),0)+O28 -> 527 | AJ28: =IF(AF28>0,_xlfn.MAXIFS(P:P,C:C,SUBSTITUTE(C28,"-儿童（加收）","")),0)+P28 -> 448
A29: 17 | B29: 012407000170000 | C29: 纵隔镜探查费 | D29: 检查费 | E29: 通过纵隔镜观察和诊断纵隔、支气管、气管、胸腺、食管、淋巴结或肺部等部位的疾病。 | F29: 所定价格涵盖设备准备、体位摆放、切开、入镜、观察、撤镜、缝合、关闭、处理用物等手术步骤所需的人力资源和基本物质资源消耗。 | G29: 次 | I29: 550 | J29: 495 | K29: 575 | L29: 500 | M29: 425 | N29: 540 | O29: 490 | P29: 415 | Q29: 医保 | T29: 理顺，调低 | U29: 平移后按不超过省级拟定 | V29: 003106050140000-310605014 | W29: 310605014 | X29: 纵隔镜检查 | Y29: 含纵隔淋巴结活检 | AA29: 次 | AC29: 575 | AD29: 500 | AE29: 425 | AF29: =IFERROR(FIND("-儿童（加收）",C29,1),0) -> 0 | AG29: =SUBSTITUTE(C29,"-儿童（加收）","") -> 纵隔镜探查费 | AH29: =IF(AF29>0,_xlfn.MAXIFS(N:N,C:C,SUBSTITUTE(C29,"-儿童（加收）","")),0)+N29 -> 540 | AI29: =IF(AF29>0,_xlfn.MAXIFS(O:O,C:C,SUBSTITUTE(C29,"-儿童（加收）","")),0)+O29 -> 490 | AJ29: =IF(AF29>0,_xlfn.MAXIFS(P:P,C:C,SUBSTITUTE(C29,"-儿童（加收）","")),0)+P29 -> 415
A30: 18 | B30: 013106000010000 | C30: 体外膈肌起搏治疗费 | D30: 治疗费 | E30: 通过电刺激，诱导膈肌主动收缩。 | F30: 所定价格涵盖设备准备、连接电极、起搏治疗、撤除、处理用物等步骤所需的人力资源和基本物质资源消耗。 | G30: 次 | I30: 15 | J30: 15 | K30: 17.3 | L30: 15 | M30: 12.8 | N30: 15 | O30: 14 | P30: 13 | Q30: 医保 | T30: 理顺，调低 | U30: 平移后按不超过省级拟定 | V30: 003106030030000-310603003 | W30: 310603003 | X30: 体外膈肌起搏治疗 | AA30: 次 | AC30: 17.3 | AD30: 15 | AE30: 12.8 | AF30: =IFERROR(FIND("-儿童（加收）",C30,1),0) -> 0 | AG30: =SUBSTITUTE(C30,"-儿童（加收）","") -> 体外膈肌起搏治疗费 | AH30: =IF(AF30>0,_xlfn.MAXIFS(N:N,C:C,SUBSTITUTE(C30,"-儿童（加收）","")),0)+N30 -> 15 | AI30: =IF(AF30>0,_xlfn.MAXIFS(O:O,C:C,SUBSTITUTE(C30,"-儿童（加收）","")),0)+O30 -> 14 | AJ30: =IF(AF30>0,_xlfn.MAXIFS(P:P,C:C,SUBSTITUTE(C30,"-儿童（加收）","")),0)+P30 -> 13
A31: 19 | B31: 013106000020000 | C31: 一氧化氮吸入治疗费 | D31: 治疗费 | E31: 通过吸入一氧化氮进行治疗。 | F31: 所定价格涵盖设备准备、气体调节、吸入治疗、调节、监测、处理用物等步骤所需的人力资源、设备运转成本消耗与基本物质资源消耗。 | G31: 小时 | I31: 50 | J31: 50 | K31: 9 | L31: 9 | M31: 9 | N31: 45 | O31: 45 | P31: 41 | Q31: 医保 | T31: 提高 | U31: 省级通过区域间比价提高价格（我省价格过低），我市按比价提高，市县持平，基层拉开比价。 | V31: 353106040090000-12030000140 | W31: 12030000140 | X31: 一氧化氮吸入 | Y31: 机械通气的同时，连接一氧化氮装置，监测一氧化氮及二氧化氮浓度，根据患者病情调节浓度，观察使用效果。 | AA31: 小时 | AB31: 每日不超过90元 | AC31: 9 | AD31: 9 | AE31: 9 | AF31: =IFERROR(FIND("-儿童（加收）",C31,1),0) -> 0 | AG31: =SUBSTITUTE(C31,"-儿童（加收）","") -> 一氧化氮吸入治疗费 | AH31: =IF(AF31>0,_xlfn.MAXIFS(N:N,C:C,SUBSTITUTE(C31,"-儿童（加收）","")),0)+N31 -> 45 | AI31: =IF(AF31>0,_xlfn.MAXIFS(O:O,C:C,SUBSTITUTE(C31,"-儿童（加收）","")),0)+O31 -> 45 | AJ31: =IF(AF31>0,_xlfn.MAXIFS(P:P,C:C,SUBSTITUTE(C31,"-儿童（加收）","")),0)+P31 -> 41
A32: 20 | B32: 013106000030000 | C32: 雾化吸入治疗费 | D32: 治疗费 | E32: 通过各种方式吸入气雾或气溶胶颗粒进行治疗。 | F32: 所定价格涵盖设备准备、成分制备、连接、调节、吸入、观察、记录、处理用物等所需的人力资源和基本物质资源消耗。 | G32: 次 | H32: 多种药物确需分开雾化吸入的可分别计价收费。 | I32: 15 | J32: 15 | K32: 12.205279 | L32: 12.202812 | M32: 11.500005 | N32: 14 | O32: 13 | P32: 12 | Q32: 医保 | T32: 提高 | U32: 一次性雾化吸入器纳入价格构成，我市医疗机构采购均价约7.2元。叠加项目价格购平移。 省级通过区域间比价提高价格（我省价格过低），我市按比价提高，同质化项目缩小价差 | V32: 001207000010000-120700001 | W32: 120700001 | X32: 雾化吸入 | Y32: 包括超声、高压泵、氧化雾化、蒸气雾化吸入及机械通气经呼吸机管道雾化给药 | Z32: 药物、一次性雾化器 | AA32: 次 | AF32: =IFERROR(FIND("-儿童（加收）",C32,1),0) -> 0 | AG32: =SUBSTITUTE(C32,"-儿童（加收）","") -> 雾化吸入治疗费 | AH32: =IF(AF32>0,_xlfn.MAXIFS(N:N,C:C,SUBSTITUTE(C32,"-儿童（加收）","")),0)+N32 -> 14 | AI32: =IF(AF32>0,_xlfn.MAXIFS(O:O,C:C,SUBSTITUTE(C32,"-儿童（加收）","")),0)+O32 -> 13 | AJ32: =IF(AF32>0,_xlfn.MAXIFS(P:P,C:C,SUBSTITUTE(C32,"-儿童（加收）","")),0)+P32 -> 12
C33: 雾化吸入治疗费 | N33: 14 | O33: 13 | P33: 12 | V33: 001207000010100-12070000101 | W33: 12070000101 | X33: 超声雾化吸入 | AA33: 次 | AC33: 5 | AD33: 5 | AE33: 4.3 | AF33: =IFERROR(FIND("-儿童（加收）",C33,1),0) -> 0 | AG33: =SUBSTITUTE(C33,"-儿童（加收）","") -> 雾化吸入治疗费 | AH33: =IF(AF33>0,_xlfn.MAXIFS(N:N,C:C,SUBSTITUTE(C33,"-儿童（加收）","")),0)+N33 -> 14 | AI33: =IF(AF33>0,_xlfn.MAXIFS(O:O,C:C,SUBSTITUTE(C33,"-儿童（加收）","")),0)+O33 -> 13 | AJ33: =IF(AF33>0,_xlfn.MAXIFS(P:P,C:C,SUBSTITUTE(C33,"-儿童（加收）","")),0)+P33 -> 12
C34: 雾化吸入治疗费 | N34: 14 | O34: 13 | P34: 12 | V34: 001207000010200-12070000102 | W34: 12070000102 | X34: 高压泵雾化吸入 | AA34: 次 | AC34: 5 | AD34: 5 | AE34: 4.3 | AF34: =IFERROR(FIND("-儿童（加收）",C34,1),0) -> 0 | AG34: =SUBSTITUTE(C34,"-儿童（加收）","") -> 雾化吸入治疗费 | AH34: =IF(AF34>0,_xlfn.MAXIFS(N:N,C:C,SUBSTITUTE(C34,"-儿童（加收）","")),0)+N34 -> 14 | AI34: =IF(AF34>0,_xlfn.MAXIFS(O:O,C:C,SUBSTITUTE(C34,"-儿童（加收）","")),0)+O34 -> 13 | AJ34: =IF(AF34>0,_xlfn.MAXIFS(P:P,C:C,SUBSTITUTE(C34,"-儿童（加收）","")),0)+P34 -> 12
C35: 雾化吸入治疗费 | N35: 14 | O35: 13 | P35: 12 | V35: 001207000010300-12070000103 | W35: 12070000103 | X35: 氧化雾化 | AA35: 次 | AC35: 5 | AD35: 5 | AE35: 4.3 | AF35: =IFERROR(FIND("-儿童（加收）",C35,1),0) -> 0 | AG35: =SUBSTITUTE(C35,"-儿童（加收）","") -> 雾化吸入治疗费 | AH35: =IF(AF35>0,_xlfn.MAXIFS(N:N,C:C,SUBSTITUTE(C35,"-儿童（加收）","")),0)+N35 -> 14 | AI35: =IF(AF35>0,_xlfn.MAXIFS(O:O,C:C,SUBSTITUTE(C35,"-儿童（加收）","")),0)+O35 -> 13 | AJ35: =IF(AF35>0,_xlfn.MAXIFS(P:P,C:C,SUBSTITUTE(C35,"-儿童（加收）","")),0)+P35 -> 12
C36: 雾化吸入治疗费 | N36: 14 | O36: 13 | P36: 12 | V36: 001207000010400-12070000104 | W36: 12070000104 | X36: 蒸气雾化吸入 | AA36: 次 | AC36: 5 | AD36: 5 | AE36: 4.3 | AF36: =IFERROR(FIND("-儿童（加收）",C36,1),0) -> 0 | AG36: =SUBSTITUTE(C36,"-儿童（加收）","") -> 雾化吸入治疗费 | AH36: =IF(AF36>0,_xlfn.MAXIFS(N:N,C:C,SUBSTITUTE(C36,"-儿童（加收）","")),0)+N36 -> 14 | AI36: =IF(AF36>0,_xlfn.MAXIFS(O:O,C:C,SUBSTITUTE(C36,"-儿童（加收）","")),0)+O36 -> 13 | AJ36: =IF(AF36>0,_xlfn.MAXIFS(P:P,C:C,SUBSTITUTE(C36,"-儿童（加收）","")),0)+P36 -> 12
C37: 雾化吸入治疗费 | N37: 14 | O37: 13 | P37: 12 | V37: 001207000010500-12070000105 | W37: 12070000105 | X37: 机械通气经呼吸机管道雾化给药 | AA37: 次 | AC37: 5 | AD37: 5 | AE37: 4.3 | AF37: =IFERROR(FIND("-儿童（加收）",C37,1),0) -> 0 | AG37: =SUBSTITUTE(C37,"-儿童（加收）","") -> 雾化吸入治疗费 | AH37: =IF(AF37>0,_xlfn.MAXIFS(N:N,C:C,SUBSTITUTE(C37,"-儿童（加收）","")),0)+N37 -> 14 | AI37: =IF(AF37>0,_xlfn.MAXIFS(O:O,C:C,SUBSTITUTE(C37,"-儿童（加收）","")),0)+O37 -> 13 | AJ37: =IF(AF37>0,_xlfn.MAXIFS(P:P,C:C,SUBSTITUTE(C37,"-儿童（加收）","")),0)+P37 -> 12
C38: 雾化吸入治疗费 | N38: 14 | O38: 13 | P38: 12 | V38: 001207000010000-12070000106 | W38: 12070000106 | X38: 新生儿雾化吸入 | AA38: 次 | AC38: 6.5 | AD38: 6.5 | AE38: 5.6 | AF38: =IFERROR(FIND("-儿童（加收）",C38,1),0) -> 0 | AG38: =SUBSTITUTE(C38,"-儿童（加收）","") -> 雾化吸入治疗费 | AH38: =IF(AF38>0,_xlfn.MAXIFS(N:N,C:C,SUBSTITUTE(C38,"-儿童（加收）","")),0)+N38 -> 14 | AI38: =IF(AF38>0,_xlfn.MAXIFS(O:O,C:C,SUBSTITUTE(C38,"-儿童（加收）","")),0)+O38 -> 13 | AJ38: =IF(AF38>0,_xlfn.MAXIFS(P:P,C:C,SUBSTITUTE(C38,"-儿童（加收）","")),0)+P38 -> 12
A39: 22 | B39: 013106000050000 | C39: 支气管肺泡灌洗费 | D39: 治疗费 | E39: 通过无创方式清除特定肺段肺泡内异物、分泌物和其他沉积物或采集样本，不含内镜检查费。 | F39: 所定价格涵盖设备准备、镜下治疗、处理用物等步骤所需的人力资源、设备运转成本消耗与基本物质资源消耗。 | G39: 次 | H39: “次”指每个肺段。 | I39: 110 | J39: 99 | K39: 115 | L39: 100 | M39: 85 | N39: 105 | O39: 95 | P39: 81 | Q39: 医保 | T39: 理顺，调低 | U39: 平移后按不超过省级拟定 | V39: 003106050060000-310605006 | W39: 310605006 | X39: 经纤支镜肺泡灌洗诊疗术 | Y39: 含生理盐水 | AA39: 每个肺段 | AC39: 115 | AD39: 100 | AE39: 85 | AF39: =IFERROR(FIND("-儿童（加收）",C39,1),0) -> 0 | AG39: =SUBSTITUTE(C39,"-儿童（加收）","") -> 支气管肺泡灌洗费 | AH39: =IF(AF39>0,_xlfn.MAXIFS(N:N,C:C,SUBSTITUTE(C39,"-儿童（加收）","")),0)+N39 -> 105 | AI39: =IF(AF39>0,_xlfn.MAXIFS(O:O,C:C,SUBSTITUTE(C39,"-儿童（加收）","")),0)+O39 -> 95 | AJ39: =IF(AF39>0,_xlfn.MAXIFS(P:P,C:C,SUBSTITUTE(C39,"-儿童（加收）","")),0)+P39 -> 81
A40: 23 | B40: 013106000060000 | C40: 支气管镜治疗费（常规） | D40: 治疗费 | E40: 通过支气管镜进行滴药、冲洗、吸痰等常规治疗，不含内镜检查费。 | F40: 所定价格涵盖设备准备、镜下治疗、处理用物等步骤所需的人力资源、设备运转成本消耗与基本物质资源消耗。 | G40: 次 | I40: 180 | J40: 162 | K40: 149.5 | L40: 130 | M40: 110.5 | N40: 165 | O40: 150 | P40: 130 | Q40: 医保 | T40: 提高 | U40: 平移后结合日常医院反馈提价意见，按比价关系提高 | V40: 003106050030000-310605003 | W40: 310605003 | X40: 经纤支镜治疗 | Y40: 含经纤支镜痰吸引和滴药、止血、化疗 | Z40: 药物 | AA40: 次 | AB40: 取异物加收100% | AC40: 149.5 | AD40: 130 | AE40: 110.5 | AF40: =IFERROR(FIND("-儿童（加收）",C40,1),0) -> 0 | AG40: =SUBSTITUTE(C40,"-儿童（加收）","") -> 支气管镜治疗费（常规） | AH40: =IF(AF40>0,_xlfn.MAXIFS(N:N,C:C,SUBSTITUTE(C40,"-儿童（加收）","")),0)+N40 -> 165 | AI40: =IF(AF40>0,_xlfn.MAXIFS(O:O,C:C,SUBSTITUTE(C40,"-儿童（加收）","")),0)+O40 -> 150 | AJ40: =IF(AF40>0,_xlfn.MAXIFS(P:P,C:C,SUBSTITUTE(C40,"-儿童（加收）","")),0)+P40 -> 130
...

Sheet Sheet1
A1: 国家结算编码 | B1: 项目编码 | C1: 项目名称 | D1: 项目内涵 | E1: 除外内容 | F1: 计价单位 | G1: 说明 | H1: 省属三甲价格（元） | I1: 省属三甲以下价格（元） | J1: 价格 (市级) | K1: 价格 (县级) | L1: 价格 (基层) | M1: 医保属性
A2: 003307020050000-33070200501 | B2: 33070200501 | C2: 肺楔形切除术（双侧） | F2: 次 | G2: 双侧 | H2: 3450 | I2: 3120 | J2: 3275 | K2: 2945 | L2: 2355 | M2: 医保
A3: 003307020040000-33070200401 | B3: 33070200401 | C3: 肺减容手术（双侧） | F3: 次 | G3: 双侧 | H3: 5760 | I3: 5190 | J3: 4320 | K3: 3890 | L3: 3310 | M3: 医保
A4: 003307020090000-33070200901 | B4: 33070200901 | C4: 肺大泡切除修补术（双侧） | F4: 次 | G4: 双侧 | H4: 3050 | I4: 2745 | J4: 2812.5 | K4: 2700 | L4: 2295 | M4: 医保
A5: 003307020150000-33070201501 | B5: 33070201501 | C5: 肺包虫病内囊摘除术（双侧） | F5: 次 | G5: 双侧 | H5: 5190 | I5: 4665 | J5: 3890 | K5: 3500 | L5: 2980 | M5: 医保
A6: 003307020040001-33070200405 | B6: 33070200405 | C6: 经胸腔镜肺减容手术（双侧） | F6: 次 | G6: 双侧 | H6: 6560 | I6: 5910 | J6: 4945 | K6: 4490 | L6: 3820 | M6: 医保
A7: 003307020050001-33070200505 | B7: 33070200505 | C7: 经胸腔镜肺楔形切除术（双侧） | F7: 次 | G7: 双侧 | H7: 4250 | I7: 3840 | J7: 3900 | K7: 3545 | L7: 2865 | M7: 医保
A8: 003307020090001-33070200905 | B8: 33070200905 | C8: 经胸腔镜肺大泡切除修补术（双侧） | F8: 次 | G8: 双侧 | H8: 3850 | I8: 3465 | J8: 3437.5 | K8: 3300 | L8: 2805 | M8: 医保
A9: 003307020150001-33070201506 | B9: 33070201506 | C9: 经胸腔镜肺包虫病内囊摘除术（双侧） | F9: 次 | G9: 双侧 | H9: 5990 | I9: 5385 | J9: 4515 | K9: 4100 | L9: 3490 | M9: 医保
A10: 003307020020000-33070200201 | B10: 33070200201 | C10: 肺癌根治术（双侧） | F10: 次 | G10: 双侧 | H10: 12600 | I10: 10590 | J10: 11970 | K10: 10770 | L10: 9155 | M10: 医保
A11: 003307020020001-33070200205 | B11: 33070200205 | C11: 经胸腔镜肺癌根治术（双侧） | F11: 次 | G11: 双侧 | H11: 13400 | I11: 11310 | J11: 12595 | K11: 11370 | L11: 9665 | M11: 医保
A12: 003307020050000-33070200503 | B12: 33070200503 | C12: 小儿肺楔形切除术（双侧） | F12: 次 | G12: 双侧 | H12: 4485 | I12: 4055 | J12: 4260 | K12: 3830 | L12: 3060 | M12: 医保
A13: 003307020040000-33070200403 | B13: 33070200403 | C13: 小儿肺减容手术（双侧） | F13: 次 | G13: 双侧 | H13: 7490 | I13: 6745 | J13: 5615 | K13: 5055 | L13: 4295 | M13: 医保
... A49: 003307020110100-33070201107 | B49: 33070201107 | C49: 小儿经胸腔镜肺修补术（双侧） | F49: 次 | G49: 双侧 | H49: 3960 | I49: 3565 | J49: 3550 | K49: 3410 | L49: 2900 | M49: 医保

Sheet Sheet2
A1: id | B1: code | C1: sever_type | D1: change_time | E1: old_hilist_code | F1: new_hilist_code | G1: hilist_name | H1: selfpay_prop | I1: old_price | J1: old_price_city | K1: old_price_town | L1: old_price_village | M1: new_price | N1: new_price_city | O1: new_price_town | P1: new_price_village | Q1: unit | R1: batch | S1: is_use_old | T1: merge_type | U1: cnt_change_model | V1: cnt_change_value | W1: ="insert into server_list_change_all_20250525 ("&_xlfn.TEXTJOIN(",",TRUE,A1:V1)&") values" -> insert into server_list_change_all_20250525 (id,code,sever_type,change_time,old_hilist_code,new_hilist_code,hilist_name,selfpay_prop,old_price,old_price_city,old_price_town,old_price_village,new_price,new_price_city,new_price_town,new_price_village,unit,batch,is_use_old,merge_type,cnt_change_model,cnt_change_value) values
A2: 2469 | B2: null | C2: 1 | D2: 2026-03-24 00:00:00 | E2: 003106010050000-310601005 | F2: 003106010050000-310601005 | G2: 残气容积测定 | H2: null | I2: null | J2: 57.5 | K2: 50 | L2: 42.5 | M2: null | N2: 50 | O2: 45 | P2: 39 | Q2: 项 | R2: 25 | S2: 1 | T2: normal | U2: main | V2: 0 | W2: ="("&A2&","&B2&","&C2&",'"&D2&"','"&E2&"','"&F2&"','"&G2&"',"&H2&","&I2&","&J2&","&K2&","&L2&","&M2&","&N2&","&O2&","&P2&",'"&Q2&"',"&R2&","&S2&",'"&T2&"','"&U2&"',"&V2&")," -> (2469,null,1,'2026-03-24 00:00:00','003106010050000-310601005','003106010050000-310601005','残气容积测定',null,null,57.5,50,42.5,null,50,45,39,'项',25,1,'normal','main',0),
A3: 2470 | B3: null | C3: 1 | D3: 2026-03-24 00:00:00 | E3: 003106010010000-310601001 | F3: 003106010010000-310601001 | G3: 肺通气功能检查 | H3: null | I3: null | J3: 74.8 | K3: 65 | L3: 55.3 | M3: null | N3: 105 | O3: 95 | P3: 85 | Q3: 次 | R3: 25 | S3: 1 | T3: normal | U3: main | V3: 0 | W3: ="("&A3&","&B3&","&C3&",'"&D3&"','"&E3&"','"&F3&"','"&G3&"',"&H3&","&I3&","&J3&","&K3&","&L3&","&M3&","&N3&","&O3&","&P3&",'"&Q3&"',"&R3&","&S3&",'"&T3&"','"&U3&"',"&V3&")," -> (2470,null,1,'2026-03-24 00:00:00','003106010010000-310601001','003106010010000-310601001','肺通气功能检查',null,null,74.8,65,55.3,null,105,95,85,'次',25,1,'normal','main',0),
A4: 2471 | B4: null | C4: 1 | D4: 2026-03-24 00:00:00 | E4: 003106010010000-31060100101 | F4: 003106010010000-31060100101 | G4: 肺通气功能检查（最大通气量加收） | H4: null | I4: null | J4: 40.3 | K4: 35 | L4: 29.8 | M4: null | N4: 0 | O4: 0 | P4: 0 | Q4: 次 | R4: 25 | S4: 1 | T4: normal | U4: main | V4: 0 | W4: ="("&A4&","&B4&","&C4&",'"&D4&"','"&E4&"','"&F4&"','"&G4&"',"&H4&","&I4&","&J4&","&K4&","&L4&","&M4&","&N4&","&O4&","&P4&",'"&Q4&"',"&R4&","&S4&",'"&T4&"','"&U4&"',"&V4&")," -> (2471,null,1,'2026-03-24 00:00:00','003106010010000-31060100101','003106010010000-31060100101','肺通气功能检查（最大通气量加收）',null,null,40.3,35,29.8,null,0,0,0,'次',25,1,'normal','main',0),
A5: 2472 | B5: null | C5: 1 | D5: 2026-03-24 00:00:00 | E5: 003106010080000-310601008 | F5: 003106010080000-310601008 | G5: 流速容量曲线（V—V曲线） | H5: null | I5: null | J5: 34.5 | K5: 30 | L5: 25.5 | M5: null | N5: 0 | O5: 0 | P5: 0 | Q5: 项 | R5: 25 | S5: 1 | T5: normal | U5: main | V5: 0 | W5: ="("&A5&","&B5&","&C5&",'"&D5&"','"&E5&"','"&F5&"','"&G5&"',"&H5&","&I5&","&J5&","&K5&","&L5&","&M5&","&N5&","&O5&","&P5&",'"&Q5&"',"&R5&","&S5&",'"&T5&"','"&U5&"',"&V5&")," -> (2472,null,1,'2026-03-24 00:00:00','003106010080000-310601008','003106010080000-310601008','流速容量曲线（V—V曲线）',null,null,34.5,30,25.5,null,0,0,0,'项',25,1,'normal','main',0),
A6: 2473 | B6: null | C6: 1 | D6: 2026-03-24 00:00:00 | E6: 003106010090000-310601009 | F6: 003106010090000-310601009 | G6: 二氧化碳反应曲线 | H6: null | I6: null | J6: 34.5 | K6: 30 | L6: 25.5 | M6: null | N6: 0 | O6: 0 | P6: 0 | Q6: 项 | R6: 25 | S6: 1 | T6: normal | U6: main | V6: 0 | W6: ="("&A6&","&B6&","&C6&",'"&D6&"','"&E6&"','"&F6&"','"&G6&"',"&H6&","&I6&","&J6&","&K6&","&L6&","&M6&","&N6&","&O6&","&P6&",'"&Q6&"',"&R6&","&S6&",'"&T6&"','"&U6&"',"&V6&")," -> (2473,null,1,'2026-03-24 00:00:00','003106010090000-310601009','003106010090000-310601009','二氧化碳反应曲线',null,null,34.5,30,25.5,null,0,0,0,'项',25,1,'normal','main',0),
A7: 2474 | B7: null | C7: 1 | D7: 2026-03-24 00:00:00 | E7: 003106010120000-310601012 | F7: 003106010120000-310601012 | G7: 支气管舒张试验 | H7: null | I7: null | J7: 115 | K7: 100 | L7: 85 | M7: null | N7: 210 | O7: 190 | P7: 170 | Q7: 项 | R7: 25 | S7: 1 | T7: normal | U7: main | V7: 0 | W7: ="("&A7&","&B7&","&C7&",'"&D7&"','"&E7&"','"&F7&"','"&G7&"',"&H7&","&I7&","&J7&","&K7&","&L7&","&M7&","&N7&","&O7&","&P7&",'"&Q7&"',"&R7&","&S7&",'"&T7&"','"&U7&"',"&V7&")," -> (2474,null,1,'2026-03-24 00:00:00','003106010120000-310601012','003106010120000-310601012','支气管舒张试验',null,null,115,100,85,null,210,190,170,'项',25,1,'normal','main',0),
A8: 2475 | B8: null | C8: 1 | D8: 2026-03-24 00:00:00 | E8: 003106020010000-310602001 | F8: 003106020010000-310602001 | G8: 床边简易肺功能测定（肺通气功能测定） | H8: null | I8: null | J8: 46 | K8: 40 | L8: 34 | M8: null | N8: 40 | O8: 36 | P8: 34 | Q8: 次 | R8: 25 | S8: 1 | T8: normal | U8: main | V8: 0 | W8: ="("&A8&","&B8&","&C8&",'"&D8&"','"&E8&"','"&F8&"','"&G8&"',"&H8&","&I8&","&J8&","&K8&","&L8&","&M8&","&N8&","&O8&","&P8&",'"&Q8&"',"&R8&","&S8&",'"&T8&"','"&U8&"',"&V8&")," -> (2475,null,1,'2026-03-24 00:00:00','003106020010000-310602001','003106020010000-310602001','床边简易肺功能测定（肺通气功能测定）',null,null,46,40,34,null,40,36,34,'次',25,1,'normal','main',0),
A9: 2476 | B9: null | C9: 1 | D9: 2026-03-24 00:00:00 | E9: 003106010100000-310601010 | F9: 003106010100000-310601010 | G9: 支气管激发试验 | H9: null | I9: null | J9: 115 | K9: 100 | L9: 85 | M9: null | N9: 100 | O9: 90 | P9: 77 | Q9: 项 | R9: 25 | S9: 1 | T9: normal | U9: main | V9: 0 | W9: ="("&A9&","&B9&","&C9&",'"&D9&"','"&E9&"','"&F9&"','"&G9&"',"&H9&","&I9&","&J9&","&K9&","&L9&","&M9&","&N9&","&O9&","&P9&",'"&Q9&"',"&R9&","&S9&",'"&T9&"','"&U9&"',"&V9&")," -> (2476,null,1,'2026-03-24 00:00:00','003106010100000-310601010','003106010100000-310601010','支气管激发试验',null,null,115,100,85,null,100,90,77,'项',25,1,'normal','main',0),
A10: 2477 | B10: null | C10: 1 | D10: 2026-03-24 00:00:00 | E10: 003106010110000-310601011 | F10: 003106010110000-310601011 | G10: 运动激发试验 | H10: null | I10: null | J10: 115 | K10: 100 | L10: 85 | M10: null | N10: 100 | O10: 90 | P10: 77 | Q10: 项 | R10: 25 | S10: 1 | T10: normal | U10: main | V10: 0 | W10: ="("&A10&","&B10&","&C10&",'"&D10&"','"&E10&"','"&F10&"','"&G10&"',"&H10&","&I10&","&J10&","&K10&","&L10&","&M10&","&N10&","&O10&","&P10&",'"&Q10&"',"&R10&","&S10&",'"&T10&"','"&U10&"',"&V10&")," -> (2477,null,1,'2026-03-24 00:00:00','003106010110000-310601011','003106010110000-310601011','运动激发试验',null,null,115,100,85,null,100,90,77,'项',25,1,'normal','main',0),
A11: 2478 | B11: null | C11: 1 | D11: 2026-03-24 00:00:00 | E11: 003106010020000-310601002 | F11: 003106010020000-310601002 | G11: 肺弥散功能检查 | H11: null | I11: null | J11: 69 | K11: 60 | L11: 51 | M11: null | N11: 60 | O11: 54 | P11: 46 | Q11: 项 | R11: 25 | S11: 1 | T11: normal | U11: main | V11: 0 | W11: ="("&A11&","&B11&","&C11&",'"&D11&"','"&E11&"','"&F11&"','"&G11&"',"&H11&","&I11&","&J11&","&K11&","&L11&","&M11&","&N11&","&O11&","&P11&",'"&Q11&"',"&R11&","&S11&",'"&T11&"','"&U11&"',"&V11&")," -> (2478,null,1,'2026-03-24 00:00:00','003106010020000-310601002','003106010020000-310601002','肺弥散功能检查',null,null,69,60,51,null,60,54,46,'项',25,1,'normal','main',0),
A12: 2479 | B12: null | C12: 1 | D12: 2026-03-24 00:00:00 | E12: 003106010040000-310601004 | F12: 003106010040000-310601004 | G12: 气道阻力测定 | H12: null | I12: null | J12: 57.5 | K12: 50 | L12: 42.5 | M12: null | N12: 100 | O12: 90 | P12: 77 | Q12: 项 | R12: 25 | S12: 1 | T12: normal | U12: main | V12: 0 | W12: ="("&A12&","&B12&","&C12&",'"&D12&"','"&E12&"','"&F12&"','"&G12&"',"&H12&","&I12&","&J12&","&K12&","&L12&","&M12&","&N12&","&O12&","&P12&",'"&Q12&"',"&R12&","&S12&",'"&T12&"','"&U12&"',"&V12&")," -> (2479,null,1,'2026-03-24 00:00:00','003106010040000-310601004','003106010040000-310601004','气道阻力测定',null,null,57.5,50,42.5,null,100,90,77,'项',25,1,'normal','main',0),
A13: 2480 | B13: null | C13: 1 | D13: 2026-03-24 00:00:00 | E13: 003106010060000-310601006 | F13: 003106010060000-310601006 | G13: 强迫振荡肺功能检查 | H13: null | I13: null | J13: 115 | K13: 100 | L13: 85 | M13: null | N13: 100 | O13: 90 | P13: 77 | Q13: 项 | R13: 25 | S13: 1 | T13: normal | U13: main | V13: 0 | W13: ="("&A13&","&B13&","&C13&",'"&D13&"','"&E13&"','"&F13&"','"&G13&"',"&H13&","&I13&","&J13&","&K13&","&L13&","&M13&","&N13&","&O13&","&P13&",'"&Q13&"',"&R13&","&S13&",'"&T13&"','"&U13&"',"&V13&")," -> (2480,null,1,'2026-03-24 00:00:00','003106010060000-310601006','003106010060000-310601006','强迫振荡肺功能检查',null,null,115,100,85,null,100,90,77,'项',25,1,'normal','main',0),
... A15: 2482 | B15: null | C15: 1 | D15: 2026-03-24 00:00:00 | E15: 003106010030000-310601003 | F15: 003106010030000-310601003 | G15: 运动心肺功能检查 | H15: null | I15: null | J15: 184 | K15: 160 | L15: 136 | M15: null | N15: 160 | O15: 144 | P15: 123 | Q15: 项 | R15: 25 | S15: 1 | T15: normal | U15: main | V15: 0 | W15: ="("&A15&","&B15&","&C15&",'"&D15&"','"&E15&"','"&F15&"','"&G15&"',"&H15&","&I15&","&J15&","&K15&","&L15&","&M15&","&N15&","&O15&","&P15&",'"&Q15&"',"&R15&","&S15&",'"&T15&"','"&U15&"',"&V15&")," -> (2482,null,1,'2026-03-24 00:00:00','003106010030000-310601003','003106010030000-310601003','运动心肺功能检查',null,null,184,160,136,null,160,144,123,'项',25,1,'normal','main',0),
A16: 2483 | B16: null | C16: 1 | D16: 2026-03-24 00:00:00 | E16: 003106020020000-310602002 | F16: 003106020020000-310602002 | G16: 肺阻抗血流图 | H16: null | I16: null | J16: 11.5 | K16: 10 | L16: 8.5 | M16: null | N16: 11.5 | O16: 10 | P16: 8.5 | R16: 25 | S16: 1 | T16: normal | U16: main | V16: 0 | W16: ="("&A16&","&B16&","&C16&",'"&D16&"','"&E16&"','"&F16&"','"&G16&"',"&H16&","&I16&","&J16&","&K16&","&L16&","&M16&","&N16&","&O16&","&P16&",'"&Q16&"',"&R16&","&S16&",'"&T16&"','"&U16&"',"&V16&")," -> (2483,null,1,'2026-03-24 00:00:00','003106020020000-310602002','003106020020000-310602002','肺阻抗血流图',null,null,11.5,10,8.5,null,11.5,10,8.5,'',25,1,'normal','main',0),
A17: 2484 | B17: null | C17: 1 | D17: 2026-03-24 00:00:00 | E17: 003106020030000-310602003 | F17: 003106020030000-310602003 | G17: 呼吸肌功能测定 | H17: null | I17: null | J17: 69 | K17: 60 | L17: 51 | M17: null | N17: 60 | O17: 54 | P17: 46 | Q17: 次 | R17: 25 | S17: 1 | T17: normal | U17: main | V17: 0 | W17: ="("&A17&","&B17&","&C17&",'"&D17&"','"&E17&"','"&F17&"','"&G17&"',"&H17&","&I17&","&J17&","&K17&","&L17&","&M17&","&N17&","&O17&","&P17&",'"&Q17&"',"&R17&","&S17&",'"&T17&"','"&U17&"',"&V17&")," -> (2484,null,1,'2026-03-24 00:00:00','003106020030000-310602003','003106020030000-310602003','呼吸肌功能测定',null,null,69,60,51,null,60,54,46,'次',25,1,'normal','main',0),
A18: 2485 | B18: null | C18: 1 | D18: 2026-03-24 00:00:00 | E18: 003106020030000-310602003 | F18: 003106020030000-310602003 | G18: 呼吸肌功能测定 | H18: null | I18: null | J18: 69 | K18: 60 | L18: 51 | M18: null | N18: 60 | O18: 54 | P18: 46 | Q18: 次 | R18: 25 | S18: 1 | T18: normal | U18: main | V18: 0 | W18: ="("&A18&","&B18&","&C18&",'"&D18&"','"&E18&"','"&F18&"','"&G18&"',"&H18&","&I18&","&J18&","&K18&","&L18&","&M18&","&N18&","&O18&","&P18&",'"&Q18&"',"&R18&","&S18&",'"&T18&"','"&U18&"',"&V18&")," -> (2485,null,1,'2026-03-24 00:00:00','003106020030000-310602003','003106020030000-310602003','呼吸肌功能测定',null,null,69,60,51,null,60,54,46,'次',25,1,'normal','main',0),
A19: 2486 | B19: null | C19: 1 | D19: 2026-03-24 00:00:00 | E19: 003106040010000-310604001 | F19: 003106040010000-310604001 | G19: 睡眠呼吸监测 | H19: null | I19: null | J19: 33 | K19: 31 | L19: 29 | M19: null | N19: =ROUND(380/11.5,2) -> 33.04 | O19: =ROUND(357/11.5,2) -> 31.04 | P19: =ROUND(335/11.5,2) -> 29.13 | Q19: 小时 | R19: 25 | S19: 1 | T19: normal | U19: main | V19: 0 | W19: ="("&A19&","&B19&","&C19&",'"&D19&"','"&E19&"','"&F19&"','"&G19&"',"&H19&","&I19&","&J19&","&K19&","&L19&","&M19&","&N19&","&O19&","&P19&",'"&Q19&"',"&R19&","&S19&",'"&T19&"','"&U19&"',"&V19&")," -> (2486,null,1,'2026-03-24 00:00:00','003106040010000-310604001','003106040010000-310604001','睡眠呼吸监测',null,null,33,31,29,null,33.04,31.04,29.13,'小时',25,1,'normal','main',0),
A20: 2487 | B20: null | C20: 1 | D20: 2026-03-24 00:00:00 | E20: 003106020040000-310602004 | F20: 003106020040000-310602004 | G20: 动态呼吸监测（呼吸Holter） | H20: null | I20: null | J20: 115 | K20: 100 | L20: 85 | M20: null | N20: 130 | O20: 115 | P20: 149 | Q20: 次 | R20: 25 | S20: 1 | T20: normal | U20: main | V20: 0 | W20: ="("&A20&","&B20&","&C20&",'"&D20&"','"&E20&"','"&F20&"','"&G20&"',"&H20&","&I20&","&J20&","&K20&","&L20&","&M20&","&N20&","&O20&","&P20&",'"&Q20&"',"&R20&","&S20&",'"&T20&"','"&U20&"',"&V20&")," -> (2487,null,1,'2026-03-24 00:00:00','003106020040000-310602004','003106020040000-310602004','动态呼吸监测（呼吸Holter）',null,null,115,100,85,null,130,115,149,'次',25,1,'normal','main',0),
A21: 2488 | B21: null | C21: 1 | D21: 2026-03-24 00:00:00 | E21: 003106040020000-310604002 | F21: 003106040020000-310604002 | G21: 睡眠呼吸监测过筛试验 | H21: null | I21: null | J21: 149.5 | K21: 130 | L21: 110.5 | M21: null | N21: 130 | O21: 115 | P21: 149 | Q21: 次 | R21: 25 | S21: 1 | T21: normal | U21: main | V21: 0 | W21: ="("&A21&","&B21&","&C21&",'"&D21&"','"&E21&"','"&F21&"','"&G21&"',"&H21&","&I21&","&J21&","&K21&","&L21&","&M21&","&N21&","&O21&","&P21&",'"&Q21&"',"&R21&","&S21&",'"&T21&"','"&U21&"',"&V21&")," -> (2488,null,1,'2026-03-24 00:00:00','003106040020000-310604002','003106040020000-310604002','睡眠呼吸监测过筛试验',null,null,149.5,130,110.5,null,130,115,149,'次',25,1,'normal','main',0),
A22: 2489 | B22: null | C22: 1 | D22: 2026-03-24 00:00:00 | E22: 003106050020000-310605002 | F22: 003106050020000-310605002 | G22: 纤维支气管镜检查 | H22: null | I22: null | J22: 138 | K22: 120 | L22: 102 | M22: null | N22: 240 | O22: 216 | P22: 190 | Q22: 次 | R22: 25 | S22: 1 | T22: normal | U22: main | V22: 0 | W22: ="("&A22&","&B22&","&C22&",'"&D22&"','"&E22&"','"&F22&"','"&G22&"',"&H22&","&I22&","&J22&","&K22&","&L22&","&M22&","&N22&","&O22&","&P22&",'"&Q22&"',"&R22&","&S22&",'"&T22&"','"&U22&"',"&V22&")," -> (2489,null,1,'2026-03-24 00:00:00','003106050020000-310605002','003106050020000-310605002','纤维支气管镜检查',null,null,138,120,102,null,240,216,190,'次',25,1,'normal','main',0),
A23: 2490 | B23: null | C23: 1 | D23: 2026-03-24 00:00:00 | E23: 003106050010000-310605001 | F23: 003106050010000-310605001 | G23: 硬质气管镜检查 | H23: null | I23: null | J23: 115 | K23: 100 | L23: 85 | M23: null | N23: 240 | O23: 216 | P23: 190 | Q23: 次 | R23: 25 | S23: 1 | T23: normal | U23: main | V23: 0 | W23: ="("&A23&","&B23&","&C23&",'"&D23&"','"&E23&"','"&F23&"','"&G23&"',"&H23&","&I23&","&J23&","&K23&","&L23&","&M23&","&N23&","&O23&","&P23&",'"&Q23&"',"&R23&","&S23&",'"&T23&"','"&U23&"',"&V23&")," -> (2490,null,1,'2026-03-24 00:00:00','003106050010000-310605001','003106050010000-310605001','硬质气管镜检查',null,null,115,100,85,null,240,216,190,'次',25,1,'normal','main',0),
A24: 2491 | B24: null | C24: 1 | D24: 2026-03-24 00:00:00 | E24: 003106050000001-31060500002 | F24: 003106050000001-31060500002 | G24: 呼吸系统窥镜诊疗（使用电子支气管镜加收） | H24: null | I24: null | J24: 138 | K24: 120 | L24: 102 | M24: null | N24: 0 | O24: 0 | P24: 0 | Q24: 次 | R24: 25 | S24: 1 | T24: normal | U24: main | V24: 0 | W24: ="("&A24&","&B24&","&C24&",'"&D24&"','"&E24&"','"&F24&"','"&G24&"',"&H24&","&I24&","&J24&","&K24&","&L24&","&M24&","&N24&","&O24&","&P24&",'"&Q24&"',"&R24&","&S24&",'"&T24&"','"&U24&"',"&V24&")," -> (2491,null,1,'2026-03-24 00:00:00','003106050000001-31060500002','003106050000001-31060500002','呼吸系统窥镜诊疗（使用电子支气管镜加收）',null,null,138,120,102,null,0,0,0,'次',25,1,'normal','main',0),
A25: 2492 | B25: null | C25: 1 | D25: 2026-03-24 00:00:00 | E25: 003106050000001-31060500001 | F25: 003106050000001-31060500001 | G25: 呼吸系统窥镜诊疗（使用电子纤维内镜加收） | H25: null | I25: null | J25: 115 | K25: 100 | L25: 85 | M25: null | N25: 0 | O25: 0 | P25: 0 | Q25: 次 | R25: 25 | S25: 1 | T25: normal | U25: main | V25: 0 | W25: ="("&A25&","&B25&","&C25&",'"&D25&"','"&E25&"','"&F25&"','"&G25&"',"&H25&","&I25&","&J25&","&K25&","&L25&","&M25&","&N25&","&O25&","&P25&",'"&Q25&"',"&R25&","&S25&",'"&T25&"','"&U25&"',"&V25&")," -> (2492,null,1,'2026-03-24 00:00:00','003106050000001-31060500001','003106050000001-31060500001','呼吸系统窥镜诊疗（使用电子纤维内镜加收）',null,null,115,100,85,null,0,0,0,'次',25,1,'normal','main',0),
A26: 2493 | B26: null | C26: 1 | D26: 2026-03-24 00:00:00 | E26: 003106050020000-310605015 | F26: 003106050020000-310605015 | G26: 超声支气管镜检查 | H26: null | I26: null | J26: 585 | K26: 527 | L26: 448 | M26: null | N26: 585 | O26: 527 | P26: 448 | Q26: 次 | R26: 25 | S26: 1 | T26: normal | U26: main | V26: 0 | W26: ="("&A26&","&B26&","&C26&",'"&D26&"','"&E26&"','"&F26&"','"&G26&"',"&H26&","&I26&","&J26&","&K26&","&L26&","&M26&","&N26&","&O26&","&P26&",'"&Q26&"',"&R26&","&S26&",'"&T26&"','"&U26&"',"&V26&")," -> (2493,null,1,'2026-03-24 00:00:00','003106050020000-310605015','003106050020000-310605015','超声支气管镜检查',null,null,585,527,448,null,585,527,448,'次',25,1,'normal','main',0),
A27: 2494 | B27: null | C27: 1 | D27: 2026-03-24 00:00:00 | E27: 003106050140000-310605014 | F27: 003106050140000-310605014 | G27: 纵隔镜检查 | H27: null | I27: null | J27: 575 | K27: 500 | L27: 425 | M27: null | N27: 540 | O27: 490 | P27: 415 | Q27: 次 | R27: 25 | S27: 1 | T27: normal | U27: main | V27: 0 | W27: ="("&A27&","&B27&","&C27&",'"&D27&"','"&E27&"','"&F27&"','"&G27&"',"&H27&","&I27&","&J27&","&K27&","&L27&","&M27&","&N27&","&O27&","&P27&",'"&Q27&"',"&R27&","&S27&",'"&T27&"','"&U27&"',"&V27&")," -> (2494,null,1,'2026-03-24 00:00:00','003106050140000-310605014','003106050140000-310605014','纵隔镜检查',null,null,575,500,425,null,540,490,415,'次',25,1,'normal','main',0),
A28: 2495 | B28: null | C28: 1 | D28: 2026-03-24 00:00:00 | E28: 003106030030000-310603003 | F28: 003106030030000-310603003 | G28: 体外膈肌起搏治疗 | H28: null | I28: null | J28: 17.3 | K28: 15 | L28: 12.8 | M28: null | N28: 15 | O28: 14 | P28: 13 | Q28: 次 | R28: 25 | S28: 1 | T28: normal | U28: main | V28: 0 | W28: ="("&A28&","&B28&","&C28&",'"&D28&"','"&E28&"','"&F28&"','"&G28&"',"&H28&","&I28&","&J28&","&K28&","&L28&","&M28&","&N28&","&O28&","&P28&",'"&Q28&"',"&R28&","&S28&",'"&T28&"','"&U28&"',"&V28&")," -> (2495,null,1,'2026-03-24 00:00:00','003106030030000-310603003','003106030030000-310603003','体外膈肌起搏治疗',null,null,17.3,15,12.8,null,15,14,13,'次',25,1,'normal','main',0),
A29: 2496 | B29: null | C29: 1 | D29: 2026-03-24 00:00:00 | E29: 353106040090000-12030000140 | F29: 353106040090000-12030000140 | G29: 一氧化氮吸入 | H29: null | I29: null | J29: 9 | K29: 9 | L29: 9 | M29: null | N29: 45 | O29: 45 | P29: 41 | Q29: 小时 | R29: 25 | S29: 1 | T29: normal | U29: main | V29: 0 | W29: ="("&A29&","&B29&","&C29&",'"&D29&"','"&E29&"','"&F29&"','"&G29&"',"&H29&","&I29&","&J29&","&K29&","&L29&","&M29&","&N29&","&O29&","&P29&",'"&Q29&"',"&R29&","&S29&",'"&T29&"','"&U29&"',"&V29&")," -> (2496,null,1,'2026-03-24 00:00:00','353106040090000-12030000140','353106040090000-12030000140','一氧化氮吸入',null,null,9,9,9,null,45,45,41,'小时',25,1,'normal','main',0),
A30: 2497 | B30: null | C30: 1 | D30: 2026-03-24 00:00:00 | E30: 001207000010000-120700001 | F30: 001207000010000-120700001 | G30: 雾化吸入 | H30: null | I30: null | J30: 0 | K30: 0 | L30: 0 | M30: null | N30: 13 | O30: 12 | P30: 11 | Q30: 次 | R30: 25 | S30: 1 | T30: normal | U30: main | V30: 0 | W30: ="("&A30&","&B30&","&C30&",'"&D30&"','"&E30&"','"&F30&"','"&G30&"',"&H30&","&I30&","&J30&","&K30&","&L30&","&M30&","&N30&","&O30&","&P30&",'"&Q30&"',"&R30&","&S30&",'"&T30&"','"&U30&"',"&V30&")," -> (2497,null,1,'2026-03-24 00:00:00','001207000010000-120700001','001207000010000-120700001','雾化吸入',null,null,0,0,0,null,13,12,11,'次',25,1,'normal','main',0),
A31: 2498 | B31: null | C31: 1 | D31: 2026-03-24 00:00:00 | E31: 001207000010100-12070000101 | F31: 001207000010100-12070000101 | G31: 超声雾化吸入 | H31: null | I31: null | J31: 5 | K31: 5 | L31: 4.3 | M31: null | N31: 13 | O31: 12 | P31: 11 | Q31: 次 | R31: 25 | S31: 1 | T31: normal | U31: main | V31: 0 | W31: ="("&A31&","&B31&","&C31&",'"&D31&"','"&E31&"','"&F31&"','"&G31&"',"&H31&","&I31&","&J31&","&K31&","&L31&","&M31&","&N31&","&O31&","&P31&",'"&Q31&"',"&R31&","&S31&",'"&T31&"','"&U31&"',"&V31&")," -> (2498,null,1,'2026-03-24 00:00:00','001207000010100-12070000101','001207000010100-12070000101','超声雾化吸入',null,null,5,5,4.3,null,13,12,11,'次',25,1,'normal','main',0),
