Workbook

Sheet 眼科项目
A1: 眼科类立项指南项目对应及拟定情况（征求意见稿）
A2: 眼科类立项指南项目 | U2: 现行项目
A3: 序号 | B3: 项目代码 | C3: 项目名称 | D3: 服务产出 | E3: 价格构成 | F3: 计价说明 | G3: 计价单位 | H3: 省三甲价格 | I3: 省三甲以下价格 | J3: 平移价格 (市级) | K3: 平移价格 (县级) | L3: 平移价格 (基层) | M3: 拟定价格 (市级) | N3: 拟定价格 (县级) | O3: 拟定价格 (基层) | P3: 医保 属性 | Q3: 医保限定支付范围 | R3: 个人先行自付比例 | S3: 调整情况 | T3: 备注 | U3: 国家结算编码 | V3: 项目代码 | W3: 项目名称 | X3: 项目内涵 | Y3: 除外内容 | Z3: 计价单位 | AA3: 说明 | AB3: 价格 (市级) | AC3: 价格 (县级) | AD3: 价格 (基层) | AE3: 医保属性
A4: 1 | B4: 012403000010000 | C4: 视力检查费（普通） | D4: 通过远视力、近视力、光机能（包括光感及光定位）、伪盲检查等多种方式对视力进行检查。 | E4: 所定价格涵盖眼部遮盖、检查、记录、出具结果报告等步骤所需的人力资源和基本物质资源消耗。 | G4: 次 | H4: 1 | I4: 1 | J4: 1.1 | K4: 1 | L4: 0.9 | M4: 1 | N4: 1 | O4: 1 | P4: 医保 | S4: 理顺 | T4: 平移后市级按不超过省级拟定，同质化项目，价格较低，市县基层同价 | U4: 003103000010000-310300001 | V4: 310300001 | W4: 普通视力检查 | X4: 含远视力、近视力、光机能（包括光感及光定位）、伪盲检查 | Z4: 次 | AB4: 1.1 | AC4: 1 | AD4: 0.9 | AE4: 医保
A5: 2 | B5: 012403000020000 | C5: 视力检查费（特殊） | D5: 通过各种特殊方式对视力进行检查。 | E5: 所定价格涵盖设备准备、检查、记录、出具结果报告等步骤所需的人力资源和基本物质资源消耗。 | F5: 1.“特殊方式”是指应用图形视力表、点视力表、条栅视力卡、视动性眼球震颤设备的方式进行视力检查。2.阿姆斯勒(Amsler)表检查按此项目收费。 | G5: 次 | H5: 13 | I5: 13 | J5: 11.896281 | K5: 10.794874 | L5: 10.797706 | M5: 12 | N5: 11.5 | O5: 11 | P5: 医保 | S5: 理顺 | T5: 同质化项目缩小价差 | U5: 003103000020000-310300002 | V5: 310300002 | W5: 特殊视力检查 | X5: 包括儿童图形视力表，点视力表，条栅视力卡，视动性眼震仪 | Z5: 项 | AB5: 2.1 | AC5: 2 | AD5: 1.7 | AE5: 医保
U6: 003103000020100-31030000201 | V6: 31030000201 | W6: 特殊视力检查（儿童图形视力表） | Z6: 项 | AA6: 儿童图形视力表 | AB6: 2.1 | AC6: 2 | AD6: 1.7 | AE6: 医保
U7: 003103000020200-31030000202 | V7: 31030000202 | W7: 特殊视力检查（点视力表） | Z7: 项 | AA7: 点视力表 | AB7: 2.1 | AC7: 2 | AD7: 1.7 | AE7: 医保
U8: 003103000020300-31030000203 | V8: 31030000203 | W8: 特殊视力检查（条栅视力卡） | Z8: 项 | AA8: 条栅视力卡 | AB8: 2.1 | AC8: 2 | AD8: 1.7 | AE8: 医保
U9: 003103000020400-31030000204 | V9: 31030000204 | W9: 特殊视力检查（视动性眼震仪） | Z9: 项 | AA9: 视动性眼震仪 | AB9: 2.1 | AC9: 2 | AD9: 1.7 | AE9: 医保
U10: 003103000030000-310300003 | V10: 310300003 | W10: 选择性观看检查 | Z10: 次 | AB10: 2.1 | AC10: 2 | AD10: 1.7 | AE10: 医保
U11: 003103000040000-310300004 | V11: 310300004 | W11: 视网膜视力检查 | Z11: 次 | AB11: 5.3 | AC11: 5 | AD11: 4.3 | AE11: 医保
U12: 003103000060000-310300006 | V12: 310300006 | W12: 阿姆斯勒（Amsler）表检查 | Z12: 次（单眼） | AB12: 2.1 | AC12: 2 | AD12: 1.7 | AE12: 医保
U13: 003103000210000-310300021 | V13: 310300021 | W13: 对比敏感度检查 | Z13: 次 | AA13: 使用微机处理基层收12.8元，县级医院收15元，市级医院收15.8元 | AB13: 3.2 | AC13: 3 | AD13: 2.6 | AE13: 医保
U14: 003103000210000-31030002101 | V14: 31030002101 | W14: 对比敏感度检查（使用微机处理） | Z14: 次 | AA14: 使用微机处理 | AB14: 15.8 | AC14: 15 | AD14: 12.8 | AE14: 医保
U15: 003103000220000-310300022 | V15: 310300022 | W15: 暗适应测定 | X15: 含图形及报告 | Z15: 次 | AB15: 15.8 | AC15: 15 | AD15: 12.8 | AE15: 医保
U16: 003103000230000-310300023 | V16: 310300023 | W16: 明适应测定 | Z16: 次 | AB16: 15.8 | AC16: 15 | AD16: 12.8 | AE16: 医保
A17: 3 | B17: 012403000030000 | C17: 散瞳验光费 | D17: 通过散瞳、电脑、检影等不同方式测量眼睛的屈光状态。 | E17: 所定价格涵盖散瞳、电脑及人工测视力、测瞳距、确定屈光度数、记录、出具结果报告等步骤所需的人力资源和基本物质资源消耗。 | G17: 次 | H17: 8 | I17: 8 | J17: 7.2693567 | K17: 6.0744562 | L17: 5.2666794 | M17: 7.5 | N17: 7 | O17: 6.5 | P17: 医保 | S17: 理顺 | T17: 同质化项目，缩小价差 | U17: 003103000070000-310300007 | V17: 310300007 | W17: 验光 | X17: 包括检影，散瞳，云雾试验，试镜 | Z17: 项 | AA17: 每增加一项基层加收1.7元，县级医院加收2元，市级医院加收2.1元 | AB17: 5.3 | AC17: 5 | AD17: 4.3 | AE17: 医保
U18: 003103000070001-31030000701 | V18: 31030000701 | W18: 验光（增加一项加收） | Z18: 项 | AA18: 每增加一项加收 | AB18: 2.1 | AC18: 2 | AD18: 1.7 | AE18: 医保
A19: 分项 | B19: 012403000030001 | C19: 散瞳验光费-儿童（加收） | G19: 次 | H19: 2.4 | I19: 2.4 | M19: 2.3 | N19: 2.1 | O19: 2 | P19: 医保
A20: 4 | B20: 012403000040000 | C20: 显然验光费 | D20: 通过反复插试镜片，确定矫正视力度数。 | E20: 所定价格涵盖戴试镜架、插试镜片、调整度数、记录、出具结果报告等步骤所需的人力资源和基本物质资源消耗。 | G20: 次 | H20: 4 | I20: 4 | M20: 3.8 | N20: 3.5 | O20: 3.3 | P20: 医保 | S20: 理顺 | T20: 根据项目间比价关系及省局定价原则，按照散瞳验光费的50%定价
A21: 分项 | B21: 012403000040001 | C21: 显然验光费-儿童（加收） | G21: 次 | H21: 1.2 | I21: 1.2 | M21: 1.1 | N21: 1 | O21: 0.9 | P21: 医保
A22: 5 | B22: 012403000050000 | C22: 眼压检查费 | D22: 通过接触或非接触方式进行眼压测量。 | E22: 所定价格涵盖检查、测量、记录、出具结果报告等步骤所需的人力资源和基本物质资源消耗。 | F22: 眼压日曲线描记按照眼压检查实际开展次数收费，每日单侧收费不超过4个计价单位。 | G22: 单侧 | H22: 8 | I22: 7 | J22: 8.3960273 | K22: 7.9476972 | L22: 6.7751148 | M22: 8 | N22: 7 | O22: 6.5 | P22: 医保 | S22: 理顺 | T22: 平移后按不超过省级下调拟定 | U22: 003103000270000-310300027 | V22: 310300027 | W22: 眼压检查 | X22: 包括Schiotz眼压计法，电眼压计法 | Z22: 次 | AA22: 非接触眼压计法、压平眼压计法分别加收100% | AB22: 4.2 | AC22: 4 | AD22: 3.4 | AE22: 医保
U23: 003103000270200-31030002701 | V23: 31030002701 | W23: 眼压检查（非接触眼压计法） | Z23: 次 | AA23: 非接触眼压计法 | AB23: 8.4 | AC23: 8 | AD23: 6.8 | AE23: 医保
U24: 003103000270400-31030002702 | V24: 31030002702 | W24: 眼压检查（压平眼压计法） | Z24: 次 | AA24: 压平眼压计法 | AB24: 8.4 | AC24: 8 | AD24: 6.8 | AE24: 医保
U25: 003103000290000-310300029 | V25: 310300029 | W25: 眼压描记 | Z25: 次 | AB25: 10.5 | AC25: 10 | AD25: 8.5 | AE25: 医保
U26: 003103000280000-310300028 | V26: 310300028 | W26: 眼压日曲线检查 | Z26: 次 | AB26: 15.8 | AC26: 15 | AD26: 12.8 | AE26: 医保
A27: 6 | B27: 012403000060000 | C27: 眼压检查费（青光眼激发） | D27: 指通过各种方式激发眼压升高后进行眼压测量。 | E27: 所定价格涵盖试验准备、眼压测量、诱导、再次测量、记录、出具结果报告等步骤所需的人力资源和基本物质资源消耗。 | F27: 不得与眼压检查费同时收取。 | G27: 次 | H27: 15 | I27: 13.5 | J27: 15.8 | K27: 15 | L27: 12.8 | M27: 15 | N27: 13.5 | O27: 12 | P27: 医保 | S27: 理顺，降低 | T27: 平移后按不超过省级下调拟定，同质化检查项目持平省级 | U27: 003103000370000-310300037 | V27: 310300037 | W27: 青光眼诱导试验 | X27: 包括饮水，暗室，妥拉苏林等 | Z27: 次 | AB27: 15.8 | AC27: 15 | AD27: 12.8 | AE27: 医保
A28: 分项 | B28: 012403000060001 | C28: 眼压检查费（青光眼激发）-饮水试验（加收） | G28: 次 | H28: 7.5 | I28: 7 | M28: 7.5 | N28: 7 | O28: 6 | P28: 医保 | T28: 新增加收项目，为主项的50%
A29: 7 | B29: 012403000070000 | C29: 色觉检查费 | D29: 通过不同方式检查色弱、色盲情况。 | E29: 所定价格涵盖检查、记录、出具结果报告等步骤所需的人力资源和基本物质资源消耗。 | G29: 次 | H29: 5 | I29: 5 | J29: 5.3 | K29: 5 | L29: 4.3 | M29: 5 | N29: 5 | O29: 4.3 | P29: 医保 | S29: 理顺，降低 | T29: 平移后市级按不超过省级下调拟定 | U29: 003103000200000-310300020 | V29: 310300020 | W29: 色觉检查 | X29: 包括普通图谱法，FM-100Hue测试盒法，色觉仪法 | Z29: 次 | AB29: 5.3 | AC29: 5 | AD29: 4.3 | AE29: 医保
A30: 8 | B30: 012403000080000 | C30: 视野检查费 | D30: 通过各种方式对视野进行评估。 | E30: 所定价格涵盖应用视野检查设备、记录、出具结果报告等步骤所需的人力资源和基本物质资源消耗。 | G30: 单侧 | H30: 30 | I30: 27 | J30: 30.81491 | K30: 29.816303 | L30: 16.425267 | M30: 30 | N30: 27 | O30: 22 | P30: 医保 | S30: 理顺 | T30: 平移后市县按不超过省级下调拟定，基层按比价上调，同质化检查项目持平省级 | U30: 003103000050000-310300005 | V30: 310300005 | W30: 视野检查 | X30: 普通视野计 | Z30: 次（单眼） | AA30: 电脑视野计、动态(Goldmann)视野计加收200% | AB30: 10.5 | AC30: 10 | AD30: 8.5 | AE30: 医保
U31: 003103000050200-31030000501 | V31: 31030000501 | W31: 视野检查（电脑视野计） | Z31: 次（单眼） | AA31: 电脑视野计 | AB31: 31.5 | AC31: 30 | AD31: 25.5 | AE31: 医保
U32: 003103000050100-31030000502 | V32: 31030000502 | W32: 视野检查（动态Goldmann视野计） | Z32: 次（单眼） | AA32: 动态(Goldmann)视野计 | AB32: 31.5 | AC32: 30 | AD32: 25.5 | AE32: 医保
A33: 9 | B33: 012403000090000 | C33: 泪液分泌功能测定费 | D33: 通过各种方式对泪液分泌功能进行测定。 | E33: 所定价格涵盖放置纸条、测定滤纸浸湿长度、记录并分析结果等步骤所需的人力资源和基本物质资源消耗。 | G33: 单侧 | H33: 8 | I33: 7 | J33: 8.4 | K33: 8 | L33: 6.8 | M33: 8 | N33: 7 | O33: 6 | P33: 医保 | S33: 理顺 | T33: 平移后按不超过省级下调拟定，同质化检查项目持平省级 | U33: 003103000350000-310300035 | V33: 310300035 | W33: 泪液分泌功能测定 | Z33: 次 | AB33: 8.4 | AC33: 8 | AD33: 6.8 | AE33: 医保
A34: 10 | B34: 012403000100000 | C34: 泪膜分析测定费 | D34: 通过各种方式对泪膜进行分析测定。 | E34: 所定价格涵盖设备准备、检查、记录、分析、出具结果报告等步骤所需的人力资源和基本物质资源消耗。 | G34: 单侧 | H34: 10 | I34: 9 | J34: 10.5 | K34: 10 | L34: 8.5 | M34: 10 | N34: 9 | O34: 8 | P34: 医保 | S34: 理顺 | T34: 平移后按不超过省级下调拟定，同质化检查项目持平省级 | U34: 003103000340000-310300034 | V34: 310300034 | W34: 泪膜破裂时间测定 | Z34: 次 | AB34: 10.5 | AC34: 10 | AD34: 8.5 | AE34: 医保
A35: 11 | B35: 012403000110000 | C35: 复视检查费 | D35: 通过各种方式对复视情况进行检查。 | E35: 所定价格涵盖设备准备、检查、记录、分析、出具结果报告等步骤所需的人力资源和基本物质资源消耗。 | G35: 次 | H35: 8 | I35: 7 | J35: 7.6968722 | K35: 7.9883268 | L35: 6.8 | M35: 8 | N35: 7 | O35: 6 | P35: 医保 | S35: 理顺 | T35: 同质化检查项目持平省级 | U35: 003103000160000-310300016 | V35: 310300016 | W35: 黑氏（Hess）屏检查 | Z35: 次 | AB35: 8.4 | AC35: 8 | AD35: 6.8 | AE35: 医保
U36: 003103000120000-310300012 | V36: 310300012 | W36: 复视检查 | Z36: 次 | AB36: 8.4 | AC36: 8 | AD36: 6.8 | AE36: 医保
U37: 003103000150000-310300015 | V37: 310300015 | W37: 线状镜检查 | Z37: 次 | AB37: 5.3 | AC37: 5 | AD37: 4.3 | AE37: 医保
A38: 分项 | B38: 012403000110001 | C38: 复视检查费-儿童（加收） | G38: 次 | H38: 2.4 | I38: 2.1 | M38: 2.4 | N38: 2.1 | O38: 1.8 | P38: 医保 | T38: 儿童加收30%
A39: 12 | B39: 012403000120000 | C39: 斜视度测定费 | D39: 通过各种方式测定斜视度数。 | E39: 所定价格涵盖设备准备、检查、记录、分析、出具结果报告等步骤所需的人力资源和基本物质资源消耗。 | F39: 每日计费不超过3次。 | G39: 次 | H39: 9 | I39: 8 | J39: 8.9290639 | K39: 7.6541327 | L39: 6.7984619 | M39: 9 | N39: 8 | O39: 7 | P39: 医保 | S39: 平移取整 | T39: 加权平移取整，同质化检查项目持平省级 | U39: 003103000130000-310300013 | V39: 310300013 | W39: 斜视度测定 | X39: 含九个注视方向双眼分别注视时的斜度，看远及看近 | Z39: 次 | AB39: 8.4 | AC39: 8 | AD39: 6.8 | AE39: 医保
U40: 003103000140000-310300014 | V40: 310300014 | W40: 三棱镜检查 | Z40: 次 | AB40: 10.5 | AC40: 10 | AD40: 8.5 | AE40: 医保
...

Sheet 眼科项目 (2)
A1: 眼科类立项指南项目对应及拟定情况（征求意见稿）
A2: 眼科类立项指南项目 | V2: 现行项目
A3: 序号 | B3: 项目代码 | C3: 项目名称 | D3: 服务产出 | E3: 价格构成 | F3: 计价说明 | G3: 计价单位 | H3: 省三甲价格 | I3: 省三甲以下价格 | J3: 平移价格 (市级) | K3: 平移价格 (县级) | L3: 平移价格 (基层) | N3: 拟定价格 (市级) | O3: 拟定价格 (县级) | P3: 拟定价格 (基层) | Q3: 医保 属性 | R3: 医保限定支付范围 | S3: 个人先行自付比例 | T3: 调整情况 | U3: 备注 | V3: 国家结算编码 | W3: 项目代码 | X3: 项目名称 | Y3: 项目内涵 | Z3: 除外内容 | AA3: 计价单位 | AB3: 说明 | AC3: 价格 (市级) | AD3: 价格 (县级) | AE3: 价格 (基层)
A4: 1 | B4: 012403000010000 | C4: 视力检查费（普通） | D4: 通过远视力、近视力、光机能（包括光感及光定位）、伪盲检查等多种方式对视力进行检查。 | E4: 所定价格涵盖眼部遮盖、检查、记录、出具结果报告等步骤所需的人力资源和基本物质资源消耗。 | G4: 次 | H4: 1 | I4: 1 | J4: 1.1 | K4: 1 | L4: 0.9 | N4: 1 | O4: 1 | P4: 1 | Q4: 医保 | T4: 理顺 | U4: 平移后市级按不超过省级拟定，同质化项目，价格较低，市县基层同价 | V4: 003103000010000-310300001 | W4: 310300001 | X4: 普通视力检查 | Y4: 含远视力、近视力、光机能（包括光感及光定位）、伪盲检查 | AA4: 次 | AC4: 1.1 | AD4: 1 | AE4: 0.9 | AF4: =IFERROR(FIND("-儿童（加收）",C4,1),0) -> 0 | AG4: =SUBSTITUTE(C4,"-儿童（加收）","") -> 视力检查费（普通） | AH4: =IF(AF4>0,_xlfn.MAXIFS(N:N,C:C,SUBSTITUTE(C4,"-儿童（加收）","")),0)+N4 -> 1 | AI4: =IF(AF4>0,_xlfn.MAXIFS(O:O,C:C,SUBSTITUTE(C4,"-儿童（加收）","")),0)+O4 -> 1 | AJ4: =IF(AF4>0,_xlfn.MAXIFS(P:P,C:C,SUBSTITUTE(C4,"-儿童（加收）","")),0)+P4 -> 1
A5: 2 | B5: 012403000020000 | C5: 视力检查费（特殊） | D5: 通过各种特殊方式对视力进行检查。 | E5: 所定价格涵盖设备准备、检查、记录、出具结果报告等步骤所需的人力资源和基本物质资源消耗。 | F5: 1.“特殊方式”是指应用图形视力表、点视力表、条栅视力卡、视动性眼球震颤设备的方式进行视力检查。2.阿姆斯勒(Amsler)表检查按此项目收费。 | G5: 次 | H5: 13 | I5: 13 | J5: 11.896281 | K5: 10.794874 | L5: 10.797706 | N5: 12 | O5: 11.5 | P5: 11 | Q5: 医保 | T5: 理顺 | U5: 同质化项目缩小价差 | V5: 003103000020000-310300002 | W5: 310300002 | X5: 特殊视力检查 | Y5: 包括儿童图形视力表，点视力表，条栅视力卡，视动性眼震仪 | AA5: 项 | AC5: 2.1 | AD5: 2 | AE5: 1.7 | AF5: =IFERROR(FIND("-儿童（加收）",C5,1),0) -> 0 | AG5: =SUBSTITUTE(C5,"-儿童（加收）","") -> 视力检查费（特殊） | AH5: =IF(AF5>0,_xlfn.MAXIFS(N:N,C:C,SUBSTITUTE(C5,"-儿童（加收）","")),0)+N5 -> 12 | AI5: =IF(AF5>0,_xlfn.MAXIFS(O:O,C:C,SUBSTITUTE(C5,"-儿童（加收）","")),0)+O5 -> 11.5 | AJ5: =IF(AF5>0,_xlfn.MAXIFS(P:P,C:C,SUBSTITUTE(C5,"-儿童（加收）","")),0)+P5 -> 11
C6: 视力检查费（特殊） | N6: 12 | O6: 11.5 | P6: 11 | V6: 003103000020100-31030000201 | W6: 31030000201 | X6: 特殊视力检查（儿童图形视力表） | AA6: 项 | AB6: 儿童图形视力表 | AC6: 2.1 | AD6: 2 | AE6: 1.7 | AF6: =IFERROR(FIND("-儿童（加收）",C6,1),0) -> 0 | AG6: =SUBSTITUTE(C6,"-儿童（加收）","") -> 视力检查费（特殊） | AH6: =IF(AF6>0,_xlfn.MAXIFS(N:N,C:C,SUBSTITUTE(C6,"-儿童（加收）","")),0)+N6 -> 12 | AI6: =IF(AF6>0,_xlfn.MAXIFS(O:O,C:C,SUBSTITUTE(C6,"-儿童（加收）","")),0)+O6 -> 11.5 | AJ6: =IF(AF6>0,_xlfn.MAXIFS(P:P,C:C,SUBSTITUTE(C6,"-儿童（加收）","")),0)+P6 -> 11
C7: 视力检查费（特殊） | N7: 12 | O7: 11.5 | P7: 11 | V7: 003103000020200-31030000202 | W7: 31030000202 | X7: 特殊视力检查（点视力表） | AA7: 项 | AB7: 点视力表 | AC7: 2.1 | AD7: 2 | AE7: 1.7 | AF7: =IFERROR(FIND("-儿童（加收）",C7,1),0) -> 0 | AG7: =SUBSTITUTE(C7,"-儿童（加收）","") -> 视力检查费（特殊） | AH7: =IF(AF7>0,_xlfn.MAXIFS(N:N,C:C,SUBSTITUTE(C7,"-儿童（加收）","")),0)+N7 -> 12 | AI7: =IF(AF7>0,_xlfn.MAXIFS(O:O,C:C,SUBSTITUTE(C7,"-儿童（加收）","")),0)+O7 -> 11.5 | AJ7: =IF(AF7>0,_xlfn.MAXIFS(P:P,C:C,SUBSTITUTE(C7,"-儿童（加收）","")),0)+P7 -> 11
C8: 视力检查费（特殊） | N8: 12 | O8: 11.5 | P8: 11 | V8: 003103000020300-31030000203 | W8: 31030000203 | X8: 特殊视力检查（条栅视力卡） | AA8: 项 | AB8: 条栅视力卡 | AC8: 2.1 | AD8: 2 | AE8: 1.7 | AF8: =IFERROR(FIND("-儿童（加收）",C8,1),0) -> 0 | AG8: =SUBSTITUTE(C8,"-儿童（加收）","") -> 视力检查费（特殊） | AH8: =IF(AF8>0,_xlfn.MAXIFS(N:N,C:C,SUBSTITUTE(C8,"-儿童（加收）","")),0)+N8 -> 12 | AI8: =IF(AF8>0,_xlfn.MAXIFS(O:O,C:C,SUBSTITUTE(C8,"-儿童（加收）","")),0)+O8 -> 11.5 | AJ8: =IF(AF8>0,_xlfn.MAXIFS(P:P,C:C,SUBSTITUTE(C8,"-儿童（加收）","")),0)+P8 -> 11
C9: 视力检查费（特殊） | N9: 12 | O9: 11.5 | P9: 11 | V9: 003103000020400-31030000204 | W9: 31030000204 | X9: 特殊视力检查（视动性眼震仪） | AA9: 项 | AB9: 视动性眼震仪 | AC9: 2.1 | AD9: 2 | AE9: 1.7 | AF9: =IFERROR(FIND("-儿童（加收）",C9,1),0) -> 0 | AG9: =SUBSTITUTE(C9,"-儿童（加收）","") -> 视力检查费（特殊） | AH9: =IF(AF9>0,_xlfn.MAXIFS(N:N,C:C,SUBSTITUTE(C9,"-儿童（加收）","")),0)+N9 -> 12 | AI9: =IF(AF9>0,_xlfn.MAXIFS(O:O,C:C,SUBSTITUTE(C9,"-儿童（加收）","")),0)+O9 -> 11.5 | AJ9: =IF(AF9>0,_xlfn.MAXIFS(P:P,C:C,SUBSTITUTE(C9,"-儿童（加收）","")),0)+P9 -> 11
C10: 视力检查费（特殊） | N10: 12 | O10: 11.5 | P10: 11 | V10: 003103000030000-310300003 | W10: 310300003 | X10: 选择性观看检查 | AA10: 次 | AC10: 2.1 | AD10: 2 | AE10: 1.7 | AF10: =IFERROR(FIND("-儿童（加收）",C10,1),0) -> 0 | AG10: =SUBSTITUTE(C10,"-儿童（加收）","") -> 视力检查费（特殊） | AH10: =IF(AF10>0,_xlfn.MAXIFS(N:N,C:C,SUBSTITUTE(C10,"-儿童（加收）","")),0)+N10 -> 12 | AI10: =IF(AF10>0,_xlfn.MAXIFS(O:O,C:C,SUBSTITUTE(C10,"-儿童（加收）","")),0)+O10 -> 11.5 | AJ10: =IF(AF10>0,_xlfn.MAXIFS(P:P,C:C,SUBSTITUTE(C10,"-儿童（加收）","")),0)+P10 -> 11
C11: 视力检查费（特殊） | N11: 12 | O11: 11.5 | P11: 11 | V11: 003103000040000-310300004 | W11: 310300004 | X11: 视网膜视力检查 | AA11: 次 | AC11: 5.3 | AD11: 5 | AE11: 4.3 | AF11: =IFERROR(FIND("-儿童（加收）",C11,1),0) -> 0 | AG11: =SUBSTITUTE(C11,"-儿童（加收）","") -> 视力检查费（特殊） | AH11: =IF(AF11>0,_xlfn.MAXIFS(N:N,C:C,SUBSTITUTE(C11,"-儿童（加收）","")),0)+N11 -> 12 | AI11: =IF(AF11>0,_xlfn.MAXIFS(O:O,C:C,SUBSTITUTE(C11,"-儿童（加收）","")),0)+O11 -> 11.5 | AJ11: =IF(AF11>0,_xlfn.MAXIFS(P:P,C:C,SUBSTITUTE(C11,"-儿童（加收）","")),0)+P11 -> 11
C12: 视力检查费（特殊） | N12: 12 | O12: 11.5 | P12: 11 | V12: 003103000060000-310300006 | W12: 310300006 | X12: 阿姆斯勒（Amsler）表检查 | AA12: 次（单眼） | AC12: 2.1 | AD12: 2 | AE12: 1.7 | AF12: =IFERROR(FIND("-儿童（加收）",C12,1),0) -> 0 | AG12: =SUBSTITUTE(C12,"-儿童（加收）","") -> 视力检查费（特殊） | AH12: =IF(AF12>0,_xlfn.MAXIFS(N:N,C:C,SUBSTITUTE(C12,"-儿童（加收）","")),0)+N12 -> 12 | AI12: =IF(AF12>0,_xlfn.MAXIFS(O:O,C:C,SUBSTITUTE(C12,"-儿童（加收）","")),0)+O12 -> 11.5 | AJ12: =IF(AF12>0,_xlfn.MAXIFS(P:P,C:C,SUBSTITUTE(C12,"-儿童（加收）","")),0)+P12 -> 11
C13: 视力检查费（特殊） | N13: 12 | O13: 11.5 | P13: 11 | V13: 003103000210000-310300021 | W13: 310300021 | X13: 对比敏感度检查 | AA13: 次 | AB13: 使用微机处理基层收12.8元，县级医院收15元，市级医院收15.8元 | AC13: 3.2 | AD13: 3 | AE13: 2.6 | AF13: =IFERROR(FIND("-儿童（加收）",C13,1),0) -> 0 | AG13: =SUBSTITUTE(C13,"-儿童（加收）","") -> 视力检查费（特殊） | AH13: =IF(AF13>0,_xlfn.MAXIFS(N:N,C:C,SUBSTITUTE(C13,"-儿童（加收）","")),0)+N13 -> 12 | AI13: =IF(AF13>0,_xlfn.MAXIFS(O:O,C:C,SUBSTITUTE(C13,"-儿童（加收）","")),0)+O13 -> 11.5 | AJ13: =IF(AF13>0,_xlfn.MAXIFS(P:P,C:C,SUBSTITUTE(C13,"-儿童（加收）","")),0)+P13 -> 11
C14: 视力检查费（特殊） | N14: 12 | O14: 11.5 | P14: 11 | V14: 003103000210000-31030002101 | W14: 31030002101 | X14: 对比敏感度检查（使用微机处理） | AA14: 次 | AB14: 使用微机处理 | AC14: 15.8 | AD14: 15 | AE14: 12.8 | AF14: =IFERROR(FIND("-儿童（加收）",C14,1),0) -> 0 | AG14: =SUBSTITUTE(C14,"-儿童（加收）","") -> 视力检查费（特殊） | AH14: =IF(AF14>0,_xlfn.MAXIFS(N:N,C:C,SUBSTITUTE(C14,"-儿童（加收）","")),0)+N14 -> 12 | AI14: =IF(AF14>0,_xlfn.MAXIFS(O:O,C:C,SUBSTITUTE(C14,"-儿童（加收）","")),0)+O14 -> 11.5 | AJ14: =IF(AF14>0,_xlfn.MAXIFS(P:P,C:C,SUBSTITUTE(C14,"-儿童（加收）","")),0)+P14 -> 11
C15: 视力检查费（特殊） | N15: 12 | O15: 11.5 | P15: 11 | V15: 003103000220000-310300022 | W15: 310300022 | X15: 暗适应测定 | Y15: 含图形及报告 | AA15: 次 | AC15: 15.8 | AD15: 15 | AE15: 12.8 | AF15: =IFERROR(FIND("-儿童（加收）",C15,1),0) -> 0 | AG15: =SUBSTITUTE(C15,"-儿童（加收）","") -> 视力检查费（特殊） | AH15: =IF(AF15>0,_xlfn.MAXIFS(N:N,C:C,SUBSTITUTE(C15,"-儿童（加收）","")),0)+N15 -> 12 | AI15: =IF(AF15>0,_xlfn.MAXIFS(O:O,C:C,SUBSTITUTE(C15,"-儿童（加收）","")),0)+O15 -> 11.5 | AJ15: =IF(AF15>0,_xlfn.MAXIFS(P:P,C:C,SUBSTITUTE(C15,"-儿童（加收）","")),0)+P15 -> 11
C16: 视力检查费（特殊） | N16: 12 | O16: 11.5 | P16: 11 | V16: 003103000230000-310300023 | W16: 310300023 | X16: 明适应测定 | AA16: 次 | AC16: 15.8 | AD16: 15 | AE16: 12.8 | AF16: =IFERROR(FIND("-儿童（加收）",C16,1),0) -> 0 | AG16: =SUBSTITUTE(C16,"-儿童（加收）","") -> 视力检查费（特殊） | AH16: =IF(AF16>0,_xlfn.MAXIFS(N:N,C:C,SUBSTITUTE(C16,"-儿童（加收）","")),0)+N16 -> 12 | AI16: =IF(AF16>0,_xlfn.MAXIFS(O:O,C:C,SUBSTITUTE(C16,"-儿童（加收）","")),0)+O16 -> 11.5 | AJ16: =IF(AF16>0,_xlfn.MAXIFS(P:P,C:C,SUBSTITUTE(C16,"-儿童（加收）","")),0)+P16 -> 11
A17: 3 | B17: 012403000030000 | C17: 散瞳验光费 | D17: 通过散瞳、电脑、检影等不同方式测量眼睛的屈光状态。 | E17: 所定价格涵盖散瞳、电脑及人工测视力、测瞳距、确定屈光度数、记录、出具结果报告等步骤所需的人力资源和基本物质资源消耗。 | G17: 次 | H17: 8 | I17: 8 | J17: 7.2693567 | K17: 6.0744562 | L17: 5.2666794 | N17: 7.5 | O17: 7 | P17: 6.5 | Q17: 医保 | T17: 理顺 | U17: 同质化项目，缩小价差 | V17: 003103000070000-310300007 | W17: 310300007 | X17: 验光 | Y17: 包括检影，散瞳，云雾试验，试镜 | AA17: 项 | AB17: 每增加一项基层加收1.7元，县级医院加收2元，市级医院加收2.1元 | AC17: 5.3 | AD17: 5 | AE17: 4.3 | AF17: =IFERROR(FIND("-儿童（加收）",C17,1),0) -> 0 | AG17: =SUBSTITUTE(C17,"-儿童（加收）","") -> 散瞳验光费 | AH17: =IF(AF17>0,_xlfn.MAXIFS(N:N,C:C,SUBSTITUTE(C17,"-儿童（加收）","")),0)+N17 -> 7.5 | AI17: =IF(AF17>0,_xlfn.MAXIFS(O:O,C:C,SUBSTITUTE(C17,"-儿童（加收）","")),0)+O17 -> 7 | AJ17: =IF(AF17>0,_xlfn.MAXIFS(P:P,C:C,SUBSTITUTE(C17,"-儿童（加收）","")),0)+P17 -> 6.5
C18: 散瞳验光费 | N18: 7.5 | O18: 7 | P18: 6.5 | V18: 003103000070001-31030000701 | W18: 31030000701 | X18: 验光（增加一项加收） | AA18: 项 | AB18: 每增加一项加收 | AC18: 2.1 | AD18: 2 | AE18: 1.7 | AF18: =IFERROR(FIND("-儿童（加收）",C18,1),0) -> 0 | AG18: =SUBSTITUTE(C18,"-儿童（加收）","") -> 散瞳验光费 | AH18: =IF(AF18>0,_xlfn.MAXIFS(N:N,C:C,SUBSTITUTE(C18,"-儿童（加收）","")),0)+N18 -> 7.5 | AI18: =IF(AF18>0,_xlfn.MAXIFS(O:O,C:C,SUBSTITUTE(C18,"-儿童（加收）","")),0)+O18 -> 7 | AJ18: =IF(AF18>0,_xlfn.MAXIFS(P:P,C:C,SUBSTITUTE(C18,"-儿童（加收）","")),0)+P18 -> 6.5
A19: 5 | B19: 012403000050000 | C19: 眼压检查费 | D19: 通过接触或非接触方式进行眼压测量。 | E19: 所定价格涵盖检查、测量、记录、出具结果报告等步骤所需的人力资源和基本物质资源消耗。 | F19: 眼压日曲线描记按照眼压检查实际开展次数收费，每日单侧收费不超过4个计价单位。 | G19: 单侧 | H19: 8 | I19: 7 | J19: 8.3960273 | K19: 7.9476972 | L19: 6.7751148 | N19: 8 | O19: 7 | P19: 6.5 | Q19: 医保 | T19: 理顺 | U19: 平移后按不超过省级下调拟定 | V19: 003103000270000-310300027 | W19: 310300027 | X19: 眼压检查 | Y19: 包括Schiotz眼压计法，电眼压计法 | AA19: 次 | AB19: 非接触眼压计法、压平眼压计法分别加收100% | AC19: 4.2 | AD19: 4 | AE19: 3.4 | AF19: =IFERROR(FIND("-儿童（加收）",C19,1),0) -> 0 | AG19: =SUBSTITUTE(C19,"-儿童（加收）","") -> 眼压检查费 | AH19: =IF(AF19>0,_xlfn.MAXIFS(N:N,C:C,SUBSTITUTE(C19,"-儿童（加收）","")),0)+N19 -> 8 | AI19: =IF(AF19>0,_xlfn.MAXIFS(O:O,C:C,SUBSTITUTE(C19,"-儿童（加收）","")),0)+O19 -> 7 | AJ19: =IF(AF19>0,_xlfn.MAXIFS(P:P,C:C,SUBSTITUTE(C19,"-儿童（加收）","")),0)+P19 -> 6.5
C20: 眼压检查费 | N20: 8 | O20: 7 | P20: 6.5 | V20: 003103000270200-31030002701 | W20: 31030002701 | X20: 眼压检查（非接触眼压计法） | AA20: 次 | AB20: 非接触眼压计法 | AC20: 8.4 | AD20: 8 | AE20: 6.8 | AF20: =IFERROR(FIND("-儿童（加收）",C20,1),0) -> 0 | AG20: =SUBSTITUTE(C20,"-儿童（加收）","") -> 眼压检查费 | AH20: =IF(AF20>0,_xlfn.MAXIFS(N:N,C:C,SUBSTITUTE(C20,"-儿童（加收）","")),0)+N20 -> 8 | AI20: =IF(AF20>0,_xlfn.MAXIFS(O:O,C:C,SUBSTITUTE(C20,"-儿童（加收）","")),0)+O20 -> 7 | AJ20: =IF(AF20>0,_xlfn.MAXIFS(P:P,C:C,SUBSTITUTE(C20,"-儿童（加收）","")),0)+P20 -> 6.5
C21: 眼压检查费 | N21: 8 | O21: 7 | P21: 6.5 | V21: 003103000270400-31030002702 | W21: 31030002702 | X21: 眼压检查（压平眼压计法） | AA21: 次 | AB21: 压平眼压计法 | AC21: 8.4 | AD21: 8 | AE21: 6.8 | AF21: =IFERROR(FIND("-儿童（加收）",C21,1),0) -> 0 | AG21: =SUBSTITUTE(C21,"-儿童（加收）","") -> 眼压检查费 | AH21: =IF(AF21>0,_xlfn.MAXIFS(N:N,C:C,SUBSTITUTE(C21,"-儿童（加收）","")),0)+N21 -> 8 | AI21: =IF(AF21>0,_xlfn.MAXIFS(O:O,C:C,SUBSTITUTE(C21,"-儿童（加收）","")),0)+O21 -> 7 | AJ21: =IF(AF21>0,_xlfn.MAXIFS(P:P,C:C,SUBSTITUTE(C21,"-儿童（加收）","")),0)+P21 -> 6.5
C22: 眼压检查费 | N22: 8 | O22: 7 | P22: 6.5 | V22: 003103000290000-310300029 | W22: 310300029 | X22: 眼压描记 | AA22: 次 | AC22: 10.5 | AD22: 10 | AE22: 8.5 | AF22: =IFERROR(FIND("-儿童（加收）",C22,1),0) -> 0 | AG22: =SUBSTITUTE(C22,"-儿童（加收）","") -> 眼压检查费 | AH22: =IF(AF22>0,_xlfn.MAXIFS(N:N,C:C,SUBSTITUTE(C22,"-儿童（加收）","")),0)+N22 -> 8 | AI22: =IF(AF22>0,_xlfn.MAXIFS(O:O,C:C,SUBSTITUTE(C22,"-儿童（加收）","")),0)+O22 -> 7 | AJ22: =IF(AF22>0,_xlfn.MAXIFS(P:P,C:C,SUBSTITUTE(C22,"-儿童（加收）","")),0)+P22 -> 6.5
C23: 眼压检查费 | N23: 8 | O23: 7 | P23: 6.5 | V23: 003103000280000-310300028 | W23: 310300028 | X23: 眼压日曲线检查 | AA23: 次 | AC23: 15.8 | AD23: 15 | AE23: 12.8 | AF23: =IFERROR(FIND("-儿童（加收）",C23,1),0) -> 0 | AG23: =SUBSTITUTE(C23,"-儿童（加收）","") -> 眼压检查费 | AH23: =IF(AF23>0,_xlfn.MAXIFS(N:N,C:C,SUBSTITUTE(C23,"-儿童（加收）","")),0)+N23 -> 8 | AI23: =IF(AF23>0,_xlfn.MAXIFS(O:O,C:C,SUBSTITUTE(C23,"-儿童（加收）","")),0)+O23 -> 7 | AJ23: =IF(AF23>0,_xlfn.MAXIFS(P:P,C:C,SUBSTITUTE(C23,"-儿童（加收）","")),0)+P23 -> 6.5
A24: 6 | B24: 012403000060000 | C24: 眼压检查费（青光眼激发） | D24: 指通过各种方式激发眼压升高后进行眼压测量。 | E24: 所定价格涵盖试验准备、眼压测量、诱导、再次测量、记录、出具结果报告等步骤所需的人力资源和基本物质资源消耗。 | F24: 不得与眼压检查费同时收取。 | G24: 次 | H24: 15 | I24: 13.5 | J24: 15.8 | K24: 15 | L24: 12.8 | N24: 15 | O24: 13.5 | P24: 12 | Q24: 医保 | T24: 理顺，降低 | U24: 平移后按不超过省级下调拟定，同质化检查项目持平省级 | V24: 003103000370000-310300037 | W24: 310300037 | X24: 青光眼诱导试验 | Y24: 包括饮水，暗室，妥拉苏林等 | AA24: 次 | AC24: 15.8 | AD24: 15 | AE24: 12.8 | AF24: =IFERROR(FIND("-儿童（加收）",C24,1),0) -> 0 | AG24: =SUBSTITUTE(C24,"-儿童（加收）","") -> 眼压检查费（青光眼激发） | AH24: =IF(AF24>0,_xlfn.MAXIFS(N:N,C:C,SUBSTITUTE(C24,"-儿童（加收）","")),0)+N24 -> 15 | AI24: =IF(AF24>0,_xlfn.MAXIFS(O:O,C:C,SUBSTITUTE(C24,"-儿童（加收）","")),0)+O24 -> 13.5 | AJ24: =IF(AF24>0,_xlfn.MAXIFS(P:P,C:C,SUBSTITUTE(C24,"-儿童（加收）","")),0)+P24 -> 12
A25: 7 | B25: 012403000070000 | C25: 色觉检查费 | D25: 通过不同方式检查色弱、色盲情况。 | E25: 所定价格涵盖检查、记录、出具结果报告等步骤所需的人力资源和基本物质资源消耗。 | G25: 次 | H25: 5 | I25: 5 | J25: 5.3 | K25: 5 | L25: 4.3 | N25: 5 | O25: 5 | P25: 4.3 | Q25: 医保 | T25: 理顺，降低 | U25: 平移后市级按不超过省级下调拟定 | V25: 003103000200000-310300020 | W25: 310300020 | X25: 色觉检查 | Y25: 包括普通图谱法，FM-100Hue测试盒法，色觉仪法 | AA25: 次 | AC25: 5.3 | AD25: 5 | AE25: 4.3 | AF25: =IFERROR(FIND("-儿童（加收）",C25,1),0) -> 0 | AG25: =SUBSTITUTE(C25,"-儿童（加收）","") -> 色觉检查费 | AH25: =IF(AF25>0,_xlfn.MAXIFS(N:N,C:C,SUBSTITUTE(C25,"-儿童（加收）","")),0)+N25 -> 5 | AI25: =IF(AF25>0,_xlfn.MAXIFS(O:O,C:C,SUBSTITUTE(C25,"-儿童（加收）","")),0)+O25 -> 5 | AJ25: =IF(AF25>0,_xlfn.MAXIFS(P:P,C:C,SUBSTITUTE(C25,"-儿童（加收）","")),0)+P25 -> 4.3
A26: 8 | B26: 012403000080000 | C26: 视野检查费 | D26: 通过各种方式对视野进行评估。 | E26: 所定价格涵盖应用视野检查设备、记录、出具结果报告等步骤所需的人力资源和基本物质资源消耗。 | G26: 单侧 | H26: 30 | I26: 27 | J26: 30.81491 | K26: 29.816303 | L26: 16.425267 | N26: 30 | O26: 27 | P26: 22 | Q26: 医保 | T26: 理顺 | U26: 平移后市县按不超过省级下调拟定，基层按比价上调，同质化检查项目持平省级 | V26: 003103000050000-310300005 | W26: 310300005 | X26: 视野检查 | Y26: 普通视野计 | AA26: 次（单眼） | AB26: 电脑视野计、动态(Goldmann)视野计加收200% | AC26: 10.5 | AD26: 10 | AE26: 8.5 | AF26: =IFERROR(FIND("-儿童（加收）",C26,1),0) -> 0 | AG26: =SUBSTITUTE(C26,"-儿童（加收）","") -> 视野检查费 | AH26: =IF(AF26>0,_xlfn.MAXIFS(N:N,C:C,SUBSTITUTE(C26,"-儿童（加收）","")),0)+N26 -> 30 | AI26: =IF(AF26>0,_xlfn.MAXIFS(O:O,C:C,SUBSTITUTE(C26,"-儿童（加收）","")),0)+O26 -> 27 | AJ26: =IF(AF26>0,_xlfn.MAXIFS(P:P,C:C,SUBSTITUTE(C26,"-儿童（加收）","")),0)+P26 -> 22
C27: 视野检查费 | N27: 30 | O27: 27 | P27: 22 | V27: 003103000050200-31030000501 | W27: 31030000501 | X27: 视野检查（电脑视野计） | AA27: 次（单眼） | AB27: 电脑视野计 | AC27: 31.5 | AD27: 30 | AE27: 25.5 | AF27: =IFERROR(FIND("-儿童（加收）",C27,1),0) -> 0 | AG27: =SUBSTITUTE(C27,"-儿童（加收）","") -> 视野检查费 | AH27: =IF(AF27>0,_xlfn.MAXIFS(N:N,C:C,SUBSTITUTE(C27,"-儿童（加收）","")),0)+N27 -> 30 | AI27: =IF(AF27>0,_xlfn.MAXIFS(O:O,C:C,SUBSTITUTE(C27,"-儿童（加收）","")),0)+O27 -> 27 | AJ27: =IF(AF27>0,_xlfn.MAXIFS(P:P,C:C,SUBSTITUTE(C27,"-儿童（加收）","")),0)+P27 -> 22
C28: 视野检查费 | N28: 30 | O28: 27 | P28: 22 | V28: 003103000050100-31030000502 | W28: 31030000502 | X28: 视野检查（动态Goldmann视野计） | AA28: 次（单眼） | AB28: 动态(Goldmann)视野计 | AC28: 31.5 | AD28: 30 | AE28: 25.5 | AF28: =IFERROR(FIND("-儿童（加收）",C28,1),0) -> 0 | AG28: =SUBSTITUTE(C28,"-儿童（加收）","") -> 视野检查费 | AH28: =IF(AF28>0,_xlfn.MAXIFS(N:N,C:C,SUBSTITUTE(C28,"-儿童（加收）","")),0)+N28 -> 30 | AI28: =IF(AF28>0,_xlfn.MAXIFS(O:O,C:C,SUBSTITUTE(C28,"-儿童（加收）","")),0)+O28 -> 27 | AJ28: =IF(AF28>0,_xlfn.MAXIFS(P:P,C:C,SUBSTITUTE(C28,"-儿童（加收）","")),0)+P28 -> 22
A29: 9 | B29: 012403000090000 | C29: 泪液分泌功能测定费 | D29: 通过各种方式对泪液分泌功能进行测定。 | E29: 所定价格涵盖放置纸条、测定滤纸浸湿长度、记录并分析结果等步骤所需的人力资源和基本物质资源消耗。 | G29: 单侧 | H29: 8 | I29: 7 | J29: 8.4 | K29: 8 | L29: 6.8 | N29: 8 | O29: 7 | P29: 6 | Q29: 医保 | T29: 理顺 | U29: 平移后按不超过省级下调拟定，同质化检查项目持平省级 | V29: 003103000350000-310300035 | W29: 310300035 | X29: 泪液分泌功能测定 | AA29: 次 | AC29: 8.4 | AD29: 8 | AE29: 6.8 | AF29: =IFERROR(FIND("-儿童（加收）",C29,1),0) -> 0 | AG29: =SUBSTITUTE(C29,"-儿童（加收）","") -> 泪液分泌功能测定费 | AH29: =IF(AF29>0,_xlfn.MAXIFS(N:N,C:C,SUBSTITUTE(C29,"-儿童（加收）","")),0)+N29 -> 8 | AI29: =IF(AF29>0,_xlfn.MAXIFS(O:O,C:C,SUBSTITUTE(C29,"-儿童（加收）","")),0)+O29 -> 7 | AJ29: =IF(AF29>0,_xlfn.MAXIFS(P:P,C:C,SUBSTITUTE(C29,"-儿童（加收）","")),0)+P29 -> 6
A30: 10 | B30: 012403000100000 | C30: 泪膜分析测定费 | D30: 通过各种方式对泪膜进行分析测定。 | E30: 所定价格涵盖设备准备、检查、记录、分析、出具结果报告等步骤所需的人力资源和基本物质资源消耗。 | G30: 单侧 | H30: 10 | I30: 9 | J30: 10.5 | K30: 10 | L30: 8.5 | N30: 10 | O30: 9 | P30: 8 | Q30: 医保 | T30: 理顺 | U30: 平移后按不超过省级下调拟定，同质化检查项目持平省级 | V30: 003103000340000-310300034 | W30: 310300034 | X30: 泪膜破裂时间测定 | AA30: 次 | AC30: 10.5 | AD30: 10 | AE30: 8.5 | AF30: =IFERROR(FIND("-儿童（加收）",C30,1),0) -> 0 | AG30: =SUBSTITUTE(C30,"-儿童（加收）","") -> 泪膜分析测定费 | AH30: =IF(AF30>0,_xlfn.MAXIFS(N:N,C:C,SUBSTITUTE(C30,"-儿童（加收）","")),0)+N30 -> 10 | AI30: =IF(AF30>0,_xlfn.MAXIFS(O:O,C:C,SUBSTITUTE(C30,"-儿童（加收）","")),0)+O30 -> 9 | AJ30: =IF(AF30>0,_xlfn.MAXIFS(P:P,C:C,SUBSTITUTE(C30,"-儿童（加收）","")),0)+P30 -> 8
A31: 11 | B31: 012403000110000 | C31: 复视检查费 | D31: 通过各种方式对复视情况进行检查。 | E31: 所定价格涵盖设备准备、检查、记录、分析、出具结果报告等步骤所需的人力资源和基本物质资源消耗。 | G31: 次 | H31: 8 | I31: 7 | J31: 7.6968722 | K31: 7.9883268 | L31: 6.8 | N31: 8 | O31: 7 | P31: 6 | Q31: 医保 | T31: 理顺 | U31: 同质化检查项目持平省级 | V31: 003103000160000-310300016 | W31: 310300016 | X31: 黑氏（Hess）屏检查 | AA31: 次 | AC31: 8.4 | AD31: 8 | AE31: 6.8 | AF31: =IFERROR(FIND("-儿童（加收）",C31,1),0) -> 0 | AG31: =SUBSTITUTE(C31,"-儿童（加收）","") -> 复视检查费 | AH31: =IF(AF31>0,_xlfn.MAXIFS(N:N,C:C,SUBSTITUTE(C31,"-儿童（加收）","")),0)+N31 -> 8 | AI31: =IF(AF31>0,_xlfn.MAXIFS(O:O,C:C,SUBSTITUTE(C31,"-儿童（加收）","")),0)+O31 -> 7 | AJ31: =IF(AF31>0,_xlfn.MAXIFS(P:P,C:C,SUBSTITUTE(C31,"-儿童（加收）","")),0)+P31 -> 6
C32: 复视检查费 | N32: 8 | O32: 7 | P32: 6 | V32: 003103000120000-310300012 | W32: 310300012 | X32: 复视检查 | AA32: 次 | AC32: 8.4 | AD32: 8 | AE32: 6.8 | AF32: =IFERROR(FIND("-儿童（加收）",C32,1),0) -> 0 | AG32: =SUBSTITUTE(C32,"-儿童（加收）","") -> 复视检查费 | AH32: =IF(AF32>0,_xlfn.MAXIFS(N:N,C:C,SUBSTITUTE(C32,"-儿童（加收）","")),0)+N32 -> 8 | AI32: =IF(AF32>0,_xlfn.MAXIFS(O:O,C:C,SUBSTITUTE(C32,"-儿童（加收）","")),0)+O32 -> 7 | AJ32: =IF(AF32>0,_xlfn.MAXIFS(P:P,C:C,SUBSTITUTE(C32,"-儿童（加收）","")),0)+P32 -> 6
C33: 复视检查费 | N33: 8 | O33: 7 | P33: 6 | V33: 003103000150000-310300015 | W33: 310300015 | X33: 线状镜检查 | AA33: 次 | AC33: 5.3 | AD33: 5 | AE33: 4.3 | AF33: =IFERROR(FIND("-儿童（加收）",C33,1),0) -> 0 | AG33: =SUBSTITUTE(C33,"-儿童（加收）","") -> 复视检查费 | AH33: =IF(AF33>0,_xlfn.MAXIFS(N:N,C:C,SUBSTITUTE(C33,"-儿童（加收）","")),0)+N33 -> 8 | AI33: =IF(AF33>0,_xlfn.MAXIFS(O:O,C:C,SUBSTITUTE(C33,"-儿童（加收）","")),0)+O33 -> 7 | AJ33: =IF(AF33>0,_xlfn.MAXIFS(P:P,C:C,SUBSTITUTE(C33,"-儿童（加收）","")),0)+P33 -> 6
A34: 12 | B34: 012403000120000 | C34: 斜视度测定费 | D34: 通过各种方式测定斜视度数。 | E34: 所定价格涵盖设备准备、检查、记录、分析、出具结果报告等步骤所需的人力资源和基本物质资源消耗。 | F34: 每日计费不超过3次。 | G34: 次 | H34: 9 | I34: 8 | J34: 8.9290639 | K34: 7.6541327 | L34: 6.7984619 | N34: 9 | O34: 8 | P34: 7 | Q34: 医保 | T34: 平移取整 | U34: 加权平移取整，同质化检查项目持平省级 | V34: 003103000130000-310300013 | W34: 310300013 | X34: 斜视度测定 | Y34: 含九个注视方向双眼分别注视时的斜度，看远及看近 | AA34: 次 | AC34: 8.4 | AD34: 8 | AE34: 6.8 | AF34: =IFERROR(FIND("-儿童（加收）",C34,1),0) -> 0 | AG34: =SUBSTITUTE(C34,"-儿童（加收）","") -> 斜视度测定费 | AH34: =IF(AF34>0,_xlfn.MAXIFS(N:N,C:C,SUBSTITUTE(C34,"-儿童（加收）","")),0)+N34 -> 9 | AI34: =IF(AF34>0,_xlfn.MAXIFS(O:O,C:C,SUBSTITUTE(C34,"-儿童（加收）","")),0)+O34 -> 8 | AJ34: =IF(AF34>0,_xlfn.MAXIFS(P:P,C:C,SUBSTITUTE(C34,"-儿童（加收）","")),0)+P34 -> 7
C35: 斜视度测定费 | N35: 9 | O35: 8 | P35: 7 | V35: 003103000140000-310300014 | W35: 310300014 | X35: 三棱镜检查 | AA35: 次 | AC35: 10.5 | AD35: 10 | AE35: 8.5 | AF35: =IFERROR(FIND("-儿童（加收）",C35,1),0) -> 0 | AG35: =SUBSTITUTE(C35,"-儿童（加收）","") -> 斜视度测定费 | AH35: =IF(AF35>0,_xlfn.MAXIFS(N:N,C:C,SUBSTITUTE(C35,"-儿童（加收）","")),0)+N35 -> 9 | AI35: =IF(AF35>0,_xlfn.MAXIFS(O:O,C:C,SUBSTITUTE(C35,"-儿童（加收）","")),0)+O35 -> 8 | AJ35: =IF(AF35>0,_xlfn.MAXIFS(P:P,C:C,SUBSTITUTE(C35,"-儿童（加收）","")),0)+P35 -> 7
C36: 斜视度测定费 | N36: 9 | O36: 8 | P36: 7 | V36: 003103000240000-310300024 | W36: 310300024 | X36: 正切尺检查 | AA36: 次 | AC36: 3.2 | AD36: 3 | AE36: 2.6 | AF36: =IFERROR(FIND("-儿童（加收）",C36,1),0) -> 0 | AG36: =SUBSTITUTE(C36,"-儿童（加收）","") -> 斜视度测定费 | AH36: =IF(AF36>0,_xlfn.MAXIFS(N:N,C:C,SUBSTITUTE(C36,"-儿童（加收）","")),0)+N36 -> 9 | AI36: =IF(AF36>0,_xlfn.MAXIFS(O:O,C:C,SUBSTITUTE(C36,"-儿童（加收）","")),0)+O36 -> 8 | AJ36: =IF(AF36>0,_xlfn.MAXIFS(P:P,C:C,SUBSTITUTE(C36,"-儿童（加收）","")),0)+P36 -> 7
C37: 斜视度测定费 | N37: 9 | O37: 8 | P37: 7 | V37: 003103000720000-310300072 | W37: 310300072 | X37: 马氏（Maddox）杆试验 | AA37: 次 | AC37: 5.3 | AD37: 5 | AE37: 4.3 | AF37: =IFERROR(FIND("-儿童（加收）",C37,1),0) -> 0 | AG37: =SUBSTITUTE(C37,"-儿童（加收）","") -> 斜视度测定费 | AH37: =IF(AF37>0,_xlfn.MAXIFS(N:N,C:C,SUBSTITUTE(C37,"-儿童（加收）","")),0)+N37 -> 9 | AI37: =IF(AF37>0,_xlfn.MAXIFS(O:O,C:C,SUBSTITUTE(C37,"-儿童（加收）","")),0)+O37 -> 8 | AJ37: =IF(AF37>0,_xlfn.MAXIFS(P:P,C:C,SUBSTITUTE(C37,"-儿童（加收）","")),0)+P37 -> 7
A38: 13 | B38: 012403000130000 | C38: 角膜地形图检查费 | D38: 通过各种方式或设备检测角膜形态。 | E38: 所定价格涵盖设备准备、扫描、记录、分析、出具结果报告等步骤所需的人力资源和基本物质资源消耗。 | G38: 单侧 | H38: 77 | I38: 69 | J38: 73.5 | K38: 70 | L38: 59.5 | N38: 74 | O38: 69 | P38: 60 | Q38: 医保 | T38: 理顺 | U38: 平移后取整，县级按不超过省级下调拟定 | V38: 003103000400000-310300040 | W38: 310300040 | X38: 角膜地形图检查 | AA38: 次（单眼） | AC38: 73.5 | AD38: 70 | AE38: 59.5 | AF38: =IFERROR(FIND("-儿童（加收）",C38,1),0) -> 0 | AG38: =SUBSTITUTE(C38,"-儿童（加收）","") -> 角膜地形图检查费 | AH38: =IF(AF38>0,_xlfn.MAXIFS(N:N,C:C,SUBSTITUTE(C38,"-儿童（加收）","")),0)+N38 -> 74 | AI38: =IF(AF38>0,_xlfn.MAXIFS(O:O,C:C,SUBSTITUTE(C38,"-儿童（加收）","")),0)+O38 -> 69 | AJ38: =IF(AF38>0,_xlfn.MAXIFS(P:P,C:C,SUBSTITUTE(C38,"-儿童（加收）","")),0)+P38 -> 60
A39: 分项 | B39: 012403000130000 | C39: 角膜地形图检查费-单独行角膜厚度检查 | G39: 单侧 | H39: 16.5 | I39: 15 | J39: 15.75 | K39: 15 | L39: 12.75 | N39: 16 | O39: 15 | P39: 13 | Q39: 医保 | U39: 计价单位改变，单次（一般双眼检查）改为单侧，平移取整 | V39: 003103000420000-310300042 | W39: 310300042 | X39: 角膜厚度检查 | Y39: 包括裂隙灯法，超声法 | AA39: 次 | AC39: 31.5 | AD39: 30 | AE39: 25.5 | AF39: =IFERROR(FIND("-儿童（加收）",C39,1),0) -> 0 | AG39: =SUBSTITUTE(C39,"-儿童（加收）","") -> 角膜地形图检查费-单独行角膜厚度检查 | AH39: =IF(AF39>0,_xlfn.MAXIFS(N:N,C:C,SUBSTITUTE(C39,"-儿童（加收）","")),0)+N39 -> 16 | AI39: =IF(AF39>0,_xlfn.MAXIFS(O:O,C:C,SUBSTITUTE(C39,"-儿童（加收）","")),0)+O39 -> 15 | AJ39: =IF(AF39>0,_xlfn.MAXIFS(P:P,C:C,SUBSTITUTE(C39,"-儿童（加收）","")),0)+P39 -> 13
A40: 14 | B40: 012403000140000 | C40: 角膜曲率测量费 | D40: 通过各种方式或设备测量角膜曲率。 | E40: 所定价格涵盖设备准备、测量、记录、分析、出具结果报告等步骤所需的人力资源和基本物质资源消耗。 | G40: 单侧 | H40: 3 | I40: 2.5 | J40: 2.65 | K40: 2.5 | L40: 2.15 | N40: 3 | O40: 2.5 | P40: 2 | Q40: 医保 | T40: 平移取整 | U40: 计价单位改变，单次（一般双眼检查）改为单侧，平移取整，同质化检查项目持平省级 | V40: 003103000390000-310300039 | W40: 310300039 | X40: 角膜曲率测量 | AA40: 次 | AC40: 5.3 | AD40: 5 | AE40: 4.3 | AF40: =IFERROR(FIND("-儿童（加收）",C40,1),0) -> 0 | AG40: =SUBSTITUTE(C40,"-儿童（加收）","") -> 角膜曲率测量费 | AH40: =IF(AF40>0,_xlfn.MAXIFS(N:N,C:C,SUBSTITUTE(C40,"-儿童（加收）","")),0)+N40 -> 3 | AI40: =IF(AF40>0,_xlfn.MAXIFS(O:O,C:C,SUBSTITUTE(C40,"-儿童（加收）","")),0)+O40 -> 2.5 | AJ40: =IF(AF40>0,_xlfn.MAXIFS(P:P,C:C,SUBSTITUTE(C40,"-儿童（加收）","")),0)+P40 -> 2
...

Sheet 改变收费方式，测算医疗费用项目
A1: 现行收费方式 | N1: 立项指南收费方式
A2: 国家结算编码 | B2: 项目代码 | C2: 项目名称 | D2: 项目内涵 | E2: 除外内容 | F2: 计价单位 | G2: 说明 | H2: 省属三甲价格（元） | I2: 省属三甲以下价格（元） | J2: 价格 (市级) | K2: 价格 (县级) | L2: 价格 (基层) | M2: 医保属性 | N2: 项目代码 | O2: 项目名称 | P2: 服务产出 | Q2: 价格构成 | R2: 计价说明 | S2: 计价单位 | T2: 拟定价格 (市级) | U2: 拟定价格 (县级) | V2: 拟定价格 (基层) | W2: 改变后价格 (市级) | X2: 改变后价格 (县级) | Y2: 改变后价格 (基层)
A3: 003103000450000-310300045 | B3: 310300045 | C3: 人工晶体度数测量 | F3: 次 | H3: 22 | I3: 20 | J3: 21 | K3: 20 | L3: 17 | M3: 医保 | N3: 012403000140000 | O3: 角膜曲率测量费 | P3: 通过各种方式或设备测量角膜曲率。 | Q3: 所定价格涵盖设备准备、测量、记录、分析、出具结果报告等步骤所需的人力资源和基本物质资源消耗。 | S3: 单侧 | T3: =VLOOKUP(O3,眼科项目!$C$3:$O$485,11,FALSE) -> 3 | U3: =VLOOKUP(O3,眼科项目!$C$3:$O$485,12,FALSE) -> 2.5 | V3: =VLOOKUP(O3,眼科项目!$C$3:$O$485,13,FALSE) -> 2 | W3: =SUM(T3:T5) -> 16.9 | X3: =SUM(U3:U5) -> 14.5 | Y3: =SUM(V3:V5) -> 12.6
N4: 012403000270000 | O4: 眼轴测量费 | P4: 应用各种检查仪器测定眼轴。 | Q4: 所定价格涵盖消毒、设备准备、测量、重复多次、记录、分析、出具结果报告等步骤所需的人力资源和基本物质资源消耗。 | S4: 单侧 | T4: =VLOOKUP(O4,眼科项目!$C$3:$O$485,11,FALSE) -> 8.5 | U4: =VLOOKUP(O4,眼科项目!$C$3:$O$485,12,FALSE) -> 7 | V4: =VLOOKUP(O4,眼科项目!$C$3:$O$485,13,FALSE) -> 6.3
N5: 012403000310000 | O5: 裂隙灯检查费 | P5: 通过应用裂隙灯显微镜进行各类检查。 | Q5: 所定价格涵盖摆位、设备准备、测试、记录、分析、出具结果报告等步骤所需的人力资源和基本物质资源消耗。 | S5: 次 | T5: =VLOOKUP(O5,眼科项目!$C$3:$O$485,11,FALSE) -> 5.4 | U5: =VLOOKUP(O5,眼科项目!$C$3:$O$485,12,FALSE) -> 5 | V5: =VLOOKUP(O5,眼科项目!$C$3:$O$485,13,FALSE) -> 4.3
A6: 003103000090000-310300009 | B6: 310300009 | C6: 隐形眼镜配置 | D6: 含验光、角膜曲率测量、泪液分泌功能(Schirmer)测定 | F6: 次 | H6: 15 | I6: 14 | J6: 15.8 | K6: 15 | L6: 12.8 | N6: 012403000040000 | O6: 显然验光费 | P6: 通过反复插试镜片，确定矫正视力度数。 | Q6: 所定价格涵盖戴试镜架、插试镜片、调整度数、记录、出具结果报告等步骤所需的人力资源和基本物质资源消耗。 | S6: 次 | T6: =VLOOKUP(O6,眼科项目!$C$3:$O$485,11,FALSE) -> 3.8 | U6: =VLOOKUP(O6,眼科项目!$C$3:$O$485,12,FALSE) -> 3.5 | V6: =VLOOKUP(O6,眼科项目!$C$3:$O$485,13,FALSE) -> 3.3 | W6: =SUM(T6:T8) -> 14.8 | X6: =SUM(U6:U8) -> 13 | Y6: =SUM(V6:V8) -> 11.3
N7: 012403000140000 | O7: 角膜曲率测量费 | P7: 通过各种方式或设备测量角膜曲率。 | Q7: 所定价格涵盖设备准备、测量、记录、分析、出具结果报告等步骤所需的人力资源和基本物质资源消耗。 | S7: 单侧 | T7: =VLOOKUP(O7,眼科项目!$C$3:$O$485,11,FALSE) -> 3 | U7: =VLOOKUP(O7,眼科项目!$C$3:$O$485,12,FALSE) -> 2.5 | V7: =VLOOKUP(O7,眼科项目!$C$3:$O$485,13,FALSE) -> 2
N8: 012403000090000 | O8: 泪液分泌功能测定费 | P8: 通过各种方式对泪液分泌功能进行测定。 | Q8: 所定价格涵盖放置纸条、测定滤纸浸湿长度、记录并分析结果等步骤所需的人力资源和基本物质资源消耗。 | S8: 单侧 | T8: =VLOOKUP(O8,眼科项目!$C$3:$O$485,11,FALSE) -> 8 | U8: =VLOOKUP(O8,眼科项目!$C$3:$O$485,12,FALSE) -> 7 | V8: =VLOOKUP(O8,眼科项目!$C$3:$O$485,13,FALSE) -> 6
A9: 003304060150000-330406015 | B9: 330406015 | C9: 白内障囊外摘除联合青光眼人工晶体植入术 | E9: 胶原膜 | F9: 次 | H9: 2880 | I9: 2590 | J9: 2480 | K9: 2230 | L9: 1900 | M9: 医保 | N9: 013304000010000 | O9: 晶状体摘除费 | P9: 通过超声乳化、娩核、晶状体切除或粉碎等各种方式完成病变晶状体摘除。 | Q9: 所定价格涵盖手术计划、术区准备、切开、晶状体取出、缝合及必要时染色等步骤所需的人力资源和基本物质资源消耗。 | R9: 晶体囊截开术三甲医院按330元，三甲以下医院按297元收取。 | S9: 单侧 | T9: =VLOOKUP(O9,眼科项目!$C$3:$O$485,11,FALSE) -> 1800 | U9: =VLOOKUP(O9,眼科项目!$C$3:$O$485,12,FALSE) -> 1650 | V9: =VLOOKUP(O9,眼科项目!$C$3:$O$485,13,FALSE) -> 1400 | W9: =T9+T10*0.5 -> 2510 | X9: =U9+U10*0.5 -> 2290 | Y9: =V9+V10*0.5 -> 1945
N10: 013304000030000 | O10: 人工晶状体植入费（常规） | S10: 单侧 | T10: =VLOOKUP(O10,眼科项目!$C$3:$O$485,11,FALSE) -> 1420 | U10: =VLOOKUP(O10,眼科项目!$C$3:$O$485,12,FALSE) -> 1280 | V10: =VLOOKUP(O10,眼科项目!$C$3:$O$485,13,FALSE) -> 1090
A11: 003304060150000-33040601501 | B11: 33040601501 | C11: 小儿白内障囊外摘除联合青光眼人工晶体植入术 | F11: 次 | H11: 3745 | I11: 3365 | J11: 3225 | K11: 2900 | L11: 2465 | M11: 医保 | N11: 013304000010000 | O11: 晶状体摘除费 | P11: 通过超声乳化、娩核、晶状体切除或粉碎等各种方式完成病变晶状体摘除。 | Q11: 所定价格涵盖手术计划、术区准备、切开、晶状体取出、缝合及必要时染色等步骤所需的人力资源和基本物质资源消耗。 | R11: 晶体囊截开术三甲医院按330元，三甲以下医院按297元收取。 | S11: 单侧 | T11: =VLOOKUP(O11,眼科项目!$C$3:$O$485,11,FALSE) -> 1800 | U11: =VLOOKUP(O11,眼科项目!$C$3:$O$485,12,FALSE) -> 1650 | V11: =VLOOKUP(O11,眼科项目!$C$3:$O$485,13,FALSE) -> 1400 | W11: =T11+T12+(T13+T14)*0.5 -> 3262.5 | X11: =U11+U12+(U13+U14)*0.5 -> 2977.5 | Y11: =V11+V12+(V13+V14)*0.5 -> 2527.5
N12: 013304000010001 | O12: 晶状体摘除费-儿童（加收） | S12: 单侧 | T12: =VLOOKUP(O12,眼科项目!$C$3:$O$485,11,FALSE) -> 540 | U12: =VLOOKUP(O12,眼科项目!$C$3:$O$485,12,FALSE) -> 495 | V12: =VLOOKUP(O12,眼科项目!$C$3:$O$485,13,FALSE) -> 420
N13: 013304000030000 | O13: 人工晶状体植入费（常规） | S13: 单侧 | T13: =VLOOKUP(O13,眼科项目!$C$3:$O$485,11,FALSE) -> 1420 | U13: =VLOOKUP(O13,眼科项目!$C$3:$O$485,12,FALSE) -> 1280 | V13: =VLOOKUP(O13,眼科项目!$C$3:$O$485,13,FALSE) -> 1090
N14: 013304000030001 | O14: 人工晶状体植入费（常规）-儿童（加收） | S14: 单侧 | T14: =VLOOKUP(O14,眼科项目!$C$3:$O$485,11,FALSE) -> 425 | U14: =VLOOKUP(O14,眼科项目!$C$3:$O$485,12,FALSE) -> 385 | V14: =VLOOKUP(O14,眼科项目!$C$3:$O$485,13,FALSE) -> 325
A15: 003304060170000-330406017 | B15: 330406017 | C15: 白内障摘除联合玻璃体切割术 | D15: 包括前路摘晶体，后路摘晶体 | E15: 玻璃体切割头、膨胀气体、硅油、重水 | F15: 次 | H15: 2880 | I15: 2590 | J15: 2530 | K15: 2280 | L15: 1940 | M15: 医保 | N15: 013304000010000 | O15: 晶状体摘除费 | P15: 通过超声乳化、娩核、晶状体切除或粉碎等各种方式完成病变晶状体摘除。 | Q15: 所定价格涵盖手术计划、术区准备、切开、晶状体取出、缝合及必要时染色等步骤所需的人力资源和基本物质资源消耗。 | R15: 晶体囊截开术三甲医院按330元，三甲以下医院按297元收取。 | S15: 单侧 | T15: =VLOOKUP(O15,眼科项目!$C$3:$O$485,11,FALSE) -> 1800 | U15: =VLOOKUP(O15,眼科项目!$C$3:$O$485,12,FALSE) -> 1650 | V15: =VLOOKUP(O15,眼科项目!$C$3:$O$485,13,FALSE) -> 1400 | W15: =T16+T15*0.5 -> 3430 | X15: =U16+U15*0.5 -> 3105 | Y15: =V16+V15*0.5 -> 2640
N16: 013304000070000 | O16: 玻璃体切除费 | P16: 通过各种手术方式切除玻璃体。 | Q16: 所定价格涵盖手术计划、术区准备、切开、穿刺、灌注、切除、必要时缝合等步骤所需的人力资源和基本物质资源消耗。 | S16: 单侧 | T16: =VLOOKUP(O16,眼科项目!$C$3:$O$485,11,FALSE) -> 2530 | U16: =VLOOKUP(O16,眼科项目!$C$3:$O$485,12,FALSE) -> 2280 | V16: =VLOOKUP(O16,眼科项目!$C$3:$O$485,13,FALSE) -> 1940
A17: 003304060170000-33040601701 | B17: 33040601701 | C17: 小儿白内障摘除联合玻璃体切割术 | F17: 次 | H17: 3745 | I17: 3365 | J17: 3290 | K17: 2965 | L17: 2520 | M17: 医保 | N17: 013304000010000 | O17: 晶状体摘除费 | P17: 通过超声乳化、娩核、晶状体切除或粉碎等各种方式完成病变晶状体摘除。 | Q17: 所定价格涵盖手术计划、术区准备、切开、晶状体取出、缝合及必要时染色等步骤所需的人力资源和基本物质资源消耗。 | R17: 晶体囊截开术三甲医院按330元，三甲以下医院按297元收取。 | S17: 单侧 | T17: =VLOOKUP(O17,眼科项目!$C$3:$O$485,11,FALSE) -> 1800 | U17: =VLOOKUP(O17,眼科项目!$C$3:$O$485,12,FALSE) -> 1650 | V17: =VLOOKUP(O17,眼科项目!$C$3:$O$485,13,FALSE) -> 1400 | W17: =T19+T20+(T17+T18)*0.5 -> 4460 | X17: =U19+U20+(U17+U18)*0.5 -> 4037.5 | Y17: =V19+V20+(V17+V18)*0.5 -> 3430
N18: 013304000010001 | O18: 晶状体摘除费-儿童（加收） | S18: 单侧 | T18: =VLOOKUP(O18,眼科项目!$C$3:$O$485,11,FALSE) -> 540 | U18: =VLOOKUP(O18,眼科项目!$C$3:$O$485,12,FALSE) -> 495 | V18: =VLOOKUP(O18,眼科项目!$C$3:$O$485,13,FALSE) -> 420
N19: 013304000070000 | O19: 玻璃体切除费 | P19: 通过各种手术方式切除玻璃体。 | Q19: 所定价格涵盖手术计划、术区准备、切开、穿刺、灌注、切除、必要时缝合等步骤所需的人力资源和基本物质资源消耗。 | S19: 单侧 | T19: =VLOOKUP(O19,眼科项目!$C$3:$O$485,11,FALSE) -> 2530 | U19: =VLOOKUP(O19,眼科项目!$C$3:$O$485,12,FALSE) -> 2280 | V19: =VLOOKUP(O19,眼科项目!$C$3:$O$485,13,FALSE) -> 1940
N20: 013304000070001 | O20: 玻璃体切除费-儿童（加收） | S20: 单侧 | T20: =VLOOKUP(O20,眼科项目!$C$3:$O$485,11,FALSE) -> 760 | U20: =VLOOKUP(O20,眼科项目!$C$3:$O$485,12,FALSE) -> 685 | V20: =VLOOKUP(O20,眼科项目!$C$3:$O$485,13,FALSE) -> 580
A21: 003304060060000-330406006 | B21: 330406006 | C21: 白内障囊外摘除+人工晶体植入术 | F21: 次 | H21: 1920 | I21: 1730 | J21: 1690 | K21: 1520 | L21: 1290 | M21: 医保 | N21: 013304000010000 | O21: 晶状体摘除费 | P21: 通过超声乳化、娩核、晶状体切除或粉碎等各种方式完成病变晶状体摘除。 | Q21: 所定价格涵盖手术计划、术区准备、切开、晶状体取出、缝合及必要时染色等步骤所需的人力资源和基本物质资源消耗。 | R21: 晶体囊截开术三甲医院按330元，三甲以下医院按297元收取。 | S21: 单侧 | T21: =VLOOKUP(O21,眼科项目!$C$3:$O$485,11,FALSE) -> 1800 | U21: =VLOOKUP(O21,眼科项目!$C$3:$O$485,12,FALSE) -> 1650 | V21: =VLOOKUP(O21,眼科项目!$C$3:$O$485,13,FALSE) -> 1400 | W21: =T21+T22*0.5 -> 2510 | X21: =U21+U22*0.5 -> 2290 | Y21: =V21+V22*0.5 -> 1945
A22: 003304060060000-330406006 | B22: 330406006 | C22: 白内障囊外摘除+人工晶体植入术 | F22: 次 | H22: 1920 | I22: 1730 | J22: 1690 | K22: 1520 | L22: 1290 | M22: 医保 | N22: 013304000030000 | O22: 人工晶状体植入费（常规） | S22: 单侧 | T22: =VLOOKUP(O22,眼科项目!$C$3:$O$485,11,FALSE) -> 1420 | U22: =VLOOKUP(O22,眼科项目!$C$3:$O$485,12,FALSE) -> 1280 | V22: =VLOOKUP(O22,眼科项目!$C$3:$O$485,13,FALSE) -> 1090
A23: 003304060060000-33040600601 | B23: 33040600601 | C23: 小儿白内障囊外摘除+人工晶体植入术 | F23: 次 | H23: 2495 | I23: 2250 | J23: 2195 | K23: 1975 | L23: 1680 | M23: 医保 | N23: 013304000010000 | O23: 晶状体摘除费 | P23: 通过超声乳化、娩核、晶状体切除或粉碎等各种方式完成病变晶状体摘除。 | Q23: 所定价格涵盖手术计划、术区准备、切开、晶状体取出、缝合及必要时染色等步骤所需的人力资源和基本物质资源消耗。 | R23: 晶体囊截开术三甲医院按330元，三甲以下医院按297元收取。 | S23: 单侧 | T23: =VLOOKUP(O23,眼科项目!$C$3:$O$485,11,FALSE) -> 1800 | U23: =VLOOKUP(O23,眼科项目!$C$3:$O$485,12,FALSE) -> 1650 | V23: =VLOOKUP(O23,眼科项目!$C$3:$O$485,13,FALSE) -> 1400 | W23: =T23+T24+(T25+T26)*0.5 -> 3262.5 | X23: =U23+U24+(U25+U26)*0.5 -> 2977.5 | Y23: =V23+V24+(V25+V26)*0.5 -> 2527.5
A24: 003304060060000-33040600601 | B24: 33040600601 | C24: 小儿白内障囊外摘除+人工晶体植入术 | F24: 次 | H24: 2495 | I24: 2250 | J24: 2195 | K24: 1975 | L24: 1680 | M24: 医保 | N24: 013304000010001 | O24: 晶状体摘除费-儿童（加收） | S24: 单侧 | T24: =VLOOKUP(O24,眼科项目!$C$3:$O$485,11,FALSE) -> 540 | U24: =VLOOKUP(O24,眼科项目!$C$3:$O$485,12,FALSE) -> 495 | V24: =VLOOKUP(O24,眼科项目!$C$3:$O$485,13,FALSE) -> 420
A25: 003304060060000-33040600601 | B25: 33040600601 | C25: 小儿白内障囊外摘除+人工晶体植入术 | F25: 次 | H25: 2495 | I25: 2250 | J25: 2195 | K25: 1975 | L25: 1680 | M25: 医保 | N25: 013304000030000 | O25: 人工晶状体植入费（常规） | S25: 单侧 | T25: =VLOOKUP(O25,眼科项目!$C$3:$O$485,11,FALSE) -> 1420 | U25: =VLOOKUP(O25,眼科项目!$C$3:$O$485,12,FALSE) -> 1280 | V25: =VLOOKUP(O25,眼科项目!$C$3:$O$485,13,FALSE) -> 1090
A26: 003304060060000-33040600601 | B26: 33040600601 | C26: 小儿白内障囊外摘除+人工晶体植入术 | F26: 次 | H26: 2495 | I26: 2250 | J26: 2195 | K26: 1975 | L26: 1680 | M26: 医保 | N26: 013304000030001 | O26: 人工晶状体植入费（常规）-儿童（加收） | S26: 单侧 | T26: =VLOOKUP(O26,眼科项目!$C$3:$O$485,11,FALSE) -> 425 | U26: =VLOOKUP(O26,眼科项目!$C$3:$O$485,12,FALSE) -> 385 | V26: =VLOOKUP(O26,眼科项目!$C$3:$O$485,13,FALSE) -> 325
A27: 003304060100000-330406010 | B27: 330406010 | C27: 白内障超声乳化摘除术+人工晶体植入术 | E27: 一次性乳化专用刀、一次性超乳包 | F27: 次 | H27: 3600 | I27: 3240 | J27: 3090 | K27: 2780 | L27: 2360 | M27: 医保 | N27: 013304000010000 | O27: 晶状体摘除费 | P27: 通过超声乳化、娩核、晶状体切除或粉碎等各种方式完成病变晶状体摘除。 | Q27: 所定价格涵盖手术计划、术区准备、切开、晶状体取出、缝合及必要时染色等步骤所需的人力资源和基本物质资源消耗。 | R27: 晶体囊截开术三甲医院按330元，三甲以下医院按297元收取。 | S27: 单侧 | T27: =VLOOKUP(O27,眼科项目!$C$3:$O$485,11,FALSE) -> 1800 | U27: =VLOOKUP(O27,眼科项目!$C$3:$O$485,12,FALSE) -> 1650 | V27: =VLOOKUP(O27,眼科项目!$C$3:$O$485,13,FALSE) -> 1400 | W27: =T27+T28*0.5 -> 2510 | X27: =U27+U28*0.5 -> 2290 | Y27: =V27+V28*0.5 -> 1945
N28: 013304000030000 | O28: 人工晶状体植入费（常规） | S28: 单侧 | T28: =VLOOKUP(O28,眼科项目!$C$3:$O$485,11,FALSE) -> 1420 | U28: =VLOOKUP(O28,眼科项目!$C$3:$O$485,12,FALSE) -> 1280 | V28: =VLOOKUP(O28,眼科项目!$C$3:$O$485,13,FALSE) -> 1090
A29: 003304060100000-33040601001 | B29: 33040601001 | C29: 小儿白内障超声乳化摘除术+人工晶体植入术 | F29: 次 | H29: 4680 | I29: 4210 | J29: 4015 | K29: 3615 | L29: 3075 | M29: 医保 | N29: 013304000010000 | O29: 晶状体摘除费 | P29: 通过超声乳化、娩核、晶状体切除或粉碎等各种方式完成病变晶状体摘除。 | Q29: 所定价格涵盖手术计划、术区准备、切开、晶状体取出、缝合及必要时染色等步骤所需的人力资源和基本物质资源消耗。 | R29: 晶体囊截开术三甲医院按330元，三甲以下医院按297元收取。 | S29: 单侧 | T29: =VLOOKUP(O29,眼科项目!$C$3:$O$485,11,FALSE) -> 1800 | U29: =VLOOKUP(O29,眼科项目!$C$3:$O$485,12,FALSE) -> 1650 | V29: =VLOOKUP(O29,眼科项目!$C$3:$O$485,13,FALSE) -> 1400 | W29: =T29+T30+(T31+T32)*0.5 -> 3262.5 | X29: =U29+U30+(U31+U32)*0.5 -> 2977.5 | Y29: =V29+V30+(V31+V32)*0.5 -> 2527.5
N30: 013304000010001 | O30: 晶状体摘除费-儿童（加收） | S30: 单侧 | T30: =VLOOKUP(O30,眼科项目!$C$3:$O$485,11,FALSE) -> 540 | U30: =VLOOKUP(O30,眼科项目!$C$3:$O$485,12,FALSE) -> 495 | V30: =VLOOKUP(O30,眼科项目!$C$3:$O$485,13,FALSE) -> 420
N31: 013304000030000 | O31: 人工晶状体植入费（常规） | S31: 单侧 | T31: =VLOOKUP(O31,眼科项目!$C$3:$O$485,11,FALSE) -> 1420 | U31: =VLOOKUP(O31,眼科项目!$C$3:$O$485,12,FALSE) -> 1280 | V31: =VLOOKUP(O31,眼科项目!$C$3:$O$485,13,FALSE) -> 1090
N32: 013304000030001 | O32: 人工晶状体植入费（常规）-儿童（加收） | S32: 单侧 | T32: =VLOOKUP(O32,眼科项目!$C$3:$O$485,11,FALSE) -> 425 | U32: =VLOOKUP(O32,眼科项目!$C$3:$O$485,12,FALSE) -> 385 | V32: =VLOOKUP(O32,眼科项目!$C$3:$O$485,13,FALSE) -> 325
A33: 003304060180000-330406018 | B33: 330406018 | C33: 球内异物取出术联合晶体玻璃体切除及人工晶体植入术（四联术） | E33: 玻璃体切割头、膨胀气体、硅油、重水、一次性超乳包 | F33: 次 | H33: 6900 | I33: 5800 | J33: 5320 | K33: 4790 | L33: 4070 | M33: 医保 | N33: 013304000610000 | O33: 球内异物取出费 | P33: 通过各种手术方式取出眼球内异物。 | Q33: 所定价格涵盖手术计划、术区准备、消毒、定位、切开、取出异物、缝合等步骤所需的人力资源和基本物质资源消耗。 | S33: 单侧 | T33: =VLOOKUP(O33,眼科项目!$C$3:$O$485,11,FALSE) -> 1150 | U33: =VLOOKUP(O33,眼科项目!$C$3:$O$485,12,FALSE) -> 1010 | V33: =VLOOKUP(O33,眼科项目!$C$3:$O$485,13,FALSE) -> 860 | W33: =T35+(T33+T34+T36)*0.5 -> 4715 | X33: =U35+(U33+U34+U36)*0.5 -> 4250 | Y33: =V35+(V33+V34+V36)*0.5 -> 3615
N34: 013304000010000 | O34: 晶状体摘除费 | P34: 通过超声乳化、娩核、晶状体切除或粉碎等各种方式完成病变晶状体摘除。 | Q34: 所定价格涵盖手术计划、术区准备、切开、晶状体取出、缝合及必要时染色等步骤所需的人力资源和基本物质资源消耗。 | R34: 晶体囊截开术三甲医院按330元，三甲以下医院按297元收取。 | S34: 单侧 | T34: =VLOOKUP(O34,眼科项目!$C$3:$O$485,11,FALSE) -> 1800 | U34: =VLOOKUP(O34,眼科项目!$C$3:$O$485,12,FALSE) -> 1650 | V34: =VLOOKUP(O34,眼科项目!$C$3:$O$485,13,FALSE) -> 1400
N35: 013304000070000 | O35: 玻璃体切除费 | P35: 通过各种手术方式切除玻璃体。 | Q35: 所定价格涵盖手术计划、术区准备、切开、穿刺、灌注、切除、必要时缝合等步骤所需的人力资源和基本物质资源消耗。 | S35: 单侧 | T35: =VLOOKUP(O35,眼科项目!$C$3:$O$485,11,FALSE) -> 2530 | U35: =VLOOKUP(O35,眼科项目!$C$3:$O$485,12,FALSE) -> 2280 | V35: =VLOOKUP(O35,眼科项目!$C$3:$O$485,13,FALSE) -> 1940
N36: 013304000030000 | O36: 人工晶状体植入费（常规） | S36: 单侧 | T36: =VLOOKUP(O36,眼科项目!$C$3:$O$485,11,FALSE) -> 1420 | U36: =VLOOKUP(O36,眼科项目!$C$3:$O$485,12,FALSE) -> 1280 | V36: =VLOOKUP(O36,眼科项目!$C$3:$O$485,13,FALSE) -> 1090
A37: 003304060180000-33040601801 | B37: 33040601801 | C37: 小儿球内异物取出术联合晶体玻璃体切除及人工晶体植入术（四联术） | F37: 次 | H37: 8970 | I37: 7540 | J37: 6915 | K37: 6225 | L37: 5290 | M37: 医保 | N37: 013304000610000 | O37: 球内异物取出费 | P37: 通过各种手术方式取出眼球内异物。 | Q37: 所定价格涵盖手术计划、术区准备、消毒、定位、切开、取出异物、缝合等步骤所需的人力资源和基本物质资源消耗。 | S37: 单侧 | T37: =VLOOKUP(O37,眼科项目!$C$3:$O$485,11,FALSE) -> 1150 | U37: =VLOOKUP(O37,眼科项目!$C$3:$O$485,12,FALSE) -> 1010 | V37: =VLOOKUP(O37,眼科项目!$C$3:$O$485,13,FALSE) -> 860 | W37: =T41+T42+(T37+T38+T39+T40+T43+T44)*0.5 -> 6130 | X37: =U41+U42+(U37+U38+U39+U40+U43+U44)*0.5 -> 5527.5 | Y37: =V41+V42+(V37+V38+V39+V40+V43+V44)*0.5 -> 4697.5
N38: 013304000610001 | O38: 球内异物取出费-儿童（加收） | S38: 单侧 | T38: =VLOOKUP(O38,眼科项目!$C$3:$O$485,11,FALSE) -> 345 | U38: =VLOOKUP(O38,眼科项目!$C$3:$O$485,12,FALSE) -> 305 | V38: =VLOOKUP(O38,眼科项目!$C$3:$O$485,13,FALSE) -> 260
N39: 013304000010000 | O39: 晶状体摘除费 | P39: 通过超声乳化、娩核、晶状体切除或粉碎等各种方式完成病变晶状体摘除。 | Q39: 所定价格涵盖手术计划、术区准备、切开、晶状体取出、缝合及必要时染色等步骤所需的人力资源和基本物质资源消耗。 | R39: 晶体囊截开术三甲医院按330元，三甲以下医院按297元收取。 | S39: 单侧 | T39: =VLOOKUP(O39,眼科项目!$C$3:$O$485,11,FALSE) -> 1800 | U39: =VLOOKUP(O39,眼科项目!$C$3:$O$485,12,FALSE) -> 1650 | V39: =VLOOKUP(O39,眼科项目!$C$3:$O$485,13,FALSE) -> 1400
N40: 013304000010001 | O40: 晶状体摘除费-儿童（加收） | S40: 单侧 | T40: =VLOOKUP(O40,眼科项目!$C$3:$O$485,11,FALSE) -> 540 | U40: =VLOOKUP(O40,眼科项目!$C$3:$O$485,12,FALSE) -> 495 | V40: =VLOOKUP(O40,眼科项目!$C$3:$O$485,13,FALSE) -> 420
...

Sheet Sheet1
A1: id | B1: code | C1: sever_type | D1: change_time | E1: old_hilist_code | F1: new_hilist_code | G1: hilist_name | H1: selfpay_prop | I1: old_price | J1: old_price_city | K1: old_price_town | L1: old_price_village | M1: new_price | N1: new_price_city | O1: new_price_town | P1: new_price_village | Q1: unit | R1: batch | S1: is_use_old | T1: merge_type | U1: cnt_change_model | V1: cnt_change_value | W1: ="insert into server_list_change_all_20250525 ("&_xlfn.TEXTJOIN(",",TRUE,A1:V1)&") values" -> insert into server_list_change_all_20250525 (id,code,sever_type,change_time,old_hilist_code,new_hilist_code,hilist_name,selfpay_prop,old_price,old_price_city,old_price_town,old_price_village,new_price,new_price_city,new_price_town,new_price_village,unit,batch,is_use_old,merge_type,cnt_change_model,cnt_change_value) values
A2: 2066 | B2: null | C2: 1 | D2: 2026-03-24 00:00:00 | E2: 003103000010000-310300001 | F2: 003103000010000-310300001 | G2: 普通视力检查 | H2: null | I2: null | J2: 1.1 | K2: 1 | L2: 0.9 | M2: null | N2: 1 | O2: 1 | P2: 1 | Q2: 次 | R2: 24 | S2: 1 | T2: normal | U2: main | V2: 0 | W2: ="("&A2&","&B2&","&C2&",'"&D2&"','"&E2&"','"&F2&"','"&G2&"',"&H2&","&I2&","&J2&","&K2&","&L2&","&M2&","&N2&","&O2&","&P2&",'"&Q2&"',"&R2&","&S2&",'"&T2&"','"&U2&"',"&V2&")," -> (2066,null,1,'2026-03-24 00:00:00','003103000010000-310300001','003103000010000-310300001','普通视力检查',null,null,1.1,1,0.9,null,1,1,1,'次',24,1,'normal','main',0),
A3: 2067 | B3: null | C3: 1 | D3: 2026-03-24 00:00:00 | E3: 003103000020000-310300002 | F3: 003103000020000-310300002 | G3: 特殊视力检查 | H3: null | I3: null | J3: 2.1 | K3: 2 | L3: 1.7 | M3: null | N3: 0 | O3: 0 | P3: 0 | Q3: 项 | R3: 24 | S3: 1 | T3: normal | U3: main | V3: 0 | W3: ="("&A3&","&B3&","&C3&",'"&D3&"','"&E3&"','"&F3&"','"&G3&"',"&H3&","&I3&","&J3&","&K3&","&L3&","&M3&","&N3&","&O3&","&P3&",'"&Q3&"',"&R3&","&S3&",'"&T3&"','"&U3&"',"&V3&")," -> (2067,null,1,'2026-03-24 00:00:00','003103000020000-310300002','003103000020000-310300002','特殊视力检查',null,null,2.1,2,1.7,null,0,0,0,'项',24,1,'normal','main',0),
A4: 2068 | B4: null | C4: 1 | D4: 2026-03-24 00:00:00 | E4: 003103000020100-31030000201 | F4: 003103000020100-31030000201 | G4: 特殊视力检查（儿童图形视力表） | H4: null | I4: null | J4: 2.1 | K4: 2 | L4: 1.7 | M4: null | N4: 0 | O4: 0 | P4: 0 | Q4: 项 | R4: 24 | S4: 1 | T4: normal | U4: main | V4: 0 | W4: ="("&A4&","&B4&","&C4&",'"&D4&"','"&E4&"','"&F4&"','"&G4&"',"&H4&","&I4&","&J4&","&K4&","&L4&","&M4&","&N4&","&O4&","&P4&",'"&Q4&"',"&R4&","&S4&",'"&T4&"','"&U4&"',"&V4&")," -> (2068,null,1,'2026-03-24 00:00:00','003103000020100-31030000201','003103000020100-31030000201','特殊视力检查（儿童图形视力表）',null,null,2.1,2,1.7,null,0,0,0,'项',24,1,'normal','main',0),
A5: 2069 | B5: null | C5: 1 | D5: 2026-03-24 00:00:00 | E5: 003103000020200-31030000202 | F5: 003103000020200-31030000202 | G5: 特殊视力检查（点视力表） | H5: null | I5: null | J5: 2.1 | K5: 2 | L5: 1.7 | M5: null | N5: 0 | O5: 0 | P5: 0 | Q5: 项 | R5: 24 | S5: 1 | T5: normal | U5: main | V5: 0 | W5: ="("&A5&","&B5&","&C5&",'"&D5&"','"&E5&"','"&F5&"','"&G5&"',"&H5&","&I5&","&J5&","&K5&","&L5&","&M5&","&N5&","&O5&","&P5&",'"&Q5&"',"&R5&","&S5&",'"&T5&"','"&U5&"',"&V5&")," -> (2069,null,1,'2026-03-24 00:00:00','003103000020200-31030000202','003103000020200-31030000202','特殊视力检查（点视力表）',null,null,2.1,2,1.7,null,0,0,0,'项',24,1,'normal','main',0),
A6: 2070 | B6: null | C6: 1 | D6: 2026-03-24 00:00:00 | E6: 003103000020300-31030000203 | F6: 003103000020300-31030000203 | G6: 特殊视力检查（条栅视力卡） | H6: null | I6: null | J6: 2.1 | K6: 2 | L6: 1.7 | M6: null | N6: 0 | O6: 0 | P6: 0 | Q6: 项 | R6: 24 | S6: 1 | T6: normal | U6: main | V6: 0 | W6: ="("&A6&","&B6&","&C6&",'"&D6&"','"&E6&"','"&F6&"','"&G6&"',"&H6&","&I6&","&J6&","&K6&","&L6&","&M6&","&N6&","&O6&","&P6&",'"&Q6&"',"&R6&","&S6&",'"&T6&"','"&U6&"',"&V6&")," -> (2070,null,1,'2026-03-24 00:00:00','003103000020300-31030000203','003103000020300-31030000203','特殊视力检查（条栅视力卡）',null,null,2.1,2,1.7,null,0,0,0,'项',24,1,'normal','main',0),
A7: 2071 | B7: null | C7: 1 | D7: 2026-03-24 00:00:00 | E7: 003103000020400-31030000204 | F7: 003103000020400-31030000204 | G7: 特殊视力检查（视动性眼震仪） | H7: null | I7: null | J7: 2.1 | K7: 2 | L7: 1.7 | M7: null | N7: 0 | O7: 0 | P7: 0 | Q7: 项 | R7: 24 | S7: 1 | T7: normal | U7: main | V7: 0 | W7: ="("&A7&","&B7&","&C7&",'"&D7&"','"&E7&"','"&F7&"','"&G7&"',"&H7&","&I7&","&J7&","&K7&","&L7&","&M7&","&N7&","&O7&","&P7&",'"&Q7&"',"&R7&","&S7&",'"&T7&"','"&U7&"',"&V7&")," -> (2071,null,1,'2026-03-24 00:00:00','003103000020400-31030000204','003103000020400-31030000204','特殊视力检查（视动性眼震仪）',null,null,2.1,2,1.7,null,0,0,0,'项',24,1,'normal','main',0),
A8: 2072 | B8: null | C8: 1 | D8: 2026-03-24 00:00:00 | E8: 003103000030000-310300003 | F8: 003103000030000-310300003 | G8: 选择性观看检查 | H8: null | I8: null | J8: 2.1 | K8: 2 | L8: 1.7 | M8: null | N8: 12 | O8: 11.5 | P8: 11 | Q8: 次 | R8: 24 | S8: 1 | T8: normal | U8: main | V8: 0 | W8: ="("&A8&","&B8&","&C8&",'"&D8&"','"&E8&"','"&F8&"','"&G8&"',"&H8&","&I8&","&J8&","&K8&","&L8&","&M8&","&N8&","&O8&","&P8&",'"&Q8&"',"&R8&","&S8&",'"&T8&"','"&U8&"',"&V8&")," -> (2072,null,1,'2026-03-24 00:00:00','003103000030000-310300003','003103000030000-310300003','选择性观看检查',null,null,2.1,2,1.7,null,12,11.5,11,'次',24,1,'normal','main',0),
A9: 2073 | B9: null | C9: 1 | D9: 2026-03-24 00:00:00 | E9: 003103000040000-310300004 | F9: 003103000040000-310300004 | G9: 视网膜视力检查 | H9: null | I9: null | J9: 5.3 | K9: 5 | L9: 4.3 | M9: null | N9: 12 | O9: 11.5 | P9: 11 | Q9: 次 | R9: 24 | S9: 1 | T9: normal | U9: main | V9: 0 | W9: ="("&A9&","&B9&","&C9&",'"&D9&"','"&E9&"','"&F9&"','"&G9&"',"&H9&","&I9&","&J9&","&K9&","&L9&","&M9&","&N9&","&O9&","&P9&",'"&Q9&"',"&R9&","&S9&",'"&T9&"','"&U9&"',"&V9&")," -> (2073,null,1,'2026-03-24 00:00:00','003103000040000-310300004','003103000040000-310300004','视网膜视力检查',null,null,5.3,5,4.3,null,12,11.5,11,'次',24,1,'normal','main',0),
A10: 2074 | B10: null | C10: 1 | D10: 2026-03-24 00:00:00 | E10: 003103000060000-310300006 | F10: 003103000060000-310300006 | G10: 阿姆斯勒（Amsler）表检查 | H10: null | I10: null | J10: 2.1 | K10: 2 | L10: 1.7 | M10: null | N10: 12 | O10: 11.5 | P10: 11 | Q10: 次（单眼） | R10: 24 | S10: 1 | T10: normal | U10: main | V10: 0 | W10: ="("&A10&","&B10&","&C10&",'"&D10&"','"&E10&"','"&F10&"','"&G10&"',"&H10&","&I10&","&J10&","&K10&","&L10&","&M10&","&N10&","&O10&","&P10&",'"&Q10&"',"&R10&","&S10&",'"&T10&"','"&U10&"',"&V10&")," -> (2074,null,1,'2026-03-24 00:00:00','003103000060000-310300006','003103000060000-310300006','阿姆斯勒（Amsler）表检查',null,null,2.1,2,1.7,null,12,11.5,11,'次（单眼）',24,1,'normal','main',0),
A11: 2075 | B11: null | C11: 1 | D11: 2026-03-24 00:00:00 | E11: 003103000210000-310300021 | F11: 003103000210000-310300021 | G11: 对比敏感度检查 | H11: null | I11: null | J11: 3.2 | K11: 3 | L11: 2.6 | M11: null | N11: 12 | O11: 11.5 | P11: 11 | Q11: 次 | R11: 24 | S11: 1 | T11: normal | U11: main | V11: 0 | W11: ="("&A11&","&B11&","&C11&",'"&D11&"','"&E11&"','"&F11&"','"&G11&"',"&H11&","&I11&","&J11&","&K11&","&L11&","&M11&","&N11&","&O11&","&P11&",'"&Q11&"',"&R11&","&S11&",'"&T11&"','"&U11&"',"&V11&")," -> (2075,null,1,'2026-03-24 00:00:00','003103000210000-310300021','003103000210000-310300021','对比敏感度检查',null,null,3.2,3,2.6,null,12,11.5,11,'次',24,1,'normal','main',0),
A12: 2076 | B12: null | C12: 1 | D12: 2026-03-24 00:00:00 | E12: 003103000210000-31030002101 | F12: 003103000210000-31030002101 | G12: 对比敏感度检查（使用微机处理） | H12: null | I12: null | J12: 15.8 | K12: 15 | L12: 12.8 | M12: null | N12: 12 | O12: 11.5 | P12: 11 | Q12: 次 | R12: 24 | S12: 1 | T12: normal | U12: main | V12: 0 | W12: ="("&A12&","&B12&","&C12&",'"&D12&"','"&E12&"','"&F12&"','"&G12&"',"&H12&","&I12&","&J12&","&K12&","&L12&","&M12&","&N12&","&O12&","&P12&",'"&Q12&"',"&R12&","&S12&",'"&T12&"','"&U12&"',"&V12&")," -> (2076,null,1,'2026-03-24 00:00:00','003103000210000-31030002101','003103000210000-31030002101','对比敏感度检查（使用微机处理）',null,null,15.8,15,12.8,null,12,11.5,11,'次',24,1,'normal','main',0),
A13: 2077 | B13: null | C13: 1 | D13: 2026-03-24 00:00:00 | E13: 003103000220000-310300022 | F13: 003103000220000-310300022 | G13: 暗适应测定 | H13: null | I13: null | J13: 15.8 | K13: 15 | L13: 12.8 | M13: null | N13: 0 | O13: 0 | P13: 0 | Q13: 次 | R13: 24 | S13: 1 | T13: normal | U13: main | V13: 0 | W13: ="("&A13&","&B13&","&C13&",'"&D13&"','"&E13&"','"&F13&"','"&G13&"',"&H13&","&I13&","&J13&","&K13&","&L13&","&M13&","&N13&","&O13&","&P13&",'"&Q13&"',"&R13&","&S13&",'"&T13&"','"&U13&"',"&V13&")," -> (2077,null,1,'2026-03-24 00:00:00','003103000220000-310300022','003103000220000-310300022','暗适应测定',null,null,15.8,15,12.8,null,0,0,0,'次',24,1,'normal','main',0),
... A404: 2468 | B404: null | C404: 1 | D404: 2026-03-24 00:00:00 | E404: 003304030080000-33040300801 | F404: 003304030080000-33040300801 | G404: 小儿球结膜放射状切开冲洗+减压术 | H404: null | I404: null | J404: 490 | K404: 470 | L404: 400 | M404: null | N404: 490 | O404: 440 | P404: 397 | Q404: 次 | R404: 24 | S404: 1 | T404: normal | U404: main | V404: 0 | W404: ="("&A404&","&B404&","&C404&",'"&D404&"','"&E404&"','"&F404&"','"&G404&"',"&H404&","&I404&","&J404&","&K404&","&L404&","&M404&","&N404&","&O404&","&P404&",'"&Q404&"',"&R404&","&S404&",'"&T404&"','"&U404&"',"&V404&")," -> (2468,null,1,'2026-03-24 00:00:00','003304030080000-33040300801','003304030080000-33040300801','小儿球结膜放射状切开冲洗+减压术',null,null,490,470,400,null,490,440,397,'次',24,1,'normal','main',0),
