Workbook

Sheet 规范整合泌尿系统医疗服务价格映射表12.11
A1: 附件1
A2: 泌尿系统类立项指南项目价格拟定情况
A3: 泌尿系统类立项指南项目 | V3: 现行价格项目
A4: 序号 | B4: 项目代码 | C4: 项目名称 | D4: 归集口径 | E4: 服务产出 | F4: 价格构成 | G4: 计价单位 | H4: 计价说明 | I4: 省三甲价格 | J4: 省三甲以下价格 | K4: 平移价格 (市级) | L4: 平移价格 (县级) | M4: 平移价格 (基层) | N4: 拟定价格 (市级) | O4: 拟定价格 (县级) | P4: 拟定价格 (基层) | Q4: 医保属性 | R4: 医保限定支付范围 | S4: 个人先行自付比例 | T4: 调整情况 | U4: 备注 | V4: 国家结算编码 | W4: 项目编码 | X4: 项目名称 | Y4: 项目内涵 | Z4: 除外内容 | AA4: 计价单位 | AB4: 说明 | AC4: 三甲 | AD4: 三甲以下 | AE4: 价格 (市级) | AF4: 价格 (县级) | AG4: 价格 (基层)
A5: 1 | B5: 012411000010000 | C5: 肾盂内压检查费 | D5: 检查费 | E5: 通过各种方式测定肾盂内压，辅助判断肾盂输尿管连接部是否存在梗阻。 | F5: 所定价格涵盖放置导管、注射、观察记录、出具报告、处理用物等步骤所需的人力资源和基本物质资源消耗。 | G5: 次 | H5: “次”指双侧，单侧按50%收取。 | I5: 240 | J5: 216 | N5: 220 | O5: 200 | P5: 170 | Q5: 非医保 | T5: 新增价格 | U5: 新增价格，按比价关系拟定 | V5: 003110000140000-311000014 | W5: 311000014 | X5: 肾盂测压 | AA5: 单侧
A6: 2 | B6: 012411000020000 | C6: 尿流动力学检查费 | D6: 检查费 | E6: 通过各种方式对尿路功能状态进行评估，辅助诊断尿路功能障碍性疾病。 | F6: 所定价格涵盖检测尿流率与动力学、出具报告、处理用物等步骤所需的人力资源和基本物质资源消耗。 | G6: 次 | H6: 尿流率检测市级医院收取66元/次，县级医院收取59元/次，基层收取51元/次。 | I6: 165 | J6: 150 | K6: 165 | L6: 150 | M6: 127.5 | N6: 165 | O6: 150 | P6: 128 | Q6: 医保 | T6: 平移 | U6: 平移后，县级按不高于省级拟定，基层取整。同质化高的项目持平省级定价。 | V6: 003110000390000-311000039 | W6: 311000039 | X6: 尿流动力学检测 | Y6: 不含摄片 | AA6: 次 | AC6: 165 | AD6: 150 | AE6: 165 | AF6: 150 | AG6: 127.5
C7: 尿流动力学检查费（尿流率检测） | K7: 66 | L7: 60 | M7: 51 | N7: 66 | O7: 59 | P7: 51 | V7: 003110000380000-311000038 | W7: 311000038 | X7: 尿流率检测 | AA7: 次 | AC7: 66 | AD7: 59 | AE7: 66 | AF7: 60 | AG7: 51
A8: 3 | B8: 012411000030000 | C8: 泌尿系镜检查费（肾镜） | D8: 检查费 | E8: 通过肾镜观察和诊断泌尿系统疾病。 | F8: 所定价格涵盖消毒、插管、扩张通道、观察、出具报告、处理用物、必要时穿刺等步骤所需的人力资源和基本物质资源消耗。 | G8: 单侧 | I8: 660 | J8: 595 | K8: 660 | L8: 600 | M8: 510 | N8: 660 | O8: 595 | P8: 510 | Q8: 医保 | T8: 理顺 | U8: 平移后，县级按不高于省级拟定 | V8: 003110000180000-311000018 | W8: 311000018 | X8: 经皮肾盂镜检查 | Y8: 含活检 | AA8: 单侧 | AC8: 660 | AD8: 595 | AE8: 660 | AF8: 600 | AG8: 510
A9: 4 | B9: 012411000040000 | C9: 泌尿系镜检查费（输尿管镜） | D9: 检查费 | E9: 通过输尿管镜观察和诊断泌尿系统疾病。 | F9: 所定价格涵盖消毒、插管、扩张通道、观察、出具报告、处理用物等步骤所需的人力资源和基本物质资源消耗。 | G9: 单侧 | I9: 499 | J9: 449 | K9: 495 | L9: 450 | M9: 382.5 | N9: 495 | O9: 445 | P9: 380 | Q9: 医保 | T9: 理顺，降低 | U9: 平移后，县级按不高于省级拟定，基层对应调整 | V9: 003110000200000-311000020 | W9: 311000020 | X9: 经尿道输尿管镜检查 | Y9: 含活检；包括取异物 | AA9: 单侧 | AC9: 495 | AD9: 445 | AE9: 495 | AF9: 450 | AG9: 382.5
A10: 分项 | B10: 012411000040100 | C10: 泌尿系镜检查费（输尿管镜）-精囊镜检查（扩展） | D10: 检查费 | G10: 单侧 | I10: 499 | J10: 449 | K10: 720 | L10: 648 | M10: 550.8 | N10: 495 | O10: 445 | P10: 380 | Q10: 医保 | U10: 扩展项按主项价格执行 | V10: 353111000290000-311100020 | W10: 311100020 | X10: 经尿道精囊镜检查 | Y10: 消毒，取Wolf4.5/6.5精囊镜连接电视成像系统，以生理盐水为灌注液，直视下将精囊镜经尿道置入膀胱，观察尿道、膀胱，将镜体退至精阜处，仔细观察射精管口，发现射精管口后稍加大灌注液速度，将镜体置入一侧射精管内，将镜体逐渐推进精囊内，观察射精管及精囊内情况，如有无结石、肿物及精囊液情况。含活检、斑马导丝。 | AA10: 侧 | AC10: 800 | AE10: 720 | AF10: 648 | AG10: 550.8
A11: 5 | B11: 012411000050000 | C11: 泌尿系镜检查费（膀胱镜尿道镜） | D11: 检查费 | E11: 通过膀胱镜尿道镜观察和诊断泌尿系统疾病。 | F11: 所定价格涵盖消毒、插管、扩张通道、观察、出具报告、处理用物等步骤所需的人力资源和基本物质资源消耗。 | G11: 次 | I11: 132 | J11: 120 | K11: 132 | L11: 120 | M11: 102 | N11: 132 | O11: 120 | P11: 102 | Q11: 医保 | T11: 平移 | U11: 平移 | V11: 003110000340000-311000034 | W11: 311000034 | X11: 膀胱镜尿道镜检查 | Y11: 含活检，包括取异物 | AA11: 次 | AC11: 132 | AD11: 120 | AE11: 132 | AF11: 120 | AG11: 102
A12: 6 | B12: 012412000010000 | C12: 性刺激勃起检查费 | D12: 检查费 | E12: 通过各种方式对患者在各类性刺激环境下勃起次数、持续时间、硬度分级等情况进行监测。 | F12: 所定价格涵盖消毒、设备准备、刺激、监测、读取结果、出具报告、处理用物等步骤所需的人力资源和基本物质资源消耗。 | G12: 次 | I12: 63 | J12: 57 | N12: 60 | O12: 54 | P12: 46 | Q12: 非医保 | T12: 新增项目 | U12: 新增项目，按比价关系拟定，同质化高的检查项目缩小价差
A13: 7 | B13: 012412000020000 | C13: 阴茎勃起检查费 | D13: 检查费 | E13: 对患者夜间或模拟夜间环境下勃起次数、持续时间、硬度分级等情况进行监测。 | F13: 所定价格涵盖消毒、设备准备、监测、读取结果、出具报告、处理用物等步骤所需的人力资源和基本物质资源消耗。 | G13: 次 | I13: 100 | J13: 90 | K13: 99 | L13: 89 | M13: 77 | N13: 99 | O13: 89 | P13: 77 | Q13: 非医保 | T13: 平移 | U13: 平移 | V13: 003111000030000-311100003 | W13: 311100003 | X13: 夜间阴茎胀大试验 | Y13: 含硬度计法 | AA13: 次 | AC13: 100 | AD13: 90 | AE13: 99 | AF13: 89 | AG13: 77
A14: 8 | B14: 012412000030000 | C14: 阴茎超声血流图检查费 | D14: 检查费 | E14: 对患者阴茎海绵体内血流情况进行检测。 | F14: 所定价格涵盖消毒、设备准备、检测、诊断、出具报告、处理用物等步骤所需的人力资源和基本物质资源消耗。 | G14: 次 | I14: 77 | J14: 69 | L14: 80 | N14: 77 | O14: 69 | P14: 60 | Q14: 非医保 | T14: 理顺，降低 | U14: 仅县级有工作量，平移后按不超过省级拟定，同质化高的项目持平省级定价。 | V14: 003111000040000-311100004 | W14: 311100004 | X14: 阴茎超声血流图检查 | AA14: 次 | AC14: 80 | AD14: 72 | AE14: 88 | AF14: 80 | AG14: 68
V15: 003111000110000-311100011 | W15: 311100011 | X15: 阴茎动脉测压术 | AA15: 次 | AC15: 44 | AD15: 40 | AE15: 44 | AF15: 40 | AG15: 34
A16: 9 | B16: 012412000040000 | C16: 阴茎勃起神经检查费 | D16: 检查费 | E16: 通过各种方式对患者勃起相关神经进行检测。 | F16: 所定价格涵盖消毒、设备准备、检测、读取结果、出具报告、处理用物等步骤所需的人力资源和基本物质资源消耗。 | G16: 次 | I16: 110 | J16: 99 | K16: 110 | L16: 100 | M16: 85 | N16: 110 | O16: 99 | P16: 85 | Q16: 非医保 | T16: 理顺 | U16: 平移后，县级按不高于省级拟定，同质化高的项目持平省级定价。 | V16: 003111000050000-311100005 | W16: 311100005 | X16: 阴茎勃起神经检查 | Y16: 含肌电图检查 | AA16: 次 | AC16: 110 | AD16: 99 | AE16: 110 | AF16: 100 | AG16: 85
A17: 10 | B17: 013110000010000 | C17: 血液透析费 | D17: 治疗费 | E17: 通过弥散和对流原理清除血液中过多水分和有害物质。 | F17: 所定价格涵盖消毒、穿刺、安装设定、连接管路、监测、血液回输、加压止血、封管、处理用物等步骤所需的人力资源和基本物质资源消耗。 | G17: 次 | H17: 本项目中的“监测”指：血温、血压、在线清除率、血容量监测，医院未完成全部四项监测事项的，每少完成一项监测减收5元。 | I17: 398 | J17: 398 | K17: 385 | L17: 370 | M17: 340 | N17: 385 | O17: 370 | P17: 340 | Q17: 医保 | T17: 已落地，直接平移 | U17: 2025年7月15日已落地执行 | V17: 013110000010000 | W17: 013110000010000 | X17: 血液透析费 | Y17: 通过弥散和对流原理清除血液中过多水分和有害物质。 | AA17: 次 | AB17: 本项目中的“监测”指：血温、血压、在线清除率、血容量监测，医院未完成全部四项监测事项的，每少完成一项监测减收5元。 | AC17: 398 | AD17: 398 | AE17: 385 | AF17: 370 | AG17: 340
A18: 11 | B18: 013110000020000 | C18: 血液滤过费 | D18: 治疗费 | E18: 通过对流原理清除血液中过多水分和有害物质。 | F18: 所定价格涵盖消毒、穿刺、建立通路、抗凝处理、连接管路、补充置换液、清除毒素及水分、监测、封管、处理用物等步骤所需的人力资源和基本物质资源消耗。 | G18: 次 | H18: 本项目中的“监测”指：血温、血压、在线清除率、血容量监测，医院未完成全部四项监测事项的，每少完成一项监测减收5元。 | I18: 398 | J18: 398 | K18: 395 | L18: 390 | M18: 355 | N18: 395 | O18: 390 | P18: 355 | Q18: 医保 | T18: 已落地，直接平移 | U18: 2025年7月15日已落地执行 | V18: 013110000020000 | W18: 013110000020000 | X18: 血液滤过费 | Y18: 通过对流原理清除血液中过多水分和有害物质。 | AA18: 次 | AB18: 本项目中的“监测”指：血温、血压、在线清除率、血容量监测，医院未完成全部四项监测事项的，每少完成一项监测减收5元。 | AC18: 398 | AD18: 398 | AE18: 395 | AF18: 390 | AG18: 355
A19: 12 | B19: 013110000030000 | C19: 血液透析滤过费 | D19: 治疗费 | E19: 通过同时进行血液透析和血液滤过清除血液中过多水分和有害物质。 | F19: 所定价格涵盖消毒、穿刺、建立通路、连接管路、参数设置、清除毒素及水分滤过、监测、封管、处理用物等步骤所需的人力资源和基本物质资源消耗。 | G19: 次 | H19: 本项目中的“监测”指：血温、血压、在线清除率、血容量监测，医院未完成全部四项监测事项的，每少完成一项监测减收5元。 | I19: 598 | J19: 598 | K19: 590 | L19: 575 | M19: 510 | N19: 590 | O19: 575 | P19: 510 | Q19: 医保 | T19: 已落地，直接平移 | U19: 2025年7月15日已落地执行 | V19: 013110000030000 | W19: 013110000030000 | X19: 血液透析滤过费 | Y19: 通过同时进行血液透析和血液滤过清除血液中过多水分和有害物质。 | AA19: 次 | AB19: 本项目中的“监测”指：血温、血压、在线清除率、血容量监测，医院未完成全部四项监测事项的，每少完成一项监测减收5元。 | AC19: 598 | AD19: 598 | AE19: 590 | AF19: 575 | AG19: 510
A20: 13 | B20: 013110000040000 | C20: 血液灌流费 | D20: 治疗费 | E20: 通过吸附原理‌直接结合血液中的中大分子及蛋白结合毒素。 | F20: 所定价格涵盖消毒、穿刺、建立通路、连接管路、参数设置、血液灌流、回输、封管、处理用物等步骤所需的人力资源和基本物质资源消耗。 | G20: 次 | I20: 300 | J20: 300 | K20: 275 | L20: 260 | M20: 250 | N20: 275 | O20: 260 | P20: 250 | T20: 已落地，直接平移 | U20: 2025年7月15日已落地执行 | V20: 013110000040000 | W20: 013110000040000 | X20: 血液灌流费 | Y20: 通过吸附原理‌直接结合血液中的中大分子及蛋白结合毒素。 | AA20: 次 | AC20: 300 | AD20: 300 | AE20: 275 | AF20: 260 | AG20: 250
A21: 14 | B21: 013110000050000 | C21: 血液透析灌流费 | D21: 治疗费 | E21: 通过同时进行血液透析和血液灌流清除血液中过多水分和有害物质。 | F21: 所定价格涵盖消毒、穿刺、建立通路、连接管路、参数设置、透析灌流、监测、封管、处理用物等步骤所需的人力资源和基本物质资源消耗。 | G21: 次 | H21: 本项目中的“监测”指：血温、血压、在线清除率、血容量监测，医院未完成全部四项监测事项的，每少完成一项监测减收5元。 | I21: 620 | J21: 620 | K21: 520 | L21: 520 | M21: 440 | N21: 520 | O21: 520 | P21: 440 | Q21: 医保 | S21: 0.05 | T21: 已落地，直接平移 | U21: 2025年7月15日已落地执行 | V21: 013110000050000 | W21: 013110000050000 | X21: 血液透析灌流费 | Y21: 通过同时进行血液透析和血液灌流清除血液中过多水分和有害物质。 | AA21: 次 | AB21: 本项目中的“监测”指：血温、血压、在线清除率、血容量监测，医院未完成全部四项监测事项的，每少完成一项监测减收5元。 | AC21: 620 | AD21: 620 | AE21: 520 | AF21: 520 | AG21: =420+20 -> 440
A22: 15 | B22: 013110000060000 | C22: 血浆置换费 | D22: 治疗费 | E22: 分离血浆、用置换液置换含有有害物质的血浆。 | F22: 所定价格涵盖消毒、穿刺、连接管路、血浆分离置换、回输、去除装置、处理用物等步骤所需的人力资源和基本物质资源消耗。 | G22: 次 | H22: 血浆置换费使用的滤器、血浆分离器、管路按零差率销售价格另行收取相应费用。 | I22: 800 | J22: 720 | N22: 750 | O22: 700 | P22: 595 | Q22: 医保 | S22: 0.2 | T22: 理顺 | U22: 2025年7月15日已落地执行，现将耗材剥离，重新制定价格。 血浆分离器、分离管路全市采购均价分别为2178元、1425元，耗材成本超过项目本身价格。 | V22: 003109050230000-310905023 | W22: 310905023 | X22: 人工肝治疗 | Z22: 一次性导管 | AA22: 次 | AC22: 1600 | AD22: 1440 | AE22: 1500 | AF22: 1350 | AG22: 1145
V23: 013110000060000 | W23: 013110000060000 | X23: 血浆置换费 | Y23: 分离血浆、用置换液置换含有有害物质的血浆。 | AC23: 2600 | AD23: 2340 | AE23: 2450 | AF23: 2325 | AG23: 2000
A24: 分项 | B24: 013110000060001 | C24: 血浆置换费-双重血浆置换（加收） | D24: 治疗费 | G24: 次 | I24: 340 | J24: 306 | N24: 320 | O24: 300 | P24: 255 | Q24: 医保 | S24: 0.2 | U24: 新增项目，按项目间比价关系拟定
A25: 16 | B25: 013110000070000 | C25: 血浆吸附费 | D25: 治疗费 | E25: 分离血浆，利用吸附原理清除血浆中特定有害物质。 | F25: 所定价格涵盖消毒、穿刺、连接管路、分离血浆、吸附清除致病物质、血细胞混合、回输、去除装置、处理用物等步骤所需的人力资源和基本物质资源消耗。 | G25: 次 | I25: 1200 | J25: 1080 | N25: 1100 | O25: 1000 | P25: 850 | Q25: 医保 | S25: 0.05 | T25: 新增价格 | U25: 新增价格，按比价关系拟定
A26: 17 | B26: 013110000080000 | C26: 连续性肾脏替代治疗费 | D26: 治疗费 | E26: 通过血液净化实现连续肾脏替代治疗和多脏器功能衰竭的生命支持治疗。 | F26: 所定价格涵盖消毒、穿刺、连接管路、上机、血液净化、体外抗凝、回输、去除装置、处理用物等步骤所需的人力资源和基本物质资源消耗。 | G26: 小时 | H26: 连续性肾脏替代治疗使用的滤器、管路按零差率销售价格另行收取相应费用。 | I26: 96 | J26: 96 | K26: 95 | L26: 95 | M26: 86 | N26: 95 | O26: 95 | P26: 86 | Q26: 医保 | T26: 已落地，直接平移 | U26: 新家 | V26: 013110000080000 | W26: 013110000080000 | X26: 连续性肾脏替代治疗费 | AA26: 小时 | AC26: 96 | AD26: 96 | AE26: 95 | AF26: 95 | AG26: 86
A27: 分项 | B27: 013110000080001 | C27: 连续性肾脏替代治疗费-连续性血浆吸附滤过治疗（加收） | D27: 治疗费 | G27: 小时 | I27: 30 | J27: 30 | K27: 28 | L27: 28 | M27: 25 | N27: 28 | O27: 28 | P27: 25 | Q27: 医保 | U27: 2025年7月15日已落地执行 | V27: 013110000080001 | W27: 013110000080001 | X27: 连续性肾脏替代治疗费-连续性血浆吸附滤过治疗（加收） | AA27: 小时 | AC27: 30 | AD27: 30 | AE27: 28 | AF27: 28 | AG27: 25
A28: 18 | B28: 013110000090000 | C28: 腹膜透析费（人工） | D28: 治疗费 | E28: 通过人工进行肾脏替代治疗，清除毒素和/或水分。 | F28: 所定价格涵盖操作前准备、透析管连接、注入透析液、引流液收集、记录等步骤所需的人力资源和基本物质资源消耗。 | G28: 次 | I28: 17 | J28: 15 | K28: 15 | L28: 15 | M28: 12.8 | N28: 15 | O28: 15 | P28: 12.8 | Q28: 医保 | T28: 已落地，直接平移 | U28: 2025年7月15日已落地执行 | W28: 013110000090000 | X28: 腹膜透析费（人工） | Y28: 通过人工进行肾脏替代治疗，清除毒素和/或水分。 | AA28: 次 | AC28: 17 | AD28: 15 | AE28: 15 | AF28: 15 | AG28: 12.8
A29: 19 | B29: 013110000100000 | C29: 腹膜透析费（自动） | D29: 治疗费 | E29: 通过设备进行肾脏替代治疗，清除毒素和/或水分。 | F29: 所定价格涵盖设备准备、透析管连接、设备运行、引流液收集、记录等步骤所需的人力资源和基本物质资源消耗。 | G29: 小时 | I29: 17 | J29: 15 | K29: 15 | L29: 15 | M29: 12.8 | N29: 15 | O29: 15 | P29: 12.8 | Q29: 医保 | S29: 0.05 | T29: 已落地，直接平移 | U29: 2025年7月15日已落地执行 | W29: 013110000100000 | X29: 腹膜透析费（自动） | Y29: 通过设备进行肾脏替代治疗，清除毒素和/或水分。 | AA29: 小时 | AC29: 17 | AD29: 15 | AE29: 15 | AF29: 15 | AG29: 12.8
A30: 20 | B30: 013110000110000 | C30: 腹膜透析操作训练费 | D30: 治疗费 | E30: 由医疗机构提供腹膜透析治疗的相关操作训练和指导，使患者具备自我操作腹膜透析和疾病自我管理的能力。 | F30: 所定价格涵盖医务人员对患者及照顾者进行培训，使其掌握家庭腹膜透析技能所需的人力资源和基本物质资源消耗。 | G30: 小时 | H30: 超过4小时按4小时收取。 | I30: 50 | J30: 45 | N30: 45 | O30: 41 | P30: 35 | Q30: 医保 | S30: 0.2 | T30: 新增项目 | U30: 新增项目，按比价关系拟定
A31: 21 | B31: 013110000120000 | C31: 腹膜透析延伸服务费 | D31: 治疗费 | E31: 通过各种方式向在院外进行腹膜透析治疗的患者提供沟通、评估及指导等医学服务。 | F31: 所定价格涵盖医务人员对患者进行沟通、评估及指导等所需的人力资源和基本物质资源消耗。 | G31: 月 | H31: 医疗机构收取该项费用应以每周最少完成一次延伸服务为前提。居家自动腹膜透析远程实时监测不得同时收取腹膜透析延伸服务费。 | I31: 150 | J31: 135 | N31: 135 | O31: 125 | P31: 110 | Q31: 医保 | S31: 0.2 | T31: 新增项目 | U31: 新增项目，按比价关系拟定
A32: 22 | B32: 013110000130000 | C32: 透析管路处理费 | D32: 治疗费 | E32: 溶解透析管路内栓塞物，恢复透析管路通畅。 | F32: 所定价格涵盖消毒、反复溶栓药物注射、留置、抽取、封管、处理用物等步骤所需的人力资源和基本物质资源消耗。 | G32: 次 | I32: 120 | J32: 108 | N32: 110 | O32: 100 | P32: 85 | Q32: 医保 | S32: 0.2 | T32: 新增项目 | U32: 新增项目，按比价关系拟定
A33: 23 | B33: 013110000140000 | C33: 腹膜透析外管更换费 | D33: 治疗费 | E33: 通过各种方式更换腹膜透析外接短管。 | F33: 所定价格涵盖消毒、更换管路、封管、处理用物等步骤所需的人力资源和基本物质资源消耗。 | G33: 次 | I33: 45 | J33: 41 | K33: 40 | L33: 40 | M33: 34 | N33: 42 | O33: 40 | P33: 34 | Q33: 医保 | T33: 理顺 | U33: 2025年7月15日已在“腹膜透析换管费”说明中落地执行，此次调整市级理顺比价 | V33: 013311000020000 | W33: 013311000020000 | X33: 腹膜透析换管费（更换外管） | AA33: 次
A34: 24 | B34: 013110000150000 | C34: 腹膜平衡试验费 | D34: 治疗费 | E34: 对腹膜功能进行检测，调整腹膜透析方案。 | F34: 所定价格涵盖腹透换液、留取标本、测量、计算、出具方案、处理用物等步骤所需的人力资源和基本物质资源消耗。 | G34: 次 | I34: 45 | J34: 41 | K34: 40 | L34: 40 | M34: 34 | N34: 42 | O34: 40 | P34: 34 | Q34: 医保 | T34: 理顺 | U34: 2025年7月15日已落地执行，此次调整市级理顺比价 | V34: 013110000150000 | W34: 013110000150000 | X34: 腹膜平衡试验费 | Y34: 对腹膜功能进行检测，调整腹膜透析方案。 | AA34: 次 | AC34: 45 | AD34: 41 | AE34: 40 | AF34: 40 | AG34: 34
A35: 25 | B35: 013311000010000 | C35: 腹膜透析置管费 | D35: 手术费 | E35: 通过各种方式放置腹膜透析导管。 | F35: 所定价格涵盖消毒、切开、穿刺或分离、置管、试水通畅、缝合、处理用物等步骤所需的人力资源和基本物质资源消耗。 | G35: 次 | I35: 440 | J35: 395 | K35: 400 | L35: 400 | M35: 340 | N35: 420 | O35: 395 | P35: 340 | Q35: 医保 | T35: 理顺 | U35: 2025年7月15日已落地执行，现微调市级、县级价格以理顺比价 | V35: 013311000010000 | W35: 013311000010000 | X35: 腹膜透析置管费 | Y35: 通过各种方式放置腹膜透析导管。 | AA35: 次 | AC35: 440 | AD35: 395 | AE35: 400 | AF35: 400 | AG35: 340
A36: 分项 | B36: 013311000010001 | C36: 腹膜透析置管费-儿童（加收） | D36: 手术费 | G36: 次 | I36: 0 | J36: 0 | N36: 0 | O36: 0 | P36: 0 | Q36: 医保 | U36: 新增儿童加收项目，福建省目前不予区分定价，因此定价为0
A37: 26 | B37: 013311000020000 | C37: 腹膜透析换管费 | D37: 手术费 | E37: 更换破损、堵塞、移位的腹膜透析导管。 | F37: 所定价格涵盖消毒、切开、拔除旧管、原位置入新管、试水通畅、缝合、处理用物等步骤所需的人力资源和基本物质资源消耗。 | G37: 次 | H37: 不与“腹膜透析置管费”“腹膜透析导管取出费”“腹膜透析导管感染清创费”同时收取。 | I37: 440 | J37: 395 | K37: 420 | L37: 420 | M37: 360 | N37: 420 | O37: 395 | P37: 340 | Q37: 医保 | T37: 理顺 | U37: 2025年7月15日已落地执行，现调整说明，更换外管独立设立项目 微调价格理顺比价 | V37: 013311000020000 | W37: 013311000020000 | X37: 腹膜透析换管费 | Y37: 更换破损、堵塞、移位的腹膜透析导管。 | AA37: 次 | AB37: 不与“腹膜透析置管费”“腹膜透析导管取出费”“腹膜透析导管感染清创费”同时收取。更换外管市、县级按40元收取，基层按34元收取。 | AC37: 440 | AD37: 395 | AE37: 420 | AF37: 420 | AG37: 360
A38: 分项 | B38: 013311000020001 | C38: 腹膜透析换管费-儿童（加收） | D38: 手术费 | G38: 次 | I38: 0 | J38: 0 | N38: 0 | O38: 0 | P38: 0 | Q38: 医保 | U38: 新增儿童加收项目，福建省目前不予区分定价，因此定价为0
A39: 27 | B39: 013110000160000 | C39: 腹膜透析导管复位费（导丝复位） | D39: 治疗费 | E39: 通过导丝调整复位移位的腹膜透析导管，恢复导管功能。 | F39: 所定价格涵盖消毒、修复、调整管路、试水通畅等步骤所需的人力资源和基本物质资源消耗。 | G39: 次 | H39: 不与“腹膜透析导管复位费（手术复位）”同时收取。 | I39: 300 | J39: 270 | N39: 270 | O39: 245 | P39: 210 | Q39: 医保 | S39: 0.2 | T39: 新增项目 | U39: 新增项目，按比价关系拟定
A40: 28 | B40: 013311000030000 | C40: 腹膜透析导管复位费（手术复位） | D40: 手术费 | E40: 通过手术调整复位移位的腹膜透析导管，恢复导管功能。 | F40: 所定价格涵盖消毒、修复、调整管路、试水通畅、缝合及必要时使用导丝调整、处理用物等步骤所需的人力资源和基本物质资源消耗。 | G40: 次 | H40: 不与“腹膜透析导管复位费（导丝复位）”同时收取。 | I40: 500 | J40: 450 | N40: 450 | O40: 410 | P40: 350 | Q40: 医保 | S40: 0.2 | T40: 新增项目 | U40: 新增项目，按比价关系拟定
...

Sheet 规范整合泌尿系统医疗服务价格映射表12.11 (2)
A1: 附件1
A2: 泌尿系统类立项指南项目价格拟定情况 | B2: 泌尿系统类立项指南项目价格拟定情况 | C2: 泌尿系统类立项指南项目价格拟定情况 | D2: 泌尿系统类立项指南项目价格拟定情况 | E2: 泌尿系统类立项指南项目价格拟定情况 | F2: 泌尿系统类立项指南项目价格拟定情况 | G2: 泌尿系统类立项指南项目价格拟定情况 | H2: 泌尿系统类立项指南项目价格拟定情况 | I2: 泌尿系统类立项指南项目价格拟定情况 | J2: 泌尿系统类立项指南项目价格拟定情况 | K2: 泌尿系统类立项指南项目价格拟定情况 | L2: 泌尿系统类立项指南项目价格拟定情况 | M2: 泌尿系统类立项指南项目价格拟定情况 | N2: 泌尿系统类立项指南项目价格拟定情况 | O2: 泌尿系统类立项指南项目价格拟定情况 | P2: 泌尿系统类立项指南项目价格拟定情况 | Q2: 泌尿系统类立项指南项目价格拟定情况 | R2: 泌尿系统类立项指南项目价格拟定情况 | S2: 泌尿系统类立项指南项目价格拟定情况 | T2: 泌尿系统类立项指南项目价格拟定情况 | U2: 泌尿系统类立项指南项目价格拟定情况 | V2: 泌尿系统类立项指南项目价格拟定情况 | W2: 泌尿系统类立项指南项目价格拟定情况 | X2: 泌尿系统类立项指南项目价格拟定情况 | Y2: 泌尿系统类立项指南项目价格拟定情况 | Z2: 泌尿系统类立项指南项目价格拟定情况 | AA2: 泌尿系统类立项指南项目价格拟定情况 | AB2: 泌尿系统类立项指南项目价格拟定情况 | AC2: 泌尿系统类立项指南项目价格拟定情况 | AD2: 泌尿系统类立项指南项目价格拟定情况 | AE2: 泌尿系统类立项指南项目价格拟定情况
A3: 泌尿系统类立项指南项目 | B3: 泌尿系统类立项指南项目 | C3: 泌尿系统类立项指南项目 | D3: 泌尿系统类立项指南项目 | E3: 泌尿系统类立项指南项目 | F3: 泌尿系统类立项指南项目 | G3: 泌尿系统类立项指南项目 | H3: 泌尿系统类立项指南项目 | I3: 泌尿系统类立项指南项目 | J3: 泌尿系统类立项指南项目 | K3: 泌尿系统类立项指南项目 | L3: 泌尿系统类立项指南项目 | M3: 泌尿系统类立项指南项目 | N3: 泌尿系统类立项指南项目 | O3: 泌尿系统类立项指南项目 | P3: 泌尿系统类立项指南项目 | Q3: 泌尿系统类立项指南项目 | R3: 泌尿系统类立项指南项目 | S3: 泌尿系统类立项指南项目 | T3: 现行价格项目 | U3: 现行价格项目 | V3: 现行价格项目 | W3: 现行价格项目 | X3: 现行价格项目 | Y3: 现行价格项目 | Z3: 现行价格项目 | AA3: 现行价格项目 | AB3: 现行价格项目 | AC3: 现行价格项目 | AD3: 现行价格项目 | AE3: 现行价格项目
A4: 序号 | B4: 项目代码 | C4: 项目名称 | D4: 归集口径 | E4: 服务产出 | F4: 价格构成 | G4: 计价单位 | H4: 计价说明 | I4: 省三甲价格 | J4: 省三甲以下价格 | K4: 平移价格 (市级) | L4: 平移价格 (县级) | M4: 平移价格 (基层) | N4: 拟定价格 (市级) | O4: 拟定价格 (县级) | P4: 拟定价格 (基层) | Q4: 医保属性 | R4: 调整情况 | S4: 备注 | T4: 国家结算编码 | U4: 项目编码 | V4: 项目名称 | W4: 项目内涵 | X4: 除外内容 | Y4: 计价单位 | Z4: 说明 | AA4: 三甲 | AB4: 三甲以下 | AC4: 价格 (市级) | AD4: 价格 (县级) | AE4: 价格 (基层)
A5: 1 | B5: 012411000010000 | C5: 肾盂内压检查费 | D5: 检查费 | E5: 通过各种方式测定肾盂内压，辅助判断肾盂输尿管连接部是否存在梗阻。 | F5: 所定价格涵盖放置导管、注射、观察记录、出具报告、处理用物等步骤所需的人力资源和基本物质资源消耗。 | G5: 次 | H5: “次”指双侧，单侧按50%收取。 | I5: 240 | J5: 216 | N5: 220 | O5: 200 | P5: 170 | Q5: 非医保 | R5: 新增价格 | S5: 新增价格，按比价关系拟定 | T5: 003110000140000-311000014 | U5: 311000014 | V5: 肾盂测压 | Y5: 单侧 | AF5: =IFERROR(FIND("（加收）",C5,1),0) -> 0 | AG5: =IF(AF5>0,LEFT(C5,IFERROR(FIND("-",C5,1),1)-1),C5) -> 肾盂内压检查费 | AH5: =IF(AF5>0,_xlfn.MAXIFS(N:N,C:C,AG5),0)+N5 -> 220 | AI5: =IF(AF5>0,_xlfn.MAXIFS(O:O,C:C,AG5),0)+O5 -> 200 | AJ5: =IF(AF5>0,_xlfn.MAXIFS(P:P,C:C,AG5),0)+P5 -> 170
A6: 2 | B6: 012411000020000 | C6: 尿流动力学检查费 | D6: 检查费 | E6: 通过各种方式对尿路功能状态进行评估，辅助诊断尿路功能障碍性疾病。 | F6: 所定价格涵盖检测尿流率与动力学、出具报告、处理用物等步骤所需的人力资源和基本物质资源消耗。 | G6: 次 | H6: 尿流率检测市级医院收取66元/次，县级医院收取59元/次，基层收取51元/次。 | I6: 165 | J6: 150 | K6: 165 | L6: 150 | M6: 127.5 | N6: 165 | O6: 150 | P6: 128 | Q6: 医保 | R6: 平移 | S6: 平移后，县级按不高于省级拟定，基层取整。同质化高的项目持平省级定价。 | T6: 003110000390000-311000039 | U6: 311000039 | V6: 尿流动力学检测 | W6: 不含摄片 | Y6: 次 | AA6: 165 | AB6: 150 | AC6: 165 | AD6: 150 | AE6: 127.5 | AF6: =IFERROR(FIND("（加收）",C6,1),0) -> 0 | AG6: =IF(AF6>0,LEFT(C6,IFERROR(FIND("-",C6,1),1)-1),C6) -> 尿流动力学检查费 | AH6: =IF(AF6>0,_xlfn.MAXIFS(N:N,C:C,AG6),0)+N6 -> 165 | AI6: =IF(AF6>0,_xlfn.MAXIFS(O:O,C:C,AG6),0)+O6 -> 150 | AJ6: =IF(AF6>0,_xlfn.MAXIFS(P:P,C:C,AG6),0)+P6 -> 128
A7: 2 | B7: 012411000020000 | C7: 尿流动力学检查费（尿流率检测） | K7: 66 | L7: 60 | M7: 51 | N7: 66 | O7: 59 | P7: 51 | Q7: 医保 | S7: 平移后，县级按不高于省级拟定，基层取整。同质化高的项目持平省级定价。 | T7: 003110000380000-311000038 | U7: 311000038 | V7: 尿流率检测 | Y7: 次 | AA7: 66 | AB7: 59 | AC7: 66 | AD7: 60 | AE7: 51 | AF7: =IFERROR(FIND("（加收）",C7,1),0) -> 0 | AG7: =IF(AF7>0,LEFT(C7,IFERROR(FIND("-",C7,1),1)-1),C7) -> 尿流动力学检查费（尿流率检测） | AH7: =IF(AF7>0,_xlfn.MAXIFS(N:N,C:C,AG7),0)+N7 -> 66 | AI7: =IF(AF7>0,_xlfn.MAXIFS(O:O,C:C,AG7),0)+O7 -> 59 | AJ7: =IF(AF7>0,_xlfn.MAXIFS(P:P,C:C,AG7),0)+P7 -> 51
A8: 3 | B8: 012411000030000 | C8: 泌尿系镜检查费（肾镜） | D8: 检查费 | E8: 通过肾镜观察和诊断泌尿系统疾病。 | F8: 所定价格涵盖消毒、插管、扩张通道、观察、出具报告、处理用物、必要时穿刺等步骤所需的人力资源和基本物质资源消耗。 | G8: 单侧 | I8: 660 | J8: 595 | K8: 660 | L8: 600 | M8: 510 | N8: 660 | O8: 595 | P8: 510 | Q8: 医保 | R8: 理顺 | S8: 平移后，县级按不高于省级拟定 | T8: 003110000180000-311000018 | U8: 311000018 | V8: 经皮肾盂镜检查 | W8: 含活检 | Y8: 单侧 | AA8: 660 | AB8: 595 | AC8: 660 | AD8: 600 | AE8: 510 | AF8: =IFERROR(FIND("（加收）",C8,1),0) -> 0 | AG8: =IF(AF8>0,LEFT(C8,IFERROR(FIND("-",C8,1),1)-1),C8) -> 泌尿系镜检查费（肾镜） | AH8: =IF(AF8>0,_xlfn.MAXIFS(N:N,C:C,AG8),0)+N8 -> 660 | AI8: =IF(AF8>0,_xlfn.MAXIFS(O:O,C:C,AG8),0)+O8 -> 595 | AJ8: =IF(AF8>0,_xlfn.MAXIFS(P:P,C:C,AG8),0)+P8 -> 510
A9: 4 | B9: 012411000040000 | C9: 泌尿系镜检查费（输尿管镜） | D9: 检查费 | E9: 通过输尿管镜观察和诊断泌尿系统疾病。 | F9: 所定价格涵盖消毒、插管、扩张通道、观察、出具报告、处理用物等步骤所需的人力资源和基本物质资源消耗。 | G9: 单侧 | I9: 499 | J9: 449 | K9: 495 | L9: 450 | M9: 382.5 | N9: 495 | O9: 445 | P9: 380 | Q9: 医保 | R9: 理顺，降低 | S9: 平移后，县级按不高于省级拟定，基层对应调整 | T9: 003110000200000-311000020 | U9: 311000020 | V9: 经尿道输尿管镜检查 | W9: 含活检；包括取异物 | Y9: 单侧 | AA9: 495 | AB9: 445 | AC9: 495 | AD9: 450 | AE9: 382.5 | AF9: =IFERROR(FIND("（加收）",C9,1),0) -> 0 | AG9: =IF(AF9>0,LEFT(C9,IFERROR(FIND("-",C9,1),1)-1),C9) -> 泌尿系镜检查费（输尿管镜） | AH9: =IF(AF9>0,_xlfn.MAXIFS(N:N,C:C,AG9),0)+N9 -> 495 | AI9: =IF(AF9>0,_xlfn.MAXIFS(O:O,C:C,AG9),0)+O9 -> 445 | AJ9: =IF(AF9>0,_xlfn.MAXIFS(P:P,C:C,AG9),0)+P9 -> 380
A10: 分项 | B10: 012411000040100 | C10: 泌尿系镜检查费（输尿管镜）-精囊镜检查（扩展） | D10: 检查费 | G10: 单侧 | I10: 499 | J10: 449 | K10: 720 | L10: 648 | M10: 550.8 | N10: 495 | O10: 445 | P10: 380 | Q10: 医保 | S10: 扩展项按主项价格执行 | T10: 353111000290000-311100020 | U10: 311100020 | V10: 经尿道精囊镜检查 | W10: 消毒，取Wolf4.5/6.5精囊镜连接电视成像系统，以生理盐水为灌注液，直视下将精囊镜经尿道置入膀胱，观察尿道、膀胱，将镜体退至精阜处，仔细观察射精管口，发现射精管口后稍加大灌注液速度，将镜体置入一侧射精管内，将镜体逐渐推进精囊内，观察射精管及精囊内情况，如有无结石、肿物及精囊液情况。含活检、斑马导丝。 | Y10: 侧 | AA10: 800 | AC10: 720 | AD10: 648 | AE10: 550.8 | AF10: =IFERROR(FIND("（加收）",C10,1),0) -> 0 | AG10: =IF(AF10>0,LEFT(C10,IFERROR(FIND("-",C10,1),1)-1),C10) -> 泌尿系镜检查费（输尿管镜）-精囊镜检查（扩展） | AH10: =IF(AF10>0,_xlfn.MAXIFS(N:N,C:C,AG10),0)+N10 -> 495 | AI10: =IF(AF10>0,_xlfn.MAXIFS(O:O,C:C,AG10),0)+O10 -> 445 | AJ10: =IF(AF10>0,_xlfn.MAXIFS(P:P,C:C,AG10),0)+P10 -> 380
A11: 5 | B11: 012411000050000 | C11: 泌尿系镜检查费（膀胱镜尿道镜） | D11: 检查费 | E11: 通过膀胱镜尿道镜观察和诊断泌尿系统疾病。 | F11: 所定价格涵盖消毒、插管、扩张通道、观察、出具报告、处理用物等步骤所需的人力资源和基本物质资源消耗。 | G11: 次 | I11: 132 | J11: 120 | K11: 132 | L11: 120 | M11: 102 | N11: 132 | O11: 120 | P11: 102 | Q11: 医保 | R11: 平移 | S11: 平移 | T11: 003110000340000-311000034 | U11: 311000034 | V11: 膀胱镜尿道镜检查 | W11: 含活检，包括取异物 | Y11: 次 | AA11: 132 | AB11: 120 | AC11: 132 | AD11: 120 | AE11: 102 | AF11: =IFERROR(FIND("（加收）",C11,1),0) -> 0 | AG11: =IF(AF11>0,LEFT(C11,IFERROR(FIND("-",C11,1),1)-1),C11) -> 泌尿系镜检查费（膀胱镜尿道镜） | AH11: =IF(AF11>0,_xlfn.MAXIFS(N:N,C:C,AG11),0)+N11 -> 132 | AI11: =IF(AF11>0,_xlfn.MAXIFS(O:O,C:C,AG11),0)+O11 -> 120 | AJ11: =IF(AF11>0,_xlfn.MAXIFS(P:P,C:C,AG11),0)+P11 -> 102
A12: 7 | B12: 012412000020000 | C12: 阴茎勃起检查费 | D12: 检查费 | E12: 对患者夜间或模拟夜间环境下勃起次数、持续时间、硬度分级等情况进行监测。 | F12: 所定价格涵盖消毒、设备准备、监测、读取结果、出具报告、处理用物等步骤所需的人力资源和基本物质资源消耗。 | G12: 次 | I12: 100 | J12: 90 | K12: 99 | L12: 89 | M12: 77 | N12: 99 | O12: 89 | P12: 77 | Q12: 非医保 | R12: 平移 | S12: 平移 | T12: 003111000030000-311100003 | U12: 311100003 | V12: 夜间阴茎胀大试验 | W12: 含硬度计法 | Y12: 次 | AA12: 100 | AB12: 90 | AC12: 99 | AD12: 89 | AE12: 77 | AF12: =IFERROR(FIND("（加收）",C12,1),0) -> 0 | AG12: =IF(AF12>0,LEFT(C12,IFERROR(FIND("-",C12,1),1)-1),C12) -> 阴茎勃起检查费 | AH12: =IF(AF12>0,_xlfn.MAXIFS(N:N,C:C,AG12),0)+N12 -> 99 | AI12: =IF(AF12>0,_xlfn.MAXIFS(O:O,C:C,AG12),0)+O12 -> 89 | AJ12: =IF(AF12>0,_xlfn.MAXIFS(P:P,C:C,AG12),0)+P12 -> 77
A13: 8 | B13: 012412000030000 | C13: 阴茎超声血流图检查费 | D13: 检查费 | E13: 对患者阴茎海绵体内血流情况进行检测。 | F13: 所定价格涵盖消毒、设备准备、检测、诊断、出具报告、处理用物等步骤所需的人力资源和基本物质资源消耗。 | G13: 次 | I13: 77 | J13: 69 | L13: 80 | N13: 77 | O13: 69 | P13: 60 | Q13: 非医保 | R13: 理顺，降低 | S13: 仅县级有工作量，平移后按不超过省级拟定，同质化高的项目持平省级定价。 | T13: 003111000040000-311100004 | U13: 311100004 | V13: 阴茎超声血流图检查 | Y13: 次 | AA13: 80 | AB13: 72 | AC13: 88 | AD13: 80 | AE13: 68 | AF13: =IFERROR(FIND("（加收）",C13,1),0) -> 0 | AG13: =IF(AF13>0,LEFT(C13,IFERROR(FIND("-",C13,1),1)-1),C13) -> 阴茎超声血流图检查费 | AH13: =IF(AF13>0,_xlfn.MAXIFS(N:N,C:C,AG13),0)+N13 -> 77 | AI13: =IF(AF13>0,_xlfn.MAXIFS(O:O,C:C,AG13),0)+O13 -> 69 | AJ13: =IF(AF13>0,_xlfn.MAXIFS(P:P,C:C,AG13),0)+P13 -> 60
A14: 8 | B14: 012412000030000 | C14: 阴茎超声血流图检查费 | D14: 检查费 | E14: 对患者阴茎海绵体内血流情况进行检测。 | F14: 所定价格涵盖消毒、设备准备、检测、诊断、出具报告、处理用物等步骤所需的人力资源和基本物质资源消耗。 | G14: 次 | I14: 77 | J14: 69 | L14: 80 | N14: 77 | O14: 69 | P14: 60 | Q14: 非医保 | R14: 理顺，降低 | S14: 仅县级有工作量，平移后按不超过省级拟定，同质化高的项目持平省级定价。 | T14: 003111000110000-311100011 | U14: 311100011 | V14: 阴茎动脉测压术 | Y14: 次 | AA14: 44 | AB14: 40 | AC14: 44 | AD14: 40 | AE14: 34 | AF14: =IFERROR(FIND("（加收）",C14,1),0) -> 0 | AG14: =IF(AF14>0,LEFT(C14,IFERROR(FIND("-",C14,1),1)-1),C14) -> 阴茎超声血流图检查费 | AH14: =IF(AF14>0,_xlfn.MAXIFS(N:N,C:C,AG14),0)+N14 -> 77 | AI14: =IF(AF14>0,_xlfn.MAXIFS(O:O,C:C,AG14),0)+O14 -> 69 | AJ14: =IF(AF14>0,_xlfn.MAXIFS(P:P,C:C,AG14),0)+P14 -> 60
A15: 9 | B15: 012412000040000 | C15: 阴茎勃起神经检查费 | D15: 检查费 | E15: 通过各种方式对患者勃起相关神经进行检测。 | F15: 所定价格涵盖消毒、设备准备、检测、读取结果、出具报告、处理用物等步骤所需的人力资源和基本物质资源消耗。 | G15: 次 | I15: 110 | J15: 99 | K15: 110 | L15: 100 | M15: 85 | N15: 110 | O15: 99 | P15: 85 | Q15: 非医保 | R15: 理顺 | S15: 平移后，县级按不高于省级拟定，同质化高的项目持平省级定价。 | T15: 003111000050000-311100005 | U15: 311100005 | V15: 阴茎勃起神经检查 | W15: 含肌电图检查 | Y15: 次 | AA15: 110 | AB15: 99 | AC15: 110 | AD15: 100 | AE15: 85 | AF15: =IFERROR(FIND("（加收）",C15,1),0) -> 0 | AG15: =IF(AF15>0,LEFT(C15,IFERROR(FIND("-",C15,1),1)-1),C15) -> 阴茎勃起神经检查费 | AH15: =IF(AF15>0,_xlfn.MAXIFS(N:N,C:C,AG15),0)+N15 -> 110 | AI15: =IF(AF15>0,_xlfn.MAXIFS(O:O,C:C,AG15),0)+O15 -> 99 | AJ15: =IF(AF15>0,_xlfn.MAXIFS(P:P,C:C,AG15),0)+P15 -> 85
A16: 10 | B16: 013110000010000 | C16: 血液透析费 | D16: 治疗费 | E16: 通过弥散和对流原理清除血液中过多水分和有害物质。 | F16: 所定价格涵盖消毒、穿刺、安装设定、连接管路、监测、血液回输、加压止血、封管、处理用物等步骤所需的人力资源和基本物质资源消耗。 | G16: 次 | H16: 本项目中的“监测”指：血温、血压、在线清除率、血容量监测，医院未完成全部四项监测事项的，每少完成一项监测减收5元。 | I16: 398 | J16: 398 | K16: 385 | L16: 370 | M16: 340 | N16: 385 | O16: 370 | P16: 340 | Q16: 医保 | R16: 已落地，直接平移 | S16: 2025年7月15日已落地执行 | T16: 013110000010000 | U16: 013110000010000 | V16: 血液透析费 | W16: 通过弥散和对流原理清除血液中过多水分和有害物质。 | Y16: 次 | Z16: 本项目中的“监测”指：血温、血压、在线清除率、血容量监测，医院未完成全部四项监测事项的，每少完成一项监测减收5元。 | AA16: 398 | AB16: 398 | AC16: 385 | AD16: 370 | AE16: 340 | AF16: =IFERROR(FIND("（加收）",C16,1),0) -> 0 | AG16: =IF(AF16>0,LEFT(C16,IFERROR(FIND("-",C16,1),1)-1),C16) -> 血液透析费 | AH16: =IF(AF16>0,_xlfn.MAXIFS(N:N,C:C,AG16),0)+N16 -> 385 | AI16: =IF(AF16>0,_xlfn.MAXIFS(O:O,C:C,AG16),0)+O16 -> 370 | AJ16: =IF(AF16>0,_xlfn.MAXIFS(P:P,C:C,AG16),0)+P16 -> 340
A17: 11 | B17: 013110000020000 | C17: 血液滤过费 | D17: 治疗费 | E17: 通过对流原理清除血液中过多水分和有害物质。 | F17: 所定价格涵盖消毒、穿刺、建立通路、抗凝处理、连接管路、补充置换液、清除毒素及水分、监测、封管、处理用物等步骤所需的人力资源和基本物质资源消耗。 | G17: 次 | H17: 本项目中的“监测”指：血温、血压、在线清除率、血容量监测，医院未完成全部四项监测事项的，每少完成一项监测减收5元。 | I17: 398 | J17: 398 | K17: 395 | L17: 390 | M17: 355 | N17: 395 | O17: 390 | P17: 355 | Q17: 医保 | R17: 已落地，直接平移 | S17: 2025年7月15日已落地执行 | T17: 013110000020000 | U17: 013110000020000 | V17: 血液滤过费 | W17: 通过对流原理清除血液中过多水分和有害物质。 | Y17: 次 | Z17: 本项目中的“监测”指：血温、血压、在线清除率、血容量监测，医院未完成全部四项监测事项的，每少完成一项监测减收5元。 | AA17: 398 | AB17: 398 | AC17: 395 | AD17: 390 | AE17: 355 | AF17: =IFERROR(FIND("（加收）",C17,1),0) -> 0 | AG17: =IF(AF17>0,LEFT(C17,IFERROR(FIND("-",C17,1),1)-1),C17) -> 血液滤过费 | AH17: =IF(AF17>0,_xlfn.MAXIFS(N:N,C:C,AG17),0)+N17 -> 395 | AI17: =IF(AF17>0,_xlfn.MAXIFS(O:O,C:C,AG17),0)+O17 -> 390 | AJ17: =IF(AF17>0,_xlfn.MAXIFS(P:P,C:C,AG17),0)+P17 -> 355
A18: 12 | B18: 013110000030000 | C18: 血液透析滤过费 | D18: 治疗费 | E18: 通过同时进行血液透析和血液滤过清除血液中过多水分和有害物质。 | F18: 所定价格涵盖消毒、穿刺、建立通路、连接管路、参数设置、清除毒素及水分滤过、监测、封管、处理用物等步骤所需的人力资源和基本物质资源消耗。 | G18: 次 | H18: 本项目中的“监测”指：血温、血压、在线清除率、血容量监测，医院未完成全部四项监测事项的，每少完成一项监测减收5元。 | I18: 598 | J18: 598 | K18: 590 | L18: 575 | M18: 510 | N18: 590 | O18: 575 | P18: 510 | Q18: 医保 | R18: 已落地，直接平移 | S18: 2025年7月15日已落地执行 | T18: 013110000030000 | U18: 013110000030000 | V18: 血液透析滤过费 | W18: 通过同时进行血液透析和血液滤过清除血液中过多水分和有害物质。 | Y18: 次 | Z18: 本项目中的“监测”指：血温、血压、在线清除率、血容量监测，医院未完成全部四项监测事项的，每少完成一项监测减收5元。 | AA18: 598 | AB18: 598 | AC18: 590 | AD18: 575 | AE18: 510 | AF18: =IFERROR(FIND("（加收）",C18,1),0) -> 0 | AG18: =IF(AF18>0,LEFT(C18,IFERROR(FIND("-",C18,1),1)-1),C18) -> 血液透析滤过费 | AH18: =IF(AF18>0,_xlfn.MAXIFS(N:N,C:C,AG18),0)+N18 -> 590 | AI18: =IF(AF18>0,_xlfn.MAXIFS(O:O,C:C,AG18),0)+O18 -> 575 | AJ18: =IF(AF18>0,_xlfn.MAXIFS(P:P,C:C,AG18),0)+P18 -> 510
A19: 13 | B19: 013110000040000 | C19: 血液灌流费 | D19: 治疗费 | E19: 通过吸附原理‌直接结合血液中的中大分子及蛋白结合毒素。 | F19: 所定价格涵盖消毒、穿刺、建立通路、连接管路、参数设置、血液灌流、回输、封管、处理用物等步骤所需的人力资源和基本物质资源消耗。 | G19: 次 | I19: 300 | J19: 300 | K19: 275 | L19: 260 | M19: 250 | N19: 275 | O19: 260 | P19: 250 | R19: 已落地，直接平移 | S19: 2025年7月15日已落地执行 | T19: 013110000040000 | U19: 013110000040000 | V19: 血液灌流费 | W19: 通过吸附原理‌直接结合血液中的中大分子及蛋白结合毒素。 | Y19: 次 | AA19: 300 | AB19: 300 | AC19: 275 | AD19: 260 | AE19: 250 | AF19: =IFERROR(FIND("（加收）",C19,1),0) -> 0 | AG19: =IF(AF19>0,LEFT(C19,IFERROR(FIND("-",C19,1),1)-1),C19) -> 血液灌流费 | AH19: =IF(AF19>0,_xlfn.MAXIFS(N:N,C:C,AG19),0)+N19 -> 275 | AI19: =IF(AF19>0,_xlfn.MAXIFS(O:O,C:C,AG19),0)+O19 -> 260 | AJ19: =IF(AF19>0,_xlfn.MAXIFS(P:P,C:C,AG19),0)+P19 -> 250
A20: 14 | B20: 013110000050000 | C20: 血液透析灌流费 | D20: 治疗费 | E20: 通过同时进行血液透析和血液灌流清除血液中过多水分和有害物质。 | F20: 所定价格涵盖消毒、穿刺、建立通路、连接管路、参数设置、透析灌流、监测、封管、处理用物等步骤所需的人力资源和基本物质资源消耗。 | G20: 次 | H20: 本项目中的“监测”指：血温、血压、在线清除率、血容量监测，医院未完成全部四项监测事项的，每少完成一项监测减收5元。 | I20: 620 | J20: 620 | K20: 520 | L20: 520 | M20: 440 | N20: 520 | O20: 520 | P20: 440 | Q20: 医保 | R20: 已落地，直接平移 | S20: 2025年7月15日已落地执行 | T20: 013110000050000 | U20: 013110000050000 | V20: 血液透析灌流费 | W20: 通过同时进行血液透析和血液灌流清除血液中过多水分和有害物质。 | Y20: 次 | Z20: 本项目中的“监测”指：血温、血压、在线清除率、血容量监测，医院未完成全部四项监测事项的，每少完成一项监测减收5元。 | AA20: 620 | AB20: 620 | AC20: 520 | AD20: 520 | AE20: 440 | AF20: =IFERROR(FIND("（加收）",C20,1),0) -> 0 | AG20: =IF(AF20>0,LEFT(C20,IFERROR(FIND("-",C20,1),1)-1),C20) -> 血液透析灌流费 | AH20: =IF(AF20>0,_xlfn.MAXIFS(N:N,C:C,AG20),0)+N20 -> 520 | AI20: =IF(AF20>0,_xlfn.MAXIFS(O:O,C:C,AG20),0)+O20 -> 520 | AJ20: =IF(AF20>0,_xlfn.MAXIFS(P:P,C:C,AG20),0)+P20 -> 440
A21: 15 | B21: 013110000060000 | C21: 血浆置换费 | D21: 治疗费 | E21: 分离血浆、用置换液置换含有有害物质的血浆。 | F21: 所定价格涵盖消毒、穿刺、连接管路、血浆分离置换、回输、去除装置、处理用物等步骤所需的人力资源和基本物质资源消耗。 | G21: 次 | H21: 血浆置换费使用的滤器、血浆分离器、管路按零差率销售价格另行收取相应费用。 | I21: 800 | J21: 720 | N21: 750 | O21: 700 | P21: 595 | Q21: 医保 | R21: 理顺 | S21: 2025年7月15日已落地执行，现将耗材剥离，重新制定价格。 血浆分离器、分离管路全市采购均价分别为2178元、1425元，耗材成本超过项目本身价格。 | T21: 003109050230000-310905023 | U21: 310905023 | V21: 人工肝治疗 | X21: 一次性导管 | Y21: 次 | AA21: 1600 | AB21: 1440 | AC21: 1500 | AD21: 1350 | AE21: 1145 | AF21: =IFERROR(FIND("（加收）",C21,1),0) -> 0 | AG21: =IF(AF21>0,LEFT(C21,IFERROR(FIND("-",C21,1),1)-1),C21) -> 血浆置换费 | AH21: =IF(AF21>0,_xlfn.MAXIFS(N:N,C:C,AG21),0)+N21 -> 750 | AI21: =IF(AF21>0,_xlfn.MAXIFS(O:O,C:C,AG21),0)+O21 -> 700 | AJ21: =IF(AF21>0,_xlfn.MAXIFS(P:P,C:C,AG21),0)+P21 -> 595
A22: 15 | B22: 013110000060000 | C22: 血浆置换费 | D22: 治疗费 | E22: 分离血浆、用置换液置换含有有害物质的血浆。 | F22: 所定价格涵盖消毒、穿刺、连接管路、血浆分离置换、回输、去除装置、处理用物等步骤所需的人力资源和基本物质资源消耗。 | G22: 次 | H22: 血浆置换费使用的滤器、血浆分离器、管路按零差率销售价格另行收取相应费用。 | I22: 800 | J22: 720 | N22: 750 | O22: 700 | P22: 595 | Q22: 医保 | R22: 理顺 | S22: 2025年7月15日已落地执行，现将耗材剥离，重新制定价格。 血浆分离器、分离管路全市采购均价分别为2178元、1425元，耗材成本超过项目本身价格。 | T22: 013110000060000 | U22: 013110000060000 | V22: 血浆置换费 | W22: 分离血浆、用置换液置换含有有害物质的血浆。 | AA22: 2600 | AB22: 2340 | AC22: 2450 | AD22: 2325 | AE22: 2000 | AF22: =IFERROR(FIND("（加收）",C22,1),0) -> 0 | AG22: =IF(AF22>0,LEFT(C22,IFERROR(FIND("-",C22,1),1)-1),C22) -> 血浆置换费 | AH22: =IF(AF22>0,_xlfn.MAXIFS(N:N,C:C,AG22),0)+N22 -> 750 | AI22: =IF(AF22>0,_xlfn.MAXIFS(O:O,C:C,AG22),0)+O22 -> 700 | AJ22: =IF(AF22>0,_xlfn.MAXIFS(P:P,C:C,AG22),0)+P22 -> 595
A23: 17 | B23: 013110000080000 | C23: 连续性肾脏替代治疗费 | D23: 治疗费 | E23: 通过血液净化实现连续肾脏替代治疗和多脏器功能衰竭的生命支持治疗。 | F23: 所定价格涵盖消毒、穿刺、连接管路、上机、血液净化、体外抗凝、回输、去除装置、处理用物等步骤所需的人力资源和基本物质资源消耗。 | G23: 小时 | H23: 连续性肾脏替代治疗使用的滤器、管路按零差率销售价格另行收取相应费用。 | I23: 96 | J23: 96 | K23: 95 | L23: 95 | M23: 86 | N23: 95 | O23: 95 | P23: 86 | Q23: 医保 | R23: 已落地，直接平移 | S23: 新家 | T23: 013110000080000 | U23: 013110000080000 | V23: 连续性肾脏替代治疗费 | Y23: 小时 | AA23: 96 | AB23: 96 | AC23: 95 | AD23: 95 | AE23: 86 | AF23: =IFERROR(FIND("（加收）",C23,1),0) -> 0 | AG23: =IF(AF23>0,LEFT(C23,IFERROR(FIND("-",C23,1),1)-1),C23) -> 连续性肾脏替代治疗费 | AH23: =IF(AF23>0,_xlfn.MAXIFS(N:N,C:C,AG23),0)+N23 -> 95 | AI23: =IF(AF23>0,_xlfn.MAXIFS(O:O,C:C,AG23),0)+O23 -> 95 | AJ23: =IF(AF23>0,_xlfn.MAXIFS(P:P,C:C,AG23),0)+P23 -> 86
A24: 分项 | B24: 013110000080001 | C24: 连续性肾脏替代治疗费-连续性血浆吸附滤过治疗（加收） | D24: 治疗费 | G24: 小时 | I24: 30 | J24: 30 | K24: 28 | L24: 28 | M24: 25 | N24: 28 | O24: 28 | P24: 25 | Q24: 医保 | S24: 2025年7月15日已落地执行 | T24: 013110000080001 | U24: 013110000080001 | V24: 连续性肾脏替代治疗费-连续性血浆吸附滤过治疗（加收） | Y24: 小时 | AA24: 30 | AB24: 30 | AC24: 28 | AD24: 28 | AE24: 25 | AF24: =IFERROR(FIND("（加收）",C24,1),0) -> 23 | AG24: =IF(AF24>0,LEFT(C24,IFERROR(FIND("-",C24,1),1)-1),C24) -> 连续性肾脏替代治疗费 | AH24: =IF(AF24>0,_xlfn.MAXIFS(N:N,C:C,AG24),0)+N24 -> 123 | AI24: =IF(AF24>0,_xlfn.MAXIFS(O:O,C:C,AG24),0)+O24 -> 123 | AJ24: =IF(AF24>0,_xlfn.MAXIFS(P:P,C:C,AG24),0)+P24 -> 111
A25: 23 | B25: 013110000140000 | C25: 腹膜透析外管更换费 | D25: 治疗费 | E25: 通过各种方式更换腹膜透析外接短管。 | F25: 所定价格涵盖消毒、更换管路、封管、处理用物等步骤所需的人力资源和基本物质资源消耗。 | G25: 次 | I25: 45 | J25: 41 | K25: 40 | L25: 40 | M25: 34 | N25: 42 | O25: 40 | P25: 34 | Q25: 医保 | R25: 理顺 | S25: 2025年7月15日已在“腹膜透析换管费”说明中落地执行，此次调整市级理顺比价 | T25: 013311000020000 | U25: 013311000020000 | V25: 腹膜透析换管费（更换外管） | Y25: 次 | AF25: =IFERROR(FIND("（加收）",C25,1),0) -> 0 | AG25: =IF(AF25>0,LEFT(C25,IFERROR(FIND("-",C25,1),1)-1),C25) -> 腹膜透析外管更换费 | AH25: =IF(AF25>0,_xlfn.MAXIFS(N:N,C:C,AG25),0)+N25 -> 42 | AI25: =IF(AF25>0,_xlfn.MAXIFS(O:O,C:C,AG25),0)+O25 -> 40 | AJ25: =IF(AF25>0,_xlfn.MAXIFS(P:P,C:C,AG25),0)+P25 -> 34
A26: 24 | B26: 013110000150000 | C26: 腹膜平衡试验费 | D26: 治疗费 | E26: 对腹膜功能进行检测，调整腹膜透析方案。 | F26: 所定价格涵盖腹透换液、留取标本、测量、计算、出具方案、处理用物等步骤所需的人力资源和基本物质资源消耗。 | G26: 次 | I26: 45 | J26: 41 | K26: 40 | L26: 40 | M26: 34 | N26: 42 | O26: 40 | P26: 34 | Q26: 医保 | R26: 理顺 | S26: 2025年7月15日已落地执行，此次调整市级理顺比价 | T26: 013110000150000 | U26: 013110000150000 | V26: 腹膜平衡试验费 | W26: 对腹膜功能进行检测，调整腹膜透析方案。 | Y26: 次 | AA26: 45 | AB26: 41 | AC26: 40 | AD26: 40 | AE26: 34 | AF26: =IFERROR(FIND("（加收）",C26,1),0) -> 0 | AG26: =IF(AF26>0,LEFT(C26,IFERROR(FIND("-",C26,1),1)-1),C26) -> 腹膜平衡试验费 | AH26: =IF(AF26>0,_xlfn.MAXIFS(N:N,C:C,AG26),0)+N26 -> 42 | AI26: =IF(AF26>0,_xlfn.MAXIFS(O:O,C:C,AG26),0)+O26 -> 40 | AJ26: =IF(AF26>0,_xlfn.MAXIFS(P:P,C:C,AG26),0)+P26 -> 34
A27: 25 | B27: 013311000010000 | C27: 腹膜透析置管费 | D27: 手术费 | E27: 通过各种方式放置腹膜透析导管。 | F27: 所定价格涵盖消毒、切开、穿刺或分离、置管、试水通畅、缝合、处理用物等步骤所需的人力资源和基本物质资源消耗。 | G27: 次 | I27: 440 | J27: 395 | K27: 400 | L27: 400 | M27: 340 | N27: 420 | O27: 395 | P27: 340 | Q27: 医保 | R27: 理顺 | S27: 2025年7月15日已落地执行，现微调市级、县级价格以理顺比价 | T27: 013311000010000 | U27: 013311000010000 | V27: 腹膜透析置管费 | W27: 通过各种方式放置腹膜透析导管。 | Y27: 次 | AA27: 440 | AB27: 395 | AC27: 400 | AD27: 400 | AE27: 340 | AF27: =IFERROR(FIND("（加收）",C27,1),0) -> 0 | AG27: =IF(AF27>0,LEFT(C27,IFERROR(FIND("-",C27,1),1)-1),C27) -> 腹膜透析置管费 | AH27: =IF(AF27>0,_xlfn.MAXIFS(N:N,C:C,AG27),0)+N27 -> 420 | AI27: =IF(AF27>0,_xlfn.MAXIFS(O:O,C:C,AG27),0)+O27 -> 395 | AJ27: =IF(AF27>0,_xlfn.MAXIFS(P:P,C:C,AG27),0)+P27 -> 340
A28: 26 | B28: 013311000020000 | C28: 腹膜透析换管费 | D28: 手术费 | E28: 更换破损、堵塞、移位的腹膜透析导管。 | F28: 所定价格涵盖消毒、切开、拔除旧管、原位置入新管、试水通畅、缝合、处理用物等步骤所需的人力资源和基本物质资源消耗。 | G28: 次 | H28: 不与“腹膜透析置管费”“腹膜透析导管取出费”“腹膜透析导管感染清创费”同时收取。 | I28: 440 | J28: 395 | K28: 420 | L28: 420 | M28: 360 | N28: 420 | O28: 395 | P28: 340 | Q28: 医保 | R28: 理顺 | S28: 2025年7月15日已落地执行，现调整说明，更换外管独立设立项目 微调价格理顺比价 | T28: 013311000020000 | U28: 013311000020000 | V28: 腹膜透析换管费 | W28: 更换破损、堵塞、移位的腹膜透析导管。 | Y28: 次 | Z28: 不与“腹膜透析置管费”“腹膜透析导管取出费”“腹膜透析导管感染清创费”同时收取。更换外管市、县级按40元收取，基层按34元收取。 | AA28: 440 | AB28: 395 | AC28: 420 | AD28: 420 | AE28: 360 | AF28: =IFERROR(FIND("（加收）",C28,1),0) -> 0 | AG28: =IF(AF28>0,LEFT(C28,IFERROR(FIND("-",C28,1),1)-1),C28) -> 腹膜透析换管费 | AH28: =IF(AF28>0,_xlfn.MAXIFS(N:N,C:C,AG28),0)+N28 -> 420 | AI28: =IF(AF28>0,_xlfn.MAXIFS(O:O,C:C,AG28),0)+O28 -> 395 | AJ28: =IF(AF28>0,_xlfn.MAXIFS(P:P,C:C,AG28),0)+P28 -> 340
A29: 31 | B29: 013110000190000 | C29: 体外冲击波碎石费 | D29: 治疗费 | E29: 通过冲击波聚焦能量，裂解尿路结石，便于结石排出。 | F29: 所定价格涵盖体位摆放、机器校准、能量释放、结石裂解、排出体外等步骤所需的人力资源和基本物质资源消耗。 | G29: 次 | H29: 第二次碎石市级医院收取350元/次，县级医院收取315元/次，基层收取268元/次；第三次碎石市级医院收取175元/次，县级医院收取158元/次，基层收取134元/次；第四次起不收费。 | I29: 700 | J29: 630 | K29: 700 | L29: 630 | M29: 535.5 | N29: 700 | O29: 630 | P29: 535 | Q29: 医保 | R29: 平移 | S29: 平移，取整 | T29: 003110000400000-311000040 | U29: 311000040 | V29: 体外冲击波碎石 | W29: 含影像学监测,不含摄片 | Y29: 次 | Z29: 第二次碎石按全价50%计价，第三次按25%计价，第四次起不收费。 | AA29: 700 | AB29: 630 | AC29: 700 | AD29: 630 | AE29: 535.5 | AF29: =IFERROR(FIND("（加收）",C29,1),0) -> 0 | AG29: =IF(AF29>0,LEFT(C29,IFERROR(FIND("-",C29,1),1)-1),C29) -> 体外冲击波碎石费 | AH29: =IF(AF29>0,_xlfn.MAXIFS(N:N,C:C,AG29),0)+N29 -> 700 | AI29: =IF(AF29>0,_xlfn.MAXIFS(O:O,C:C,AG29),0)+O29 -> 630 | AJ29: =IF(AF29>0,_xlfn.MAXIFS(P:P,C:C,AG29),0)+P29 -> 535
A30: 31 | B30: 013110000190000 | C30: 体外冲击波碎石费（第二次） | D30: 治疗费 | G30: 次 | I30: 350 | J30: 315 | K30: 350 | L30: 315 | M30: 267.75 | N30: 350 | O30: 315 | P30: 268 | S30: 平移，取整 | T30: 003110000400000-31100004003 | U30: 31100004003 | V30: 体外冲击波碎石（第二次） | Y30: 次 | Z30: 第二次 | AA30: 350 | AB30: 315 | AC30: 350 | AD30: 315 | AE30: 267.8 | AF30: =IFERROR(FIND("（加收）",C30,1),0) -> 0 | AG30: =IF(AF30>0,LEFT(C30,IFERROR(FIND("-",C30,1),1)-1),C30) -> 体外冲击波碎石费（第二次） | AH30: =IF(AF30>0,_xlfn.MAXIFS(N:N,C:C,AG30),0)+N30 -> 350 | AI30: =IF(AF30>0,_xlfn.MAXIFS(O:O,C:C,AG30),0)+O30 -> 315 | AJ30: =IF(AF30>0,_xlfn.MAXIFS(P:P,C:C,AG30),0)+P30 -> 268
A31: 31 | B31: 013110000190000 | C31: 体外冲击波碎石费（第三次） | D31: 治疗费 | G31: 次 | I31: 175 | J31: 158 | K31: 175 | L31: 157.5 | M31: 133.875 | N31: 175 | O31: 158 | P31: 134 | S31: 平移，取整 | T31: 003110000400000-31100004006 | U31: 31100004006 | V31: 体外冲击波碎石（第三次） | Y31: 次 | Z31: 第三次 | AA31: 175 | AB31: 158 | AC31: 175 | AD31: 157.5 | AE31: 133.9 | AF31: =IFERROR(FIND("（加收）",C31,1),0) -> 0 | AG31: =IF(AF31>0,LEFT(C31,IFERROR(FIND("-",C31,1),1)-1),C31) -> 体外冲击波碎石费（第三次） | AH31: =IF(AF31>0,_xlfn.MAXIFS(N:N,C:C,AG31),0)+N31 -> 175 | AI31: =IF(AF31>0,_xlfn.MAXIFS(O:O,C:C,AG31),0)+O31 -> 158 | AJ31: =IF(AF31>0,_xlfn.MAXIFS(P:P,C:C,AG31),0)+P31 -> 134
A32: 32 | B32: 013110000200000 | C32: 泌尿系镜下治疗费（常规） | D32: 治疗费 | E32: 通过置物、取物等方式对泌尿系统及男性生殖系统病灶进行治疗。 | F32: 所定价格涵盖消毒、下镜、治疗、撤镜等步骤所需的人力资源和基本物质资源消耗。（不含泌尿系镜下检查） | G32: 次 | H32: 同时行常规治疗和特殊治疗的，按照“泌尿系镜下治疗费（特殊）”收取。 | I32: 825 | J32: 743 | K32: 817.32836 | L32: 741.1044 | M32: 640.94595 | N32: 815 | O32: 740 | P32: 640 | Q32: 医保 | R32: 平移取整 | S32: 加权平移取整 | T32: 003110000190200-31100001901 | U32: 31100001901 | V32: 经皮肾盂镜取石术（取异物） | Y32: 次 | Z32: 取异物 | AA32: 880 | AB32: 790 | AC32: 880 | AD32: 800 | AE32: 680 | AF32: =IFERROR(FIND("（加收）",C32,1),0) -> 0 | AG32: =IF(AF32>0,LEFT(C32,IFERROR(FIND("-",C32,1),1)-1),C32) -> 泌尿系镜下治疗费（常规） | AH32: =IF(AF32>0,_xlfn.MAXIFS(N:N,C:C,AG32),0)+N32 -> 815 | AI32: =IF(AF32>0,_xlfn.MAXIFS(O:O,C:C,AG32),0)+O32 -> 740 | AJ32: =IF(AF32>0,_xlfn.MAXIFS(P:P,C:C,AG32),0)+P32 -> 640
A33: 32 | B33: 013110000200000 | C33: 泌尿系镜下治疗费（常规） | D33: 治疗费 | E33: 通过置物、取物等方式对泌尿系统及男性生殖系统病灶进行治疗。 | F33: 所定价格涵盖消毒、下镜、治疗、撤镜等步骤所需的人力资源和基本物质资源消耗。（不含泌尿系镜下检查） | G33: 次 | H33: 同时行常规治疗和特殊治疗的，按照“泌尿系镜下治疗费（特殊）”收取。 | I33: 825 | J33: 743 | K33: 817.32836 | L33: 741.1044 | M33: 640.94595 | N33: 815 | O33: 740 | P33: 640 | Q33: 医保 | R33: 平移取整 | S33: 加权平移取整 | T33: 003311030270000-331103027 | U33: 331103027 | V33: 经尿道膀胱碎石取石术 | W33: 包括血块、异物取出 | Y33: 次 | AA33: 1250 | AB33: 1125 | AC33: 1250 | AD33: 1200 | AE33: 1020 | AF33: =IFERROR(FIND("（加收）",C33,1),0) -> 0 | AG33: =IF(AF33>0,LEFT(C33,IFERROR(FIND("-",C33,1),1)-1),C33) -> 泌尿系镜下治疗费（常规） | AH33: =IF(AF33>0,_xlfn.MAXIFS(N:N,C:C,AG33),0)+N33 -> 815 | AI33: =IF(AF33>0,_xlfn.MAXIFS(O:O,C:C,AG33),0)+O33 -> 740 | AJ33: =IF(AF33>0,_xlfn.MAXIFS(P:P,C:C,AG33),0)+P33 -> 640
A34: 32 | B34: 013110000200000 | C34: 泌尿系镜下治疗费（常规） | D34: 治疗费 | E34: 通过置物、取物等方式对泌尿系统及男性生殖系统病灶进行治疗。 | F34: 所定价格涵盖消毒、下镜、治疗、撤镜等步骤所需的人力资源和基本物质资源消耗。（不含泌尿系镜下检查） | G34: 次 | H34: 同时行常规治疗和特殊治疗的，按照“泌尿系镜下治疗费（特殊）”收取。 | I34: 825 | J34: 743 | K34: 817.32836 | L34: 741.1044 | M34: 640.94595 | N34: 815 | O34: 740 | P34: 640 | Q34: 医保 | R34: 平移取整 | S34: 加权平移取整 | T34: 003311030270000-33110302701 | U34: 33110302701 | V34: 小儿经尿道膀胱碎石取石术 | Y34: 次 | AA34: 1625 | AB34: 1465 | AC34: 1625 | AD34: 1560 | AE34: 1325 | AF34: =IFERROR(FIND("（加收）",C34,1),0) -> 0 | AG34: =IF(AF34>0,LEFT(C34,IFERROR(FIND("-",C34,1),1)-1),C34) -> 泌尿系镜下治疗费（常规） | AH34: =IF(AF34>0,_xlfn.MAXIFS(N:N,C:C,AG34),0)+N34 -> 815 | AI34: =IF(AF34>0,_xlfn.MAXIFS(O:O,C:C,AG34),0)+O34 -> 740 | AJ34: =IF(AF34>0,_xlfn.MAXIFS(P:P,C:C,AG34),0)+P34 -> 640
A35: 32 | B35: 013110000200000 | C35: 泌尿系镜下治疗费（常规） | D35: 治疗费 | E35: 通过置物、取物等方式对泌尿系统及男性生殖系统病灶进行治疗。 | F35: 所定价格涵盖消毒、下镜、治疗、撤镜等步骤所需的人力资源和基本物质资源消耗。（不含泌尿系镜下检查） | G35: 次 | H35: 同时行常规治疗和特殊治疗的，按照“泌尿系镜下治疗费（特殊）”收取。 | I35: 825 | J35: 743 | K35: 817.32836 | L35: 741.1044 | M35: 640.94595 | N35: 815 | O35: 740 | P35: 640 | Q35: 医保 | R35: 平移取整 | S35: 加权平移取整 | T35: 003110000200000-311000020 | U35: 311000020 | V35: 经尿道输尿管镜检查 | W35: 含活检；包括取异物 | Y35: 单侧 | AA35: 495 | AB35: 445 | AC35: 495 | AD35: 450 | AE35: 382.5 | AF35: =IFERROR(FIND("（加收）",C35,1),0) -> 0 | AG35: =IF(AF35>0,LEFT(C35,IFERROR(FIND("-",C35,1),1)-1),C35) -> 泌尿系镜下治疗费（常规） | AH35: =IF(AF35>0,_xlfn.MAXIFS(N:N,C:C,AG35),0)+N35 -> 815 | AI35: =IF(AF35>0,_xlfn.MAXIFS(O:O,C:C,AG35),0)+O35 -> 740 | AJ35: =IF(AF35>0,_xlfn.MAXIFS(P:P,C:C,AG35),0)+P35 -> 640
A36: 32 | B36: 013110000200000 | C36: 泌尿系镜下治疗费（常规） | D36: 治疗费 | E36: 通过置物、取物等方式对泌尿系统及男性生殖系统病灶进行治疗。 | F36: 所定价格涵盖消毒、下镜、治疗、撤镜等步骤所需的人力资源和基本物质资源消耗。（不含泌尿系镜下检查） | G36: 次 | H36: 同时行常规治疗和特殊治疗的，按照“泌尿系镜下治疗费（特殊）”收取。 | I36: 825 | J36: 743 | K36: 817.32836 | L36: 741.1044 | M36: 640.94595 | N36: 815 | O36: 740 | P36: 640 | Q36: 医保 | R36: 平移取整 | S36: 加权平移取整 | T36: 003110000370000-311000037 | U36: 311000037 | V36: 经尿道治疗尿失禁 | W36: 含硬化剂局部注射 | Y36: 次 | AA36: 220 | AB36: 200 | AC36: 220 | AD36: 200 | AE36: 170 | AF36: =IFERROR(FIND("（加收）",C36,1),0) -> 0 | AG36: =IF(AF36>0,LEFT(C36,IFERROR(FIND("-",C36,1),1)-1),C36) -> 泌尿系镜下治疗费（常规） | AH36: =IF(AF36>0,_xlfn.MAXIFS(N:N,C:C,AG36),0)+N36 -> 815 | AI36: =IF(AF36>0,_xlfn.MAXIFS(O:O,C:C,AG36),0)+O36 -> 740 | AJ36: =IF(AF36>0,_xlfn.MAXIFS(P:P,C:C,AG36),0)+P36 -> 640
A37: 32 | B37: 013110000200000 | C37: 泌尿系镜下治疗费（常规） | D37: 治疗费 | E37: 通过置物、取物等方式对泌尿系统及男性生殖系统病灶进行治疗。 | F37: 所定价格涵盖消毒、下镜、治疗、撤镜等步骤所需的人力资源和基本物质资源消耗。（不含泌尿系镜下检查） | G37: 次 | H37: 同时行常规治疗和特殊治疗的，按照“泌尿系镜下治疗费（特殊）”收取。 | I37: 825 | J37: 743 | K37: 817.32836 | L37: 741.1044 | M37: 640.94595 | N37: 815 | O37: 740 | P37: 640 | Q37: 医保 | R37: 平移取整 | S37: 加权平移取整 | T37: 003312010070000-331201007 | U37: 331201007 | V37: 经尿道前列腺气囊扩张术 | X37: 气囊导管 | Y37: 次 | AA37: 250 | AB37: 225 | AC37: 250 | AD37: 240 | AE37: 204 | AF37: =IFERROR(FIND("（加收）",C37,1),0) -> 0 | AG37: =IF(AF37>0,LEFT(C37,IFERROR(FIND("-",C37,1),1)-1),C37) -> 泌尿系镜下治疗费（常规） | AH37: =IF(AF37>0,_xlfn.MAXIFS(N:N,C:C,AG37),0)+N37 -> 815 | AI37: =IF(AF37>0,_xlfn.MAXIFS(O:O,C:C,AG37),0)+O37 -> 740 | AJ37: =IF(AF37>0,_xlfn.MAXIFS(P:P,C:C,AG37),0)+P37 -> 640
A38: 32 | B38: 013110000200000 | C38: 泌尿系镜下治疗费（常规） | D38: 治疗费 | E38: 通过置物、取物等方式对泌尿系统及男性生殖系统病灶进行治疗。 | F38: 所定价格涵盖消毒、下镜、治疗、撤镜等步骤所需的人力资源和基本物质资源消耗。（不含泌尿系镜下检查） | G38: 次 | H38: 同时行常规治疗和特殊治疗的，按照“泌尿系镜下治疗费（特殊）”收取。 | I38: 825 | J38: 743 | K38: 817.32836 | L38: 741.1044 | M38: 640.94595 | N38: 815 | O38: 740 | P38: 640 | Q38: 医保 | R38: 平移取整 | S38: 加权平移取整 | T38: 003312010070000-33120100701 | U38: 33120100701 | V38: 小儿经尿道前列腺气囊扩张术 | Y38: 次 | AA38: 325 | AB38: 295 | AC38: 325 | AD38: 310 | AE38: 265 | AF38: =IFERROR(FIND("（加收）",C38,1),0) -> 0 | AG38: =IF(AF38>0,LEFT(C38,IFERROR(FIND("-",C38,1),1)-1),C38) -> 泌尿系镜下治疗费（常规） | AH38: =IF(AF38>0,_xlfn.MAXIFS(N:N,C:C,AG38),0)+N38 -> 815 | AI38: =IF(AF38>0,_xlfn.MAXIFS(O:O,C:C,AG38),0)+O38 -> 740 | AJ38: =IF(AF38>0,_xlfn.MAXIFS(P:P,C:C,AG38),0)+P38 -> 640
A39: 32 | B39: 013110000200000 | C39: 泌尿系镜下治疗费（常规） | D39: 治疗费 | E39: 通过置物、取物等方式对泌尿系统及男性生殖系统病灶进行治疗。 | F39: 所定价格涵盖消毒、下镜、治疗、撤镜等步骤所需的人力资源和基本物质资源消耗。（不含泌尿系镜下检查） | G39: 次 | H39: 同时行常规治疗和特殊治疗的，按照“泌尿系镜下治疗费（特殊）”收取。 | I39: 825 | J39: 743 | K39: 817.32836 | L39: 741.1044 | M39: 640.94595 | N39: 815 | O39: 740 | P39: 640 | Q39: 医保 | R39: 平移取整 | S39: 加权平移取整 | T39: 003312010070000-33120100702 | U39: 33120100702 | V39: 经膀胱镜经尿道前列腺气囊扩张术 | Y39: 次 | AA39: 500 | AB39: 450 | AC39: 500 | AD39: 465 | AE39: 394 | AF39: =IFERROR(FIND("（加收）",C39,1),0) -> 0 | AG39: =IF(AF39>0,LEFT(C39,IFERROR(FIND("-",C39,1),1)-1),C39) -> 泌尿系镜下治疗费（常规） | AH39: =IF(AF39>0,_xlfn.MAXIFS(N:N,C:C,AG39),0)+N39 -> 815 | AI39: =IF(AF39>0,_xlfn.MAXIFS(O:O,C:C,AG39),0)+O39 -> 740 | AJ39: =IF(AF39>0,_xlfn.MAXIFS(P:P,C:C,AG39),0)+P39 -> 640
A40: 32 | B40: 013110000200000 | C40: 泌尿系镜下治疗费（常规） | D40: 治疗费 | E40: 通过置物、取物等方式对泌尿系统及男性生殖系统病灶进行治疗。 | F40: 所定价格涵盖消毒、下镜、治疗、撤镜等步骤所需的人力资源和基本物质资源消耗。（不含泌尿系镜下检查） | G40: 次 | H40: 同时行常规治疗和特殊治疗的，按照“泌尿系镜下治疗费（特殊）”收取。 | I40: 825 | J40: 743 | K40: 817.32836 | L40: 741.1044 | M40: 640.94595 | N40: 815 | O40: 740 | P40: 640 | Q40: 医保 | R40: 平移取整 | S40: 加权平移取整 | T40: 003312010070000-33120100703 | U40: 33120100703 | V40: 小儿经膀胱镜经尿道前列腺气囊扩张术 | Y40: 次 | AA40: 575 | AB40: 520 | AC40: 575 | AD40: 535 | AE40: 455 | AF40: =IFERROR(FIND("（加收）",C40,1),0) -> 0 | AG40: =IF(AF40>0,LEFT(C40,IFERROR(FIND("-",C40,1),1)-1),C40) -> 泌尿系镜下治疗费（常规） | AH40: =IF(AF40>0,_xlfn.MAXIFS(N:N,C:C,AG40),0)+N40 -> 815 | AI40: =IF(AF40>0,_xlfn.MAXIFS(O:O,C:C,AG40),0)+O40 -> 740 | AJ40: =IF(AF40>0,_xlfn.MAXIFS(P:P,C:C,AG40),0)+P40 -> 640
...

Sheet Sheet1
A1: id | B1: code | C1: sever_type | D1: change_time | E1: old_hilist_code | F1: new_hilist_code | G1: hilist_name | H1: selfpay_prop | I1: old_price | J1: old_price_city | K1: old_price_town | L1: old_price_village | M1: new_price | N1: new_price_city | O1: new_price_town | P1: new_price_village | Q1: unit | R1: batch | S1: is_use_old | T1: merge_type | U1: cnt_change_model | V1: cnt_change_value | W1: ="insert into server_list_change_all_20250525 ("&_xlfn.TEXTJOIN(",",TRUE,A1:V1)&") values" -> insert into server_list_change_all_20250525 (id,code,sever_type,change_time,old_hilist_code,new_hilist_code,hilist_name,selfpay_prop,old_price,old_price_city,old_price_town,old_price_village,new_price,new_price_city,new_price_town,new_price_village,unit,batch,is_use_old,merge_type,cnt_change_model,cnt_change_value) values
A2: 3094 | B2: null | C2: 1 | D2: 2026-04-28 00:00:00 | E2: 003110000390000-311000039 | F2: 003110000390000-311000039 | G2: 尿流动力学检测 | H2: null | I2: null | J2: 165 | K2: 150 | L2: 127.5 | M2: null | N2: 165 | O2: 150 | P2: 128 | Q2: 次 | R2: 27 | S2: 1 | T2: normal | U2: main | V2: 0 | W2: ="("&A2&","&B2&","&C2&",'"&D2&"','"&E2&"','"&F2&"','"&G2&"',"&H2&","&I2&","&J2&","&K2&","&L2&","&M2&","&N2&","&O2&","&P2&",'"&Q2&"',"&R2&","&S2&",'"&T2&"','"&U2&"',"&V2&")," -> (3094,null,1,'2026-04-28 00:00:00','003110000390000-311000039','003110000390000-311000039','尿流动力学检测',null,null,165,150,127.5,null,165,150,128,'次',27,1,'normal','main',0),
A3: 3095 | B3: null | C3: 1 | D3: 2026-04-28 00:00:00 | E3: 003110000380000-311000038 | F3: 003110000380000-311000038 | G3: 尿流率检测 | H3: null | I3: null | J3: 66 | K3: 60 | L3: 51 | M3: null | N3: 66 | O3: 59 | P3: 51 | Q3: 次 | R3: 27 | S3: 1 | T3: normal | U3: main | V3: 0 | W3: ="("&A3&","&B3&","&C3&",'"&D3&"','"&E3&"','"&F3&"','"&G3&"',"&H3&","&I3&","&J3&","&K3&","&L3&","&M3&","&N3&","&O3&","&P3&",'"&Q3&"',"&R3&","&S3&",'"&T3&"','"&U3&"',"&V3&")," -> (3095,null,1,'2026-04-28 00:00:00','003110000380000-311000038','003110000380000-311000038','尿流率检测',null,null,66,60,51,null,66,59,51,'次',27,1,'normal','main',0),
A4: 3096 | B4: null | C4: 1 | D4: 2026-04-28 00:00:00 | E4: 003110000180000-311000018 | F4: 003110000180000-311000018 | G4: 经皮肾盂镜检查 | H4: null | I4: null | J4: 660 | K4: 600 | L4: 510 | M4: null | N4: 660 | O4: 595 | P4: 510 | Q4: 单侧 | R4: 27 | S4: 1 | T4: normal | U4: main | V4: 0 | W4: ="("&A4&","&B4&","&C4&",'"&D4&"','"&E4&"','"&F4&"','"&G4&"',"&H4&","&I4&","&J4&","&K4&","&L4&","&M4&","&N4&","&O4&","&P4&",'"&Q4&"',"&R4&","&S4&",'"&T4&"','"&U4&"',"&V4&")," -> (3096,null,1,'2026-04-28 00:00:00','003110000180000-311000018','003110000180000-311000018','经皮肾盂镜检查',null,null,660,600,510,null,660,595,510,'单侧',27,1,'normal','main',0),
A5: 3097 | B5: null | C5: 1 | D5: 2026-04-28 00:00:00 | E5: 003110000200000-311000020 | F5: 003110000200000-311000020 | G5: 经尿道输尿管镜检查 | H5: null | I5: null | J5: 495 | K5: 450 | L5: 382.5 | M5: null | N5: 495 | O5: 445 | P5: 380 | Q5: 单侧 | R5: 27 | S5: 1 | T5: normal | U5: main | V5: 0 | W5: ="("&A5&","&B5&","&C5&",'"&D5&"','"&E5&"','"&F5&"','"&G5&"',"&H5&","&I5&","&J5&","&K5&","&L5&","&M5&","&N5&","&O5&","&P5&",'"&Q5&"',"&R5&","&S5&",'"&T5&"','"&U5&"',"&V5&")," -> (3097,null,1,'2026-04-28 00:00:00','003110000200000-311000020','003110000200000-311000020','经尿道输尿管镜检查',null,null,495,450,382.5,null,495,445,380,'单侧',27,1,'normal','main',0),
A6: 3098 | B6: null | C6: 1 | D6: 2026-04-28 00:00:00 | E6: 353111000290000-311100020 | F6: 353111000290000-311100020 | G6: 经尿道精囊镜检查 | H6: null | I6: null | J6: 720 | K6: 648 | L6: 550.8 | M6: null | N6: 495 | O6: 445 | P6: 380 | Q6: 侧 | R6: 27 | S6: 1 | T6: normal | U6: main | V6: 0 | W6: ="("&A6&","&B6&","&C6&",'"&D6&"','"&E6&"','"&F6&"','"&G6&"',"&H6&","&I6&","&J6&","&K6&","&L6&","&M6&","&N6&","&O6&","&P6&",'"&Q6&"',"&R6&","&S6&",'"&T6&"','"&U6&"',"&V6&")," -> (3098,null,1,'2026-04-28 00:00:00','353111000290000-311100020','353111000290000-311100020','经尿道精囊镜检查',null,null,720,648,550.8,null,495,445,380,'侧',27,1,'normal','main',0),
A7: 3099 | B7: null | C7: 1 | D7: 2026-04-28 00:00:00 | E7: 003110000340000-311000034 | F7: 003110000340000-311000034 | G7: 膀胱镜尿道镜检查 | H7: null | I7: null | J7: 132 | K7: 120 | L7: 102 | M7: null | N7: 132 | O7: 120 | P7: 102 | Q7: 次 | R7: 27 | S7: 1 | T7: normal | U7: main | V7: 0 | W7: ="("&A7&","&B7&","&C7&",'"&D7&"','"&E7&"','"&F7&"','"&G7&"',"&H7&","&I7&","&J7&","&K7&","&L7&","&M7&","&N7&","&O7&","&P7&",'"&Q7&"',"&R7&","&S7&",'"&T7&"','"&U7&"',"&V7&")," -> (3099,null,1,'2026-04-28 00:00:00','003110000340000-311000034','003110000340000-311000034','膀胱镜尿道镜检查',null,null,132,120,102,null,132,120,102,'次',27,1,'normal','main',0),
A8: 3100 | B8: null | C8: 1 | D8: 2026-04-28 00:00:00 | E8: 003111000030000-311100003 | F8: 003111000030000-311100003 | G8: 夜间阴茎胀大试验 | H8: null | I8: null | J8: 99 | K8: 89 | L8: 77 | M8: null | N8: 99 | O8: 89 | P8: 77 | Q8: 次 | R8: 27 | S8: 1 | T8: normal | U8: main | V8: 0 | W8: ="("&A8&","&B8&","&C8&",'"&D8&"','"&E8&"','"&F8&"','"&G8&"',"&H8&","&I8&","&J8&","&K8&","&L8&","&M8&","&N8&","&O8&","&P8&",'"&Q8&"',"&R8&","&S8&",'"&T8&"','"&U8&"',"&V8&")," -> (3100,null,1,'2026-04-28 00:00:00','003111000030000-311100003','003111000030000-311100003','夜间阴茎胀大试验',null,null,99,89,77,null,99,89,77,'次',27,1,'normal','main',0),
A9: 3101 | B9: null | C9: 1 | D9: 2026-04-28 00:00:00 | E9: 003111000040000-311100004 | F9: 003111000040000-311100004 | G9: 阴茎超声血流图检查 | H9: null | I9: null | J9: 88 | K9: 80 | L9: 68 | M9: null | N9: 77 | O9: 69 | P9: 60 | Q9: 次 | R9: 27 | S9: 1 | T9: normal | U9: main | V9: 0 | W9: ="("&A9&","&B9&","&C9&",'"&D9&"','"&E9&"','"&F9&"','"&G9&"',"&H9&","&I9&","&J9&","&K9&","&L9&","&M9&","&N9&","&O9&","&P9&",'"&Q9&"',"&R9&","&S9&",'"&T9&"','"&U9&"',"&V9&")," -> (3101,null,1,'2026-04-28 00:00:00','003111000040000-311100004','003111000040000-311100004','阴茎超声血流图检查',null,null,88,80,68,null,77,69,60,'次',27,1,'normal','main',0),
A10: 3102 | B10: null | C10: 1 | D10: 2026-04-28 00:00:00 | E10: 003111000110000-311100011 | F10: 003111000110000-311100011 | G10: 阴茎动脉测压术 | H10: null | I10: null | J10: 44 | K10: 40 | L10: 34 | M10: null | N10: 77 | O10: 69 | P10: 60 | Q10: 次 | R10: 27 | S10: 1 | T10: normal | U10: main | V10: 0 | W10: ="("&A10&","&B10&","&C10&",'"&D10&"','"&E10&"','"&F10&"','"&G10&"',"&H10&","&I10&","&J10&","&K10&","&L10&","&M10&","&N10&","&O10&","&P10&",'"&Q10&"',"&R10&","&S10&",'"&T10&"','"&U10&"',"&V10&")," -> (3102,null,1,'2026-04-28 00:00:00','003111000110000-311100011','003111000110000-311100011','阴茎动脉测压术',null,null,44,40,34,null,77,69,60,'次',27,1,'normal','main',0),
A11: 3103 | B11: null | C11: 1 | D11: 2026-04-28 00:00:00 | E11: 003111000050000-311100005 | F11: 003111000050000-311100005 | G11: 阴茎勃起神经检查 | H11: null | I11: null | J11: 110 | K11: 100 | L11: 85 | M11: null | N11: 110 | O11: 99 | P11: 85 | Q11: 次 | R11: 27 | S11: 1 | T11: normal | U11: main | V11: 0 | W11: ="("&A11&","&B11&","&C11&",'"&D11&"','"&E11&"','"&F11&"','"&G11&"',"&H11&","&I11&","&J11&","&K11&","&L11&","&M11&","&N11&","&O11&","&P11&",'"&Q11&"',"&R11&","&S11&",'"&T11&"','"&U11&"',"&V11&")," -> (3103,null,1,'2026-04-28 00:00:00','003111000050000-311100005','003111000050000-311100005','阴茎勃起神经检查',null,null,110,100,85,null,110,99,85,'次',27,1,'normal','main',0),
A12: 3104 | B12: null | C12: 1 | D12: 2026-04-28 00:00:00 | E12: 003109050230000-310905023 | F12: 003109050230000-310905023 | G12: 人工肝治疗 | H12: null | I12: null | J12: 1500 | K12: 1350 | L12: 1145 | M12: null | N12: 2250 | O12: 2050 | P12: 1740 | Q12: 次 | R12: 27 | S12: 1 | T12: normal | U12: main | V12: 0 | W12: ="("&A12&","&B12&","&C12&",'"&D12&"','"&E12&"','"&F12&"','"&G12&"',"&H12&","&I12&","&J12&","&K12&","&L12&","&M12&","&N12&","&O12&","&P12&",'"&Q12&"',"&R12&","&S12&",'"&T12&"','"&U12&"',"&V12&")," -> (3104,null,1,'2026-04-28 00:00:00','003109050230000-310905023','003109050230000-310905023','人工肝治疗',null,null,1500,1350,1145,null,2250,2050,1740,'次',27,1,'normal','main',0),
A13: 3105 | B13: null | C13: 1 | D13: 2026-04-28 00:00:00 | E13: 013110000060000 | F13: 013110000060000 | G13: 血浆置换费 | H13: null | I13: null | J13: 2450 | K13: 2325 | L13: 2000 | M13: null | N13: 3200 | O13: 3025 | P13: 2595 | R13: 27 | S13: 1 | T13: normal | U13: main | V13: 0 | W13: ="("&A13&","&B13&","&C13&",'"&D13&"','"&E13&"','"&F13&"','"&G13&"',"&H13&","&I13&","&J13&","&K13&","&L13&","&M13&","&N13&","&O13&","&P13&",'"&Q13&"',"&R13&","&S13&",'"&T13&"','"&U13&"',"&V13&")," -> (3105,null,1,'2026-04-28 00:00:00','013110000060000','013110000060000','血浆置换费',null,null,2450,2325,2000,null,3200,3025,2595,'',27,1,'normal','main',0),
A14: 3106 | B14: null | C14: 1 | D14: 2026-04-28 00:00:00 | E14: 013110000150000 | F14: 013110000150000 | G14: 腹膜平衡试验费 | H14: null | I14: null | J14: 40 | K14: 40 | L14: 34 | M14: null | N14: 42 | O14: 40 | P14: 34 | Q14: 次 | R14: 27 | S14: 1 | T14: normal | U14: main | V14: 0 | W14: ="("&A14&","&B14&","&C14&",'"&D14&"','"&E14&"','"&F14&"','"&G14&"',"&H14&","&I14&","&J14&","&K14&","&L14&","&M14&","&N14&","&O14&","&P14&",'"&Q14&"',"&R14&","&S14&",'"&T14&"','"&U14&"',"&V14&")," -> (3106,null,1,'2026-04-28 00:00:00','013110000150000','013110000150000','腹膜平衡试验费',null,null,40,40,34,null,42,40,34,'次',27,1,'normal','main',0),
A15: 3107 | B15: null | C15: 1 | D15: 2026-04-28 00:00:00 | E15: 013311000010000 | F15: 013311000010000 | G15: 腹膜透析置管费 | H15: null | I15: null | J15: 400 | K15: 400 | L15: 340 | M15: null | N15: 420 | O15: 395 | P15: 340 | Q15: 次 | R15: 27 | S15: 1 | T15: normal | U15: main | V15: 0 | W15: ="("&A15&","&B15&","&C15&",'"&D15&"','"&E15&"','"&F15&"','"&G15&"',"&H15&","&I15&","&J15&","&K15&","&L15&","&M15&","&N15&","&O15&","&P15&",'"&Q15&"',"&R15&","&S15&",'"&T15&"','"&U15&"',"&V15&")," -> (3107,null,1,'2026-04-28 00:00:00','013311000010000','013311000010000','腹膜透析置管费',null,null,400,400,340,null,420,395,340,'次',27,1,'normal','main',0),
A16: 3108 | B16: null | C16: 1 | D16: 2026-04-28 00:00:00 | E16: 003110000010000-311000001 | F16: 003110000010000-311000001 | G16: 腹膜透析置管费 | H16: null | I16: null | J16: 400 | K16: 400 | L16: 340 | M16: null | N16: 420 | O16: 395 | P16: 340 | Q16: 次 | R16: 27 | S16: 1 | T16: normal | U16: main | V16: 0 | W16: ="("&A16&","&B16&","&C16&",'"&D16&"','"&E16&"','"&F16&"','"&G16&"',"&H16&","&I16&","&J16&","&K16&","&L16&","&M16&","&N16&","&O16&","&P16&",'"&Q16&"',"&R16&","&S16&",'"&T16&"','"&U16&"',"&V16&")," -> (3108,null,1,'2026-04-28 00:00:00','003110000010000-311000001','003110000010000-311000001','腹膜透析置管费',null,null,400,400,340,null,420,395,340,'次',27,1,'normal','main',0),
A17: 3109 | B17: null | C17: 1 | D17: 2026-04-28 00:00:00 | E17: 013311000020000 | F17: 013311000020000 | G17: 腹膜透析换管费 | H17: null | I17: null | J17: 420 | K17: 420 | L17: 360 | M17: null | N17: 420 | O17: 395 | P17: 340 | Q17: 次 | R17: 27 | S17: 1 | T17: normal | U17: main | V17: 0 | W17: ="("&A17&","&B17&","&C17&",'"&D17&"','"&E17&"','"&F17&"','"&G17&"',"&H17&","&I17&","&J17&","&K17&","&L17&","&M17&","&N17&","&O17&","&P17&",'"&Q17&"',"&R17&","&S17&",'"&T17&"','"&U17&"',"&V17&")," -> (3109,null,1,'2026-04-28 00:00:00','013311000020000','013311000020000','腹膜透析换管费',null,null,420,420,360,null,420,395,340,'次',27,1,'normal','main',0),
A18: 3110 | B18: null | C18: 1 | D18: 2026-04-28 00:00:00 | E18: 013110000170000 | F18: 013110000170000 | G18: 腹膜透析导管取出费 | H18: null | I18: null | J18: 400 | K18: 400 | L18: 340 | M18: null | N18: 420 | O18: 395 | P18: 340 | Q18: 次 | R18: 27 | S18: 1 | T18: normal | U18: main | V18: 0 | W18: ="("&A18&","&B18&","&C18&",'"&D18&"','"&E18&"','"&F18&"','"&G18&"',"&H18&","&I18&","&J18&","&K18&","&L18&","&M18&","&N18&","&O18&","&P18&",'"&Q18&"',"&R18&","&S18&",'"&T18&"','"&U18&"',"&V18&")," -> (3110,null,1,'2026-04-28 00:00:00','013110000170000','013110000170000','腹膜透析导管取出费',null,null,400,400,340,null,420,395,340,'次',27,1,'normal','main',0),
A19: 3111 | B19: null | C19: 1 | D19: 2026-04-28 00:00:00 | E19: 003110000010100-31100000101 | F19: 003110000010100-31100000101 | G19: 腹膜透析导管取出费 | H19: null | I19: null | J19: 400 | K19: 400 | L19: 340 | M19: null | N19: 420 | O19: 395 | P19: 340 | Q19: 次 | R19: 27 | S19: 1 | T19: normal | U19: main | V19: 0 | W19: ="("&A19&","&B19&","&C19&",'"&D19&"','"&E19&"','"&F19&"','"&G19&"',"&H19&","&I19&","&J19&","&K19&","&L19&","&M19&","&N19&","&O19&","&P19&",'"&Q19&"',"&R19&","&S19&",'"&T19&"','"&U19&"',"&V19&")," -> (3111,null,1,'2026-04-28 00:00:00','003110000010100-31100000101','003110000010100-31100000101','腹膜透析导管取出费',null,null,400,400,340,null,420,395,340,'次',27,1,'normal','main',0),
A20: 3112 | B20: null | C20: 1 | D20: 2026-04-28 00:00:00 | E20: 003110000400000-311000040 | F20: 003110000400000-311000040 | G20: 体外冲击波碎石 | H20: null | I20: null | J20: 700 | K20: 630 | L20: 535.5 | M20: null | N20: 700 | O20: 630 | P20: 535 | Q20: 次 | R20: 27 | S20: 1 | T20: normal | U20: main | V20: 0 | W20: ="("&A20&","&B20&","&C20&",'"&D20&"','"&E20&"','"&F20&"','"&G20&"',"&H20&","&I20&","&J20&","&K20&","&L20&","&M20&","&N20&","&O20&","&P20&",'"&Q20&"',"&R20&","&S20&",'"&T20&"','"&U20&"',"&V20&")," -> (3112,null,1,'2026-04-28 00:00:00','003110000400000-311000040','003110000400000-311000040','体外冲击波碎石',null,null,700,630,535.5,null,700,630,535,'次',27,1,'normal','main',0),
A21: 3113 | B21: null | C21: 1 | D21: 2026-04-28 00:00:00 | E21: 003110000400000-31100004003 | F21: 003110000400000-31100004003 | G21: 体外冲击波碎石（第二次） | H21: null | I21: null | J21: 350 | K21: 315 | L21: 267.8 | M21: null | N21: 350 | O21: 315 | P21: 268 | Q21: 次 | R21: 27 | S21: 1 | T21: normal | U21: main | V21: 0 | W21: ="("&A21&","&B21&","&C21&",'"&D21&"','"&E21&"','"&F21&"','"&G21&"',"&H21&","&I21&","&J21&","&K21&","&L21&","&M21&","&N21&","&O21&","&P21&",'"&Q21&"',"&R21&","&S21&",'"&T21&"','"&U21&"',"&V21&")," -> (3113,null,1,'2026-04-28 00:00:00','003110000400000-31100004003','003110000400000-31100004003','体外冲击波碎石（第二次）',null,null,350,315,267.8,null,350,315,268,'次',27,1,'normal','main',0),
A22: 3114 | B22: null | C22: 1 | D22: 2026-04-28 00:00:00 | E22: 003110000400000-31100004006 | F22: 003110000400000-31100004006 | G22: 体外冲击波碎石（第三次） | H22: null | I22: null | J22: 175 | K22: 157.5 | L22: 133.9 | M22: null | N22: 175 | O22: 158 | P22: 134 | Q22: 次 | R22: 27 | S22: 1 | T22: normal | U22: main | V22: 0 | W22: ="("&A22&","&B22&","&C22&",'"&D22&"','"&E22&"','"&F22&"','"&G22&"',"&H22&","&I22&","&J22&","&K22&","&L22&","&M22&","&N22&","&O22&","&P22&",'"&Q22&"',"&R22&","&S22&",'"&T22&"','"&U22&"',"&V22&")," -> (3114,null,1,'2026-04-28 00:00:00','003110000400000-31100004006','003110000400000-31100004006','体外冲击波碎石（第三次）',null,null,175,157.5,133.9,null,175,158,134,'次',27,1,'normal','main',0),
A23: 3115 | B23: null | C23: 1 | D23: 2026-04-28 00:00:00 | E23: 003110000190200-31100001901 | F23: 003110000190200-31100001901 | G23: 经皮肾盂镜取石术（取异物） | H23: null | I23: null | J23: 880 | K23: 800 | L23: 680 | M23: null | N23: 815 | O23: 740 | P23: 640 | Q23: 次 | R23: 27 | S23: 1 | T23: normal | U23: main | V23: 0 | W23: ="("&A23&","&B23&","&C23&",'"&D23&"','"&E23&"','"&F23&"','"&G23&"',"&H23&","&I23&","&J23&","&K23&","&L23&","&M23&","&N23&","&O23&","&P23&",'"&Q23&"',"&R23&","&S23&",'"&T23&"','"&U23&"',"&V23&")," -> (3115,null,1,'2026-04-28 00:00:00','003110000190200-31100001901','003110000190200-31100001901','经皮肾盂镜取石术（取异物）',null,null,880,800,680,null,815,740,640,'次',27,1,'normal','main',0),
A24: 3116 | B24: null | C24: 1 | D24: 2026-04-28 00:00:00 | E24: 003311030270000-331103027 | F24: 003311030270000-331103027 | G24: 经尿道膀胱碎石取石术 | H24: null | I24: null | J24: 1250 | K24: 1200 | L24: 1020 | M24: null | N24: 815 | O24: 740 | P24: 640 | Q24: 次 | R24: 27 | S24: 1 | T24: normal | U24: main | V24: 0 | W24: ="("&A24&","&B24&","&C24&",'"&D24&"','"&E24&"','"&F24&"','"&G24&"',"&H24&","&I24&","&J24&","&K24&","&L24&","&M24&","&N24&","&O24&","&P24&",'"&Q24&"',"&R24&","&S24&",'"&T24&"','"&U24&"',"&V24&")," -> (3116,null,1,'2026-04-28 00:00:00','003311030270000-331103027','003311030270000-331103027','经尿道膀胱碎石取石术',null,null,1250,1200,1020,null,815,740,640,'次',27,1,'normal','main',0),
