Workbook

Sheet Sheet1
A1: 附件2
A2: 神经系统类立项指南项目价格拟定情况
A3: 神经系统立项指南项目 | V3: 现行价格项目（颅内镜辅助操作费用纳入测算）
A4: 序号 | B4: 项目代码 | C4: 项目名称 | D4: 归集口径 | E4: 服务产出 | F4: 价格构成 | G4: 计价单位 | H4: 计价说明 | I4: 省三甲价格 | J4: 省三甲以下价格 | K4: 平移价格 (市级) | L4: 平移价格 (县级) | M4: 平移价格 (基层) | N4: 拟定价格 (市级) | O4: 拟定价格 (县级) | P4: 拟定价格 (基层) | Q4: 医保属性 | R4: 医保限定支付范围 | S4: 个人先行自付比例 | T4: 调整情况 | U4: 备注 | V4: 国家结算编码 | W4: 项目编码 | X4: 项目名称 | Y4: 项目内涵 | Z4: 除外内容 | AA4: 计价单位 | AB4: 说明 | AC4: 三甲 | AD4: 三甲以下 | AE4: 价格 (市级) | AF4: 价格 (县级) | AG4: 价格 (基层) | AH4: 医保属性 | AI4: 医保限定支付范围 | AJ4: 个人先行自付比例
A5: 1 | B5: 012401000010000 | C5: 脑电图检查费 | D5: 检查费 | E5: 通过脑电图仪器采集分析脑电活动。 | F5: 所定价格涵盖设备准备、安装、记录、分析、出具报告等步骤所需的人力资源和基本物质资源消耗。 | G5: 次 | H5: 1.本项目所称“特殊电极脑电图检查”指：使用鼻咽、蝶骨、皮层特殊电极进行脑电图检查。 2.本项目所称“特殊诱发脑电图检查”指：光、电等特殊诱发后进行脑电图检查。 3.本项目所称“高密度脑电图”指：128导联及以上脑电图。 4.4个小时及以内按一次收费，4个小时以上每增加1小时加收15%。 | I5: 100 | J5: 90 | K5: 97.670576 | L5: 89.622122 | M5: 59.874352 | N5: 98 | O5: 90 | P5: 78 | Q5: 医保 | S5: 0.2 | T5: 平移取整 | U5: 加权平移取整，基层调整理顺比价 | V5: 003101000010000-310100001 | W5: 310100001 | X5: 脑电图 | Y5: 含深呼吸诱发，至少8导 | AA5: 次 | AB5: 脑电发生源定位加收50%；术中监测基层17元/小时，县级医院20元/小时，市级医院22元/小时 | AC5: 40 | AD5: 36 | AE5: 33 | AF5: 30 | AG5: 25.5 | AH5: 医保
C6: 脑电图检查费 | V6: 003101000010001-31010000101 | W6: 31010000101 | X6: 脑电图（脑电发生源定位） | AA6: 次 | AB6: 脑电发生源定位 | AC6: 65 | AD6: 59 | AE6: 49.5 | AF6: 45 | AG6: 38.3 | AH6: 医保
C7: 脑电图检查费 | V7: 003101000030000-310100003 | W7: 310100003 | X7: 脑地形图 | Y7: 含二维脑地形图(至少16导) | AA7: 次 | AC7: 115 | AD7: 105 | AE7: 110 | AF7: 100 | AG7: 85 | AH7: 医保 | AJ7: 0.2
C8: 脑电图检查费 | V8: 003101000040000-310100004 | W8: 310100004 | X8: 动态脑电图 | Y8: 包括24小时脑电视频监测或脑电Holter | AA8: 次 | AC8: 286 | AD8: 255 | AE8: 286 | AF8: 260 | AG8: 221 | AH8: 医保 | AJ8: 0.2
C9: 脑电图检查费 | V9: 003101000040100-31010000401 | W9: 31010000401 | X9: 动态脑电图（24小时脑电视频监测） | AA9: 次 | AB9: 24小时脑电视频监测 | AC9: 286 | AD9: 255 | AE9: 286 | AF9: 260 | AG9: 221 | AH9: 医保 | AJ9: 0.2
C10: 脑电图检查费 | V10: 003101000040200-31010000402 | W10: 31010000402 | X10: 动态脑电图（24小时脑电Holter） | AA10: 次 | AB10: 24小时脑电Holter | AC10: 286 | AD10: 255 | AE10: 286 | AF10: 260 | AG10: 221 | AH10: 医保 | AJ10: 0.2
C11: 脑电图检查费 | V11: 003101000050000-310100005 | W11: 310100005 | X11: 脑电图录象监测 | Y11: 含摄像观测患者行为及脑电图监测 | AA11: 小时 | AB11: 颅内电极视频脑电图录像监测市级115元/小时，县级105元/小时，基层95元/小时。 | AC11: 25 | AD11: 23 | AE11: 27.5 | AF11: 25 | AG11: 21.3 | AH11: 医保 | AJ11: 0.2
A12: 分项 | B12: 012401000010001 | C12: 脑电图检查费-床旁（加收） | D12: 检查费 | G12: 次 | I12: 10 | J12: 9 | N12: 9 | O12: 8 | P12: 7 | Q12: 医保 | U12: 新增加收项目，按比价关系拟定（床旁统一加收价格）
A13: 分项 | B13: 012401000010011 | C13: 脑电图检查费-特殊电极脑电图检查（加收） | D13: 检查费 | G13: 次 | I13: 10 | J13: 9 | N13: =N12 -> 9 | O13: =O12 -> 8 | P13: =P12 -> 7 | Q13: 医保 | S13: 0.2 | U13: 省级按项目间及区域间比价关系定价，我市按比价关系拟定。（同床旁加收） | V13: 003101000020000-310100002 | W13: 310100002 | X13: 特殊脑电图 | Y13: 包括特殊电极(鼻咽或蝶骨或皮层等)、特殊诱发 | AA13: 次 | AC13: 90 | AD13: 81 | AE13: 66 | AF13: 60 | AG13: 51 | AH13: 医保
C14: 脑电图检查费-特殊电极脑电图检查（加收） | V14: 003101000020100-31010000201 | W14: 31010000201 | X14: 特殊脑电图（特殊电极鼻咽或蝶骨或皮层等） | AA14: 次 | AB14: 特殊电极(鼻咽或蝶骨或皮层等) | AC14: 90 | AD14: 81 | AE14: 66 | AF14: 60 | AG14: 51 | AH14: 医保
A15: 分项 | B15: 012401000010021 | C15: 脑电图检查费-特殊诱发脑电图检查（加收） | D15: 检查费 | G15: 次 | I15: 10 | J15: 9 | N15: =N12 -> 9 | O15: =O12 -> 8 | P15: =P12 -> 7 | Q15: 医保 | S15: 0.2 | U15: 省级按项目间及区域间比价关系定价，我市按比价关系拟定。（同床旁加收） | V15: 003101000020200-31010000202 | W15: 31010000202 | X15: 特殊脑电图（特殊诱发） | AA15: 次 | AB15: 特殊诱发 | AC15: 90 | AD15: 81 | AE15: 66 | AF15: 60 | AG15: 51 | AH15: 医保
A16: 分项 | B16: 012401000010031 | C16: 脑电图检查费-高密度脑电图检查（加收） | D16: 检查费 | G16: 次 | H16: 4个小时及以内按一次收费，4个小时以上每增加1小时加收15%。 | I16: 150 | J16: 135 | N16: =N5*1.5 -> 147 | O16: =O5*1.5 -> 135 | P16: =P5*1.5 -> 117 | Q16: 医保 | S16: 0.2 | U16: 无开展量，按项目间比价关系拟定 | V16: 003101000050000-31010000501 | W16: 31010000501 | X16: 颅内电极视频脑电图录像监测 | Y16: 颅内脑电图是一种癫痫外科术前的评估手段，通过前期置入颅内电极，在癫痫视频脑电监测单元记录颅内大脑表面皮层和大脑深部电活动并直接电刺激，并同期录像患者临床表现确定局灶性癫痫患者致痫区，可定位一些致痫区位于的局灶性癫痫。 | AA16: 小时 | AC16: 120 | AE16: 115 | AF16: 105 | AG16: 95
A17: 2 | B17: 012401000020000 | C17: 脑磁图检查费 | D17: 检查费 | E17: 通过仪器采集分析脑磁图电波。 | F17: 所定价格涵盖设备准备、安装、定位、采集、记录、出具报告等步骤所需的人力资源和基本物质资源消耗。 | G17: 次 | H17: 脑功能区定位三甲医院按照1400元/次收取，三甲以下医院按照1260元/次收取。 脑功能区定位市级医院按照1300元/次收取，县级医院按照1200元/次收取，基层按1020元/次收取。 | I17: 4200 | J17: 3780 | N17: 3900 | O17: 3600 | P17: =O17*0.85 -> 3060 | Q17: 非医保 | T17: 新增价格 | U17: 新增价格，检查适当缩小价差 | V17: 003101000060000-310100006 | W17: 310100006 | X17: 脑磁图 | AA17: 次
A18: 分项 | B18: 012401000020000 | C18: 脑磁图检查费（脑功能区定位） | D18: 检查费 | G18: 次 | I18: 1400 | J18: 1260 | N18: =N17/3 -> 1300 | O18: =O17/3 -> 1200 | P18: =P17/3 -> 1020 | U18: 新增加收项目，按主项的1/3拟定
A19: 3 | B19: 012401000030000 | C19: 针极肌电图检查费 | D19: 检查费 | E19: 通过仪器采集分析静息状态或特定运动中各组肌群数据。 | F19: 所定价格涵盖设备准备、安装、采集、分析、出具报告等步骤所需的人力资源和基本物质资源消耗。 | G19: 次 | H19: 1.次指1条肌肉，每增加1条肌肉加收50%，以12条肌肉费用设置封顶线。 2.震颤分析按单侧（头部左右侧、单肢）收费。 | I19: 30 | J19: 27 | K19: 22.152263 | L19: 20.001238 | M19: 17 | N19: 27 | O19: 25 | P19: 21 | Q19: 医保 | R19: 限有明确的神经肌肉功能障碍，每年医保支付不超过4次，医保支付间隔时间不短于14天。 | T19: 理顺，提高 | U19: 我市原项目价格仅为省级价格的73.3%，现提高理顺。 | V19: 003101000150000-310100015 | W19: 310100015 | X19: 感觉阈值测量 | Y19: 包括感觉障碍电生理诊断 | AA19: 次
C20: 针极肌电图检查费 | V20: 003101000210000-310100021 | W20: 310100021 | X20: 植物神经功能检查 | AA20: 次 | AC20: 20 | AD20: 18 | AE20: 22 | AF20: 20 | AG20: 17 | AH20: 医保
C21: 针极肌电图检查费 | V21: 003101000220000-310100022 | W21: 310100022 | X21: 多功能神经肌肉功能监测 | Y21: 包括表面肌电测定 | AA21: 小时 | AC21: 5 | AD21: 4.5 | AE21: 4.5 | AF21: 4 | AG21: 3.5 | AH21: 医保
C22: 针极肌电图检查费 | V22: 003101000220100-31010002201 | W22: 31010002201 | X22: 多功能神经肌肉功能监测（表面肌电测定） | AA22: 小时 | AC22: 5 | AD22: 4.5 | AE22: 4.5 | AF22: 4 | AG22: 3.5 | AH22: 医保
C23: 针极肌电图检查费 | V23: 003101000230000-310100023 | W23: 310100023 | X23: 肌电图 | Y23: 包括眼肌电图 | Z23: 一次性针电极 | AA23: 每条肌肉 | AC23: 30 | AD23: 27 | AE23: 22 | AF23: 20 | AG23: 17 | AH23: 医保 | AI23: 限有明确的神经肌肉功能障碍，一个疾病过程支付不超过两次。
C24: 针极肌电图检查费 | V24: 003101000260000-310100026 | W24: 310100026 | X24: 多轨迹断层肌电图 | AA24: 次 | AC24: 90 | AD24: 81 | AE24: 66 | AF24: 60 | AG24: 51 | AH24: 医保
C25: 针极肌电图检查费 | V25: 003105040030000-310504003 | W25: 310504003 | X25: 面神经肌电图检查 | Y25: 1.包括额、眼、上唇及下唇四个功能区；2.每功能区均含双侧 | AA25: 每区 | AC25: 20 | AD25: 20 | AE25: 21 | AF25: 20 | AG25: 17 | AH25: 医保
A26: 分项 | B26: 012401000030001 | C26: 针极肌电图检查费-床旁（加收） | D26: 检查费 | G26: 次 | I26: 10 | J26: 9 | N26: 9 | O26: 8 | P26: 7 | Q26: 医保 | U26: 新增加收项目，按比价关系拟定（床旁统一加收价格）
A27: 分项 | B27: 012401000030011 | C27: 针极肌电图检查费-单纤维检查（加收） | D27: 检查费 | G27: 次 | I27: 30 | J27: 27 | K27: 17 | L27: 15 | M27: 13 | N27: =N19 -> 27 | O27: =O19 -> 25 | P27: =P19 -> 21 | Q27: 医保 | R27: 限有明确的神经肌肉功能障碍，每年医保支付不超过4次，医保支付间隔时间不短于14天。 | U27: 我市原项目价格仅为省级价格的73.3%，现提高理顺。 | V27: 003101000240000-310100024 | W27: 310100024 | X27: 单纤维肌电图 | AA27: 每条肌肉 | AC27: 60 | AD27: 54 | AE27: 44 | AF27: 40 | AG27: 34 | AH27: 医保
A28: 分项 | B28: 012401000030021 | C28: 针极肌电图检查费-震颤分析（加收） | D28: 检查费 | G28: 单侧 | I28: 30 | J28: 27 | N28: =N19 -> 27 | O28: =O19 -> 25 | P28: =P19 -> 21 | Q28: 医保 | R28: 限有明确的神经肌肉功能障碍，每年医保支付不超过4次，医保支付间隔时间不短于14天。
A29: 4 | B29: 012401000040000 | C29: 神经传导速度测定费 | D29: 检查费 | E29: 通过仪器对感觉神经或混合神经进行测量。 | F29: 所定价格涵盖设备准备、安装、刺激、分析、出具报告等步骤所需的人力资源和基本物质资源消耗。 | G29: 每根神经 | H29: 长时程运动诱发试验按次收费。 | I29: 22 | J29: 20 | K29: 22 | L29: 20 | M29: 17 | N29: 22 | O29: 20 | P29: 17 | Q29: 医保 | T29: 平移 | U29: 平移，同质化高的检查项目持平省级定价 | V29: 003101000070000-310100007 | W29: 310100007 | X29: 神经传导速度测定 | Y29: 含感觉神经与运动神经传导速度、重复神经电刺激 | AA29: 每条神经 | AC29: 22 | AD29: 20 | AE29: 22 | AF29: 20 | AG29: 17 | AH29: 医保
A30: 分项 | B30: 012401000040001 | C30: 神经传导速度测定费-床旁（加收） | D30: 检查费 | G30: 每根神经 | I30: 10 | J30: 9 | N30: 9 | O30: 8 | P30: 7 | Q30: 医保 | U30: 新增加收项目，按比价关系拟定（床旁统一加收价格）
A31: 分项 | B31: 012401000040011 | C31: 神经传导速度测定费-长时程运动诱发试验（加收） | D31: 检查费 | G31: 次 | I31: 100 | J31: 90 | N31: 90 | O31: 82 | P31: 70 | Q31: 医保 | U31: 新增加收项目，按比价关系拟定
A32: 分项 | B32: 012401000040021 | C32: 神经传导速度测定费-寸移运动神经传导测定（加收） | D32: 检查费 | G32: 每根神经 | H32: 每增加一根神经可加收50%。 | I32: 50 | J32: 45 | N32: 45 | O32: 41 | P32: 35 | Q32: 医保 | U32: 新增加收项目，按比价关系拟定
A33: 5 | B33: 012401000050000 | C33: 神经电图费 | D33: 检查费 | E33: 通过仪器刺激周围神经，评定H反射、F波、瞬目反射以及重复神经电刺激等周围神经功能。 | F33: 所定价格涵盖设备准备、安装、刺激、记录、分析、出具报告等步骤所需的人力资源和基本物质资源消耗。 | G33: 次 | I33: 120 | J33: 108 | K33: 110 | L33: 100 | M33: 85 | N33: 110 | O33: 100 | P33: 85 | Q33: 医保 | T33: 平移 | U33: 计价单位改变，根据临床实际，每人次检查约4.8根神经，取整按5根神经计算 | V33: 003101000080000-310100008 | W33: 310100008 | X33: 神经电图 | Y33: 含检查F波、H反射、瞬目反射及重复神经电刺激 | AA33: 每条神经 | AC33: 30 | AD33: 27 | AE33: 22 | AF33: 20 | AG33: 17 | AH33: 医保
A34: 分项 | B34: 012401000050001 | C34: 神经电图费-床旁（加收） | D34: 检查费 | G34: 次 | I34: 10 | J34: 9 | N34: 9 | O34: 8 | P34: 7 | Q34: 医保 | U34: 新增加收项目，按比价关系拟定（床旁统一加收价格）
A35: 6 | B35: 012401000060000 | C35: 皮肤交感反应检查费 | D35: 检查费 | E35: 通过仪器刺激对四肢交感神经功能进行检查。 | F35: 所定价格涵盖设备准备、安装、刺激、采集、分析、出具报告等步骤所需的人力资源和基本物质资源消耗。 | G35: 次 | I35: 47 | J35: 42 | N35: 43 | O35: 39 | P35: 33 | Q35: 非医保 | T35: 新增价格 | U35: 新增加收项目，按比价关系拟定
A36: 7 | B36: 012401000070000 | C36: 事件相关电位费 | D36: 检查费 | E36: 通过采集脑诱发电位，对患者注意力、记忆力等认知功能进行评估。 | F36: 所定价格涵盖设备准备、安装、刺激、采集、分析、出具报告等步骤所需的人力资源和基本物质资源消耗。 | G36: 项 | H36: 以3项费用设置封顶线。 | I36: 66 | J36: 59 | K36: 66 | L36: 60 | M36: 51 | N36: 66 | O36: 59 | P36: 51 | Q36: 医保 | T36: 理顺，降低 | U36: 平移后县级按不高于省级拟定 | V36: 003101000110000-310100011 | W36: 310100011 | X36: 事件相关电位 | Y36: 包括视觉、体感刺激P300与听觉P300 | AA36: 次 | AB36: 增加N400检查加收50% | AC36: 66 | AD36: 59 | AE36: 66 | AF36: 60 | AG36: 51 | AH36: 医保
C37: 事件相关电位费 | V37: 003101000110001-31010001101 | W37: 31010001101 | X37: 事件相关电位（增加N400检查） | AA37: 次 | AB37: 增加N400检查 | AC37: 99 | AD37: 89 | AE37: 99 | AF37: 90 | AG37: 76.5 | AH37: 医保
A38: 8 | B38: 012401000080000 | C38: 脑干听觉诱发电位费 | D38: 检查费 | E38: 通过仪器测定主观听阈和双侧听觉诱发电位，评定听觉传导通路功能。 | F38: 所定价格涵盖设备准备、安装、刺激、采集、分析、出具报告等步骤所需的人力资源和基本物质资源消耗。 | G38: 次 | H38: 不与耳鼻喉科立项指南中的“听阈检查费”同时收取。 | I38: 66 | J38: 59 | K38: 66 | L38: 60 | M38: 51 | N38: 66 | O38: 59 | P38: 51 | Q38: 医保 | T38: 理顺，降低 | U38: 平移后县级按不高于省级拟定 | V38: 003101000120000-310100012 | W38: 310100012 | X38: 脑干听觉诱发电位 | AA38: 次 | AC38: 66 | AD38: 59 | AE38: 66 | AF38: 60 | AG38: 51 | AH38: 医保
A39: 分项 | B39: 012401000080001 | C39: 脑干听觉诱发电位费-床旁（加收） | D39: 检查费 | G39: 次 | I39: 10 | J39: 9 | N39: 9 | O39: 8 | P39: 7 | Q39: 医保 | U39: 新增加收项目，按比价关系拟定（床旁统一加收价格）
A40: 9 | B40: 012401000090000 | C40: 体感诱发电位费 | D40: 检查费 | E40: 通过刺激体感通路采集分析诱发电位。 | F40: 所定价格涵盖设备准备、安装、刺激、采集、分析、出具报告等步骤所需的人力资源和基本物质资源消耗。 | G40: 单肢 | I40: 96 | J40: 86 | K40: 88.009447 | L40: 80.040205 | M40: 68 | N40: 88 | O40: 80 | P40: 68 | Q40: 医保 | T40: 平移取整 | U40: 加权平移取整 | V40: 003101000090000-310100009 | W40: 310100009 | X40: 体感诱发电位 | Y40: 包括上肢体感诱发电位检查应含头皮、颈部、Erb氏点记录，下肢体感诱发电位检查应含头皮、腰部记录 | AA40: 单肢 | AB40: 诱发电位地形图分析加收20%；术中监测基层17元/小时，县级医院20元/小时，市级医院22元/小时 | AC40: 88 | AD40: 79 | AE40: 88 | AF40: 80 | AG40: 68 | AH40: 医保
...

Sheet Sheet1 (2)
A1: 附件2
A2: 神经系统类立项指南项目价格拟定情况 | B2: 神经系统类立项指南项目价格拟定情况 | C2: 神经系统类立项指南项目价格拟定情况 | D2: 神经系统类立项指南项目价格拟定情况 | E2: 神经系统类立项指南项目价格拟定情况 | F2: 神经系统类立项指南项目价格拟定情况 | G2: 神经系统类立项指南项目价格拟定情况 | H2: 神经系统类立项指南项目价格拟定情况 | I2: 神经系统类立项指南项目价格拟定情况 | J2: 神经系统类立项指南项目价格拟定情况 | K2: 神经系统类立项指南项目价格拟定情况 | L2: 神经系统类立项指南项目价格拟定情况 | M2: 神经系统类立项指南项目价格拟定情况 | N2: 神经系统类立项指南项目价格拟定情况 | O2: 神经系统类立项指南项目价格拟定情况 | P2: 神经系统类立项指南项目价格拟定情况 | Q2: 神经系统类立项指南项目价格拟定情况 | R2: 神经系统类立项指南项目价格拟定情况 | S2: 神经系统类立项指南项目价格拟定情况 | T2: 神经系统类立项指南项目价格拟定情况 | U2: 神经系统类立项指南项目价格拟定情况 | V2: 神经系统类立项指南项目价格拟定情况 | W2: 神经系统类立项指南项目价格拟定情况 | X2: 神经系统类立项指南项目价格拟定情况 | Y2: 神经系统类立项指南项目价格拟定情况 | Z2: 神经系统类立项指南项目价格拟定情况 | AA2: 神经系统类立项指南项目价格拟定情况 | AB2: 神经系统类立项指南项目价格拟定情况 | AC2: 神经系统类立项指南项目价格拟定情况 | AD2: 神经系统类立项指南项目价格拟定情况 | AE2: 神经系统类立项指南项目价格拟定情况
A3: 神经系统立项指南项目 | B3: 神经系统立项指南项目 | C3: 神经系统立项指南项目 | D3: 神经系统立项指南项目 | E3: 神经系统立项指南项目 | F3: 神经系统立项指南项目 | G3: 神经系统立项指南项目 | H3: 神经系统立项指南项目 | I3: 神经系统立项指南项目 | J3: 神经系统立项指南项目 | K3: 神经系统立项指南项目 | L3: 神经系统立项指南项目 | M3: 神经系统立项指南项目 | N3: 神经系统立项指南项目 | O3: 神经系统立项指南项目 | P3: 神经系统立项指南项目 | Q3: 神经系统立项指南项目 | R3: 神经系统立项指南项目 | S3: 神经系统立项指南项目 | T3: 现行价格项目（颅内镜辅助操作费用纳入测算） | U3: 现行价格项目（颅内镜辅助操作费用纳入测算） | V3: 现行价格项目（颅内镜辅助操作费用纳入测算） | W3: 现行价格项目（颅内镜辅助操作费用纳入测算） | X3: 现行价格项目（颅内镜辅助操作费用纳入测算） | Y3: 现行价格项目（颅内镜辅助操作费用纳入测算） | Z3: 现行价格项目（颅内镜辅助操作费用纳入测算） | AA3: 现行价格项目（颅内镜辅助操作费用纳入测算） | AB3: 现行价格项目（颅内镜辅助操作费用纳入测算） | AC3: 现行价格项目（颅内镜辅助操作费用纳入测算） | AD3: 现行价格项目（颅内镜辅助操作费用纳入测算） | AE3: 现行价格项目（颅内镜辅助操作费用纳入测算）
A4: 序号 | B4: 项目代码 | C4: 项目名称 | D4: 归集口径 | E4: 服务产出 | F4: 价格构成 | G4: 计价单位 | H4: 计价说明 | I4: 省三甲价格 | J4: 省三甲以下价格 | K4: 平移价格 (市级) | L4: 平移价格 (县级) | M4: 平移价格 (基层) | N4: 拟定价格 (市级) | O4: 拟定价格 (县级) | P4: 拟定价格 (基层) | Q4: 医保属性 | R4: 调整情况 | S4: 备注 | T4: 国家结算编码 | U4: 项目编码 | V4: 项目名称 | W4: 项目内涵 | X4: 除外内容 | Y4: 计价单位 | Z4: 说明 | AA4: 三甲 | AB4: 三甲以下 | AC4: 价格 (市级) | AD4: 价格 (县级) | AE4: 价格 (基层)
A5: 1 | B5: 012401000010000 | C5: 脑电图检查费 | D5: 检查费 | E5: 通过脑电图仪器采集分析脑电活动。 | F5: 所定价格涵盖设备准备、安装、记录、分析、出具报告等步骤所需的人力资源和基本物质资源消耗。 | G5: 次 | H5: 1.本项目所称“特殊电极脑电图检查”指：使用鼻咽、蝶骨、皮层特殊电极进行脑电图检查。 2.本项目所称“特殊诱发脑电图检查”指：光、电等特殊诱发后进行脑电图检查。 3.本项目所称“高密度脑电图”指：128导联及以上脑电图。 4.4个小时及以内按一次收费，4个小时以上每增加1小时加收15%。 | I5: 100 | J5: 90 | K5: 97.670576 | L5: 89.622122 | M5: 59.874352 | N5: 98 | O5: 90 | P5: 78 | Q5: 医保 | R5: 平移取整 | S5: 加权平移取整，基层调整理顺比价 | T5: 003101000010000-310100001 | U5: 310100001 | V5: 脑电图 | W5: 含深呼吸诱发，至少8导 | Y5: 次 | Z5: 脑电发生源定位加收50%；术中监测基层17元/小时，县级医院20元/小时，市级医院22元/小时 | AA5: 40 | AB5: 36 | AC5: 33 | AD5: 30 | AE5: 25.5 | AF5: =IFERROR(FIND("-儿童（加收）",C5,1),0) -> 0 | AG5: =SUBSTITUTE(C5,"-儿童（加收）","") -> 脑电图检查费 | AH5: =IF(AF5>0,_xlfn.MAXIFS(N:N,C:C,SUBSTITUTE(C5,"-儿童（加收）","")),0)+N5 -> 98 | AI5: =IF(AF5>0,_xlfn.MAXIFS(O:O,C:C,SUBSTITUTE(C5,"-儿童（加收）","")),0)+O5 -> 90 | AJ5: =IF(AF5>0,_xlfn.MAXIFS(P:P,C:C,SUBSTITUTE(C5,"-儿童（加收）","")),0)+P5 -> 78
A6: 1 | B6: 012401000010000 | C6: 脑电图检查费 | D6: 检查费 | E6: 通过脑电图仪器采集分析脑电活动。 | F6: 所定价格涵盖设备准备、安装、记录、分析、出具报告等步骤所需的人力资源和基本物质资源消耗。 | G6: 次 | H6: 1.本项目所称“特殊电极脑电图检查”指：使用鼻咽、蝶骨、皮层特殊电极进行脑电图检查。 2.本项目所称“特殊诱发脑电图检查”指：光、电等特殊诱发后进行脑电图检查。 3.本项目所称“高密度脑电图”指：128导联及以上脑电图。 4.4个小时及以内按一次收费，4个小时以上每增加1小时加收15%。 | I6: 100 | J6: 90 | K6: 97.670576 | L6: 89.622122 | M6: 59.874352 | N6: 98 | O6: 90 | P6: 78 | Q6: 医保 | R6: 平移取整 | S6: 加权平移取整，基层调整理顺比价 | T6: 003101000010001-31010000101 | U6: 31010000101 | V6: 脑电图（脑电发生源定位） | Y6: 次 | Z6: 脑电发生源定位 | AA6: 65 | AB6: 59 | AC6: 49.5 | AD6: 45 | AE6: 38.3 | AF6: =IFERROR(FIND("-儿童（加收）",C6,1),0) -> 0 | AG6: =SUBSTITUTE(C6,"-儿童（加收）","") -> 脑电图检查费 | AH6: =IF(AF6>0,_xlfn.MAXIFS(N:N,C:C,SUBSTITUTE(C6,"-儿童（加收）","")),0)+N6 -> 98 | AI6: =IF(AF6>0,_xlfn.MAXIFS(O:O,C:C,SUBSTITUTE(C6,"-儿童（加收）","")),0)+O6 -> 90 | AJ6: =IF(AF6>0,_xlfn.MAXIFS(P:P,C:C,SUBSTITUTE(C6,"-儿童（加收）","")),0)+P6 -> 78
A7: 1 | B7: 012401000010000 | C7: 脑电图检查费 | D7: 检查费 | E7: 通过脑电图仪器采集分析脑电活动。 | F7: 所定价格涵盖设备准备、安装、记录、分析、出具报告等步骤所需的人力资源和基本物质资源消耗。 | G7: 次 | H7: 1.本项目所称“特殊电极脑电图检查”指：使用鼻咽、蝶骨、皮层特殊电极进行脑电图检查。 2.本项目所称“特殊诱发脑电图检查”指：光、电等特殊诱发后进行脑电图检查。 3.本项目所称“高密度脑电图”指：128导联及以上脑电图。 4.4个小时及以内按一次收费，4个小时以上每增加1小时加收15%。 | I7: 100 | J7: 90 | K7: 97.670576 | L7: 89.622122 | M7: 59.874352 | N7: 98 | O7: 90 | P7: 78 | Q7: 医保 | R7: 平移取整 | S7: 加权平移取整，基层调整理顺比价 | T7: 003101000030000-310100003 | U7: 310100003 | V7: 脑地形图 | W7: 含二维脑地形图(至少16导) | Y7: 次 | AA7: 115 | AB7: 105 | AC7: 110 | AD7: 100 | AE7: 85 | AF7: =IFERROR(FIND("-儿童（加收）",C7,1),0) -> 0 | AG7: =SUBSTITUTE(C7,"-儿童（加收）","") -> 脑电图检查费 | AH7: =IF(AF7>0,_xlfn.MAXIFS(N:N,C:C,SUBSTITUTE(C7,"-儿童（加收）","")),0)+N7 -> 98 | AI7: =IF(AF7>0,_xlfn.MAXIFS(O:O,C:C,SUBSTITUTE(C7,"-儿童（加收）","")),0)+O7 -> 90 | AJ7: =IF(AF7>0,_xlfn.MAXIFS(P:P,C:C,SUBSTITUTE(C7,"-儿童（加收）","")),0)+P7 -> 78
A8: 1 | B8: 012401000010000 | C8: 脑电图检查费 | D8: 检查费 | E8: 通过脑电图仪器采集分析脑电活动。 | F8: 所定价格涵盖设备准备、安装、记录、分析、出具报告等步骤所需的人力资源和基本物质资源消耗。 | G8: 次 | H8: 1.本项目所称“特殊电极脑电图检查”指：使用鼻咽、蝶骨、皮层特殊电极进行脑电图检查。 2.本项目所称“特殊诱发脑电图检查”指：光、电等特殊诱发后进行脑电图检查。 3.本项目所称“高密度脑电图”指：128导联及以上脑电图。 4.4个小时及以内按一次收费，4个小时以上每增加1小时加收15%。 | I8: 100 | J8: 90 | K8: 97.670576 | L8: 89.622122 | M8: 59.874352 | N8: 98 | O8: 90 | P8: 78 | Q8: 医保 | R8: 平移取整 | S8: 加权平移取整，基层调整理顺比价 | T8: 003101000040000-310100004 | U8: 310100004 | V8: 动态脑电图 | W8: 包括24小时脑电视频监测或脑电Holter | Y8: 次 | AA8: 286 | AB8: 255 | AC8: 286 | AD8: 260 | AE8: 221 | AF8: =IFERROR(FIND("-儿童（加收）",C8,1),0) -> 0 | AG8: =SUBSTITUTE(C8,"-儿童（加收）","") -> 脑电图检查费 | AH8: =IF(AF8>0,_xlfn.MAXIFS(N:N,C:C,SUBSTITUTE(C8,"-儿童（加收）","")),0)+N8 -> 98 | AI8: =IF(AF8>0,_xlfn.MAXIFS(O:O,C:C,SUBSTITUTE(C8,"-儿童（加收）","")),0)+O8 -> 90 | AJ8: =IF(AF8>0,_xlfn.MAXIFS(P:P,C:C,SUBSTITUTE(C8,"-儿童（加收）","")),0)+P8 -> 78
A9: 1 | B9: 012401000010000 | C9: 脑电图检查费 | D9: 检查费 | E9: 通过脑电图仪器采集分析脑电活动。 | F9: 所定价格涵盖设备准备、安装、记录、分析、出具报告等步骤所需的人力资源和基本物质资源消耗。 | G9: 次 | H9: 1.本项目所称“特殊电极脑电图检查”指：使用鼻咽、蝶骨、皮层特殊电极进行脑电图检查。 2.本项目所称“特殊诱发脑电图检查”指：光、电等特殊诱发后进行脑电图检查。 3.本项目所称“高密度脑电图”指：128导联及以上脑电图。 4.4个小时及以内按一次收费，4个小时以上每增加1小时加收15%。 | I9: 100 | J9: 90 | K9: 97.670576 | L9: 89.622122 | M9: 59.874352 | N9: 98 | O9: 90 | P9: 78 | Q9: 医保 | R9: 平移取整 | S9: 加权平移取整，基层调整理顺比价 | T9: 003101000040100-31010000401 | U9: 31010000401 | V9: 动态脑电图（24小时脑电视频监测） | Y9: 次 | Z9: 24小时脑电视频监测 | AA9: 286 | AB9: 255 | AC9: 286 | AD9: 260 | AE9: 221 | AF9: =IFERROR(FIND("-儿童（加收）",C9,1),0) -> 0 | AG9: =SUBSTITUTE(C9,"-儿童（加收）","") -> 脑电图检查费 | AH9: =IF(AF9>0,_xlfn.MAXIFS(N:N,C:C,SUBSTITUTE(C9,"-儿童（加收）","")),0)+N9 -> 98 | AI9: =IF(AF9>0,_xlfn.MAXIFS(O:O,C:C,SUBSTITUTE(C9,"-儿童（加收）","")),0)+O9 -> 90 | AJ9: =IF(AF9>0,_xlfn.MAXIFS(P:P,C:C,SUBSTITUTE(C9,"-儿童（加收）","")),0)+P9 -> 78
A10: 1 | B10: 012401000010000 | C10: 脑电图检查费 | D10: 检查费 | E10: 通过脑电图仪器采集分析脑电活动。 | F10: 所定价格涵盖设备准备、安装、记录、分析、出具报告等步骤所需的人力资源和基本物质资源消耗。 | G10: 次 | H10: 1.本项目所称“特殊电极脑电图检查”指：使用鼻咽、蝶骨、皮层特殊电极进行脑电图检查。 2.本项目所称“特殊诱发脑电图检查”指：光、电等特殊诱发后进行脑电图检查。 3.本项目所称“高密度脑电图”指：128导联及以上脑电图。 4.4个小时及以内按一次收费，4个小时以上每增加1小时加收15%。 | I10: 100 | J10: 90 | K10: 97.670576 | L10: 89.622122 | M10: 59.874352 | N10: 98 | O10: 90 | P10: 78 | Q10: 医保 | R10: 平移取整 | S10: 加权平移取整，基层调整理顺比价 | T10: 003101000040200-31010000402 | U10: 31010000402 | V10: 动态脑电图（24小时脑电Holter） | Y10: 次 | Z10: 24小时脑电Holter | AA10: 286 | AB10: 255 | AC10: 286 | AD10: 260 | AE10: 221 | AF10: =IFERROR(FIND("-儿童（加收）",C10,1),0) -> 0 | AG10: =SUBSTITUTE(C10,"-儿童（加收）","") -> 脑电图检查费 | AH10: =IF(AF10>0,_xlfn.MAXIFS(N:N,C:C,SUBSTITUTE(C10,"-儿童（加收）","")),0)+N10 -> 98 | AI10: =IF(AF10>0,_xlfn.MAXIFS(O:O,C:C,SUBSTITUTE(C10,"-儿童（加收）","")),0)+O10 -> 90 | AJ10: =IF(AF10>0,_xlfn.MAXIFS(P:P,C:C,SUBSTITUTE(C10,"-儿童（加收）","")),0)+P10 -> 78
A11: 1 | B11: 012401000010000 | C11: 脑电图检查费 | D11: 检查费 | E11: 通过脑电图仪器采集分析脑电活动。 | F11: 所定价格涵盖设备准备、安装、记录、分析、出具报告等步骤所需的人力资源和基本物质资源消耗。 | G11: 次 | H11: 1.本项目所称“特殊电极脑电图检查”指：使用鼻咽、蝶骨、皮层特殊电极进行脑电图检查。 2.本项目所称“特殊诱发脑电图检查”指：光、电等特殊诱发后进行脑电图检查。 3.本项目所称“高密度脑电图”指：128导联及以上脑电图。 4.4个小时及以内按一次收费，4个小时以上每增加1小时加收15%。 | I11: 100 | J11: 90 | K11: 97.670576 | L11: 89.622122 | M11: 59.874352 | N11: 98 | O11: 90 | P11: 78 | Q11: 医保 | R11: 平移取整 | S11: 加权平移取整，基层调整理顺比价 | T11: 003101000050000-310100005 | U11: 310100005 | V11: 脑电图录象监测 | W11: 含摄像观测患者行为及脑电图监测 | Y11: 小时 | Z11: 颅内电极视频脑电图录像监测市级115元/小时，县级105元/小时，基层95元/小时。 | AA11: 25 | AB11: 23 | AC11: 27.5 | AD11: 25 | AE11: 21.3 | AF11: =IFERROR(FIND("-儿童（加收）",C11,1),0) -> 0 | AG11: =SUBSTITUTE(C11,"-儿童（加收）","") -> 脑电图检查费 | AH11: =IF(AF11>0,_xlfn.MAXIFS(N:N,C:C,SUBSTITUTE(C11,"-儿童（加收）","")),0)+N11 -> 98 | AI11: =IF(AF11>0,_xlfn.MAXIFS(O:O,C:C,SUBSTITUTE(C11,"-儿童（加收）","")),0)+O11 -> 90 | AJ11: =IF(AF11>0,_xlfn.MAXIFS(P:P,C:C,SUBSTITUTE(C11,"-儿童（加收）","")),0)+P11 -> 78
A12: 分项 | B12: 012401000010011 | C12: 脑电图检查费-特殊电极脑电图检查（加收） | D12: 检查费 | G12: 次 | I12: 10 | J12: 9 | N12: 9 | O12: 8 | P12: 7 | Q12: 医保 | S12: 省级按项目间及区域间比价关系定价，我市按比价关系拟定。（同床旁加收） | T12: 003101000020000-310100002 | U12: 310100002 | V12: 特殊脑电图 | W12: 包括特殊电极(鼻咽或蝶骨或皮层等)、特殊诱发 | Y12: 次 | AA12: 90 | AB12: 81 | AC12: 66 | AD12: 60 | AE12: 51 | AF12: =IFERROR(FIND("-儿童（加收）",C12,1),0) -> 0 | AG12: =SUBSTITUTE(C12,"-儿童（加收）","") -> 脑电图检查费-特殊电极脑电图检查（加收） | AH12: =IF(AF12>0,_xlfn.MAXIFS(N:N,C:C,SUBSTITUTE(C12,"-儿童（加收）","")),0)+N12 -> 9 | AI12: =IF(AF12>0,_xlfn.MAXIFS(O:O,C:C,SUBSTITUTE(C12,"-儿童（加收）","")),0)+O12 -> 8 | AJ12: =IF(AF12>0,_xlfn.MAXIFS(P:P,C:C,SUBSTITUTE(C12,"-儿童（加收）","")),0)+P12 -> 7
A13: 分项 | B13: 012401000010011 | C13: 脑电图检查费-特殊电极脑电图检查（加收） | D13: 检查费 | G13: 次 | I13: 10 | J13: 9 | N13: 9 | O13: 8 | P13: 7 | Q13: 医保 | S13: 省级按项目间及区域间比价关系定价，我市按比价关系拟定。（同床旁加收） | T13: 003101000020100-31010000201 | U13: 31010000201 | V13: 特殊脑电图（特殊电极鼻咽或蝶骨或皮层等） | Y13: 次 | Z13: 特殊电极(鼻咽或蝶骨或皮层等) | AA13: 90 | AB13: 81 | AC13: 66 | AD13: 60 | AE13: 51 | AF13: =IFERROR(FIND("-儿童（加收）",C13,1),0) -> 0 | AG13: =SUBSTITUTE(C13,"-儿童（加收）","") -> 脑电图检查费-特殊电极脑电图检查（加收） | AH13: =IF(AF13>0,_xlfn.MAXIFS(N:N,C:C,SUBSTITUTE(C13,"-儿童（加收）","")),0)+N13 -> 9 | AI13: =IF(AF13>0,_xlfn.MAXIFS(O:O,C:C,SUBSTITUTE(C13,"-儿童（加收）","")),0)+O13 -> 8 | AJ13: =IF(AF13>0,_xlfn.MAXIFS(P:P,C:C,SUBSTITUTE(C13,"-儿童（加收）","")),0)+P13 -> 7
A14: 分项 | B14: 012401000010021 | C14: 脑电图检查费-特殊诱发脑电图检查（加收） | D14: 检查费 | G14: 次 | I14: 10 | J14: 9 | N14: 9 | O14: 8 | P14: 7 | Q14: 医保 | S14: 省级按项目间及区域间比价关系定价，我市按比价关系拟定。（同床旁加收） | T14: 003101000020200-31010000202 | U14: 31010000202 | V14: 特殊脑电图（特殊诱发） | Y14: 次 | Z14: 特殊诱发 | AA14: 90 | AB14: 81 | AC14: 66 | AD14: 60 | AE14: 51 | AF14: =IFERROR(FIND("-儿童（加收）",C14,1),0) -> 0 | AG14: =SUBSTITUTE(C14,"-儿童（加收）","") -> 脑电图检查费-特殊诱发脑电图检查（加收） | AH14: =IF(AF14>0,_xlfn.MAXIFS(N:N,C:C,SUBSTITUTE(C14,"-儿童（加收）","")),0)+N14 -> 9 | AI14: =IF(AF14>0,_xlfn.MAXIFS(O:O,C:C,SUBSTITUTE(C14,"-儿童（加收）","")),0)+O14 -> 8 | AJ14: =IF(AF14>0,_xlfn.MAXIFS(P:P,C:C,SUBSTITUTE(C14,"-儿童（加收）","")),0)+P14 -> 7
A15: 分项 | B15: 012401000010031 | C15: 脑电图检查费-高密度脑电图检查（加收） | D15: 检查费 | G15: 次 | H15: 4个小时及以内按一次收费，4个小时以上每增加1小时加收15%。 | I15: 150 | J15: 135 | N15: 147 | O15: 135 | P15: 117 | Q15: 医保 | S15: 无开展量，按项目间比价关系拟定 | T15: 003101000050000-31010000501 | U15: 31010000501 | V15: 颅内电极视频脑电图录像监测 | W15: 颅内脑电图是一种癫痫外科术前的评估手段，通过前期置入颅内电极，在癫痫视频脑电监测单元记录颅内大脑表面皮层和大脑深部电活动并直接电刺激，并同期录像患者临床表现确定局灶性癫痫患者致痫区，可定位一些致痫区位于的局灶性癫痫。 | Y15: 小时 | AA15: 120 | AC15: 115 | AD15: 105 | AE15: 95 | AF15: =IFERROR(FIND("-儿童（加收）",C15,1),0) -> 0 | AG15: =SUBSTITUTE(C15,"-儿童（加收）","") -> 脑电图检查费-高密度脑电图检查（加收） | AH15: =IF(AF15>0,_xlfn.MAXIFS(N:N,C:C,SUBSTITUTE(C15,"-儿童（加收）","")),0)+N15 -> 147 | AI15: =IF(AF15>0,_xlfn.MAXIFS(O:O,C:C,SUBSTITUTE(C15,"-儿童（加收）","")),0)+O15 -> 135 | AJ15: =IF(AF15>0,_xlfn.MAXIFS(P:P,C:C,SUBSTITUTE(C15,"-儿童（加收）","")),0)+P15 -> 117
A16: 2 | B16: 012401000020000 | C16: 脑磁图检查费 | D16: 检查费 | E16: 通过仪器采集分析脑磁图电波。 | F16: 所定价格涵盖设备准备、安装、定位、采集、记录、出具报告等步骤所需的人力资源和基本物质资源消耗。 | G16: 次 | H16: 脑功能区定位三甲医院按照1400元/次收取，三甲以下医院按照1260元/次收取。 脑功能区定位市级医院按照1300元/次收取，县级医院按照1200元/次收取，基层按1020元/次收取。 | I16: 4200 | J16: 3780 | N16: 3900 | O16: 3600 | P16: 3060 | Q16: 非医保 | R16: 新增价格 | S16: 新增价格，检查适当缩小价差 | T16: 003101000060000-310100006 | U16: 310100006 | V16: 脑磁图 | Y16: 次 | AF16: =IFERROR(FIND("-儿童（加收）",C16,1),0) -> 0 | AG16: =SUBSTITUTE(C16,"-儿童（加收）","") -> 脑磁图检查费 | AH16: =IF(AF16>0,_xlfn.MAXIFS(N:N,C:C,SUBSTITUTE(C16,"-儿童（加收）","")),0)+N16 -> 3900 | AI16: =IF(AF16>0,_xlfn.MAXIFS(O:O,C:C,SUBSTITUTE(C16,"-儿童（加收）","")),0)+O16 -> 3600 | AJ16: =IF(AF16>0,_xlfn.MAXIFS(P:P,C:C,SUBSTITUTE(C16,"-儿童（加收）","")),0)+P16 -> 3060
A17: 3 | B17: 012401000030000 | C17: 针极肌电图检查费 | D17: 检查费 | E17: 通过仪器采集分析静息状态或特定运动中各组肌群数据。 | F17: 所定价格涵盖设备准备、安装、采集、分析、出具报告等步骤所需的人力资源和基本物质资源消耗。 | G17: 次 | H17: 1.次指1条肌肉，每增加1条肌肉加收50%，以12条肌肉费用设置封顶线。 2.震颤分析按单侧（头部左右侧、单肢）收费。 | I17: 30 | J17: 27 | K17: 22.152263 | L17: 20.001238 | M17: 17 | N17: 27 | O17: 25 | P17: 21 | Q17: 医保 | R17: 理顺，提高 | S17: 我市原项目价格仅为省级价格的73.3%，现提高理顺。 | T17: 003101000150000-310100015 | U17: 310100015 | V17: 感觉阈值测量 | W17: 包括感觉障碍电生理诊断 | Y17: 次 | AF17: =IFERROR(FIND("-儿童（加收）",C17,1),0) -> 0 | AG17: =SUBSTITUTE(C17,"-儿童（加收）","") -> 针极肌电图检查费 | AH17: =IF(AF17>0,_xlfn.MAXIFS(N:N,C:C,SUBSTITUTE(C17,"-儿童（加收）","")),0)+N17 -> 27 | AI17: =IF(AF17>0,_xlfn.MAXIFS(O:O,C:C,SUBSTITUTE(C17,"-儿童（加收）","")),0)+O17 -> 25 | AJ17: =IF(AF17>0,_xlfn.MAXIFS(P:P,C:C,SUBSTITUTE(C17,"-儿童（加收）","")),0)+P17 -> 21
A18: 3 | B18: 012401000030000 | C18: 针极肌电图检查费 | D18: 检查费 | E18: 通过仪器采集分析静息状态或特定运动中各组肌群数据。 | F18: 所定价格涵盖设备准备、安装、采集、分析、出具报告等步骤所需的人力资源和基本物质资源消耗。 | G18: 次 | H18: 1.次指1条肌肉，每增加1条肌肉加收50%，以12条肌肉费用设置封顶线。 2.震颤分析按单侧（头部左右侧、单肢）收费。 | I18: 30 | J18: 27 | K18: 22.152263 | L18: 20.001238 | M18: 17 | N18: 27 | O18: 25 | P18: 21 | Q18: 医保 | R18: 理顺，提高 | S18: 我市原项目价格仅为省级价格的73.3%，现提高理顺。 | T18: 003101000210000-310100021 | U18: 310100021 | V18: 植物神经功能检查 | Y18: 次 | AA18: 20 | AB18: 18 | AC18: 22 | AD18: 20 | AE18: 17 | AF18: =IFERROR(FIND("-儿童（加收）",C18,1),0) -> 0 | AG18: =SUBSTITUTE(C18,"-儿童（加收）","") -> 针极肌电图检查费 | AH18: =IF(AF18>0,_xlfn.MAXIFS(N:N,C:C,SUBSTITUTE(C18,"-儿童（加收）","")),0)+N18 -> 27 | AI18: =IF(AF18>0,_xlfn.MAXIFS(O:O,C:C,SUBSTITUTE(C18,"-儿童（加收）","")),0)+O18 -> 25 | AJ18: =IF(AF18>0,_xlfn.MAXIFS(P:P,C:C,SUBSTITUTE(C18,"-儿童（加收）","")),0)+P18 -> 21
A19: 3 | B19: 012401000030000 | C19: 针极肌电图检查费 | D19: 检查费 | E19: 通过仪器采集分析静息状态或特定运动中各组肌群数据。 | F19: 所定价格涵盖设备准备、安装、采集、分析、出具报告等步骤所需的人力资源和基本物质资源消耗。 | G19: 次 | H19: 1.次指1条肌肉，每增加1条肌肉加收50%，以12条肌肉费用设置封顶线。 2.震颤分析按单侧（头部左右侧、单肢）收费。 | I19: 30 | J19: 27 | K19: 22.152263 | L19: 20.001238 | M19: 17 | N19: 27 | O19: 25 | P19: 21 | Q19: 医保 | R19: 理顺，提高 | S19: 我市原项目价格仅为省级价格的73.3%，现提高理顺。 | T19: 003101000220000-310100022 | U19: 310100022 | V19: 多功能神经肌肉功能监测 | W19: 包括表面肌电测定 | Y19: 小时 | AA19: 5 | AB19: 4.5 | AC19: 4.5 | AD19: 4 | AE19: 3.5 | AF19: =IFERROR(FIND("-儿童（加收）",C19,1),0) -> 0 | AG19: =SUBSTITUTE(C19,"-儿童（加收）","") -> 针极肌电图检查费 | AH19: =IF(AF19>0,_xlfn.MAXIFS(N:N,C:C,SUBSTITUTE(C19,"-儿童（加收）","")),0)+N19 -> 27 | AI19: =IF(AF19>0,_xlfn.MAXIFS(O:O,C:C,SUBSTITUTE(C19,"-儿童（加收）","")),0)+O19 -> 25 | AJ19: =IF(AF19>0,_xlfn.MAXIFS(P:P,C:C,SUBSTITUTE(C19,"-儿童（加收）","")),0)+P19 -> 21
A20: 3 | B20: 012401000030000 | C20: 针极肌电图检查费 | D20: 检查费 | E20: 通过仪器采集分析静息状态或特定运动中各组肌群数据。 | F20: 所定价格涵盖设备准备、安装、采集、分析、出具报告等步骤所需的人力资源和基本物质资源消耗。 | G20: 次 | H20: 1.次指1条肌肉，每增加1条肌肉加收50%，以12条肌肉费用设置封顶线。 2.震颤分析按单侧（头部左右侧、单肢）收费。 | I20: 30 | J20: 27 | K20: 22.152263 | L20: 20.001238 | M20: 17 | N20: 27 | O20: 25 | P20: 21 | Q20: 医保 | R20: 理顺，提高 | S20: 我市原项目价格仅为省级价格的73.3%，现提高理顺。 | T20: 003101000220100-31010002201 | U20: 31010002201 | V20: 多功能神经肌肉功能监测（表面肌电测定） | Y20: 小时 | AA20: 5 | AB20: 4.5 | AC20: 4.5 | AD20: 4 | AE20: 3.5 | AF20: =IFERROR(FIND("-儿童（加收）",C20,1),0) -> 0 | AG20: =SUBSTITUTE(C20,"-儿童（加收）","") -> 针极肌电图检查费 | AH20: =IF(AF20>0,_xlfn.MAXIFS(N:N,C:C,SUBSTITUTE(C20,"-儿童（加收）","")),0)+N20 -> 27 | AI20: =IF(AF20>0,_xlfn.MAXIFS(O:O,C:C,SUBSTITUTE(C20,"-儿童（加收）","")),0)+O20 -> 25 | AJ20: =IF(AF20>0,_xlfn.MAXIFS(P:P,C:C,SUBSTITUTE(C20,"-儿童（加收）","")),0)+P20 -> 21
A21: 3 | B21: 012401000030000 | C21: 针极肌电图检查费 | D21: 检查费 | E21: 通过仪器采集分析静息状态或特定运动中各组肌群数据。 | F21: 所定价格涵盖设备准备、安装、采集、分析、出具报告等步骤所需的人力资源和基本物质资源消耗。 | G21: 次 | H21: 1.次指1条肌肉，每增加1条肌肉加收50%，以12条肌肉费用设置封顶线。 2.震颤分析按单侧（头部左右侧、单肢）收费。 | I21: 30 | J21: 27 | K21: 22.152263 | L21: 20.001238 | M21: 17 | N21: 27 | O21: 25 | P21: 21 | Q21: 医保 | R21: 理顺，提高 | S21: 我市原项目价格仅为省级价格的73.3%，现提高理顺。 | T21: 003101000230000-310100023 | U21: 310100023 | V21: 肌电图 | W21: 包括眼肌电图 | X21: 一次性针电极 | Y21: 每条肌肉 | AA21: 30 | AB21: 27 | AC21: 22 | AD21: 20 | AE21: 17 | AF21: =IFERROR(FIND("-儿童（加收）",C21,1),0) -> 0 | AG21: =SUBSTITUTE(C21,"-儿童（加收）","") -> 针极肌电图检查费 | AH21: =IF(AF21>0,_xlfn.MAXIFS(N:N,C:C,SUBSTITUTE(C21,"-儿童（加收）","")),0)+N21 -> 27 | AI21: =IF(AF21>0,_xlfn.MAXIFS(O:O,C:C,SUBSTITUTE(C21,"-儿童（加收）","")),0)+O21 -> 25 | AJ21: =IF(AF21>0,_xlfn.MAXIFS(P:P,C:C,SUBSTITUTE(C21,"-儿童（加收）","")),0)+P21 -> 21
A22: 3 | B22: 012401000030000 | C22: 针极肌电图检查费 | D22: 检查费 | E22: 通过仪器采集分析静息状态或特定运动中各组肌群数据。 | F22: 所定价格涵盖设备准备、安装、采集、分析、出具报告等步骤所需的人力资源和基本物质资源消耗。 | G22: 次 | H22: 1.次指1条肌肉，每增加1条肌肉加收50%，以12条肌肉费用设置封顶线。 2.震颤分析按单侧（头部左右侧、单肢）收费。 | I22: 30 | J22: 27 | K22: 22.152263 | L22: 20.001238 | M22: 17 | N22: 27 | O22: 25 | P22: 21 | Q22: 医保 | R22: 理顺，提高 | S22: 我市原项目价格仅为省级价格的73.3%，现提高理顺。 | T22: 003101000260000-310100026 | U22: 310100026 | V22: 多轨迹断层肌电图 | Y22: 次 | AA22: 90 | AB22: 81 | AC22: 66 | AD22: 60 | AE22: 51 | AF22: =IFERROR(FIND("-儿童（加收）",C22,1),0) -> 0 | AG22: =SUBSTITUTE(C22,"-儿童（加收）","") -> 针极肌电图检查费 | AH22: =IF(AF22>0,_xlfn.MAXIFS(N:N,C:C,SUBSTITUTE(C22,"-儿童（加收）","")),0)+N22 -> 27 | AI22: =IF(AF22>0,_xlfn.MAXIFS(O:O,C:C,SUBSTITUTE(C22,"-儿童（加收）","")),0)+O22 -> 25 | AJ22: =IF(AF22>0,_xlfn.MAXIFS(P:P,C:C,SUBSTITUTE(C22,"-儿童（加收）","")),0)+P22 -> 21
A23: 3 | B23: 012401000030000 | C23: 针极肌电图检查费 | D23: 检查费 | E23: 通过仪器采集分析静息状态或特定运动中各组肌群数据。 | F23: 所定价格涵盖设备准备、安装、采集、分析、出具报告等步骤所需的人力资源和基本物质资源消耗。 | G23: 次 | H23: 1.次指1条肌肉，每增加1条肌肉加收50%，以12条肌肉费用设置封顶线。 2.震颤分析按单侧（头部左右侧、单肢）收费。 | I23: 30 | J23: 27 | K23: 22.152263 | L23: 20.001238 | M23: 17 | N23: 27 | O23: 25 | P23: 21 | Q23: 医保 | R23: 理顺，提高 | S23: 我市原项目价格仅为省级价格的73.3%，现提高理顺。 | T23: 003105040030000-310504003 | U23: 310504003 | V23: 面神经肌电图检查 | W23: 1.包括额、眼、上唇及下唇四个功能区；2.每功能区均含双侧 | Y23: 每区 | AA23: 20 | AB23: 20 | AC23: 21 | AD23: 20 | AE23: 17 | AF23: =IFERROR(FIND("-儿童（加收）",C23,1),0) -> 0 | AG23: =SUBSTITUTE(C23,"-儿童（加收）","") -> 针极肌电图检查费 | AH23: =IF(AF23>0,_xlfn.MAXIFS(N:N,C:C,SUBSTITUTE(C23,"-儿童（加收）","")),0)+N23 -> 27 | AI23: =IF(AF23>0,_xlfn.MAXIFS(O:O,C:C,SUBSTITUTE(C23,"-儿童（加收）","")),0)+O23 -> 25 | AJ23: =IF(AF23>0,_xlfn.MAXIFS(P:P,C:C,SUBSTITUTE(C23,"-儿童（加收）","")),0)+P23 -> 21
A24: 分项 | B24: 012401000030011 | C24: 针极肌电图检查费-单纤维检查（加收） | D24: 检查费 | G24: 次 | I24: 30 | J24: 27 | K24: 17 | L24: 15 | M24: 13 | N24: 27 | O24: 25 | P24: 21 | Q24: 医保 | S24: 我市原项目价格仅为省级价格的73.3%，现提高理顺。 | T24: 003101000240000-310100024 | U24: 310100024 | V24: 单纤维肌电图 | Y24: 每条肌肉 | AA24: 60 | AB24: 54 | AC24: 44 | AD24: 40 | AE24: 34 | AF24: =IFERROR(FIND("-儿童（加收）",C24,1),0) -> 0 | AG24: =SUBSTITUTE(C24,"-儿童（加收）","") -> 针极肌电图检查费-单纤维检查（加收） | AH24: =IF(AF24>0,_xlfn.MAXIFS(N:N,C:C,SUBSTITUTE(C24,"-儿童（加收）","")),0)+N24 -> 27 | AI24: =IF(AF24>0,_xlfn.MAXIFS(O:O,C:C,SUBSTITUTE(C24,"-儿童（加收）","")),0)+O24 -> 25 | AJ24: =IF(AF24>0,_xlfn.MAXIFS(P:P,C:C,SUBSTITUTE(C24,"-儿童（加收）","")),0)+P24 -> 21
A25: 4 | B25: 012401000040000 | C25: 神经传导速度测定费 | D25: 检查费 | E25: 通过仪器对感觉神经或混合神经进行测量。 | F25: 所定价格涵盖设备准备、安装、刺激、分析、出具报告等步骤所需的人力资源和基本物质资源消耗。 | G25: 每根神经 | H25: 长时程运动诱发试验按次收费。 | I25: 22 | J25: 20 | K25: 22 | L25: 20 | M25: 17 | N25: 22 | O25: 20 | P25: 17 | Q25: 医保 | R25: 平移 | S25: 平移，同质化高的检查项目持平省级定价 | T25: 003101000070000-310100007 | U25: 310100007 | V25: 神经传导速度测定 | W25: 含感觉神经与运动神经传导速度、重复神经电刺激 | Y25: 每条神经 | AA25: 22 | AB25: 20 | AC25: 22 | AD25: 20 | AE25: 17 | AF25: =IFERROR(FIND("-儿童（加收）",C25,1),0) -> 0 | AG25: =SUBSTITUTE(C25,"-儿童（加收）","") -> 神经传导速度测定费 | AH25: =IF(AF25>0,_xlfn.MAXIFS(N:N,C:C,SUBSTITUTE(C25,"-儿童（加收）","")),0)+N25 -> 22 | AI25: =IF(AF25>0,_xlfn.MAXIFS(O:O,C:C,SUBSTITUTE(C25,"-儿童（加收）","")),0)+O25 -> 20 | AJ25: =IF(AF25>0,_xlfn.MAXIFS(P:P,C:C,SUBSTITUTE(C25,"-儿童（加收）","")),0)+P25 -> 17
A26: 5 | B26: 012401000050000 | C26: 神经电图费 | D26: 检查费 | E26: 通过仪器刺激周围神经，评定H反射、F波、瞬目反射以及重复神经电刺激等周围神经功能。 | F26: 所定价格涵盖设备准备、安装、刺激、记录、分析、出具报告等步骤所需的人力资源和基本物质资源消耗。 | G26: 次 | I26: 120 | J26: 108 | K26: 110 | L26: 100 | M26: 85 | N26: 110 | O26: 100 | P26: 85 | Q26: 医保 | R26: 平移 | S26: 计价单位改变，根据临床实际，每人次检查约4.8根神经，取整按5根神经计算 | T26: 003101000080000-310100008 | U26: 310100008 | V26: 神经电图 | W26: 含检查F波、H反射、瞬目反射及重复神经电刺激 | Y26: 每条神经 | AA26: 30 | AB26: 27 | AC26: 22 | AD26: 20 | AE26: 17 | AF26: =IFERROR(FIND("-儿童（加收）",C26,1),0) -> 0 | AG26: =SUBSTITUTE(C26,"-儿童（加收）","") -> 神经电图费 | AH26: =IF(AF26>0,_xlfn.MAXIFS(N:N,C:C,SUBSTITUTE(C26,"-儿童（加收）","")),0)+N26 -> 110 | AI26: =IF(AF26>0,_xlfn.MAXIFS(O:O,C:C,SUBSTITUTE(C26,"-儿童（加收）","")),0)+O26 -> 100 | AJ26: =IF(AF26>0,_xlfn.MAXIFS(P:P,C:C,SUBSTITUTE(C26,"-儿童（加收）","")),0)+P26 -> 85
A27: 7 | B27: 012401000070000 | C27: 事件相关电位费 | D27: 检查费 | E27: 通过采集脑诱发电位，对患者注意力、记忆力等认知功能进行评估。 | F27: 所定价格涵盖设备准备、安装、刺激、采集、分析、出具报告等步骤所需的人力资源和基本物质资源消耗。 | G27: 项 | H27: 以3项费用设置封顶线。 | I27: 66 | J27: 59 | K27: 66 | L27: 60 | M27: 51 | N27: 66 | O27: 59 | P27: 51 | Q27: 医保 | R27: 理顺，降低 | S27: 平移后县级按不高于省级拟定 | T27: 003101000110000-310100011 | U27: 310100011 | V27: 事件相关电位 | W27: 包括视觉、体感刺激P300与听觉P300 | Y27: 次 | Z27: 增加N400检查加收50% | AA27: 66 | AB27: 59 | AC27: 66 | AD27: 60 | AE27: 51 | AF27: =IFERROR(FIND("-儿童（加收）",C27,1),0) -> 0 | AG27: =SUBSTITUTE(C27,"-儿童（加收）","") -> 事件相关电位费 | AH27: =IF(AF27>0,_xlfn.MAXIFS(N:N,C:C,SUBSTITUTE(C27,"-儿童（加收）","")),0)+N27 -> 66 | AI27: =IF(AF27>0,_xlfn.MAXIFS(O:O,C:C,SUBSTITUTE(C27,"-儿童（加收）","")),0)+O27 -> 59 | AJ27: =IF(AF27>0,_xlfn.MAXIFS(P:P,C:C,SUBSTITUTE(C27,"-儿童（加收）","")),0)+P27 -> 51
A28: 7 | B28: 012401000070000 | C28: 事件相关电位费 | D28: 检查费 | E28: 通过采集脑诱发电位，对患者注意力、记忆力等认知功能进行评估。 | F28: 所定价格涵盖设备准备、安装、刺激、采集、分析、出具报告等步骤所需的人力资源和基本物质资源消耗。 | G28: 项 | H28: 以3项费用设置封顶线。 | I28: 66 | J28: 59 | K28: 66 | L28: 60 | M28: 51 | N28: 66 | O28: 59 | P28: 51 | Q28: 医保 | R28: 理顺，降低 | S28: 平移后县级按不高于省级拟定 | T28: 003101000110001-31010001101 | U28: 31010001101 | V28: 事件相关电位（增加N400检查） | Y28: 次 | Z28: 增加N400检查 | AA28: 99 | AB28: 89 | AC28: 99 | AD28: 90 | AE28: 76.5 | AF28: =IFERROR(FIND("-儿童（加收）",C28,1),0) -> 0 | AG28: =SUBSTITUTE(C28,"-儿童（加收）","") -> 事件相关电位费 | AH28: =IF(AF28>0,_xlfn.MAXIFS(N:N,C:C,SUBSTITUTE(C28,"-儿童（加收）","")),0)+N28 -> 66 | AI28: =IF(AF28>0,_xlfn.MAXIFS(O:O,C:C,SUBSTITUTE(C28,"-儿童（加收）","")),0)+O28 -> 59 | AJ28: =IF(AF28>0,_xlfn.MAXIFS(P:P,C:C,SUBSTITUTE(C28,"-儿童（加收）","")),0)+P28 -> 51
A29: 8 | B29: 012401000080000 | C29: 脑干听觉诱发电位费 | D29: 检查费 | E29: 通过仪器测定主观听阈和双侧听觉诱发电位，评定听觉传导通路功能。 | F29: 所定价格涵盖设备准备、安装、刺激、采集、分析、出具报告等步骤所需的人力资源和基本物质资源消耗。 | G29: 次 | H29: 不与耳鼻喉科立项指南中的“听阈检查费”同时收取。 | I29: 66 | J29: 59 | K29: 66 | L29: 60 | M29: 51 | N29: 66 | O29: 59 | P29: 51 | Q29: 医保 | R29: 理顺，降低 | S29: 平移后县级按不高于省级拟定 | T29: 003101000120000-310100012 | U29: 310100012 | V29: 脑干听觉诱发电位 | Y29: 次 | AA29: 66 | AB29: 59 | AC29: 66 | AD29: 60 | AE29: 51 | AF29: =IFERROR(FIND("-儿童（加收）",C29,1),0) -> 0 | AG29: =SUBSTITUTE(C29,"-儿童（加收）","") -> 脑干听觉诱发电位费 | AH29: =IF(AF29>0,_xlfn.MAXIFS(N:N,C:C,SUBSTITUTE(C29,"-儿童（加收）","")),0)+N29 -> 66 | AI29: =IF(AF29>0,_xlfn.MAXIFS(O:O,C:C,SUBSTITUTE(C29,"-儿童（加收）","")),0)+O29 -> 59 | AJ29: =IF(AF29>0,_xlfn.MAXIFS(P:P,C:C,SUBSTITUTE(C29,"-儿童（加收）","")),0)+P29 -> 51
A30: 9 | B30: 012401000090000 | C30: 体感诱发电位费 | D30: 检查费 | E30: 通过刺激体感通路采集分析诱发电位。 | F30: 所定价格涵盖设备准备、安装、刺激、采集、分析、出具报告等步骤所需的人力资源和基本物质资源消耗。 | G30: 单肢 | I30: 96 | J30: 86 | K30: 88.009447 | L30: 80.040205 | M30: 68 | N30: 88 | O30: 80 | P30: 68 | Q30: 医保 | R30: 平移取整 | S30: 加权平移取整 | T30: 003101000090000-310100009 | U30: 310100009 | V30: 体感诱发电位 | W30: 包括上肢体感诱发电位检查应含头皮、颈部、Erb氏点记录，下肢体感诱发电位检查应含头皮、腰部记录 | Y30: 单肢 | Z30: 诱发电位地形图分析加收20%；术中监测基层17元/小时，县级医院20元/小时，市级医院22元/小时 | AA30: 88 | AB30: 79 | AC30: 88 | AD30: 80 | AE30: 68 | AF30: =IFERROR(FIND("-儿童（加收）",C30,1),0) -> 0 | AG30: =SUBSTITUTE(C30,"-儿童（加收）","") -> 体感诱发电位费 | AH30: =IF(AF30>0,_xlfn.MAXIFS(N:N,C:C,SUBSTITUTE(C30,"-儿童（加收）","")),0)+N30 -> 88 | AI30: =IF(AF30>0,_xlfn.MAXIFS(O:O,C:C,SUBSTITUTE(C30,"-儿童（加收）","")),0)+O30 -> 80 | AJ30: =IF(AF30>0,_xlfn.MAXIFS(P:P,C:C,SUBSTITUTE(C30,"-儿童（加收）","")),0)+P30 -> 68
A31: 9 | B31: 012401000090000 | C31: 体感诱发电位费 | D31: 检查费 | E31: 通过刺激体感通路采集分析诱发电位。 | F31: 所定价格涵盖设备准备、安装、刺激、采集、分析、出具报告等步骤所需的人力资源和基本物质资源消耗。 | G31: 单肢 | I31: 96 | J31: 86 | K31: 88.009447 | L31: 80.040205 | M31: 68 | N31: 88 | O31: 80 | P31: 68 | Q31: 医保 | R31: 平移取整 | S31: 加权平移取整 | T31: 003101000090001-31010000901 | U31: 31010000901 | V31: 体感诱发电位（诱发电位地形图分析） | Y31: 单肢 | Z31: 诱发电位地形图分析 | AA31: 105 | AB31: 95 | AC31: 105.6 | AD31: 96 | AE31: 81.6 | AF31: =IFERROR(FIND("-儿童（加收）",C31,1),0) -> 0 | AG31: =SUBSTITUTE(C31,"-儿童（加收）","") -> 体感诱发电位费 | AH31: =IF(AF31>0,_xlfn.MAXIFS(N:N,C:C,SUBSTITUTE(C31,"-儿童（加收）","")),0)+N31 -> 88 | AI31: =IF(AF31>0,_xlfn.MAXIFS(O:O,C:C,SUBSTITUTE(C31,"-儿童（加收）","")),0)+O31 -> 80 | AJ31: =IF(AF31>0,_xlfn.MAXIFS(P:P,C:C,SUBSTITUTE(C31,"-儿童（加收）","")),0)+P31 -> 68
A32: 10 | B32: 012401000100000 | C32: 运动诱发电位费 | D32: 检查费 | E32: 通过刺激运动通路采集分析诱发电位。 | F32: 所定价格涵盖设备准备、安装、刺激、采集、分析、出具报告等步骤所需的人力资源和基本物质资源消耗。 | G32: 单肢 | H32: 电诊断三甲医院按照34元/单肢收取，三甲以下医院按照31元/单肢收取。 电诊断市级医院按照31元/单肢收取。县级医院按照29元/单肢收取，基层按照25元/单肢收取。 | I32: 60 | J32: 54 | K32: 54 | L32: 50 | M32: 42 | N32: 54 | O32: 50 | P32: 42 | Q32: 非医保 | R32: 平移 | S32: 平移 | T32: 003101000100000-310100010 | U32: 310100010 | V32: 运动诱发电位 | W32: 含大脑皮层和周围神经刺激 | Y32: 次 | Z32: 限神经外科术中监测 | AA32: 60 | AB32: 54 | AC32: 54 | AD32: 50 | AE32: 42 | AF32: =IFERROR(FIND("-儿童（加收）",C32,1),0) -> 0 | AG32: =SUBSTITUTE(C32,"-儿童（加收）","") -> 运动诱发电位费 | AH32: =IF(AF32>0,_xlfn.MAXIFS(N:N,C:C,SUBSTITUTE(C32,"-儿童（加收）","")),0)+N32 -> 54 | AI32: =IF(AF32>0,_xlfn.MAXIFS(O:O,C:C,SUBSTITUTE(C32,"-儿童（加收）","")),0)+O32 -> 50 | AJ32: =IF(AF32>0,_xlfn.MAXIFS(P:P,C:C,SUBSTITUTE(C32,"-儿童（加收）","")),0)+P32 -> 42
A33: 新增分项 | B33: 012401000100000 | C33: 运动诱发电位费（电诊断） | G33: 单肢 | I33: 34 | J33: 31 | K33: 32 | L33: 32 | M33: 27.2 | N33: 32 | O33: 30 | P33: 27 | Q33: 非医保 | S33: 新增项目 根据指导意见，电诊断取数每人次3-4块肌肉和神经，平移后理顺比价 | T33: 003401000070000-340100007 | U33: 340100007 | V33: 电诊断 | W33: 包括直流电检查、感应电检查、直流-感应电检查、时值检查、强度-频率曲线检查、中频脉冲电检查。 | Y33: 每块肌肉或每条神经 | AA33: 8.5 | AB33: 8.5 | AC33: 8 | AD33: 8 | AE33: 6.8 | AF33: =IFERROR(FIND("-儿童（加收）",C33,1),0) -> 0 | AG33: =SUBSTITUTE(C33,"-儿童（加收）","") -> 运动诱发电位费（电诊断） | AH33: =IF(AF33>0,_xlfn.MAXIFS(N:N,C:C,SUBSTITUTE(C33,"-儿童（加收）","")),0)+N33 -> 32 | AI33: =IF(AF33>0,_xlfn.MAXIFS(O:O,C:C,SUBSTITUTE(C33,"-儿童（加收）","")),0)+O33 -> 30 | AJ33: =IF(AF33>0,_xlfn.MAXIFS(P:P,C:C,SUBSTITUTE(C33,"-儿童（加收）","")),0)+P33 -> 27
A34: 12 | B34: 012401000120000 | C34: 颅内压监测费（有创） | D34: 检查费 | E34: 通过有创方式监测颅内压变化。 | F34: 所定价格涵盖摆位、设备准备、安装、监测、记录、分析等步骤所需的人力资源和基本物质资源消耗。 | G34: 小时 | I34: 6 | J34: 6 | N34: 6 | O34: 5.8 | P34: 5.4 | Q34: 医保 | R34: 新增项目 | S34: 新增项目。按无创的2倍拟定 | T34: 003101000140000-310100014 | AF34: =IFERROR(FIND("-儿童（加收）",C34,1),0) -> 0 | AG34: =SUBSTITUTE(C34,"-儿童（加收）","") -> 颅内压监测费（有创） | AH34: =IF(AF34>0,_xlfn.MAXIFS(N:N,C:C,SUBSTITUTE(C34,"-儿童（加收）","")),0)+N34 -> 6 | AI34: =IF(AF34>0,_xlfn.MAXIFS(O:O,C:C,SUBSTITUTE(C34,"-儿童（加收）","")),0)+O34 -> 5.8 | AJ34: =IF(AF34>0,_xlfn.MAXIFS(P:P,C:C,SUBSTITUTE(C34,"-儿童（加收）","")),0)+P34 -> 5.4
A35: 13 | B35: 012401000130000 | C35: 颅内压监测费（无创） | D35: 检查费 | E35: 通过无创方式监测颅内压变化。 | F35: 所定价格涵盖摆位、设备准备、安装、监测、记录、分析等步骤所需的人力资源和基本物质资源消耗。 | G35: 小时 | I35: 3 | J35: 3 | K35: 3.3 | L35: 3 | M35: 2.6 | N35: 3 | O35: 2.9 | P35: 2.7 | Q35: 医保 | R35: 理顺，降低 | S35: 平移后按不高于省级拟定，同质化项目缩小差距 | T35: 003101000140000-310100014 | U35: 310100014 | V35: 颅内压监测 | Y35: 小时 | AA35: 3 | AB35: 3 | AC35: 3.3 | AD35: 3 | AE35: 2.6 | AF35: =IFERROR(FIND("-儿童（加收）",C35,1),0) -> 0 | AG35: =SUBSTITUTE(C35,"-儿童（加收）","") -> 颅内压监测费（无创） | AH35: =IF(AF35>0,_xlfn.MAXIFS(N:N,C:C,SUBSTITUTE(C35,"-儿童（加收）","")),0)+N35 -> 3 | AI35: =IF(AF35>0,_xlfn.MAXIFS(O:O,C:C,SUBSTITUTE(C35,"-儿童（加收）","")),0)+O35 -> 2.9 | AJ35: =IF(AF35>0,_xlfn.MAXIFS(P:P,C:C,SUBSTITUTE(C35,"-儿童（加收）","")),0)+P35 -> 2.7
A36: 13 | B36: 012401000130000 | C36: 颅内压监测费（无创） | D36: 检查费 | E36: 通过无创方式监测颅内压变化。 | F36: 所定价格涵盖摆位、设备准备、安装、监测、记录、分析等步骤所需的人力资源和基本物质资源消耗。 | G36: 小时 | I36: 3 | J36: 3 | K36: 3.3 | L36: 3 | M36: 2.6 | N36: 3 | O36: 2.9 | P36: 2.7 | Q36: 医保 | R36: 理顺，降低 | S36: 平移后按不高于省级拟定，同质化项目缩小差距 | T36: 003112020020000-311202002 | U36: 311202002 | V36: 新生儿测颅压 | Y36: 次 | AF36: =IFERROR(FIND("-儿童（加收）",C36,1),0) -> 0 | AG36: =SUBSTITUTE(C36,"-儿童（加收）","") -> 颅内压监测费（无创） | AH36: =IF(AF36>0,_xlfn.MAXIFS(N:N,C:C,SUBSTITUTE(C36,"-儿童（加收）","")),0)+N36 -> 3 | AI36: =IF(AF36>0,_xlfn.MAXIFS(O:O,C:C,SUBSTITUTE(C36,"-儿童（加收）","")),0)+O36 -> 2.9 | AJ36: =IF(AF36>0,_xlfn.MAXIFS(P:P,C:C,SUBSTITUTE(C36,"-儿童（加收）","")),0)+P36 -> 2.7
A37: 14 | B37: 012401000140000 | C37: 脑血管造影费 | D37: 检查费 | E37: 通过介入方式对脑血管进行造影检查。 | F37: 所定价格涵盖手术计划、术区准备、消毒铺巾、建立通路、脑血管造影、撤除、闭合血管通路等步骤所需的人力资源和基本物质资源消耗。 | G37: 次 | H37: 次指3根及以下血管，超过3根血管，每增加1根血管加收20%，以8根血管费用设置封顶线。 | I37: 2250 | J37: 2025 | K37: 2090.625 | L37: 1884.375 | M37: 1509.375 | N37: 2090 | O37: 1885 | P37: 1510 | Q37: 医保 | R37: 平移取整 | S37: 原项目含双侧颈内动脉、颈外动脉、椎动脉，合计6根血管，现拆分为3根血管为基础价，每增加1根加收20%。则原来收取1次费用，现收取1+0.2×3=1.6次。按原项目价格除以1.6得出基础价格，取整拟定。 | T37: 003206000010000-320600001 | U37: 320600001 | V37: 经股动脉插管全脑动脉造影术 | W37: 含颈动脉、椎动脉，包括经颈动脉插管 | Y37: 次 | AA37: 3600 | AB37: 3240 | AC37: 3345 | AD37: 3015 | AE37: 2415 | AF37: =IFERROR(FIND("-儿童（加收）",C37,1),0) -> 0 | AG37: =SUBSTITUTE(C37,"-儿童（加收）","") -> 脑血管造影费 | AH37: =IF(AF37>0,_xlfn.MAXIFS(N:N,C:C,SUBSTITUTE(C37,"-儿童（加收）","")),0)+N37 -> 2090 | AI37: =IF(AF37>0,_xlfn.MAXIFS(O:O,C:C,SUBSTITUTE(C37,"-儿童（加收）","")),0)+O37 -> 1885 | AJ37: =IF(AF37>0,_xlfn.MAXIFS(P:P,C:C,SUBSTITUTE(C37,"-儿童（加收）","")),0)+P37 -> 1510
A38: 14 | B38: 012401000140000 | C38: 脑血管造影费 | D38: 检查费 | E38: 通过介入方式对脑血管进行造影检查。 | F38: 所定价格涵盖手术计划、术区准备、消毒铺巾、建立通路、脑血管造影、撤除、闭合血管通路等步骤所需的人力资源和基本物质资源消耗。 | G38: 次 | H38: 次指3根及以下血管，超过3根血管，每增加1根血管加收20%，以8根血管费用设置封顶线。 | I38: 2250 | J38: 2025 | K38: 2090.625 | L38: 1884.375 | M38: 1509.375 | N38: 2090 | O38: 1885 | P38: 1510 | Q38: 医保 | R38: 平移取整 | S38: 原项目含双侧颈内动脉、颈外动脉、椎动脉，合计6根血管，现拆分为3根血管为基础价，每增加1根加收20%。则原来收取1次费用，现收取1+0.2×3=1.6次。按原项目价格除以1.6得出基础价格，取整拟定。 | T38: 003206000010000-32060000101 | U38: 32060000101 | V38: 小儿经股动脉插管全脑动脉造影术 | Y38: 次 | AA38: 4680 | AB38: 4210 | AC38: 4350 | AD38: 3920 | AE38: 3140 | AF38: =IFERROR(FIND("-儿童（加收）",C38,1),0) -> 0 | AG38: =SUBSTITUTE(C38,"-儿童（加收）","") -> 脑血管造影费 | AH38: =IF(AF38>0,_xlfn.MAXIFS(N:N,C:C,SUBSTITUTE(C38,"-儿童（加收）","")),0)+N38 -> 2090 | AI38: =IF(AF38>0,_xlfn.MAXIFS(O:O,C:C,SUBSTITUTE(C38,"-儿童（加收）","")),0)+O38 -> 1885 | AJ38: =IF(AF38>0,_xlfn.MAXIFS(P:P,C:C,SUBSTITUTE(C38,"-儿童（加收）","")),0)+P38 -> 1510
A39: 15 | B39: 012401000150000 | C39: 脊髓血管造影费 | D39: 检查费 | E39: 通过介入方式对脊髓血管进行造影检查。 | F39: 所定价格涵盖手术计划、术区准备、消毒铺巾、建立通路、脊髓血管造影、撤除、闭合血管通路等步骤所需的人力资源和基本物质资源消耗。 | G39: 次 | H39: 次指4根及以下血管，超过4根血管，每增加1根血管加收5%。以12根血管费用设置封顶线。 | I39: 2000 | J39: 1800 | K39: 1944 | L39: 1760 | M39: 1496 | N39: 1950 | O39: 1760 | P39: 1500 | Q39: 医保 | R39: 平移取整 | S39: 脊髓动脉造影通常需要完成双侧椎动脉、甲状颈干、肋颈干等10根血管，现拆分为4根血管为基础价，每增加1根加收5%。现收取1+0.05×5=1.25次。按原项目价格除以1.25得出基础价格，取整拟定。 | T39: 003206000100000-320600010 | U39: 320600010 | V39: 脊髓动脉造影术 | Y39: 次 | AA39: 2700 | AB39: 2430 | AC39: 2430 | AD39: 2200 | AE39: 1870 | AF39: =IFERROR(FIND("-儿童（加收）",C39,1),0) -> 0 | AG39: =SUBSTITUTE(C39,"-儿童（加收）","") -> 脊髓血管造影费 | AH39: =IF(AF39>0,_xlfn.MAXIFS(N:N,C:C,SUBSTITUTE(C39,"-儿童（加收）","")),0)+N39 -> 1950 | AI39: =IF(AF39>0,_xlfn.MAXIFS(O:O,C:C,SUBSTITUTE(C39,"-儿童（加收）","")),0)+O39 -> 1760 | AJ39: =IF(AF39>0,_xlfn.MAXIFS(P:P,C:C,SUBSTITUTE(C39,"-儿童（加收）","")),0)+P39 -> 1500
A40: 15 | B40: 012401000150000 | C40: 脊髓血管造影费 | D40: 检查费 | E40: 通过介入方式对脊髓血管进行造影检查。 | F40: 所定价格涵盖手术计划、术区准备、消毒铺巾、建立通路、脊髓血管造影、撤除、闭合血管通路等步骤所需的人力资源和基本物质资源消耗。 | G40: 次 | H40: 次指4根及以下血管，超过4根血管，每增加1根血管加收5%。以12根血管费用设置封顶线。 | I40: 2000 | J40: 1800 | K40: 1944 | L40: 1760 | M40: 1496 | N40: 1950 | O40: 1760 | P40: 1500 | Q40: 医保 | R40: 平移取整 | S40: 脊髓动脉造影通常需要完成双侧椎动脉、甲状颈干、肋颈干等10根血管，现拆分为4根血管为基础价，每增加1根加收5%。现收取1+0.05×5=1.25次。按原项目价格除以1.25得出基础价格，取整拟定。 | T40: 003206000100000-32060001001 | U40: 32060001001 | V40: 小儿脊髓动脉造影术 | Y40: 次 | AA40: 3510 | AB40: 3160 | AC40: 3160 | AD40: 2860 | AE40: 2430 | AF40: =IFERROR(FIND("-儿童（加收）",C40,1),0) -> 0 | AG40: =SUBSTITUTE(C40,"-儿童（加收）","") -> 脊髓血管造影费 | AH40: =IF(AF40>0,_xlfn.MAXIFS(N:N,C:C,SUBSTITUTE(C40,"-儿童（加收）","")),0)+N40 -> 1950 | AI40: =IF(AF40>0,_xlfn.MAXIFS(O:O,C:C,SUBSTITUTE(C40,"-儿童（加收）","")),0)+O40 -> 1760 | AJ40: =IF(AF40>0,_xlfn.MAXIFS(P:P,C:C,SUBSTITUTE(C40,"-儿童（加收）","")),0)+P40 -> 1500
...

Sheet Sheet2
A1: id | B1: code | C1: sever_type | D1: change_time | E1: old_hilist_code | F1: new_hilist_code | G1: hilist_name | H1: selfpay_prop | I1: old_price | J1: old_price_city | K1: old_price_town | L1: old_price_village | M1: new_price | N1: new_price_city | O1: new_price_town | P1: new_price_village | Q1: unit | R1: batch | S1: is_use_old | T1: merge_type | U1: cnt_change_model | V1: cnt_change_value | W1: ="insert into server_list_change_all_20250525 ("&_xlfn.TEXTJOIN(",",TRUE,A1:V1)&") values" -> insert into server_list_change_all_20250525 (id,code,sever_type,change_time,old_hilist_code,new_hilist_code,hilist_name,selfpay_prop,old_price,old_price_city,old_price_town,old_price_village,new_price,new_price_city,new_price_town,new_price_village,unit,batch,is_use_old,merge_type,cnt_change_model,cnt_change_value) values
A2: 2714 | B2: null | C2: 1 | D2: 2026-04-28 00:00:00 | E2: 003101000010000-310100001 | F2: 003101000010000-310100001 | G2: 脑电图 | H2: null | I2: null | J2: 33 | K2: 30 | L2: 25.5 | M2: null | N2: 98 | O2: 90 | P2: 78 | Q2: 次 | R2: 26 | S2: 1 | T2: normal | U2: main | V2: 0 | W2: ="("&A2&","&B2&","&C2&",'"&D2&"','"&E2&"','"&F2&"','"&G2&"',"&H2&","&I2&","&J2&","&K2&","&L2&","&M2&","&N2&","&O2&","&P2&",'"&Q2&"',"&R2&","&S2&",'"&T2&"','"&U2&"',"&V2&")," -> (2714,null,1,'2026-04-28 00:00:00','003101000010000-310100001','003101000010000-310100001','脑电图',null,null,33,30,25.5,null,98,90,78,'次',26,1,'normal','main',0),
A3: 2715 | B3: null | C3: 1 | D3: 2026-04-28 00:00:00 | E3: 003101000010001-31010000101 | F3: 003101000010001-31010000101 | G3: 脑电图（脑电发生源定位） | H3: null | I3: null | J3: 49.5 | K3: 45 | L3: 38.3 | M3: null | N3: 98 | O3: 90 | P3: 78 | Q3: 次 | R3: 26 | S3: 1 | T3: normal | U3: main | V3: 0 | W3: ="("&A3&","&B3&","&C3&",'"&D3&"','"&E3&"','"&F3&"','"&G3&"',"&H3&","&I3&","&J3&","&K3&","&L3&","&M3&","&N3&","&O3&","&P3&",'"&Q3&"',"&R3&","&S3&",'"&T3&"','"&U3&"',"&V3&")," -> (2715,null,1,'2026-04-28 00:00:00','003101000010001-31010000101','003101000010001-31010000101','脑电图（脑电发生源定位）',null,null,49.5,45,38.3,null,98,90,78,'次',26,1,'normal','main',0),
A4: 2716 | B4: null | C4: 1 | D4: 2026-04-28 00:00:00 | E4: 003101000030000-310100003 | F4: 003101000030000-310100003 | G4: 脑地形图 | H4: null | I4: null | J4: 110 | K4: 100 | L4: 85 | M4: null | N4: 98 | O4: 90 | P4: 78 | Q4: 次 | R4: 26 | S4: 1 | T4: normal | U4: main | V4: 0 | W4: ="("&A4&","&B4&","&C4&",'"&D4&"','"&E4&"','"&F4&"','"&G4&"',"&H4&","&I4&","&J4&","&K4&","&L4&","&M4&","&N4&","&O4&","&P4&",'"&Q4&"',"&R4&","&S4&",'"&T4&"','"&U4&"',"&V4&")," -> (2716,null,1,'2026-04-28 00:00:00','003101000030000-310100003','003101000030000-310100003','脑地形图',null,null,110,100,85,null,98,90,78,'次',26,1,'normal','main',0),
A5: 2717 | B5: null | C5: 1 | D5: 2026-04-28 00:00:00 | E5: 003101000040000-310100004 | F5: 003101000040000-310100004 | G5: 动态脑电图 | H5: null | I5: null | J5: 286 | K5: 260 | L5: 221 | M5: null | N5: 98 | O5: 90 | P5: 78 | Q5: 次 | R5: 26 | S5: 1 | T5: normal | U5: main | V5: 0 | W5: ="("&A5&","&B5&","&C5&",'"&D5&"','"&E5&"','"&F5&"','"&G5&"',"&H5&","&I5&","&J5&","&K5&","&L5&","&M5&","&N5&","&O5&","&P5&",'"&Q5&"',"&R5&","&S5&",'"&T5&"','"&U5&"',"&V5&")," -> (2717,null,1,'2026-04-28 00:00:00','003101000040000-310100004','003101000040000-310100004','动态脑电图',null,null,286,260,221,null,98,90,78,'次',26,1,'normal','main',0),
A6: 2718 | B6: null | C6: 1 | D6: 2026-04-28 00:00:00 | E6: 003101000040100-31010000401 | F6: 003101000040100-31010000401 | G6: 动态脑电图（24小时脑电视频监测） | H6: null | I6: null | J6: 286 | K6: 260 | L6: 221 | M6: null | N6: 98 | O6: 90 | P6: 78 | Q6: 次 | R6: 26 | S6: 1 | T6: normal | U6: main | V6: 0 | W6: ="("&A6&","&B6&","&C6&",'"&D6&"','"&E6&"','"&F6&"','"&G6&"',"&H6&","&I6&","&J6&","&K6&","&L6&","&M6&","&N6&","&O6&","&P6&",'"&Q6&"',"&R6&","&S6&",'"&T6&"','"&U6&"',"&V6&")," -> (2718,null,1,'2026-04-28 00:00:00','003101000040100-31010000401','003101000040100-31010000401','动态脑电图（24小时脑电视频监测）',null,null,286,260,221,null,98,90,78,'次',26,1,'normal','main',0),
A7: 2719 | B7: null | C7: 1 | D7: 2026-04-28 00:00:00 | E7: 003101000040200-31010000402 | F7: 003101000040200-31010000402 | G7: 动态脑电图（24小时脑电Holter） | H7: null | I7: null | J7: 286 | K7: 260 | L7: 221 | M7: null | N7: 98 | O7: 90 | P7: 78 | Q7: 次 | R7: 26 | S7: 1 | T7: normal | U7: main | V7: 0 | W7: ="("&A7&","&B7&","&C7&",'"&D7&"','"&E7&"','"&F7&"','"&G7&"',"&H7&","&I7&","&J7&","&K7&","&L7&","&M7&","&N7&","&O7&","&P7&",'"&Q7&"',"&R7&","&S7&",'"&T7&"','"&U7&"',"&V7&")," -> (2719,null,1,'2026-04-28 00:00:00','003101000040200-31010000402','003101000040200-31010000402','动态脑电图（24小时脑电Holter）',null,null,286,260,221,null,98,90,78,'次',26,1,'normal','main',0),
A8: 2720 | B8: null | C8: 1 | D8: 2026-04-28 00:00:00 | E8: 003101000050000-310100005 | F8: 003101000050000-310100005 | G8: 脑电图录象监测 | H8: null | I8: null | J8: 27.5 | K8: 25 | L8: 21.3 | M8: null | N8: 24.5 | O8: 22.5 | P8: 19.5 | Q8: 小时 | R8: 26 | S8: 1 | T8: normal | U8: main | V8: 0 | W8: ="("&A8&","&B8&","&C8&",'"&D8&"','"&E8&"','"&F8&"','"&G8&"',"&H8&","&I8&","&J8&","&K8&","&L8&","&M8&","&N8&","&O8&","&P8&",'"&Q8&"',"&R8&","&S8&",'"&T8&"','"&U8&"',"&V8&")," -> (2720,null,1,'2026-04-28 00:00:00','003101000050000-310100005','003101000050000-310100005','脑电图录象监测',null,null,27.5,25,21.3,null,24.5,22.5,19.5,'小时',26,1,'normal','main',0),
A9: 2721 | B9: null | C9: 1 | D9: 2026-04-28 00:00:00 | E9: 003101000020000-310100002 | F9: 003101000020000-310100002 | G9: 特殊脑电图 | H9: null | I9: null | J9: 66 | K9: 60 | L9: 51 | M9: null | N9: 107 | O9: 98 | P9: 85 | Q9: 次 | R9: 26 | S9: 1 | T9: normal | U9: main | V9: 0 | W9: ="("&A9&","&B9&","&C9&",'"&D9&"','"&E9&"','"&F9&"','"&G9&"',"&H9&","&I9&","&J9&","&K9&","&L9&","&M9&","&N9&","&O9&","&P9&",'"&Q9&"',"&R9&","&S9&",'"&T9&"','"&U9&"',"&V9&")," -> (2721,null,1,'2026-04-28 00:00:00','003101000020000-310100002','003101000020000-310100002','特殊脑电图',null,null,66,60,51,null,107,98,85,'次',26,1,'normal','main',0),
A10: 2722 | B10: null | C10: 1 | D10: 2026-04-28 00:00:00 | E10: 003101000020100-31010000201 | F10: 003101000020100-31010000201 | G10: 特殊脑电图（特殊电极鼻咽或蝶骨或皮层等） | H10: null | I10: null | J10: 66 | K10: 60 | L10: 51 | M10: null | N10: 107 | O10: 98 | P10: 85 | Q10: 次 | R10: 26 | S10: 1 | T10: normal | U10: main | V10: 0 | W10: ="("&A10&","&B10&","&C10&",'"&D10&"','"&E10&"','"&F10&"','"&G10&"',"&H10&","&I10&","&J10&","&K10&","&L10&","&M10&","&N10&","&O10&","&P10&",'"&Q10&"',"&R10&","&S10&",'"&T10&"','"&U10&"',"&V10&")," -> (2722,null,1,'2026-04-28 00:00:00','003101000020100-31010000201','003101000020100-31010000201','特殊脑电图（特殊电极鼻咽或蝶骨或皮层等）',null,null,66,60,51,null,107,98,85,'次',26,1,'normal','main',0),
A11: 2723 | B11: null | C11: 1 | D11: 2026-04-28 00:00:00 | E11: 003101000020200-31010000202 | F11: 003101000020200-31010000202 | G11: 特殊脑电图（特殊诱发） | H11: null | I11: null | J11: 66 | K11: 60 | L11: 51 | M11: null | N11: 107 | O11: 98 | P11: 85 | Q11: 次 | R11: 26 | S11: 1 | T11: normal | U11: main | V11: 0 | W11: ="("&A11&","&B11&","&C11&",'"&D11&"','"&E11&"','"&F11&"','"&G11&"',"&H11&","&I11&","&J11&","&K11&","&L11&","&M11&","&N11&","&O11&","&P11&",'"&Q11&"',"&R11&","&S11&",'"&T11&"','"&U11&"',"&V11&")," -> (2723,null,1,'2026-04-28 00:00:00','003101000020200-31010000202','003101000020200-31010000202','特殊脑电图（特殊诱发）',null,null,66,60,51,null,107,98,85,'次',26,1,'normal','main',0),
A12: 2724 | B12: null | C12: 1 | D12: 2026-04-28 00:00:00 | E12: 003101000050000-31010000501 | F12: 003101000050000-31010000501 | G12: 颅内电极视频脑电图录像监测 | H12: null | I12: null | J12: 115 | K12: 105 | L12: 95 | M12: null | N12: 61.25 | O12: 56.25 | P12: 48.75 | Q12: 小时 | R12: 26 | S12: 1 | T12: normal | U12: main | V12: 0 | W12: ="("&A12&","&B12&","&C12&",'"&D12&"','"&E12&"','"&F12&"','"&G12&"',"&H12&","&I12&","&J12&","&K12&","&L12&","&M12&","&N12&","&O12&","&P12&",'"&Q12&"',"&R12&","&S12&",'"&T12&"','"&U12&"',"&V12&")," -> (2724,null,1,'2026-04-28 00:00:00','003101000050000-31010000501','003101000050000-31010000501','颅内电极视频脑电图录像监测',null,null,115,105,95,null,61.25,56.25,48.75,'小时',26,1,'normal','main',0),
A13: 2725 | B13: null | C13: 1 | D13: 2026-04-28 00:00:00 | E13: 003101000060000-310100006 | F13: 003101000060000-310100006 | G13: 脑磁图 | H13: null | I13: null | J13: 0 | K13: 0 | L13: 0 | M13: null | N13: 3900 | O13: 3600 | P13: 3060 | Q13: 次 | R13: 26 | S13: 1 | T13: normal | U13: main | V13: 0 | W13: ="("&A13&","&B13&","&C13&",'"&D13&"','"&E13&"','"&F13&"','"&G13&"',"&H13&","&I13&","&J13&","&K13&","&L13&","&M13&","&N13&","&O13&","&P13&",'"&Q13&"',"&R13&","&S13&",'"&T13&"','"&U13&"',"&V13&")," -> (2725,null,1,'2026-04-28 00:00:00','003101000060000-310100006','003101000060000-310100006','脑磁图',null,null,0,0,0,null,3900,3600,3060,'次',26,1,'normal','main',0),
... A30: 2742 | B30: null | C30: 1 | D30: 2026-04-28 00:00:00 | E30: 003401000070000-340100007 | F30: 003401000070000-340100007 | G30: 电诊断 | H30: null | I30: null | J30: 8 | K30: 8 | L30: 6.8 | M30: null | N30: 32 | O30: 30 | P30: 27 | Q30: 每块肌肉或每条神经 | R30: 26 | S30: 1 | T30: normal | U30: main | V30: 0 | W30: ="("&A30&","&B30&","&C30&",'"&D30&"','"&E30&"','"&F30&"','"&G30&"',"&H30&","&I30&","&J30&","&K30&","&L30&","&M30&","&N30&","&O30&","&P30&",'"&Q30&"',"&R30&","&S30&",'"&T30&"','"&U30&"',"&V30&")," -> (2742,null,1,'2026-04-28 00:00:00','003401000070000-340100007','003401000070000-340100007','电诊断',null,null,8,8,6.8,null,32,30,27,'每块肌肉或每条神经',26,1,'normal','main',0),
A31: 2743 | B31: null | C31: 1 | D31: 2026-04-28 00:00:00 | E31: 003101000140000-310100014 | F31: 003101000140000-310100014 | H31: null | I31: null | J31: 0 | K31: 0 | L31: 0 | M31: null | N31: 6 | O31: 5.8 | P31: 5.4 | R31: 26 | S31: 1 | T31: normal | U31: main | V31: 0 | W31: ="("&A31&","&B31&","&C31&",'"&D31&"','"&E31&"','"&F31&"','"&G31&"',"&H31&","&I31&","&J31&","&K31&","&L31&","&M31&","&N31&","&O31&","&P31&",'"&Q31&"',"&R31&","&S31&",'"&T31&"','"&U31&"',"&V31&")," -> (2743,null,1,'2026-04-28 00:00:00','003101000140000-310100014','003101000140000-310100014','',null,null,0,0,0,null,6,5.8,5.4,'',26,1,'normal','main',0),
A32: 2744 | B32: null | C32: 1 | D32: 2026-04-28 00:00:00 | E32: 003101000140000-310100014 | F32: 003101000140000-310100014 | G32: 颅内压监测 | H32: null | I32: null | J32: 3.3 | K32: 3 | L32: 2.6 | M32: null | N32: 3 | O32: 2.9 | P32: 2.7 | Q32: 小时 | R32: 26 | S32: 1 | T32: normal | U32: main | V32: 0 | W32: ="("&A32&","&B32&","&C32&",'"&D32&"','"&E32&"','"&F32&"','"&G32&"',"&H32&","&I32&","&J32&","&K32&","&L32&","&M32&","&N32&","&O32&","&P32&",'"&Q32&"',"&R32&","&S32&",'"&T32&"','"&U32&"',"&V32&")," -> (2744,null,1,'2026-04-28 00:00:00','003101000140000-310100014','003101000140000-310100014','颅内压监测',null,null,3.3,3,2.6,null,3,2.9,2.7,'小时',26,1,'normal','main',0),
A33: 2745 | B33: null | C33: 1 | D33: 2026-04-28 00:00:00 | E33: 003112020020000-311202002 | F33: 003112020020000-311202002 | G33: 新生儿测颅压 | H33: null | I33: null | J33: 0 | K33: 0 | L33: 0 | M33: null | N33: 3 | O33: 2.9 | P33: 2.7 | Q33: 次 | R33: 26 | S33: 1 | T33: normal | U33: main | V33: 0 | W33: ="("&A33&","&B33&","&C33&",'"&D33&"','"&E33&"','"&F33&"','"&G33&"',"&H33&","&I33&","&J33&","&K33&","&L33&","&M33&","&N33&","&O33&","&P33&",'"&Q33&"',"&R33&","&S33&",'"&T33&"','"&U33&"',"&V33&")," -> (2745,null,1,'2026-04-28 00:00:00','003112020020000-311202002','003112020020000-311202002','新生儿测颅压',null,null,0,0,0,null,3,2.9,2.7,'次',26,1,'normal','main',0),
A34: 2746 | B34: null | C34: 1 | D34: 2026-04-28 00:00:00 | E34: 003206000010000-320600001 | F34: 003206000010000-320600001 | G34: 经股动脉插管全脑动脉造影术 | H34: null | I34: null | J34: 3345 | K34: 3015 | L34: 2415 | M34: null | N34: 3344 | O34: 3016 | P34: 2416 | Q34: 次 | R34: 26 | S34: 1 | T34: normal | U34: main | V34: 0 | W34: ="("&A34&","&B34&","&C34&",'"&D34&"','"&E34&"','"&F34&"','"&G34&"',"&H34&","&I34&","&J34&","&K34&","&L34&","&M34&","&N34&","&O34&","&P34&",'"&Q34&"',"&R34&","&S34&",'"&T34&"','"&U34&"',"&V34&")," -> (2746,null,1,'2026-04-28 00:00:00','003206000010000-320600001','003206000010000-320600001','经股动脉插管全脑动脉造影术',null,null,3345,3015,2415,null,3344,3016,2416,'次',26,1,'normal','main',0),
A35: 2747 | B35: null | C35: 1 | D35: 2026-04-28 00:00:00 | E35: 003206000010000-32060000101 | F35: 003206000010000-32060000101 | G35: 小儿经股动脉插管全脑动脉造影术 | H35: null | I35: null | J35: 4350 | K35: 3920 | L35: 3140 | M35: null | N35: 3344 | O35: 3016 | P35: 2416 | Q35: 次 | R35: 26 | S35: 1 | T35: normal | U35: main | V35: 0 | W35: ="("&A35&","&B35&","&C35&",'"&D35&"','"&E35&"','"&F35&"','"&G35&"',"&H35&","&I35&","&J35&","&K35&","&L35&","&M35&","&N35&","&O35&","&P35&",'"&Q35&"',"&R35&","&S35&",'"&T35&"','"&U35&"',"&V35&")," -> (2747,null,1,'2026-04-28 00:00:00','003206000010000-32060000101','003206000010000-32060000101','小儿经股动脉插管全脑动脉造影术',null,null,4350,3920,3140,null,3344,3016,2416,'次',26,1,'normal','main',0),
A36: 2748 | B36: null | C36: 1 | D36: 2026-04-28 00:00:00 | E36: 003206000100000-320600010 | F36: 003206000100000-320600010 | G36: 脊髓动脉造影术 | H36: null | I36: null | J36: 2430 | K36: 2200 | L36: 1870 | M36: null | N36: 2437.5 | O36: 2200 | P36: 1875 | Q36: 次 | R36: 26 | S36: 1 | T36: normal | U36: main | V36: 0 | W36: ="("&A36&","&B36&","&C36&",'"&D36&"','"&E36&"','"&F36&"','"&G36&"',"&H36&","&I36&","&J36&","&K36&","&L36&","&M36&","&N36&","&O36&","&P36&",'"&Q36&"',"&R36&","&S36&",'"&T36&"','"&U36&"',"&V36&")," -> (2748,null,1,'2026-04-28 00:00:00','003206000100000-320600010','003206000100000-320600010','脊髓动脉造影术',null,null,2430,2200,1870,null,2437.5,2200,1875,'次',26,1,'normal','main',0),
A37: 2749 | B37: null | C37: 1 | D37: 2026-04-28 00:00:00 | E37: 003206000100000-32060001001 | F37: 003206000100000-32060001001 | G37: 小儿脊髓动脉造影术 | H37: null | I37: null | J37: 3160 | K37: 2860 | L37: 2430 | M37: null | N37: 2437.5 | O37: 2200 | P37: 1875 | Q37: 次 | R37: 26 | S37: 1 | T37: normal | U37: main | V37: 0 | W37: ="("&A37&","&B37&","&C37&",'"&D37&"','"&E37&"','"&F37&"','"&G37&"',"&H37&","&I37&","&J37&","&K37&","&L37&","&M37&","&N37&","&O37&","&P37&",'"&Q37&"',"&R37&","&S37&",'"&T37&"','"&U37&"',"&V37&")," -> (2749,null,1,'2026-04-28 00:00:00','003206000100000-32060001001','003206000100000-32060001001','小儿脊髓动脉造影术',null,null,3160,2860,2430,null,2437.5,2200,1875,'次',26,1,'normal','main',0),
A38: 2750 | B38: null | C38: 1 | D38: 2026-04-28 00:00:00 | E38: 003101000130000-310100013 | F38: 003101000130000-310100013 | G38: 术中颅神经监测 | H38: null | I38: null | J38: 55 | K38: 50 | L38: 42.5 | M38: null | N38: 48 | O38: 45 | P38: 40 | Q38: 小时 | R38: 26 | S38: 1 | T38: normal | U38: main | V38: 0 | W38: ="("&A38&","&B38&","&C38&",'"&D38&"','"&E38&"','"&F38&"','"&G38&"',"&H38&","&I38&","&J38&","&K38&","&L38&","&M38&","&N38&","&O38&","&P38&",'"&Q38&"',"&R38&","&S38&",'"&T38&"','"&U38&"',"&V38&")," -> (2750,null,1,'2026-04-28 00:00:00','003101000130000-310100013','003101000130000-310100013','术中颅神经监测',null,null,55,50,42.5,null,48,45,40,'小时',26,1,'normal','main',0),
A39: 2751 | B39: null | C39: 1 | D39: 2026-04-28 00:00:00 | E39: 003101000010000-31010000102 | F39: 003101000010000-31010000102 | G39: 脑电图（术中监测） | H39: null | I39: null | J39: 22 | K39: 20 | L39: 17 | M39: null | N39: 48 | O39: 45 | P39: 40 | Q39: 小时 | R39: 26 | S39: 1 | T39: normal | U39: main | V39: 0 | W39: ="("&A39&","&B39&","&C39&",'"&D39&"','"&E39&"','"&F39&"','"&G39&"',"&H39&","&I39&","&J39&","&K39&","&L39&","&M39&","&N39&","&O39&","&P39&",'"&Q39&"',"&R39&","&S39&",'"&T39&"','"&U39&"',"&V39&")," -> (2751,null,1,'2026-04-28 00:00:00','003101000010000-31010000102','003101000010000-31010000102','脑电图（术中监测）',null,null,22,20,17,null,48,45,40,'小时',26,1,'normal','main',0),
A40: 2752 | B40: null | C40: 1 | D40: 2026-04-28 00:00:00 | E40: 003101000090000-31010000902 | F40: 003101000090000-31010000902 | G40: 体感诱发电位术中监测 | H40: null | I40: null | J40: 22 | K40: 20 | L40: 17 | M40: null | N40: 48 | O40: 45 | P40: 40 | Q40: 小时 | R40: 26 | S40: 1 | T40: normal | U40: main | V40: 0 | W40: ="("&A40&","&B40&","&C40&",'"&D40&"','"&E40&"','"&F40&"','"&G40&"',"&H40&","&I40&","&J40&","&K40&","&L40&","&M40&","&N40&","&O40&","&P40&",'"&Q40&"',"&R40&","&S40&",'"&T40&"','"&U40&"',"&V40&")," -> (2752,null,1,'2026-04-28 00:00:00','003101000090000-31010000902','003101000090000-31010000902','体感诱发电位术中监测',null,null,22,20,17,null,48,45,40,'小时',26,1,'normal','main',0),
A41: 2753 | B41: null | C41: 1 | D41: 2026-04-28 00:00:00 | E41: 003302000000002-330202023 | F41: 003302000000002-330202023 | G41: 神经刺激器引导下神经定位 | H41: null | I41: null | J41: 100 | K41: 100 | L41: 85 | M41: null | N41: 48 | O41: 45 | P41: 40 | Q41: 半小时 | R41: 26 | S41: 1 | T41: normal | U41: main | V41: 0 | W41: ="("&A41&","&B41&","&C41&",'"&D41&"','"&E41&"','"&F41&"','"&G41&"',"&H41&","&I41&","&J41&","&K41&","&L41&","&M41&","&N41&","&O41&","&P41&",'"&Q41&"',"&R41&","&S41&",'"&T41&"','"&U41&"',"&V41&")," -> (2753,null,1,'2026-04-28 00:00:00','003302000000002-330202023','003302000000002-330202023','神经刺激器引导下神经定位',null,null,100,100,85,null,48,45,40,'半小时',26,1,'normal','main',0),
A42: 2754 | B42: null | C42: 1 | D42: 2026-04-28 00:00:00 | E42: 003101000250000-310100025 | F42: 003101000250000-310100025 | G42: 肌电图监测 | H42: null | I42: null | J42: 5.5 | K42: 5 | L42: 4.3 | M42: null | N42: 5 | O42: 4.8 | P42: 4.5 | Q42: 小时 | R42: 26 | S42: 1 | T42: normal | U42: main | V42: 0 | W42: ="("&A42&","&B42&","&C42&",'"&D42&"','"&E42&"','"&F42&"','"&G42&"',"&H42&","&I42&","&J42&","&K42&","&L42&","&M42&","&N42&","&O42&","&P42&",'"&Q42&"',"&R42&","&S42&",'"&T42&"','"&U42&"',"&V42&")," -> (2754,null,1,'2026-04-28 00:00:00','003101000250000-310100025','003101000250000-310100025','肌电图监测',null,null,5.5,5,4.3,null,5,4.8,4.5,'小时',26,1,'normal','main',0),
